Workbook

Sheet Assumptions
C1: Assumptions | E1: Source | F1: 2026 | G1: =F1+1 -> 2027 | H1: =G1+1 -> 2028 | I1: =H1+1 -> 2029 | J1: =I1+1 -> 2030 | K1: =J1+1 -> 2031 | L1: =K1+1 -> 2032 | M1: =L1+1 -> 2033 | N1: =M1+1 -> 2034 | ... AL1: =AK1+1 -> 2058
F2: 0 | G2: 1 | H2: 2 | I2: 3 | J2: 4 | K2: 5 | L2: 6 | M2: 7 | N2: 8 | O2: 9 | P2: 10 | Q2: 11 | R2: 12 | S2: 13 | T2: 14 | U2: 15 | V2: 16 | W2: 17 | X2: 18 | Y2: 19 | Z2: 20 | AA2: 21 | AB2: 22 | AC2: 23 | AD2: 24 | AE2: 25 | AF2: 26 | AG2: 27 | AH2: 28 | AI2: 29 | AJ2: 30
C3: Macro
C4: Inflation, EUR | D4: % | F4: 1 | G4: 1.01 | H4: =G4 -> 1.01 | I4: =H4 -> 1.01 | J4: =I4 -> 1.01 | K4: =J4 -> 1.01 | L4: =K4 -> 1.01 | M4: =L4 -> 1.01 | N4: =M4 -> 1.01 | O4: =N4 -> 1.01 | ... AL4: =AK4 -> 1.01
C5: Inflation, USD | F5: 1 | G5: 1.02 | H5: =G5 -> 1.02 | I5: =H5 -> 1.02 | J5: =I5 -> 1.02 | K5: =J5 -> 1.02 | L5: =K5 -> 1.02 | M5: =L5 -> 1.02 | N5: =M5 -> 1.02 | O5: =N5 -> 1.02 | ... AL5: =AK5 -> 1.02
C6: Inflation, Country | D6: % | F6: =F11 -> 0 | G6: 1.02 | H6: =G6 -> 1.02 | I6: =H6 -> 1.02 | J6: =I6 -> 1.02 | K6: =J6 -> 1.02 | L6: =K6 -> 1.02 | M6: =L6 -> 1.02 | N6: =M6 -> 1.02 | O6: =N6 -> 1.02 | ... AL6: =AK6 -> 1.02
C8: USD/EUR | F8: 1.04
C10: Tariff Indexation
C11: Electricity tariff indexation per year | D11: % | G11: 1 | H11: 1 | I11: =H11 -> 1 | J11: =I11 -> 1 | K11: =J11 -> 1 | L11: =K11 -> 1 | M11: =L11 -> 1 | N11: =M11 -> 1 | O11: =N11 -> 1 | P11: =O11 -> 1 | ... AL11: =AK11 -> 1
C12: Electricity tariff indexation per year Cumul | D12: % | G12: =G11 -> 1 | H12: =G12*H11 -> 1 | I12: =H12*I11 -> 1 | J12: =I12*J11 -> 1 | K12: =J12*K11 -> 1 | L12: =K12*L11 -> 1 | M12: =L12*M11 -> 1 | N12: =M12*N11 -> 1 | O12: =N12*O11 -> 1 | ... AL12: =AK12*AL11 -> 1
F13: CUF | G13: Fin output | H13: Curtailment | I13: Av.h per day | J13: Av. MWh per day
C14: Technical specifications | D14: CUF | E14: Output culc | F14: =IF((F15+F16+F17)>F15,F15,(F15+F16+F17)) -> 0.17639947 | G14: =F14*8760 -> 1545.2594 | H14: 0.2 | I14: =G14/365 -> 4.2335873 | J14: =14*I14 -> 59.270223
D15: Nominal CUF | F15: =(1568)/(8760) -> 0.17899543 | I15: =F15*24 -> 4.2958904
D16: Rejected CUF | F16: =-F15*H14 -> -0.035799087 | I16: =F16*24 -> -0.85917808
D17: ESS effect on CUF | F17: =I17/24 -> 0.033203125 | I17: =F22/F20*0.75 -> 0.796875
C18: Project start date (funding) | D18: DD/MM/YY | F18: 46082
C19: SPP COD | D19: DD/MM/YY | F19: 46388
C20: SPP Capacity | D20: MWp | F20: 3.2 | G20: =$F$20 -> 3.2 | H20: =$F$20 -> 3.2 | I20: =$F$20 -> 3.2 | J20: =$F$20 -> 3.2 | K20: =$F$20 -> 3.2 | L20: =$F$20 -> 3.2 | M20: =$F$20 -> 3.2 | N20: =$F$20 -> 3.2 | ... AL20: =$F$20 -> 3.2
C21: Nominal Storage capacity | D21: MWh | F21: 4
C22: Effective Storage capacity | D22: MWh | F22: =F21*0.85 -> 3.4
C23: Capacity (Invertors) | D23: MW | F23: 2.7 | G23: =$F$23 -> 2.7 | H23: =$F$23 -> 2.7 | I23: =$F$23 -> 2.7 | J23: =$F$23 -> 2.7 | K23: =$F$23 -> 2.7 | L23: =$F$23 -> 2.7 | M23: =$F$23 -> 2.7 | N23: =$F$23 -> 2.7 | ... AL23: =$F$23 -> 2.7
C24: Degradation | D24: % | G24: 0.004 | H24: 0.004 | I24: =$H$24 -> 0.004 | J24: =$H$24 -> 0.004 | K24: =$H$24 -> 0.004 | L24: =$H$24 -> 0.004 | M24: =$H$24 -> 0.004 | N24: =$H$24 -> 0.004 | O24: =$H$24 -> 0.004 | P24: =$H$24 -> 0.004 | ... AL24: =$H$24 -> 0.004
C25: Energy output | D25: MWh/year | G25: =F20*F14*8766 -> 4948.2169 | H25: =G25-$G$25*H24 -> 4928.424 | I25: =H25-$G$25*I24 -> 4908.6311 | J25: =I25-$G$25*J24 -> 4888.8383 | K25: =J25-$G$25*K24 -> 4869.0454 | L25: =K25-$G$25*L24 -> 4849.2525 | M25: =L25-$G$25*M24 -> 4829.4597 | N25: =M25-$G$25*N24 -> 4809.6668 | O25: =N25-$G$25*O24 -> 4789.8739 | ... AL25: =AK25-$G$25*AL24 -> 4334.638
G26: =G25 -> 4948.2169 | H26: =G26*0.996 -> 4928.424 | I26: =H26*0.996 -> 4908.7103 | J26: =I26*0.996 -> 4889.0755 | K26: =J26*0.996 -> 4869.5192 | L26: =K26*0.996 -> 4850.0411 | M26: =L26*0.996 -> 4830.6409 | N26: =M26*0.996 -> 4811.3184 | O26: =N26*0.996 -> 4792.0731 | ... AL26: =AK26*0.996 -> 4370.0682
C27: Losses and internal consumption of SPP | D27: % | E27: included in CUF | F27: 0 | G27: =$F$27 -> 0 | H27: =$F$27 -> 0 | I27: =$F$27 -> 0 | J27: =$F$27 -> 0 | K27: =$F$27 -> 0 | L27: =$F$27 -> 0 | M27: =$F$27 -> 0 | N27: =$F$27 -> 0 | ... AL27: =$F$27 -> 0
C29: PPA | G29: 160 | H29: =G29 -> 160 | I29: =H29 -> 160 | J29: =I29 -> 160 | K29: =J29 -> 160 | L29: =K29*L4 -> 161.6 | M29: =L29*M4 -> 163.216 | N29: =M29*N4 -> 164.84816 | O29: =N29*O4 -> 166.49664 | P29: =O29*P4 -> 168.16161 | Q29: =P29*Q4 -> 169.84322 | R29: =Q29*R4 -> 171.54166 | S29: =R29*S4 -> 173.25707 | ... AL29: =AK29*AL4 -> 209.31342
C30: PPA / Sales tenure | D30: years | G30: 1 | H30: 2 | I30: 3 | J30: 4 | K30: 5 | L30: 6 | M30: 7 | N30: 8 | O30: 9 | P30: 10 | Q30: 11 | R30: 12 | S30: 13 | T30: 14 | U30: 15 | V30: 16 | W30: 17 | X30: 18 | Y30: 19 | Z30: 20 | AA30: 21 | AB30: 22 | AC30: 23 | AD30: 24 | AE30: 25 | AF30: 26 | AG30: 27 | AH30: 28 | AI30: 29 | AJ30: 30
C31: Tariff rate | D31: USD/kWh | G31: =G29/1000 -> 0.16 | H31: =H29/1000 -> 0.16 | I31: =I29/1000 -> 0.16 | J31: =J29/1000 -> 0.16 | K31: =K29/1000 -> 0.16 | L31: =L29/1000 -> 0.1616 | M31: =M29/1000 -> 0.163216 | N31: =N29/1000 -> 0.16484816 | ... AE31: =AE29/1000 -> 0.19523041 | AF31: =AE31 -> 0.19523041 | AG31: =AF31 -> 0.19523041 | AH31: =AG31 -> 0.19523041 | AI31: =AH31 -> 0.19523041 | AJ31: =AI31 -> 0.19523041 | AK31: =AJ31 -> 0.19523041 | AL31: =AK31 -> 0.19523041
C32: GO price | D32: EUR/t | G32: 0 | H32: =G32*H6 -> 0 | I32: =H32*I6 -> 0 | J32: =I32*J6 -> 0 | K32: =J32*K6 -> 0 | L32: =K32*L6 -> 0 | M32: =L32*M6 -> 0 | N32: =M32*N6 -> 0 | O32: =N32*O6 -> 0 | ... AL32: =AK32*AL6 -> 0
C33: OPEX | D33: kEUR/MW | G33: =G34+G36+G37+G35 -> 29.875 | H33: =H34+H36+H37+H35 -> 29.7495 | I33: =I34+I36+I37+I35 -> 30.34449 | J33: =J34+J36+J37+J35 -> 30.95138 | K33: =K34+K36+K37+K35 -> 31.570407 | L33: =L34+L36+L37+L35 -> 32.201816 | M33: =M34+M36+M37+M35 -> 32.845852 | N33: =N34+N36+N37+N35 -> 33.502769 | ... AL33: =AL34+AL36+AL37+AL35 -> 53.887101
C34: O&M | D34: kEUR/MW | G34: 10 | H34: =H43/H20 -> 10.2 | I34: =I43/I20 -> 10.404 | J34: =J43/J20 -> 10.61208 | K34: =K43/K20 -> 10.824322 | L34: =L43/L20 -> 11.040808 | M34: =M43/M20 -> 11.261624 | N34: =N43/N20 -> 11.486857 | O34: =O43/O20 -> 11.716594 | ... AL34: =AL43/AL20 -> 18.475888
C35: Project management | G35: =G44/G20 -> 5 | H35: =H44/H20 -> 5.1 | I35: =I44/I20 -> 5.202 | J35: =J44/J20 -> 5.30604 | K35: =K44/K20 -> 5.4121608 | L35: =L44/L20 -> 5.520404 | M35: =M44/M20 -> 5.6308121 | N35: =N44/N20 -> 5.7434283 | ... AL35: =AL44/AL20 -> 9.2379441
C36: Lease payment | D36: kEUR/MW | G36: 9.9 | H36: =H46/H20 -> 9.375 | I36: =I46/I20 -> 9.5625 | J36: =J46/J20 -> 9.75375 | K36: =K46/K20 -> 9.948825 | L36: =L46/L20 -> 10.147802 | M36: =M46/M20 -> 10.350758 | N36: =N46/N20 -> 10.557773 | O36: =O46/O20 -> 10.768928 | ... AL36: =AL46/AL20 -> 16.981515
C37: Equipment insurance | D37: kEUR/MW | G37: =G45/G20 -> 4.975 | H37: =H45/H20 -> 5.0745 | I37: =I45/I20 -> 5.17599 | J37: =J45/J20 -> 5.2795098 | K37: =K45/K20 -> 5.3851 | L37: =L45/L20 -> 5.492802 | M37: =M45/M20 -> 5.602658 | N37: =N45/N20 -> 5.7147112 | ... AL37: =AL45/AL20 -> 9.1917544
C39: O&M Indexation | F39: 1 | G39: =G6 -> 1.02 | H39: =$G$39 -> 1.02 | I39: =$G$39 -> 1.02 | J39: =$G$39 -> 1.02 | K39: =$G$39 -> 1.02 | L39: =$G$39 -> 1.02 | M39: =$G$39 -> 1.02 | N39: =$G$39 -> 1.02 | O39: =$G$39 -> 1.02 | ... AL39: =$G$39 -> 1.02
C40: Lease payment Indexation | G40: 1 | H40: =G40 -> 1 | I40: =H40 -> 1 | J40: =I40 -> 1 | K40: =J40 -> 1 | L40: =K40 -> 1 | M40: =L40 -> 1 | N40: =M40 -> 1 | O40: =N40 -> 1 | ... AL40: =AK40 -> 1
G41: =G1 -> 2027 | H41: =H1 -> 2028 | I41: =I1 -> 2029 | J41: =J1 -> 2030 | K41: =K1 -> 2031 | L41: =L1 -> 2032 | M41: =M1 -> 2033 | N41: =N1 -> 2034 | ... AL41: =AL1 -> 2058
C42: Total OPEX | D42: kEUR/Year | G42: =G43+G46+G45+G44 -> 93.92 | H42: =H43+H46+H45+H44 -> 95.1984 | I42: =I43+I46+I45+I44 -> 97.102368 | J42: =J43+J46+J45+J44 -> 99.044415 | K42: =K43+K46+K45+K44 -> 101.0253 | L42: =L43+L46+L45+L44 -> 103.04581 | M42: =M43+M46+M45+M44 -> 105.10673 | N42: =N43+N46+N45+N44 -> 107.20886 | ... AL42: =AL43+AL46+AL45+AL44 -> 172.43872
C43: O&M | D43: kEUR/Year | G43: =$G$34*G20 -> 32 | H43: =G43*H39 -> 32.64 | I43: =H43*I39 -> 33.2928 | J43: =I43*J39 -> 33.958656 | K43: =J43*K39 -> 34.637829 | L43: =K43*L39 -> 35.330586 | M43: =L43*M39 -> 36.037197 | N43: =M43*N39 -> 36.757941 | O43: =N43*O39 -> 37.4931 | ... AL43: =AK43*AL39 -> 59.122842
C44: Project management | D44: kEUR/Year | E44: 5 | G44: =$E44*G20 -> 16 | H44: =G44*H6 -> 16.32 | I44: =H44*I6 -> 16.6464 | J44: =I44*J6 -> 16.979328 | K44: =J44*K6 -> 17.318915 | L44: =K44*L6 -> 17.665293 | M44: =L44*M6 -> 18.018599 | N44: =M44*N6 -> 18.378971 | O44: =N44*O6 -> 18.74655 | ... AL44: =AK44*AL6 -> 29.561421
...

Sheet Depr
C1: Depreciation
E2: =Assumptions!F1 -> 2026 | F2: =Assumptions!G1 -> 2027 | G2: =Assumptions!H1 -> 2028 | H2: =Assumptions!I1 -> 2029 | I2: =Assumptions!J1 -> 2030 | J2: =Assumptions!K1 -> 2031 | K2: =Assumptions!L1 -> 2032 | L2: =Assumptions!M1 -> 2033 | ... AI2: =Assumptions!AJ1 -> 2056
E3: 0 | F3: 1 | G3: 2 | H3: 3 | I3: 4 | J3: 5 | K3: 6 | L3: 7 | M3: 8 | N3: 9 | O3: 10 | P3: 11 | Q3: 12 | R3: 13 | S3: 14 | T3: 15 | U3: 16 | V3: 17 | W3: 18 | X3: 19 | Y3: 20 | Z3: 21 | AA3: 22 | AB3: 23 | AC3: 24 | AD3: 25 | AE3: 26 | AF3: 27 | AG3: 28 | AH3: 29 | AI3: 30
C5: CAPEX (no VAT) | D5: kEUR | E5: =E7 -> 3184
C6: Development cost | E6: =Assumptions!H66 -> 1600
C7: Solar Power Plant | D7: kEUR | E7: =Assumptions!G77 -> 3184
C9: Fixed assets
C10: Input of fixed assets | D10: kEUR | E10: =SUM(E11:E12) -> 0 | F10: =SUM(F11:F12) -> 4784 | G10: =SUM(G11:G12) -> 0 | H10: =SUM(H11:H12) -> 0 | I10: =SUM(I11:I12) -> 0 | J10: =SUM(J11:J12) -> 0 | K10: =SUM(K11:K12) -> 0 | L10: =SUM(L11:L12) -> 0 | ... AI10: =SUM(AI11:AI12) -> 0
C11: Immovables | D11: kEUR | F11: =(E5+E6)*100% -> 4784
C12: Movables | D12: kEUR | F12: =(E5+E6)-F11 -> 0
C13: Depreciation | D13: kEUR | E13: =SUM(E14:E15) -> 0 | F13: =SUM(F14:F15) -> -478.4 | G13: =SUM(G14:G15) -> -478.4 | H13: =SUM(H14:H15) -> -478.4 | I13: =SUM(I14:I15) -> -478.4 | J13: =SUM(J14:J15) -> -478.4 | K13: =SUM(K14:K15) -> -478.4 | L13: =SUM(L14:L15) -> -478.4 | ... AI13: =SUM(AI14:AI15) -> 0
C14: Immovables | D14: kEUR | E14: =-$E$11/Assumptions!$F$63/12 -> 0 | F14: =-$F$11/Assumptions!$F$63 -> -478.4 | G14: =-$F$11/Assumptions!$F$63 -> -478.4 | H14: =-$F$11/Assumptions!$F$63 -> -478.4 | I14: =-$F$11/Assumptions!$F$63 -> -478.4 | J14: =-$F$11/Assumptions!$F$63 -> -478.4 | K14: =-$F$11/Assumptions!$F$63 -> -478.4 | L14: =-$F$11/Assumptions!$F$63 -> -478.4 | M14: =-$F$11/Assumptions!$F$63 -> -478.4 | ... O14: =-$F$11/Assumptions!$F$63 -> -478.4
C15: Movables | D15: kEUR | E15: =-$E$12/Assumptions!$F$63/12 -> 0 | F15: =-$F$12/Assumptions!$F$63 -> 0 | G15: =-$F$12/Assumptions!$F$63 -> 0 | H15: =-$F$12/Assumptions!$F$63 -> 0 | I15: =-$F$12/Assumptions!$F$63 -> 0 | J15: =-$F$12/Assumptions!$F$63 -> 0 | K15: =-$F$12/Assumptions!$F$63 -> 0 | L15: =-$F$12/Assumptions!$F$63 -> 0 | M15: =-$F$12/Assumptions!$F$63 -> 0 | ... T15: =-$F$12/Assumptions!$F$63 -> 0
C16: residual value | D16: kEUR | E16: =SUM(E17:E18) -> 0 | F16: =SUM(F17:F18) -> 4305.6 | G16: =SUM(G17:G18) -> 3827.2 | H16: =SUM(H17:H18) -> 3348.8 | I16: =SUM(I17:I18) -> 2870.4 | J16: =SUM(J17:J18) -> 2392 | K16: =SUM(K17:K18) -> 1913.6 | L16: =SUM(L17:L18) -> 1435.2 | ... AI16: =SUM(AI17:AI18) -> 0
C17: Immovables | D17: kEUR | E17: =E11+E14 -> 0 | F17: =E17+F11+F14 -> 4305.6 | G17: =F17+G11+G14 -> 3827.2 | H17: =G17+H11+H14 -> 3348.8 | I17: =H17+I11+I14 -> 2870.4 | J17: =I17+J11+J14 -> 2392 | K17: =J17+K11+K14 -> 1913.6 | L17: =K17+L11+L14 -> 1435.2 | M17: =L17+M11+M14 -> 956.8 | ... AI17: =AH17+AI11+AI14 -> 0
C18: Movables | D18: kEUR | E18: =E12+E15 -> 0 | F18: =E18+F12+F15 -> 0 | G18: =F18+G12+G15 -> 0 | H18: =G18+H12+H15 -> 0 | I18: =H18+I12+I15 -> 0 | J18: =I18+J12+J15 -> 0 | K18: =J18+K12+K15 -> 0 | L18: =K18+L12+L15 -> 0 | M18: =L18+M12+M15 -> 0 | ... AI18: =AH18+AI12+AI15 -> 0
C20: Property tax | D20: kEUR | E20: =-(E21)*Assumptions!F59 -> 0 | F20: =-(F21)*Assumptions!G59 -> 0 | G20: =-(G21)*Assumptions!H59 -> 0 | H20: =-(H21)*Assumptions!I59 -> 0 | I20: =-(I21)*Assumptions!J59 -> 0 | J20: =-(J21)*Assumptions!K59 -> 0 | K20: =-(K21)*Assumptions!L59 -> 0 | L20: =-(L21)*Assumptions!M59 -> 0 | ... AI20: =-(AI21)*Assumptions!AJ59 -> 0
C21: Tax base for real estate tax | D21: kEUR | E21: =(E11+E17)/12 -> 0 | F21: =(E17+F17) -> 4305.6 | G21: =(F17+G17)/2 -> 4066.4 | H21: =(G17+H17)/2 -> 3588 | I21: =(H17+I17)/2 -> 3109.6 | J21: =(I17+J17)/2 -> 2631.2 | K21: =(J17+K17)/2 -> 2152.8 | L21: =(K17+L17)/2 -> 1674.4 | M21: =(L17+M17)/2 -> 1196 | N21: =(M17+N17)/2 -> 717.6 | ... AI21: =(AH17+AI17)/2 -> 0
C24: Check (CAPEX Eur/Watt) | D24: =(E5+E6)/Assumptions!F20/1000 -> 1.495
C25: VAT, EUR | D25: =E5*Assumptions!$F$61 -> 0

Sheet Rep.forms_Financing
C1: P&L
E2: Total | F2: =Assumptions!F1 -> 2026 | G2: =Assumptions!G1 -> 2027 | H2: =Assumptions!H1 -> 2028 | I2: =Assumptions!I1 -> 2029 | J2: =Assumptions!J1 -> 2030 | K2: =Assumptions!K1 -> 2031 | L2: =Assumptions!L1 -> 2032 | M2: =Assumptions!M1 -> 2033 | ... AJ2: =Assumptions!AJ1 -> 2056
F3: 0 | G3: 1 | H3: 2 | I3: 3 | J3: 4 | K3: 5 | L3: 6 | M3: 7 | N3: 8 | O3: 9 | P3: 10 | Q3: 11 | R3: 12 | S3: 13 | T3: 14 | U3: 15 | V3: 16 | W3: 17 | X3: 18 | Y3: 19 | Z3: 20 | AA3: 21 | AB3: 22 | AC3: 23 | AD3: 24 | AE3: 25 | AF3: 26 | AG3: 27 | AH3: 28 | AI3: 29 | AJ3: 30
C5: Revenue | D5: kEUR | E5: =SUM(F5:V5) -> 12802.465 | F5: =F6*F7+F8 -> 0 | G5: =G6*G7+G8 -> 791.7147 | H5: =H6*H7+H8 -> 788.54784 | I5: =I6*I7+I8 -> 785.38098 | J5: =J6*J7+J8 -> 782.21412 | K5: =K6*K7+K8 -> 779.04726 | L5: =L6*L7+L8 -> 783.63921 | M5: =M6*M7+M8 -> 788.24509 | ... AJ5: =AJ6*AJ7+AJ8 -> 853.98147
C6: Energy Output | D6: MWh | E6: =SUM(F6:V6) -> 76796.326 | F6: 0 | G6: =Assumptions!G25 -> 4948.2169 | H6: =Assumptions!H25 -> 4928.424 | I6: =Assumptions!I25 -> 4908.6311 | J6: =Assumptions!J25 -> 4888.8383 | K6: =Assumptions!K25 -> 4869.0454 | L6: =Assumptions!L25 -> 4849.2525 | M6: =Assumptions!M25 -> 4829.4597 | N6: =Assumptions!N25 -> 4809.6668 | ... AJ6: =Assumptions!AJ25 -> 4374.2237
C7: Energy tariff | D7: =Assumptions!D31 -> USD/kWh | G7: =Assumptions!G31 -> 0.16 | H7: =Assumptions!H31 -> 0.16 | I7: =Assumptions!I31 -> 0.16 | J7: =Assumptions!J31 -> 0.16 | K7: =Assumptions!K31 -> 0.16 | L7: =Assumptions!L31 -> 0.1616 | M7: =Assumptions!M31 -> 0.163216 | N7: =Assumptions!N31 -> 0.16484816 | ... AJ7: =Assumptions!AJ31 -> 0.19523041
C8: GO Revenue | D8: kEUR | E8: =SUM(F8:V8) -> 0 | G8: =Assumptions!G32*Assumptions!G25/1000 -> 0 | H8: =Assumptions!H32*Assumptions!H25/1000 -> 0 | I8: =Assumptions!I32*Assumptions!I25/1000 -> 0 | J8: =Assumptions!J32*Assumptions!J25/1000 -> 0 | K8: =Assumptions!K32*Assumptions!K25/1000 -> 0 | L8: =Assumptions!L32*Assumptions!L25/1000 -> 0 | M8: =Assumptions!M32*Assumptions!M25/1000 -> 0 | N8: =Assumptions!N32*Assumptions!N25/1000 -> 0 | ... AJ8: =Assumptions!AJ32*Assumptions!AJ25/1000 -> 0
C10: OPEX | D10: kEUR | E10: =SUM(F10:V10) -> -1740.2256 | F10: =SUM(F11:F12) -> 0 | G10: =SUM(G11:G12) -> -93.92 | H10: =SUM(H11:H12) -> -95.1984 | I10: =SUM(I11:I12) -> -97.102368 | J10: =SUM(J11:J12) -> -99.044415 | K10: =SUM(K11:K12) -> -101.0253 | L10: =SUM(L11:L12) -> -103.04581 | M10: =SUM(M11:M12) -> -105.10673 | ... AJ10: =SUM(AJ11:AJ12) -> -165.74272
C11: OPEX | F11: 0 | G11: =-Assumptions!G42 -> -93.92 | H11: =-Assumptions!H42 -> -95.1984 | I11: =-Assumptions!I42 -> -97.102368 | J11: =-Assumptions!J42 -> -99.044415 | K11: =-Assumptions!K42 -> -101.0253 | L11: =-Assumptions!L42 -> -103.04581 | M11: =-Assumptions!M42 -> -105.10673 | N11: =-Assumptions!N42 -> -107.20886 | ... AJ11: =-Assumptions!AJ42 -> -165.74272
C12: Property tax | F12: =Depr!E20 -> 0 | G12: =Depr!F20 -> 0 | H12: =Depr!G20 -> 0 | I12: =Depr!H20 -> 0 | J12: =Depr!I20 -> 0 | K12: =Depr!J20 -> 0 | L12: =Depr!K20 -> 0 | M12: =Depr!L20 -> 0 | ... AJ12: =Depr!AI20 -> 0
C14: EBITDA | D14: kEUR | E14: =SUM(F14:V14) -> 11062.24 | F14: =F5+F10 -> 0 | G14: =G5+G10 -> 697.7947 | H14: =H5+H10 -> 693.34944 | I14: =I5+I10 -> 688.27861 | J14: =J5+J10 -> 683.16971 | K14: =K5+K10 -> 678.02196 | L14: =L5+L10 -> 680.5934 | M14: =M5+M10 -> 683.13836 | ... AJ14: =AJ5+AJ10 -> 688.23875
C15: Depreciation | D15: kEUR | E15: =SUM(F15:V15) -> -4784 | F15: =Depr!E13 -> 0 | G15: =Depr!F13 -> -478.4 | H15: =Depr!G13 -> -478.4 | I15: =Depr!H13 -> -478.4 | J15: =Depr!I13 -> -478.4 | K15: =Depr!J13 -> -478.4 | L15: =Depr!K13 -> -478.4 | M15: =Depr!L13 -> -478.4 | ... AJ15: =Depr!AI13 -> 0
C17: EBIT | D17: kEUR | E17: =SUM(F17:V17) -> 6278.2397 | F17: =F14+F15 -> 0 | G17: =G14+G15 -> 219.3947 | H17: =H14+H15 -> 214.94944 | I17: =I14+I15 -> 209.87861 | J17: =J14+J15 -> 204.76971 | K17: =K14+K15 -> 199.62196 | L17: =L14+L15 -> 202.1934 | M17: =M14+M15 -> 204.73836 | ... AJ17: =AJ14+AJ15 -> 688.23875
C18: Interests payable | D18: kEUR | E18: =SUM(F18:V18) -> -889.80749 | F18: =F40 -> -37.226667 | G18: =G40 -> -108.62728 | H18: =H40 -> -102.39975 | I18: =I40 -> -95.923104 | J18: =J40 -> -89.187397 | K18: =K40 -> -82.182262 | L18: =L40 -> -74.896922 | M18: =M40 -> -67.320168 | ... AJ18: =AJ40 -> 0
C19: Bank commissions | D19: kEUR | E19: =SUM(F19:V19) -> 0 | F19: =F41 -> 0 | G19: =G41 -> 0 | H19: =H41 -> 0 | I19: =I41 -> 0 | J19: =J41 -> 0 | K19: =K41 -> 0 | L19: =L41 -> 0 | M19: =M41 -> 0 | ... AJ19: =AJ41 -> 0
C20: Exchange rate differences | D20: kEUR | E20: =SUM(F20:V20) -> 0
C22: EBT | D22: kEUR | E22: =SUM(F22:V22) -> 5388.4322 | F22: =F17+F18+F19+F20 -> -37.226667 | G22: =G17+G18+G19+G20 -> 110.76741 | H22: =H17+H18+H19+H20 -> 112.5497 | I22: =I17+I18+I19+I20 -> 113.95551 | J22: =J17+J18+J19+J20 -> 115.58231 | K22: =K17+K18+K19+K20 -> 117.4397 | L22: =L17+L18+L19+L20 -> 127.29648 | M22: =M17+M18+M19+M20 -> 137.4182 | ... AJ22: =AJ17+AJ18+AJ19+AJ20 -> 688.23875
C23: Nat int on capital | D23: 7% | E23: =SUM(F23:V23) -> -2272.7339 | G23: =-D23*F69 -> -142.04587 | H23: =G23 -> -142.04587 | I23: =H23 -> -142.04587 | J23: =I23 -> -142.04587 | K23: =J23 -> -142.04587 | L23: =K23 -> -142.04587 | M23: =L23 -> -142.04587 | N23: =M23 -> -142.04587 | O23: =N23 -> -142.04587 | ... AJ23: =AI23 -> -142.04587
C24: Corporate Tax | D24: kEUR | E24: =SUM(F24:V24) -> -394.11563 | F24: =IF(F22>0,-F22*Assumptions!F60,0) -> 0 | G24: =IF(G22>0,-(G22+G23)*Assumptions!G60,0) -> 3.9098065 | H24: =IF(H22>0,-(H22+H23)*Assumptions!H60,0) -> 3.6870214 | I24: =IF(I22>0,-(I22+I23)*Assumptions!I60,0) -> 3.5112946 | J24: =IF(J22>0,-(J22+J23)*Assumptions!J60,0) -> 3.3079445 | K24: =IF(K22>0,-(K22+K23)*Assumptions!K60,0) -> 3.0757711 | L24: =IF(L22>0,-(L22+L23)*Assumptions!L60,0) -> 1.8436736 | M24: =IF(M22>0,-(M22+M23)*Assumptions!M60,0) -> 0.57845895 | N24: =IF(N22>0,-(N22+N23)*Assumptions!N60,0) -> -0.7212064 | ... AJ24: =IF(AJ22>0,-(AJ22+AJ23)*Assumptions!AJ60,0) -> -68.274111
C26: Net profit (loss) | D26: kEUR | E26: =SUM(F26:V26) -> 4994.3166 | F26: =F22+F24 -> -37.226667 | G26: =G22+G24 -> 114.67722 | H26: =H22+H24 -> 116.23672 | I26: =I22+I24 -> 117.4668 | J26: =J22+J24 -> 118.89025 | K26: =K22+K24 -> 120.51547 | L26: =L22+L24 -> 129.14015 | M26: =M22+M24 -> 137.99665 | ... AJ26: =AJ22+AJ24 -> 619.96464
C29: Debt | D29: Loan tenure | F29: 1 | G29: 2 | H29: 3 | I29: 4 | J29: 5 | K29: 6 | L29: 7 | M29: 8 | N29: 9 | O29: 10 | P29: 11 | Q29: 12 | R29: 13 | S29: 14 | T29: 15 | U29: 16 | V29: 17 | W29: 18 | X29: 19 | Y29: 20 | Z29: 21 | AA29: 22 | AB29: 23 | AC29: 24 | AD29: 25 | AE29: 26 | AF29: 27 | AG29: 28 | AH29: 29 | AI29: 30 | AJ29: 31
D30: Repayment, years | G30: 1 | H30: 2 | I30: 3 | J30: 4 | K30: 5 | L30: 6 | M30: 7 | N30: 8 | O30: 9 | P30: 10 | Q30: 11 | R30: 12 | S30: 13 | T30: 14 | U30: 15 | V30: 16 | W30: 17 | X30: 18 | Y30: 19 | Z30: 20 | AA30: 21 | AB30: 22 | AC30: 23 | AD30: 24 | AE30: 25 | AF30: 26 | AG30: 27 | AH30: 28 | AI30: 29 | AJ30: 29
C32: Bank loan
C33: Opening balance | D33: kEUR | F33: 0 | G33: =F37 -> 2792 | H33: =G37 -> 2639.3642 | I33: =H37 -> 2480.623 | J33: =I37 -> 2315.5322 | K33: =J37 -> 2143.8377 | L33: =K37 -> 1965.2754 | M33: =L37 -> 1779.5707 | N33: =M37 -> 1586.4377 | ... Q33: =P37 -> 959.43856 | R33: =Q33+Q34+Q36 -> 733.50033 | S33: =R33+R34+R36 -> 498.52457 | T33: =S33+S34+S36 -> 254.14978 | U33: =T33+T34+T36 -> 0 | V33: =U33+U34+U36 -> 0 | W33: =V33+V34+V36 -> 0 | X33: =W33+W34+W36 -> 0 | Y33: =X33+X34+X36 -> 0 | ... AI33: =AH33+AH34+AH36 -> 0
C34: Receipt of credit | D34: kEUR | E34: =SUM(F34:AI34) -> 2792 | F34: =Assumptions!F53*Assumptions!F20*(1+Assumptions!F61) -> 2792 | G34: 0
C35: Bank VAT | D35: kEUR | E35: =SUM(F35:AI35) -> 0 | G35: =-G65*$D46 -> 0 | H35: =-H65*$D46 -> 0 | I35: =-I65*$D46 -> 0 | J35: =-J65*$D46 -> 0 | K35: =-K65*$D46 -> 0 | L35: =-L65*$D46 -> 0 | M35: =-M65*$D46 -> 0
C36: Repayment of credit | D36: kEUR | E36: =SUM(F36:AI36) -> -2792 | F36: 0 | G36: =IF(G30>$D$45-1,0,PPMT($D$44,G30,$D$45-1,$G$33)+G35) -> -152.63577 | H36: =IF(H30>$D$45-1,0,PPMT($D$44,H30,$D$45-1,$G$33)+H35) -> -158.7412 | I36: =IF(I30>$D$45-1,0,PPMT($D$44,I30,$D$45-1,$G$33)+I35) -> -165.09085 | J36: =IF(J30>$D$45-1,0,PPMT($D$44,J30,$D$45-1,$G$33)+J35) -> -171.69449 | K36: =IF(K30>$D$45-1,0,PPMT($D$44,K30,$D$45-1,$G$33)+K35) -> -178.56227 | L36: =IF(L30>$D$45-1,0,PPMT($D$44,L30,$D$45-1,$G$33)+L35) -> -185.70476 | M36: =IF(M30>$D$45-1,0,PPMT($D$44,M30,$D$45-1,$G$33)+M35) -> -193.13295 | N36: =IF(N30>$D$45-1,0,PPMT($D$44,N30,$D$45-1,$G$33)+N35) -> -200.85826 | ... AI36: =IF(AI30>$D$45-1,0,PPMT($D$44,AI30,$D$45-1,$G$33)+AI35) -> 0
C37: Closing balance | D37: kEUR | F37: =F33+F34+F36 -> 2792 | G37: =G33+G34+G36 -> 2639.3642 | H37: =H33+H34+H36 -> 2480.623 | I37: =I33+I34+I36 -> 2315.5322 | J37: =J33+J34+J36 -> 2143.8377 | K37: =K33+K34+K36 -> 1965.2754 | L37: =L33+L34+L36 -> 1779.5707 | M37: =M33+M34+M36 -> 1586.4377 | ... AI37: =AI33+AI34+AI36 -> 0
C39: Interests accrued | D39: kEUR | F39: =-(F33+F37)*$D$44/3 -> -37.226667 | G39: =-(G33+G37)/2*$D$44 -> -108.62728 | H39: =-(H33+H37)/2*$D$44 -> -102.39975 | I39: =-(I33+I37)/2*$D$44 -> -95.923104 | J39: =-(J33+J37)/2*$D$44 -> -89.187397 | K39: =-(K33+K37)/2*$D$44 -> -82.182262 | L39: =-(L33+L37)/2*$D$44 -> -74.896922 | M39: =-(M33+M37)/2*$D$44 -> -67.320168 | N39: =-(N33+N37)/2*$D$44 -> -59.440343 | ... AI39: =-(AI33+AI37)/2*$D$44 -> 0
C40: Interests payable | D40: kEUR | F40: =F39 -> -37.226667 | G40: =G39 -> -108.62728 | H40: =H39 -> -102.39975 | I40: =I39 -> -95.923104 | J40: =J39 -> -89.187397 | K40: =K39 -> -82.182262 | L40: =L39 -> -74.896922 | M40: =M39 -> -67.320168 | ... AI40: =AI39 -> 0
C41: Commissions | D41: kEUR | F41: 0
C42: Аннуитет | G42: =SUM(G36+G39) -> -261.26306 | H42: =SUM(H36+H39) -> -261.14095 | I42: =SUM(I36+I39) -> -261.01396 | J42: =SUM(J36+J39) -> -260.88188 | K42: =SUM(K36+K39) -> -260.74453 | L42: =SUM(L36+L39) -> -260.60168 | M42: =SUM(M36+M39) -> -260.45311 | N42: =SUM(N36+N39) -> -260.29861 | ... T42: =SUM(T36+T39) -> -259.23278
C43: Debt share | D43: =Assumptions!F51 -> 0.57910573 | E43: =E34/4.9 -> 569.79592
C44: Rate | D44: =Assumptions!F52 -> 0.04
C45: Loan term | D45: =Assumptions!F54 -> 15
C46: VAT to bank | D46: 0
C47: DSCR | D47: average | E47: =AVERAGEIF(G51:AI51,"1",G47:AI47) -> 2.5793536 | F47: =F48/F49 -> -128.51003 | G47: =G48/G49 -> 2.685816 | H47: =H48/H49 -> 2.6691963 | I47: =I48/I49 -> 2.6503943 | J47: =J48/J49 -> 2.6313734 | K47: =K48/K49 -> 2.6121267 | L47: =L48/L49 -> 2.6186979 | M47: =M48/M49 -> 2.6251052 | ... AI47: =AI48/AI49 -> #DIV/0!
C48: CFADS | F48: =F14+F24+F63 -> -4784 | G48: =G14+G24+G63-G65*(100%-D46) -> 701.70451 | H48: =H14+H24+H63 -> 697.03646 | I48: =I14+I24+I63 -> 691.78991 | J48: =J14+J24+J63 -> 686.47765 | K48: =K14+K24+K63 -> 681.09773 | L48: =L14+L24+L63 -> 682.43707 | M48: =M14+M24+M63 -> 683.71682 | N48: =N14+N24+N63 -> 684.93465 | O48: =O14+O24+O63 -> 686.08817 | ... AJ48: =AJ14+AJ24+AJ63 -> 619.96464
C49: DEBT SERVICE | F49: =-F36-F39 -> 37.226667 | G49: =-G36-G39 -> 261.26306 | H49: =-H36-H39 -> 261.14095 | I49: =-I36-I39 -> 261.01396 | J49: =-J36-J39 -> 260.88188 | K49: =-K36-K39 -> 260.74453 | L49: =-L36-L39 -> 260.60168 | M49: =-M36-M39 -> 260.45311 | ... AJ49: =-AJ36-AJ39 -> 0
C50: DEBT/EBITDA | F50: =F37/F14 -> #DIV/0! | G50: =G37/G14 -> 3.7824366 | H50: =H37/H14 -> 3.5777386 | I50: =I37/I14 -> 3.3642367 | J50: =J37/J14 -> 3.1380749 | K50: =K37/K14 -> 2.8985424 | L50: =L37/L14 -> 2.6147339 | M50: =M37/M14 -> 2.3222788 | ... AJ50: =AJ37/AJ14 -> 0
...

Sheet PPI
C1: PPI | E1: Operation | F1: =Assumptions!F18 -> 46082 | G1: 1 | H1: 2 | I1: 3 | J1: 4 | K1: 5 | L1: 6 | M1: 7 | N1: 8 | O1: 9 | P1: 10 | Q1: 11 | R1: 12 | S1: 13 | T1: 14 | U1: 15 | V1: 16 | W1: 17 | X1: 18 | Y1: 19 | Z1: 20 | AA1: 21 | AB1: 22 | AC1: 23 | AD1: 24 | AE1: 25 | AF1: 26 | AG1: 27 | AH1: 28 | AI1: 29 | AJ1: 30
E2: Total | F2: =Assumptions!F1 -> 2026 | G2: =Assumptions!G1 -> 2027 | H2: =Assumptions!H1 -> 2028 | I2: =Assumptions!I1 -> 2029 | J2: =Assumptions!J1 -> 2030 | K2: =Assumptions!K1 -> 2031 | L2: =Assumptions!L1 -> 2032 | M2: =Assumptions!M1 -> 2033 | ... AJ2: =Assumptions!AJ1 -> 2056
F3: 0 | G3: 1 | H3: 2 | I3: 3 | J3: 4 | K3: 5 | L3: 6 | M3: 7 | N3: 8 | O3: 9 | P3: 10 | Q3: 11 | R3: 12 | S3: 13 | T3: 14 | U3: 15 | V3: 16 | W3: 17 | X3: 18 | Y3: 19 | Z3: 20 | AA3: 21 | AB3: 22 | AC3: 23 | AD3: 24 | AE3: 25 | AF3: 26 | AG3: 27 | AH3: 28 | AI3: 29 | AJ3: 30
C4: FCFF
C5: FCFF | D5: kEUR | E5: =SUM(F5:V5) -> 5031.5433 | F5: ='Rep.forms_Financing'!F57+'Rep.forms_Financing'!F60+'Rep.forms_Financing'!F61+'Rep.forms_Financing'!F63 -> -4784 | G5: ='Rep.forms_Financing'!G56+'Rep.forms_Financing'!G63 -> 593.07722 | H5: ='Rep.forms_Financing'!H56+'Rep.forms_Financing'!H63 -> 594.63672 | I5: ='Rep.forms_Financing'!I56+'Rep.forms_Financing'!I63 -> 595.8668 | J5: ='Rep.forms_Financing'!J56+'Rep.forms_Financing'!J63 -> 597.29025 | K5: ='Rep.forms_Financing'!K56+'Rep.forms_Financing'!K63 -> 598.91547 | L5: ='Rep.forms_Financing'!L56+'Rep.forms_Financing'!L63 -> 607.54015 | M5: ='Rep.forms_Financing'!M56+'Rep.forms_Financing'!M63 -> 616.39665 | N5: ='Rep.forms_Financing'!N56+'Rep.forms_Financing'!N63 -> 625.49431 | ... AJ5: ='Rep.forms_Financing'!AJ56+'Rep.forms_Financing'!AJ63 -> 619.96464
C6: FCFF Cumulatively | D6: kEUR | E6: =V6 -> 5031.5433 | F6: =F5 -> -4784 | G6: =F6+G5 -> -4190.9228 | H6: =G6+H5 -> -3596.2861 | I6: =H6+I5 -> -3000.4193 | J6: =I6+J5 -> -2403.129 | K6: =J6+K5 -> -1804.2135 | L6: =K6+L5 -> -1196.6734 | M6: =L6+M5 -> -580.27673 | N6: =M6+N5 -> 45.217583 | ... AJ6: =AI6+AJ5 -> 13985.442
C7: DFCFF | D7: kEUR | E7: =SUM(F7:U7) -> 735.17771 | F7: =F5/POWER(1+$E$10,F3) -> -4784 | G7: =G5/POWER(1+$E$10,G3) -> 553.87608 | H7: =H5/POWER(1+$E$10,H3) -> 518.6262 | I7: =I5/POWER(1+$E$10,I3) -> 485.34805 | J7: =J5/POWER(1+$E$10,J3) -> 454.35038 | K7: =K5/POWER(1+$E$10,K3) -> 425.47335 | L7: =L5/POWER(1+$E$10,L3) -> 403.07251 | M7: =M5/POWER(1+$E$10,M3) -> 381.91774 | ... AJ7: =AJ5/POWER(1+$E$10,AJ3) -> 79.69075
C8: DFCFF Cumulatively | D8: kEUR | E8: =V8 -> 947.57653 | F8: =F7 -> -4784 | G8: =F8+G7 -> -4230.1239 | H8: =G8+H7 -> -3711.4977 | I8: =H8+I7 -> -3226.1497 | J8: =I8+J7 -> -2771.7993 | K8: =J8+K7 -> -2346.3259 | L8: =K8+L7 -> -1943.2534 | M8: =L8+M7 -> -1561.3357 | N8: =M8+N7 -> -1199.3976 | ... AJ8: =AI8+AJ7 -> 2813.9394
E9: 30 years | F9: 15 years
C10: WACC | D10: % | E10: =E22*Assumptions!F50+(Assumptions!F52*Assumptions!F51)*(1-Assumptions!F60) -> 0.070776013
C11: NPV | D11: kEUR | E11: =NPV(E10,F5:AJ5) -> 2627.944
C12: IRR project | D12: % | E12: =IRR(F5:AJ5) -> 0.12401301 | F12: =IRR(F5:U5) -> 0.094106161
C13: PB | D13: years | E13: =MATCH(0,F6:AJ6,1)-OFFSET(F6,0,MATCH(0,F6:AJ6,1)-1)/OFFSET(F5,0,MATCH(0,F6:AJ6,1))-((MONTH($F$1)-1)/12) -> 8.7610424
C14: DPB | D14: years | E14: =IF(E11<0,0,MATCH(0,F8:AJ8,1)-OFFSET(F8,0,MATCH(0,F8:AJ8,1)-1)/OFFSET(F7,0,MATCH(0,F8:AJ8,1))-((MONTH($F$1)-1)/12)) -> 12.775882
C16: FCFE for Investor
C17: FCFE | D17: kEUR | E17: =SUM(F17:AE17) -> 13578.696 | F17: ='Rep.forms_Financing'!F74-'Rep.forms_Financing'!F69-'Rep.forms_Financing'!F70+Assumptions!G76*0 -> -2029.2267 | G17: =G5 -> 593.07722 | H17: =H5 -> 594.63672 | I17: =I5 -> 595.8668 | J17: =J5 -> 597.29025 | K17: =K5 -> 598.91547 | L17: =L5 -> 607.54015 | M17: =M5 -> 616.39665 | N17: =N5 -> 625.49431 | ... AJ17: =AJ5 -> 619.96464
C18: FCFE cumulatively | D18: kEUR | E18: =AE18 -> 13578.696 | F18: =F17 -> -2029.2267 | G18: =F18+G17 -> -1436.1494 | H18: =G18+H17 -> -841.51273 | I18: =H18+I17 -> -245.64592 | J18: =I18+J17 -> 351.64433 | K18: =J18+K17 -> 950.5598 | L18: =K18+L17 -> 1558.1 | M18: =L18+M17 -> 2174.4966 | N18: =M18+N17 -> 2799.9909 | ... AJ18: =AI18+AJ17 -> 16740.215
C19: DFCFE | D19: kEUR | E19: =SUM(F19:AE19) -> 2766.0004 | F19: =F17/POWER(1+$E$22,F3) -> -2029.2267 | G19: =G17/POWER(1+$E$22,G3) -> 529.53323 | H19: =H17/POWER(1+$E$22,H3) -> 474.04075 | I19: =I17/POWER(1+$E$22,I3) -> 424.12622 | J19: =J17/POWER(1+$E$22,J3) -> 379.58875 | K19: =K17/POWER(1+$E$22,K3) -> 339.84072 | L19: =L17/POWER(1+$E$22,L3) -> 307.79875 | M19: =M17/POWER(1+$E$22,M3) -> 278.82654 | ... AJ19: =AJ17/POWER(1+$E$22,AJ3) -> 20.693133
C20: DFCFE cumulatively | D20: kEUR | E20: =AE20 -> 2766.0004 | F20: =F19 -> -2029.2267 | G20: =F20+G19 -> -1499.6934 | H20: =G20+H19 -> -1025.6527 | I20: =H20+I19 -> -601.52646 | J20: =I20+J19 -> -221.93771 | K20: =J20+K19 -> 117.90301 | L20: =K20+L19 -> 425.70176 | M20: =L20+M19 -> 704.52831 | N20: =M20+N19 -> 957.15497 | ... AJ20: =AI20+AJ19 -> 2900.3706
C22: Disc. Rate | D22: % | E22: 0.12
C23: NPV | D23: kEUR | E23: =NPV(E22,F17:AJ17) -> 2589.6166
C24: IRR Equity | D24: % | E24: =IRR(F17:AJ17) -> 0.29655172 | F24: =IRR(F17:U17) -> 0.28987295
C25: PB | D25: years | E25: =MATCH(0,F18:AJ18,1)-OFFSET(F18,0,MATCH(0,F18:AJ18,1)-1)/OFFSET(F17,0,MATCH(0,F18:AJ18,1))-((MONTH($F$1)-1)/12) -> 4.2446006
C26: DPB | D26: years | E26: =IF(E23<0,0,MATCH(0,F20:AJ20,1)-OFFSET(F20,0,MATCH(0,F20:AJ20,1)-1)/OFFSET(F19,0,MATCH(0,F20:AJ20,1))-((MONTH($F$1)-1)/12)) -> 5.4863972
