Workbook
Name CANYON: #REF!
Name TP_LINK: #REF!
Name DELL: #REF!
Name GENERIC: #REF!
Name SEAGATE: #REF!
Name DELL_EMC: #REF!
Name MANTA_MULTIMEDIA: #REF!
Name PRESTIGIO: #REF!
Name PERENIO: #REF!
Name LOGITECH: #REF!
Name APPLE: #REF!

Sheet Inverter price analysis BayWa
A1: BEU: | C1: Partner: | G1: Location: | P1: COMPETITION PRICES
G2: *distr.price+freight | J2: *devide (LCP CY)/(1-GM)
B3: Brand | C3: Description | D3: Type | E3: QTY | F3: Distributor BayWa r.e. Price | G3: LCP CY (€) | H3: Final LCP CY | I3: ASKY GM % | J3: Final Price to Customer | K3: Revenue | L3: LCP CY Revenue | M3: Desired GM | N3: LANITIS ENERGY | O3: BIG SOLAR | P3: DR. ENERGY | Q3: TRIKKIS ENERGY | R3: KAFKAS | S3: MERXU
B4: ='ALL DATA & IT4PROFIT'!A6 -> HUAWEI | C4: ='ALL DATA & IT4PROFIT'!B6 -> SUN2000-2KTL-L1 | D4: ='ALL DATA & IT4PROFIT'!C6 -> 1PH HYBRID | E4: 1 | F4: ='ALL DATA & IT4PROFIT'!J6 -> *se container | G4: =F4+$G$193 -> #VALUE! | H4: =(G4*$E$193)+G4 -> #VALUE! | I4: =(J4-H4)/J4 -> #VALUE! | J4: =H4/(1-M4) -> #VALUE! | K4: =SUM(E4*J4) -> #VALUE! | L4: =SUM(E4*H4) -> #VALUE! | M4: 0.07 | N4: 420 | P4: ='ALL DATA & IT4PROFIT'!H6 -> 557 | Q4: ='ALL DATA & IT4PROFIT'!K6 -> 344 | R4: ='ALL DATA & IT4PROFIT'!D6 -> 489
B5: ='ALL DATA & IT4PROFIT'!A7 -> HUAWEI | C5: ='ALL DATA & IT4PROFIT'!B7 -> SUN2000-3KTL-L1 | D5: ='ALL DATA & IT4PROFIT'!C7 -> 1PH HYBRID | E5: 1 | F5: ='ALL DATA & IT4PROFIT'!J7 -> 550 | G5: =F5+$G$193 -> 575 | H5: =(G5*$E$193)+G5 -> 589.375 | I5: =(J5-H5)/J5 -> 0 | J5: =H5/(1-M5) -> 589.375 | K5: =SUM(E5*J5) -> 589.375 | L5: =SUM(E5*H5) -> 589.375 | M5: 0 | N5: 510 | P5: ='ALL DATA & IT4PROFIT'!H7 -> 545 | Q5: ='ALL DATA & IT4PROFIT'!K7 -> 432 | R5: ='ALL DATA & IT4PROFIT'!D7 -> 575
B6: ='ALL DATA & IT4PROFIT'!A8 -> HUAWEI | C6: ='ALL DATA & IT4PROFIT'!B8 -> SUN2000-3.68KTL-L1 | D6: ='ALL DATA & IT4PROFIT'!C8 -> 1PH HYBRID | E6: 1 | F6: ='ALL DATA & IT4PROFIT'!J8 | G6: =F6+$G$193 -> 25 | H6: =(G6*$E$193)+G6 -> 25.625 | I6: =(J6-H6)/J6 -> 0.05 | J6: =H6/(1-M6) -> 26.973684 | K6: =SUM(E6*J6) -> 26.973684 | L6: =SUM(E6*H6) -> 25.625 | M6: 0.05 | N6: 580 | P6: ='ALL DATA & IT4PROFIT'!H8 | Q6: ='ALL DATA & IT4PROFIT'!K8 | R6: ='ALL DATA & IT4PROFIT'!D8 -> 677
B7: ='ALL DATA & IT4PROFIT'!A9 -> HUAWEI | C7: ='ALL DATA & IT4PROFIT'!B9 -> SUN2000-4KTL-L1 | D7: ='ALL DATA & IT4PROFIT'!C9 -> 1PH HYBRID | E7: 1 | F7: ='ALL DATA & IT4PROFIT'!J9 -> 674 | G7: =F7+$G$193 -> 699 | H7: =(G7*$E$193)+G7 -> 716.475 | I7: =(J7-H7)/J7 -> 0 | J7: =H7/(1-M7) -> 716.475 | K7: =SUM(E7*J7) -> 716.475 | L7: =SUM(E7*H7) -> 716.475 | M7: 0 | N7: 620 | P7: ='ALL DATA & IT4PROFIT'!H9 -> 580 | Q7: ='ALL DATA & IT4PROFIT'!K9 -> 563 | R7: ='ALL DATA & IT4PROFIT'!D9 -> 705
B8: ='ALL DATA & IT4PROFIT'!A10 -> HUAWEI | C8: ='ALL DATA & IT4PROFIT'!B10 -> SUN2000-4.6KTL-L1 | D8: ='ALL DATA & IT4PROFIT'!C10 -> 1PH HYBRID | E8: 1 | F8: ='ALL DATA & IT4PROFIT'!J10 | G8: =F8+$G$193 -> 25 | H8: =(G8*$E$193)+G8 -> 25.625 | I8: =(J8-H8)/J8 -> 0.05 | J8: =H8/(1-M8) -> 26.973684 | K8: =SUM(E8*J8) -> 26.973684 | L8: =SUM(E8*H8) -> 25.625 | M8: 0.05 | N8: 645 | P8: ='ALL DATA & IT4PROFIT'!H10 -> 595 | Q8: ='ALL DATA & IT4PROFIT'!K10 -> 616 | R8: ='ALL DATA & IT4PROFIT'!D10 -> 756
B9: ='ALL DATA & IT4PROFIT'!A11 -> HUAWEI | C9: ='ALL DATA & IT4PROFIT'!B11 -> SUN2000-5KTL-L1 | D9: ='ALL DATA & IT4PROFIT'!C11 -> 1PH HYBRID | E9: 1 | F9: ='ALL DATA & IT4PROFIT'!J11 -> 731 | G9: =F9+$G$193 -> 756 | H9: =(G9*$E$193)+G9 -> 774.9 | I9: =(J9-H9)/J9 -> 0 | J9: =H9/(1-M9) -> 774.9 | K9: =SUM(E9*J9) -> 774.9 | L9: =SUM(E9*H9) -> 774.9 | M9: 0 | N9: 660 | P9: ='ALL DATA & IT4PROFIT'!H11 -> 620 | Q9: ='ALL DATA & IT4PROFIT'!K11 -> 624 | R9: ='ALL DATA & IT4PROFIT'!D11 -> 764
B10: ='ALL DATA & IT4PROFIT'!A12 -> HUAWEI | C10: ='ALL DATA & IT4PROFIT'!B12 -> SUN2000-6KTL-L1 | D10: ='ALL DATA & IT4PROFIT'!C12 -> 1PH HYBRID | E10: 1 | F10: ='ALL DATA & IT4PROFIT'!J12 | G10: =F10+$G$193 -> 25 | H10: =(G10*$E$193)+G10 -> 25.625 | I10: =(J10-H10)/J10 -> 0.05 | J10: =H10/(1-M10) -> 26.973684 | K10: =SUM(E10*J10) -> 26.973684 | L10: =SUM(E10*H10) -> 25.625 | M10: 0.05 | P10: ='ALL DATA & IT4PROFIT'!H12 | Q10: ='ALL DATA & IT4PROFIT'!K12 | R10: ='ALL DATA & IT4PROFIT'!D12 -> 868
B11: ='ALL DATA & IT4PROFIT'!A13 -> HUAWEI | C11: ='ALL DATA & IT4PROFIT'!B13 -> SUN2000-3KTL-M1 | D11: ='ALL DATA & IT4PROFIT'!C13 -> 3PH HYBRID | E11: 1 | F11: ='ALL DATA & IT4PROFIT'!J13 -> 794 | G11: =F11+$G$193 -> 819 | H11: =(G11*$E$193)+G11 -> 839.475 | I11: =(J11-H11)/J11 -> 0.01 | J11: =H11/(1-M11) -> 847.95455 | K11: =SUM(E11*J11) -> 847.95455 | L11: =SUM(E11*H11) -> 839.475 | M11: 0.01 | N11: 845 | P11: ='ALL DATA & IT4PROFIT'!H13 -> 907 | Q11: ='ALL DATA & IT4PROFIT'!K13 -> 832 | R11: ='ALL DATA & IT4PROFIT'!D13 -> 880
B12: ='ALL DATA & IT4PROFIT'!A14 -> HUAWEI | C12: ='ALL DATA & IT4PROFIT'!B14 -> SUN2000-4KTL-M1 | D12: ='ALL DATA & IT4PROFIT'!C14 -> 3PH HYBRID | E12: 1 | F12: ='ALL DATA & IT4PROFIT'!J14 -> 830 | G12: =F12+$G$193 -> 855 | H12: =(G12*$E$193)+G12 -> 876.375 | I12: =(J12-H12)/J12 -> 0.01 | J12: =H12/(1-M12) -> 885.22727 | K12: =SUM(E12*J12) -> 885.22727 | L12: =SUM(E12*H12) -> 876.375 | M12: 0.01 | N12: 880 | P12: ='ALL DATA & IT4PROFIT'!H14 -> 906 | Q12: ='ALL DATA & IT4PROFIT'!K14 -> 871 | R12: ='ALL DATA & IT4PROFIT'!D14 -> 920
B13: ='ALL DATA & IT4PROFIT'!A15 -> HUAWEI | C13: ='ALL DATA & IT4PROFIT'!B15 -> SUN2000-5KTL-M1 | D13: ='ALL DATA & IT4PROFIT'!C15 -> 3PH HYBRID | E13: 1 | F13: ='ALL DATA & IT4PROFIT'!J15 -> 876 | G13: =F13+$G$193 -> 901 | H13: =(G13*$E$193)+G13 -> 923.525 | I13: =(J13-H13)/J13 -> 0.01 | J13: =H13/(1-M13) -> 932.85354 | K13: =SUM(E13*J13) -> 932.85354 | L13: =SUM(E13*H13) -> 923.525 | M13: 0.01 | N13: 930 | P13: ='ALL DATA & IT4PROFIT'!H15 -> 930 | Q13: ='ALL DATA & IT4PROFIT'!K15 -> 919 | R13: ='ALL DATA & IT4PROFIT'!D15 -> 971
B14: ='ALL DATA & IT4PROFIT'!A16 -> HUAWEI | C14: ='ALL DATA & IT4PROFIT'!B16 -> SUN2000-6KTL-M1 | D14: ='ALL DATA & IT4PROFIT'!C16 -> 3PH HYBRID | E14: 1 | F14: ='ALL DATA & IT4PROFIT'!J16 -> 980 | G14: =F14+$G$193 -> 1005 | H14: =(G14*$E$193)+G14 -> 1030.125 | I14: =(J14-H14)/J14 -> 0.01 | J14: =H14/(1-M14) -> 1040.5303 | K14: =SUM(E14*J14) -> 1040.5303 | L14: =SUM(E14*H14) -> 1030.125 | M14: 0.01 | N14: 1040 | P14: ='ALL DATA & IT4PROFIT'!H16 -> 1090 | Q14: ='ALL DATA & IT4PROFIT'!K16 -> 1028 | R14: ='ALL DATA & IT4PROFIT'!D16 -> 1086
B15: ='ALL DATA & IT4PROFIT'!A17 -> HUAWEI | C15: ='ALL DATA & IT4PROFIT'!B17 -> SUN2000-8KTL-M1 | D15: ='ALL DATA & IT4PROFIT'!C17 -> 3PH HYBRID | E15: 1 | F15: ='ALL DATA & IT4PROFIT'!J17 -> 1162 | G15: =F15+$G$193 -> 1187 | H15: =(G15*$E$193)+G15 -> 1216.675 | I15: =(J15-H15)/J15 -> 0.015 | J15: =H15/(1-M15) -> 1235.203 | K15: =SUM(E15*J15) -> 1235.203 | L15: =SUM(E15*H15) -> 1216.675 | M15: 0.015 | N15: 1235 | P15: ='ALL DATA & IT4PROFIT'!H17 -> 1260 | Q15: ='ALL DATA & IT4PROFIT'!K17 -> 1219 | R15: ='ALL DATA & IT4PROFIT'!D17 -> 1289
B16: ='ALL DATA & IT4PROFIT'!A18 -> HUAWEI | C16: ='ALL DATA & IT4PROFIT'!B18 -> SUN2000-10KTL-M1 | D16: ='ALL DATA & IT4PROFIT'!C18 -> 3PH HYBRID | E16: 1 | F16: ='ALL DATA & IT4PROFIT'!J18 -> 1306 | G16: =F16+$G$193 -> 1331 | H16: =(G16*$E$193)+G16 -> 1364.275 | I16: =(J16-H16)/J16 -> 0.015 | J16: =H16/(1-M16) -> 1385.0508 | K16: =SUM(E16*J16) -> 1385.0508 | L16: =SUM(E16*H16) -> 1364.275 | M16: 0.015 | N16: 1385 | P16: ='ALL DATA & IT4PROFIT'!H18 -> 1385 | Q16: ='ALL DATA & IT4PROFIT'!K18 -> 1369 | R16: ='ALL DATA & IT4PROFIT'!D18 -> 1448
B17: ='ALL DATA & IT4PROFIT'!A19 -> HUAWEI | C17: ='ALL DATA & IT4PROFIT'!B19 -> SUN2000-12KTL-M5 | D17: ='ALL DATA & IT4PROFIT'!C19 -> 3PH HYBRID | E17: 1 | F17: ='ALL DATA & IT4PROFIT'!J19 -> 1420 | G17: =F17+$G$193 -> 1445 | H17: =(G17*$E$193)+G17 -> 1481.125 | I17: =(J17-H17)/J17 -> 0 | J17: =H17/(1-M17) -> 1481.125 | K17: =SUM(E17*J17) -> 1481.125 | L17: =SUM(E17*H17) -> 1481.125 | M17: 0 | N17: 1450 | P17: ='ALL DATA & IT4PROFIT'!H19 | Q17: ='ALL DATA & IT4PROFIT'!K19 -> 947.6 | R17: ='ALL DATA & IT4PROFIT'!D19 -> 1515
B18: ='ALL DATA & IT4PROFIT'!A20 -> HUAWEI | C18: ='ALL DATA & IT4PROFIT'!B20 -> SUN2000-15KTL-M5 | D18: ='ALL DATA & IT4PROFIT'!C20 -> 3PH HYBRID | E18: 1 | F18: ='ALL DATA & IT4PROFIT'!J20 -> 1580 | G18: =F18+$G$193 -> 1605 | H18: =(G18*$E$193)+G18 -> 1645.125 | I18: =(J18-H18)/J18 -> 0 | J18: =H18/(1-M18) -> 1645.125 | K18: =SUM(E18*J18) -> 1645.125 | L18: =SUM(E18*H18) -> 1645.125 | M18: 0 | N18: 1640 | P18: ='ALL DATA & IT4PROFIT'!H20 | Q18: ='ALL DATA & IT4PROFIT'!K20 -> 1133.5 | R18: ='ALL DATA & IT4PROFIT'!D20 -> 1710
B19: ='ALL DATA & IT4PROFIT'!A21 -> HUAWEI | C19: ='ALL DATA & IT4PROFIT'!B21 -> SUN2000-17KTL-M5 | D19: ='ALL DATA & IT4PROFIT'!C21 -> 3PH HYBRID | E19: 1 | F19: ='ALL DATA & IT4PROFIT'!J21 -> 1615 | G19: =F19+$G$193 -> 1640 | H19: =(G19*$E$193)+G19 -> 1681 | I19: =(J19-H19)/J19 -> 0 | J19: =H19/(1-M19) -> 1681 | K19: =SUM(E19*J19) -> 1681 | L19: =SUM(E19*H19) -> 1681 | M19: 0 | N19: 1675 | P19: ='ALL DATA & IT4PROFIT'!H21 | Q19: ='ALL DATA & IT4PROFIT'!K21 -> 1167.6 | R19: ='ALL DATA & IT4PROFIT'!D21 -> 1447
B20: ='ALL DATA & IT4PROFIT'!A22 -> HUAWEI | C20: ='ALL DATA & IT4PROFIT'!B22 -> SUN2000-20KTL-M5 | D20: ='ALL DATA & IT4PROFIT'!C22 -> 3PH HYBRID | E20: 1 | F20: ='ALL DATA & IT4PROFIT'!J22 -> 1704 | G20: =F20+$G$193 -> 1729 | H20: =(G20*$E$193)+G20 -> 1772.225 | I20: =(J20-H20)/J20 -> 0.01 | J20: =H20/(1-M20) -> 1790.1263 | K20: =SUM(E20*J20) -> 1790.1263 | L20: =SUM(E20*H20) -> 1772.225 | M20: 0.01 | N20: 1790 | P20: ='ALL DATA & IT4PROFIT'!H22 | Q20: ='ALL DATA & IT4PROFIT'!K22 -> 1262.2 | R20: ='ALL DATA & IT4PROFIT'!D22 -> 1844
B21: ='ALL DATA & IT4PROFIT'!A23 -> HUAWEI | C21: ='ALL DATA & IT4PROFIT'!B23 -> SUN2000-25KTL-M5 | D21: ='ALL DATA & IT4PROFIT'!C23 -> 3PH HYBRID | E21: 1 | F21: ='ALL DATA & IT4PROFIT'!J23 | G21: =F21+$G$193 -> 25 | H21: =(G21*$E$193)+G21 -> 25.625 | I21: =(J21-H21)/J21 -> 0.05 | J21: =H21/(1-M21) -> 26.973684 | K21: =SUM(E21*J21) -> 26.973684 | L21: =SUM(E21*H21) -> 25.625 | M21: 0.05 | N21: 1825 | P21: ='ALL DATA & IT4PROFIT'!H23 | Q21: ='ALL DATA & IT4PROFIT'!K23 -> 1320.5 | R21: ='ALL DATA & IT4PROFIT'!D23 -> 1906
B22: ='ALL DATA & IT4PROFIT'!A24 -> HUAWEI | C22: ='ALL DATA & IT4PROFIT'!B24 -> SUN2000-30KTL-M3 | D22: ='ALL DATA & IT4PROFIT'!C24 -> 3PH HYBRID | E22: 1 | F22: ='ALL DATA & IT4PROFIT'!J24 -> 1945 | G22: =F22+$G$193 -> 1970 | H22: =(G22*$E$193)+G22 -> 2019.25 | I22: =(J22-H22)/J22 -> 0.03 | J22: =H22/(1-M22) -> 2081.701 | K22: =SUM(E22*J22) -> 2081.701 | L22: =SUM(E22*H22) -> 2019.25 | M22: 0.03 | N22: 2080 | P22: ='ALL DATA & IT4PROFIT'!H24 | Q22: ='ALL DATA & IT4PROFIT'!K24 -> 1993 | R22: ='ALL DATA & IT4PROFIT'!D24 -> 2106
... B25: ='ALL DATA & IT4PROFIT'!A27 -> HUAWEI | C25: ='ALL DATA & IT4PROFIT'!B27 -> SUN2000-50KTL-M3 | D25: ='ALL DATA & IT4PROFIT'!C27 -> 3PH HYBRID | E25: 1 | F25: ='ALL DATA & IT4PROFIT'!J27 -> 2350 | G25: =F25+$G$193 -> 2375 | H25: =(G25*$E$193)+G25 -> 2434.375 | I25: =(J25-H25)/J25 -> 0 | J25: =H25/(1-M25) -> 2434.375 | K25: =SUM(E25*J25) -> 2434.375 | L25: =SUM(E25*H25) -> 2434.375 | M25: 0 | N25: 2400 | P25: ='ALL DATA & IT4PROFIT'!H27 | Q25: ='ALL DATA & IT4PROFIT'!K27 -> 2405 | R25: ='ALL DATA & IT4PROFIT'!D27 -> 2543
B26: ='ALL DATA & IT4PROFIT'!A28 -> HUAWEI | C26: ='ALL DATA & IT4PROFIT'!B28 -> SUN2000-100KTL-M2-AFCI | D26: ='ALL DATA & IT4PROFIT'!C28 -> 3PH HYBRID | E26: 1 | F26: ='ALL DATA & IT4PROFIT'!J28 | G26: =F26+$G$193 -> 25 | H26: =(G26*$E$193)+G26 -> 25.625 | I26: =(J26-H26)/J26 -> 0.07 | J26: =H26/(1-M26) -> 27.553763 | K26: =SUM(E26*J26) -> 27.553763 | L26: =SUM(E26*H26) -> 25.625 | M26: 0.07 | P26: ='ALL DATA & IT4PROFIT'!H28 | Q26: ='ALL DATA & IT4PROFIT'!K28 -> 3800 | R26: ='ALL DATA & IT4PROFIT'!D28 -> 4020
B27: ='ALL DATA & IT4PROFIT'!A29 -> HUAWEI | C27: ='ALL DATA & IT4PROFIT'!B29 -> IV HU SUN2000 115 KTL M2 | D27: ='ALL DATA & IT4PROFIT'!C29 | E27: 1 | F27: ='ALL DATA & IT4PROFIT'!J29 | G27: =F27+$G$193 -> 25 | H27: =(G27*$E$193)+G27 -> 25.625 | I27: =(J27-H27)/J27 -> 0.07 | J27: =H27/(1-M27) -> 27.553763 | K27: =SUM(E27*J27) -> 27.553763 | L27: =SUM(E27*H27) -> 25.625 | M27: 0.07 | P27: ='ALL DATA & IT4PROFIT'!H29 | Q27: ='ALL DATA & IT4PROFIT'!K29 -> 3842.6 | R27: ='ALL DATA & IT4PROFIT'!D29
B28: ='ALL DATA & IT4PROFIT'!A30 -> HUAWEI | C28: ='ALL DATA & IT4PROFIT'!B30 -> IV HU SUN2000 105 KTL H1 (1500V) | D28: ='ALL DATA & IT4PROFIT'!C30 | E28: 1 | F28: ='ALL DATA & IT4PROFIT'!J30 | G28: =F28+$G$193 -> 25 | H28: =(G28*$E$193)+G28 -> 25.625 | I28: =(J28-H28)/J28 -> 0.07 | J28: =H28/(1-M28) -> 27.553763 | K28: =SUM(E28*J28) -> 27.553763 | L28: =SUM(E28*H28) -> 25.625 | M28: 0.07 | P28: ='ALL DATA & IT4PROFIT'!H30 | Q28: ='ALL DATA & IT4PROFIT'!K30 | R28: ='ALL DATA & IT4PROFIT'!D30
B29: ='ALL DATA & IT4PROFIT'!A31 -> HUAWEI | C29: ='ALL DATA & IT4PROFIT'!B31 -> IV HU SUN2000 215 KTL-H3 (1500V) | D29: ='ALL DATA & IT4PROFIT'!C31 | E29: 1 | F29: ='ALL DATA & IT4PROFIT'!J31 | G29: =F29+$G$193 -> 25 | H29: =(G29*$E$193)+G29 -> 25.625 | I29: =(J29-H29)/J29 -> 0.07 | J29: =H29/(1-M29) -> 27.553763 | K29: =SUM(E29*J29) -> 27.553763 | L29: =SUM(E29*H29) -> 25.625 | M29: 0.07 | P29: ='ALL DATA & IT4PROFIT'!H31 | Q29: ='ALL DATA & IT4PROFIT'!K31 | R29: ='ALL DATA & IT4PROFIT'!D31
B30: ='ALL DATA & IT4PROFIT'!A32 -> HUAWEI | C30: ='ALL DATA & IT4PROFIT'!B32 -> IV HU SUN2000-330KTL-H1 (1500V) | D30: ='ALL DATA & IT4PROFIT'!C32 | E30: 1 | F30: ='ALL DATA & IT4PROFIT'!J32 | G30: =F30+$G$193 -> 25 | H30: =(G30*$E$193)+G30 -> 25.625 | I30: =(J30-H30)/J30 -> 0.07 | J30: =H30/(1-M30) -> 27.553763 | K30: =SUM(E30*J30) -> 27.553763 | L30: =SUM(E30*H30) -> 25.625 | M30: 0.07 | P30: ='ALL DATA & IT4PROFIT'!H32 | Q30: ='ALL DATA & IT4PROFIT'!K32 | R30: ='ALL DATA & IT4PROFIT'!D32
B31: ='ALL DATA & IT4PROFIT'!A34 | C31: ='ALL DATA & IT4PROFIT'!B34 | D31: ='ALL DATA & IT4PROFIT'!C34 | E31: 1 | F31: ='ALL DATA & IT4PROFIT'!J34 | G31: =F31+$G$193 -> 25 | H31: =(G31*$E$193)+G31 -> 25.625 | I31: =(J31-H31)/J31 -> 0.07 | J31: =H31/(1-M31) -> 27.553763 | K31: =SUM(E31*J31) -> 27.553763 | L31: =SUM(E31*H31) -> 25.625 | M31: 0.07 | P31: ='ALL DATA & IT4PROFIT'!H34 | Q31: ='ALL DATA & IT4PROFIT'!K34 | R31: ='ALL DATA & IT4PROFIT'!D34
B32: ='ALL DATA & IT4PROFIT'!A35 -> HUAWEI | C32: ='ALL DATA & IT4PROFIT'!B35 -> SUN2000-450W-P2 | D32: ='ALL DATA & IT4PROFIT'!C35 -> OPTIMIZER | E32: 1 | F32: ='ALL DATA & IT4PROFIT'!J35 -> 45 | G32: =F32+$G$194 -> 48 | H32: =(G32*$E$193)+G32 -> 49.2 | I32: =(J32-H32)/J32 -> 0 | J32: =H32/(1-M32) -> 49.2 | K32: =SUM(E32*J32) -> 49.2 | L32: =SUM(E32*H32) -> 49.2 | M32: 0 | N32: 40 | P32: ='ALL DATA & IT4PROFIT'!H35 | Q32: ='ALL DATA & IT4PROFIT'!K35 -> 38.5 | R32: ='ALL DATA & IT4PROFIT'!D35 -> 41
B33: ='ALL DATA & IT4PROFIT'!A36 -> HUAWEI | C33: ='ALL DATA & IT4PROFIT'!B36 -> SUN2000-600W-P | D33: ='ALL DATA & IT4PROFIT'!C36 -> OPTIMIZER | E33: 1 | F33: ='ALL DATA & IT4PROFIT'!J36 -> 45 | G33: =F33+$G$194 -> 48 | H33: =(G33*$E$193)+G33 -> 49.2 | I33: =(J33-H33)/J33 -> 0 | J33: =H33/(1-M33) -> 49.2 | K33: =SUM(E33*J33) -> 49.2 | L33: =SUM(E33*H33) -> 49.2 | M33: 0 | N33: 40 | P33: ='ALL DATA & IT4PROFIT'!H36 | Q33: ='ALL DATA & IT4PROFIT'!K36 -> 39 | R33: ='ALL DATA & IT4PROFIT'!D36 -> 41
B34: ='ALL DATA & IT4PROFIT'!A37 | C34: ='ALL DATA & IT4PROFIT'!B37 | D34: ='ALL DATA & IT4PROFIT'!C37 | E34: 1 | F34: ='ALL DATA & IT4PROFIT'!J37 | G34: =F34+$G$193 -> 25 | H34: =(G34*$E$193)+G34 -> 25.625 | I34: =(J34-H34)/J34 -> 0.07 | J34: =H34/(1-M34) -> 27.553763 | K34: =SUM(E34*J34) -> 27.553763 | L34: =SUM(E34*H34) -> 25.625 | M34: 0.07 | P34: ='ALL DATA & IT4PROFIT'!H37 | Q34: ='ALL DATA & IT4PROFIT'!K37 | R34: ='ALL DATA & IT4PROFIT'!D37
B35: ='ALL DATA & IT4PROFIT'!A38 | C35: ='ALL DATA & IT4PROFIT'!B38 | D35: ='ALL DATA & IT4PROFIT'!C38 | E35: 1 | F35: ='ALL DATA & IT4PROFIT'!J38 | G35: =F35+$G$193 -> 25 | H35: =(G35*$E$193)+G35 -> 25.625 | I35: =(J35-H35)/J35 -> 0.07 | J35: =H35/(1-M35) -> 27.553763 | K35: =SUM(E35*J35) -> 27.553763 | L35: =SUM(E35*H35) -> 25.625 | M35: 0.07 | P35: ='ALL DATA & IT4PROFIT'!H38 | Q35: ='ALL DATA & IT4PROFIT'!K38 | R35: ='ALL DATA & IT4PROFIT'!D38
B36: ='ALL DATA & IT4PROFIT'!A39 -> SUNGROW | C36: ='ALL DATA & IT4PROFIT'!B39 -> IV SUNG SG2.0RS | D36: ='ALL DATA & IT4PROFIT'!C39 -> 1PH | E36: 1 | F36: ='ALL DATA & IT4PROFIT'!J39 | G36: =F36+$G$193 -> 25 | H36: =(G36*$E$193)+G36 -> 25.625 | I36: =(J36-H36)/J36 -> 0.07 | J36: =H36/(1-M36) -> 27.553763 | K36: =SUM(E36*J36) -> 27.553763 | L36: =SUM(E36*H36) -> 25.625 | M36: 0.07 | P36: ='ALL DATA & IT4PROFIT'!H39 | Q36: ='ALL DATA & IT4PROFIT'!K39 | R36: ='ALL DATA & IT4PROFIT'!D39
B37: ='ALL DATA & IT4PROFIT'!A40 -> SUNGROW | C37: ='ALL DATA & IT4PROFIT'!B40 -> IV SUNG SG3.0RS | D37: ='ALL DATA & IT4PROFIT'!C40 -> 1PH | E37: 1 | F37: ='ALL DATA & IT4PROFIT'!J40 | G37: =F37+$G$193 -> 25 | H37: =(G37*$E$193)+G37 -> 25.625 | I37: =(J37-H37)/J37 -> 0.07 | J37: =H37/(1-M37) -> 27.553763 | K37: =SUM(E37*J37) -> 27.553763 | L37: =SUM(E37*H37) -> 25.625 | M37: 0.07 | P37: ='ALL DATA & IT4PROFIT'!H40 | Q37: ='ALL DATA & IT4PROFIT'!K40 | R37: ='ALL DATA & IT4PROFIT'!D40
B38: ='ALL DATA & IT4PROFIT'!A41 -> SUNGROW | C38: ='ALL DATA & IT4PROFIT'!B41 -> IV SUNG SG4.0RS | D38: ='ALL DATA & IT4PROFIT'!C41 -> 1PH | E38: 1 | F38: ='ALL DATA & IT4PROFIT'!J41 | G38: =F38+$G$193 -> 25 | H38: =(G38*$E$193)+G38 -> 25.625 | I38: =(J38-H38)/J38 -> 0.07 | J38: =H38/(1-M38) -> 27.553763 | K38: =SUM(E38*J38) -> 27.553763 | L38: =SUM(E38*H38) -> 25.625 | M38: 0.07 | P38: ='ALL DATA & IT4PROFIT'!H41 | Q38: ='ALL DATA & IT4PROFIT'!K41 | R38: ='ALL DATA & IT4PROFIT'!D41
B39: ='ALL DATA & IT4PROFIT'!A42 -> SUNGROW | C39: ='ALL DATA & IT4PROFIT'!B42 -> IV SUNG SG5.0RS | D39: ='ALL DATA & IT4PROFIT'!C42 -> 1PH | E39: 1 | F39: ='ALL DATA & IT4PROFIT'!J42 | G39: =F39+$G$193 -> 25 | H39: =(G39*$E$193)+G39 -> 25.625 | I39: =(J39-H39)/J39 -> 0.07 | J39: =H39/(1-M39) -> 27.553763 | K39: =SUM(E39*J39) -> 27.553763 | L39: =SUM(E39*H39) -> 25.625 | M39: 0.07 | P39: ='ALL DATA & IT4PROFIT'!H42 | Q39: ='ALL DATA & IT4PROFIT'!K42 | R39: ='ALL DATA & IT4PROFIT'!D42
B40: ='ALL DATA & IT4PROFIT'!A43 -> SUNGROW | C40: ='ALL DATA & IT4PROFIT'!B43 -> IV SUNG SG3.0RT | D40: ='ALL DATA & IT4PROFIT'!C43 -> 3PH | E40: 1 | F40: ='ALL DATA & IT4PROFIT'!J43 | G40: =F40+$G$193 -> 25 | H40: =(G40*$E$193)+G40 -> 25.625 | I40: =(J40-H40)/J40 -> 0.07 | J40: =H40/(1-M40) -> 27.553763 | K40: =SUM(E40*J40) -> 27.553763 | L40: =SUM(E40*H40) -> 25.625 | M40: 0.07 | P40: ='ALL DATA & IT4PROFIT'!H43 | Q40: ='ALL DATA & IT4PROFIT'!K43 | R40: ='ALL DATA & IT4PROFIT'!D43
B41: ='ALL DATA & IT4PROFIT'!A44 -> SUNGROW | C41: ='ALL DATA & IT4PROFIT'!B44 -> IV SUNG SG4.0RT | D41: ='ALL DATA & IT4PROFIT'!C44 -> 3PH | E41: 1 | F41: ='ALL DATA & IT4PROFIT'!J44 | G41: =F41+$G$193 -> 25 | H41: =(G41*$E$193)+G41 -> 25.625 | I41: =(J41-H41)/J41 -> 0.07 | J41: =H41/(1-M41) -> 27.553763 | K41: =SUM(E41*J41) -> 27.553763 | L41: =SUM(E41*H41) -> 25.625 | M41: 0.07 | P41: ='ALL DATA & IT4PROFIT'!H44 | Q41: ='ALL DATA & IT4PROFIT'!K44 | R41: ='ALL DATA & IT4PROFIT'!D44
B42: ='ALL DATA & IT4PROFIT'!A45 -> SUNGROW | C42: ='ALL DATA & IT4PROFIT'!B45 -> IV SUNG SG5.0RT | D42: ='ALL DATA & IT4PROFIT'!C45 -> 3PH | E42: 1 | F42: ='ALL DATA & IT4PROFIT'!J45 | G42: =F42+$G$193 -> 25 | H42: =(G42*$E$193)+G42 -> 25.625 | I42: =(J42-H42)/J42 -> 0.07 | J42: =H42/(1-M42) -> 27.553763 | K42: =SUM(E42*J42) -> 27.553763 | L42: =SUM(E42*H42) -> 25.625 | M42: 0.07 | P42: ='ALL DATA & IT4PROFIT'!H45 | Q42: ='ALL DATA & IT4PROFIT'!K45 | R42: ='ALL DATA & IT4PROFIT'!D45
...

Sheet Inverter price analysis Krannic
A1: BEU: | C1: Partner: | G1: Location: | P1: COMPETITION PRICES
G2: *distr.price+freight | J2: *devide (LCP CY)/(1-GM)
B3: Brand | C3: Description | D3: Type | E3: QTY | F3: Distributor Krannich Price | G3: LCP CY (€) | H3: Final LCP CY | I3: ASKY GM % | J3: Final Price to Customer | K3: Revenue | L3: LCP CY Revenue | M3: Desired GM | N3: LANITIS ENERGY | O3: BIG SOLAR | P3: DR. ENERGY | Q3: TRIKKIS ENERGY | R3: KAFKAS
B4: ='ALL DATA & IT4PROFIT'!A6 -> HUAWEI | C4: ='ALL DATA & IT4PROFIT'!B6 -> SUN2000-2KTL-L1 | D4: ='ALL DATA & IT4PROFIT'!C6 -> 1PH HYBRID | E4: 1 | F4: ='ALL DATA & IT4PROFIT'!F6 -> 0 | G4: =F4+$G$204 -> 30 | H4: =(G4*$E$204)+G4 -> 30.75 | I4: =(J4-H4)/J4 -> 0.07 | J4: =H4/(1-M4) -> 33.064516 | K4: =SUM(E4*J4) -> 33.064516 | L4: =SUM(E4*H4) -> 30.75 | M4: 0.07 | N4: ='ALL DATA & IT4PROFIT'!L6 -> 420 | P4: ='ALL DATA & IT4PROFIT'!H6 -> 557 | Q4: ='ALL DATA & IT4PROFIT'!K6 -> 344 | R4: ='ALL DATA & IT4PROFIT'!D6 -> 489
B5: ='ALL DATA & IT4PROFIT'!A7 -> HUAWEI | C5: ='ALL DATA & IT4PROFIT'!B7 -> SUN2000-3KTL-L1 | D5: ='ALL DATA & IT4PROFIT'!C7 -> 1PH HYBRID | E5: 1 | F5: ='ALL DATA & IT4PROFIT'!F7 -> 355.8 | G5: =F5+$G$204 -> 385.8 | H5: =(G5*$E$204)+G5 -> 395.445 | I5: =(J5-H5)/J5 -> 0.20911 | J5: =H5/(1-M5) -> 500 | K5: =SUM(E5*J5) -> 500 | L5: =SUM(E5*H5) -> 395.445 | M5: 0.20911 | N5: ='ALL DATA & IT4PROFIT'!L7 -> 510 | P5: ='ALL DATA & IT4PROFIT'!H7 -> 545 | Q5: ='ALL DATA & IT4PROFIT'!K7 -> 432 | R5: ='ALL DATA & IT4PROFIT'!D7 -> 575
B6: ='ALL DATA & IT4PROFIT'!A8 -> HUAWEI | C6: ='ALL DATA & IT4PROFIT'!B8 -> SUN2000-3.68KTL-L1 | D6: ='ALL DATA & IT4PROFIT'!C8 -> 1PH HYBRID | E6: 1 | F6: ='ALL DATA & IT4PROFIT'!F8 -> 0 | G6: =F6+$G$204 -> 30 | H6: =(G6*$E$204)+G6 -> 30.75 | I6: =(J6-H6)/J6 -> 0.05 | J6: =H6/(1-M6) -> 32.368421 | K6: =SUM(E6*J6) -> 32.368421 | L6: =SUM(E6*H6) -> 30.75 | M6: 0.05 | N6: ='ALL DATA & IT4PROFIT'!L8 -> 580 | P6: ='ALL DATA & IT4PROFIT'!H8 | Q6: ='ALL DATA & IT4PROFIT'!K8 | R6: ='ALL DATA & IT4PROFIT'!D8 -> 677
B7: ='ALL DATA & IT4PROFIT'!A9 -> HUAWEI | C7: ='ALL DATA & IT4PROFIT'!B9 -> SUN2000-4KTL-L1 | D7: ='ALL DATA & IT4PROFIT'!C9 -> 1PH HYBRID | E7: 1 | F7: ='ALL DATA & IT4PROFIT'!F9 -> 417.6 | G7: =F7+$G$204 -> 447.6 | H7: =(G7*$E$204)+G7 -> 458.79 | I7: =(J7-H7)/J7 -> 0.18073 | J7: =H7/(1-M7) -> 559.99854 | K7: =SUM(E7*J7) -> 559.99854 | L7: =SUM(E7*H7) -> 458.79 | M7: 0.18073 | N7: ='ALL DATA & IT4PROFIT'!L9 -> 620 | P7: ='ALL DATA & IT4PROFIT'!H9 -> 580 | Q7: ='ALL DATA & IT4PROFIT'!K9 -> 563 | R7: ='ALL DATA & IT4PROFIT'!D9 -> 705
B8: ='ALL DATA & IT4PROFIT'!A10 -> HUAWEI | C8: ='ALL DATA & IT4PROFIT'!B10 -> SUN2000-4.6KTL-L1 | D8: ='ALL DATA & IT4PROFIT'!C10 -> 1PH HYBRID | E8: 1 | F8: ='ALL DATA & IT4PROFIT'!F10 -> 518.4 | G8: =F8+$G$204 -> 548.4 | H8: =(G8*$E$204)+G8 -> 562.11 | I8: =(J8-H8)/J8 -> 0.10063 | J8: =H8/(1-M8) -> 625.00417 | K8: =SUM(E8*J8) -> 625.00417 | L8: =SUM(E8*H8) -> 562.11 | M8: 0.10063 | N8: ='ALL DATA & IT4PROFIT'!L10 -> 645 | P8: ='ALL DATA & IT4PROFIT'!H10 -> 595 | Q8: ='ALL DATA & IT4PROFIT'!K10 -> 616 | R8: ='ALL DATA & IT4PROFIT'!D10 -> 756
B9: ='ALL DATA & IT4PROFIT'!A11 -> HUAWEI | C9: ='ALL DATA & IT4PROFIT'!B11 -> SUN2000-5KTL-L1 | D9: ='ALL DATA & IT4PROFIT'!C11 -> 1PH HYBRID | E9: 1 | F9: ='ALL DATA & IT4PROFIT'!F11 -> 465.6 | G9: =F9+$G$204 -> 495.6 | H9: =(G9*$E$204)+G9 -> 507.99 | I9: =(J9-H9)/J9 -> 0.20001 | J9: =H9/(1-M9) -> 634.99544 | K9: =SUM(E9*J9) -> 634.99544 | L9: =SUM(E9*H9) -> 507.99 | M9: 0.20001 | N9: ='ALL DATA & IT4PROFIT'!L11 -> 660 | P9: ='ALL DATA & IT4PROFIT'!H11 -> 620 | Q9: ='ALL DATA & IT4PROFIT'!K11 -> 624 | R9: ='ALL DATA & IT4PROFIT'!D11 -> 764
B10: ='ALL DATA & IT4PROFIT'!A12 -> HUAWEI | C10: ='ALL DATA & IT4PROFIT'!B12 -> SUN2000-6KTL-L1 | D10: ='ALL DATA & IT4PROFIT'!C12 -> 1PH HYBRID | E10: 1 | F10: ='ALL DATA & IT4PROFIT'!F12 -> 445.8 | G10: =F10+$G$204 -> 475.8 | H10: =(G10*$E$204)+G10 -> 487.695 | I10: =(J10-H10)/J10 -> 0 | J10: =H10/(1-M10) -> 487.695 | K10: =SUM(E10*J10) -> 487.695 | L10: =SUM(E10*H10) -> 487.695 | N10: ='ALL DATA & IT4PROFIT'!L12 | P10: ='ALL DATA & IT4PROFIT'!H12 | Q10: ='ALL DATA & IT4PROFIT'!K12 | R10: ='ALL DATA & IT4PROFIT'!D12 -> 868
B11: ='ALL DATA & IT4PROFIT'!A13 -> HUAWEI | C11: ='ALL DATA & IT4PROFIT'!B13 -> SUN2000-3KTL-M1 | D11: ='ALL DATA & IT4PROFIT'!C13 -> 3PH HYBRID | E11: 1 | F11: ='ALL DATA & IT4PROFIT'!F13 -> 808.2 | G11: =F11+$G$204 -> 838.2 | H11: =(G11*$E$204)+G11 -> 859.155 | I11: =(J11-H11)/J11 -> 0.05 | J11: =H11/(1-M11) -> 904.37368 | K11: =SUM(E11*J11) -> 904.37368 | L11: =SUM(E11*H11) -> 859.155 | M11: 0.05 | N11: ='ALL DATA & IT4PROFIT'!L13 -> 845 | P11: ='ALL DATA & IT4PROFIT'!H13 -> 907 | Q11: ='ALL DATA & IT4PROFIT'!K13 -> 832 | R11: ='ALL DATA & IT4PROFIT'!D13 -> 880
B12: ='ALL DATA & IT4PROFIT'!A14 -> HUAWEI | C12: ='ALL DATA & IT4PROFIT'!B14 -> SUN2000-4KTL-M1 | D12: ='ALL DATA & IT4PROFIT'!C14 -> 3PH HYBRID | E12: 1 | F12: ='ALL DATA & IT4PROFIT'!F14 -> 844.8 | G12: =F12+$G$204 -> 874.8 | H12: =(G12*$E$204)+G12 -> 896.67 | I12: =(J12-H12)/J12 -> 0.05 | J12: =H12/(1-M12) -> 943.86316 | K12: =SUM(E12*J12) -> 943.86316 | L12: =SUM(E12*H12) -> 896.67 | M12: 0.05 | N12: ='ALL DATA & IT4PROFIT'!L14 -> 880 | P12: ='ALL DATA & IT4PROFIT'!H14 -> 906 | Q12: ='ALL DATA & IT4PROFIT'!K14 -> 871 | R12: ='ALL DATA & IT4PROFIT'!D14 -> 920
B13: ='ALL DATA & IT4PROFIT'!A15 -> HUAWEI | C13: ='ALL DATA & IT4PROFIT'!B15 -> SUN2000-5KTL-M1 | D13: ='ALL DATA & IT4PROFIT'!C15 -> 3PH HYBRID | E13: 1 | F13: ='ALL DATA & IT4PROFIT'!F15 -> 891 | G13: =F13+$G$204 -> 921 | H13: =(G13*$E$204)+G13 -> 944.025 | I13: =(J13-H13)/J13 -> 0.05 | J13: =H13/(1-M13) -> 993.71053 | K13: =SUM(E13*J13) -> 993.71053 | L13: =SUM(E13*H13) -> 944.025 | M13: 0.05 | N13: ='ALL DATA & IT4PROFIT'!L15 -> 930 | P13: ='ALL DATA & IT4PROFIT'!H15 -> 930 | Q13: ='ALL DATA & IT4PROFIT'!K15 -> 919 | R13: ='ALL DATA & IT4PROFIT'!D15 -> 971
B14: ='ALL DATA & IT4PROFIT'!A16 -> HUAWEI | C14: ='ALL DATA & IT4PROFIT'!B16 -> SUN2000-6KTL-M1 | D14: ='ALL DATA & IT4PROFIT'!C16 -> 3PH HYBRID | E14: 1 | F14: ='ALL DATA & IT4PROFIT'!F16 -> 996 | G14: =F14+$G$204 -> 1026 | H14: =(G14*$E$204)+G14 -> 1051.65 | I14: =(J14-H14)/J14 -> 0.05 | J14: =H14/(1-M14) -> 1107 | K14: =SUM(E14*J14) -> 1107 | L14: =SUM(E14*H14) -> 1051.65 | M14: 0.05 | N14: ='ALL DATA & IT4PROFIT'!L16 -> 1040 | P14: ='ALL DATA & IT4PROFIT'!H16 -> 1090 | Q14: ='ALL DATA & IT4PROFIT'!K16 -> 1028 | R14: ='ALL DATA & IT4PROFIT'!D16 -> 1086
B15: ='ALL DATA & IT4PROFIT'!A17 -> HUAWEI | C15: ='ALL DATA & IT4PROFIT'!B17 -> SUN2000-8KTL-M1 | D15: ='ALL DATA & IT4PROFIT'!C17 -> 3PH HYBRID | E15: 1 | F15: ='ALL DATA & IT4PROFIT'!F17 -> 1179.6 | G15: =F15+$G$204 -> 1209.6 | H15: =(G15*$E$204)+G15 -> 1239.84 | I15: =(J15-H15)/J15 -> 0.05 | J15: =H15/(1-M15) -> 1305.0947 | K15: =SUM(E15*J15) -> 1305.0947 | L15: =SUM(E15*H15) -> 1239.84 | M15: 0.05 | N15: ='ALL DATA & IT4PROFIT'!L17 -> 1235 | P15: ='ALL DATA & IT4PROFIT'!H17 -> 1260 | Q15: ='ALL DATA & IT4PROFIT'!K17 -> 1219 | R15: ='ALL DATA & IT4PROFIT'!D17 -> 1289
B16: ='ALL DATA & IT4PROFIT'!A18 -> HUAWEI | C16: ='ALL DATA & IT4PROFIT'!B18 -> SUN2000-10KTL-M1 | D16: ='ALL DATA & IT4PROFIT'!C18 -> 3PH HYBRID | E16: 1 | F16: ='ALL DATA & IT4PROFIT'!F18 -> 1324.2 | G16: =F16+$G$204 -> 1354.2 | H16: =(G16*$E$204)+G16 -> 1388.055 | I16: =(J16-H16)/J16 -> 0.05 | J16: =H16/(1-M16) -> 1461.1105 | K16: =SUM(E16*J16) -> 1461.1105 | L16: =SUM(E16*H16) -> 1388.055 | M16: 0.05 | N16: ='ALL DATA & IT4PROFIT'!L18 -> 1385 | P16: ='ALL DATA & IT4PROFIT'!H18 -> 1385 | Q16: ='ALL DATA & IT4PROFIT'!K18 -> 1369 | R16: ='ALL DATA & IT4PROFIT'!D18 -> 1448
B17: ='ALL DATA & IT4PROFIT'!A19 -> HUAWEI | C17: ='ALL DATA & IT4PROFIT'!B19 -> SUN2000-12KTL-M5 | D17: ='ALL DATA & IT4PROFIT'!C19 -> 3PH HYBRID | E17: 1 | F17: ='ALL DATA & IT4PROFIT'!F19 -> 1387.2 | G17: =F17+$G$204 -> 1417.2 | H17: =(G17*$E$204)+G17 -> 1452.63 | I17: =(J17-H17)/J17 -> 0.05 | J17: =H17/(1-M17) -> 1529.0842 | K17: =SUM(E17*J17) -> 1529.0842 | L17: =SUM(E17*H17) -> 1452.63 | M17: 0.05 | N17: ='ALL DATA & IT4PROFIT'!L19 -> 1450 | P17: ='ALL DATA & IT4PROFIT'!H19 | Q17: ='ALL DATA & IT4PROFIT'!K19 -> 947.6 | R17: ='ALL DATA & IT4PROFIT'!D19 -> 1515
B18: ='ALL DATA & IT4PROFIT'!A20 -> HUAWEI | C18: ='ALL DATA & IT4PROFIT'!B20 -> SUN2000-15KTL-M5 | D18: ='ALL DATA & IT4PROFIT'!C20 -> 3PH HYBRID | E18: 1 | F18: ='ALL DATA & IT4PROFIT'!F20 -> 1564.2 | G18: =F18+$G$204 -> 1594.2 | H18: =(G18*$E$204)+G18 -> 1634.055 | I18: =(J18-H18)/J18 -> 0.05 | J18: =H18/(1-M18) -> 1720.0579 | K18: =SUM(E18*J18) -> 1720.0579 | L18: =SUM(E18*H18) -> 1634.055 | M18: 0.05 | N18: ='ALL DATA & IT4PROFIT'!L20 -> 1640 | P18: ='ALL DATA & IT4PROFIT'!H20 | Q18: ='ALL DATA & IT4PROFIT'!K20 -> 1133.5 | R18: ='ALL DATA & IT4PROFIT'!D20 -> 1710
B19: ='ALL DATA & IT4PROFIT'!A21 -> HUAWEI | C19: ='ALL DATA & IT4PROFIT'!B21 -> SUN2000-17KTL-M5 | D19: ='ALL DATA & IT4PROFIT'!C21 -> 3PH HYBRID | E19: 1 | F19: ='ALL DATA & IT4PROFIT'!F21 -> 1597.2 | G19: =F19+$G$204 -> 1627.2 | H19: =(G19*$E$204)+G19 -> 1667.88 | I19: =(J19-H19)/J19 -> 0.05 | J19: =H19/(1-M19) -> 1755.6632 | K19: =SUM(E19*J19) -> 1755.6632 | L19: =SUM(E19*H19) -> 1667.88 | M19: 0.05 | N19: ='ALL DATA & IT4PROFIT'!L21 -> 1675 | P19: ='ALL DATA & IT4PROFIT'!H21 | Q19: ='ALL DATA & IT4PROFIT'!K21 -> 1167.6 | R19: ='ALL DATA & IT4PROFIT'!D21 -> 1447
B20: ='ALL DATA & IT4PROFIT'!A22 -> HUAWEI | C20: ='ALL DATA & IT4PROFIT'!B22 -> SUN2000-20KTL-M5 | D20: ='ALL DATA & IT4PROFIT'!C22 -> 3PH HYBRID | E20: 1 | F20: ='ALL DATA & IT4PROFIT'!F22 -> 1687.2 | G20: =F20+$G$204 -> 1717.2 | H20: =(G20*$E$204)+G20 -> 1760.13 | I20: =(J20-H20)/J20 -> 0.05 | J20: =H20/(1-M20) -> 1852.7684 | K20: =SUM(E20*J20) -> 1852.7684 | L20: =SUM(E20*H20) -> 1760.13 | M20: 0.05 | N20: ='ALL DATA & IT4PROFIT'!L22 -> 1790 | P20: ='ALL DATA & IT4PROFIT'!H22 | Q20: ='ALL DATA & IT4PROFIT'!K22 -> 1262.2 | R20: ='ALL DATA & IT4PROFIT'!D22 -> 1844
B21: ='ALL DATA & IT4PROFIT'!A23 -> HUAWEI | C21: ='ALL DATA & IT4PROFIT'!B23 -> SUN2000-25KTL-M5 | D21: ='ALL DATA & IT4PROFIT'!C23 -> 3PH HYBRID | E21: 1 | F21: ='ALL DATA & IT4PROFIT'!F23 -> 1742.4 | G21: =F21+$G$204 -> 1772.4 | H21: =(G21*$E$204)+G21 -> 1816.71 | I21: =(J21-H21)/J21 -> 0.05 | J21: =H21/(1-M21) -> 1912.3263 | K21: =SUM(E21*J21) -> 1912.3263 | L21: =SUM(E21*H21) -> 1816.71 | M21: 0.05 | N21: ='ALL DATA & IT4PROFIT'!L23 -> 1825 | P21: ='ALL DATA & IT4PROFIT'!H23 | Q21: ='ALL DATA & IT4PROFIT'!K23 -> 1320.5 | R21: ='ALL DATA & IT4PROFIT'!D23 -> 1906
B22: ='ALL DATA & IT4PROFIT'!A24 -> HUAWEI | C22: ='ALL DATA & IT4PROFIT'!B24 -> SUN2000-30KTL-M3 | D22: ='ALL DATA & IT4PROFIT'!C24 -> 3PH HYBRID | E22: 1 | F22: ='ALL DATA & IT4PROFIT'!F24 -> 1926 | G22: =F22+$G$204 -> 1956 | H22: =(G22*$E$204)+G22 -> 2004.9 | I22: =(J22-H22)/J22 -> 0.05 | J22: =H22/(1-M22) -> 2110.4211 | K22: =SUM(E22*J22) -> 2110.4211 | L22: =SUM(E22*H22) -> 2004.9 | M22: 0.05 | N22: ='ALL DATA & IT4PROFIT'!L24 -> 2080 | P22: ='ALL DATA & IT4PROFIT'!H24 | Q22: ='ALL DATA & IT4PROFIT'!K24 -> 1993 | R22: ='ALL DATA & IT4PROFIT'!D24 -> 2106
... B31: ='ALL DATA & IT4PROFIT'!A33 -> HUAWEI | C31: ='ALL DATA & IT4PROFIT'!B33 -> SUN2000-20KTL-MBO | D31: ='ALL DATA & IT4PROFIT'!C33 -> 3PH HYBRID | E31: 1 | F31: ='ALL DATA & IT4PROFIT'!F33 -> 2034 | G31: =F31+$G$204 -> 2064 | H31: =(G31*$E$204)+G31 -> 2115.6 | I31: =(J31-H31)/J31 -> 0.05 | J31: =H31/(1-M31) -> 2226.9474 | K31: =SUM(E31*J31) -> 2226.9474 | L31: =SUM(E31*H31) -> 2115.6 | M31: 0.05 | N31: ='ALL DATA & IT4PROFIT'!L33 -> 2150 | P31: ='ALL DATA & IT4PROFIT'!H33 | Q31: ='ALL DATA & IT4PROFIT'!K33 | R31: ='ALL DATA & IT4PROFIT'!D33
B32: ='ALL DATA & IT4PROFIT'!A35 -> HUAWEI | C32: ='ALL DATA & IT4PROFIT'!B35 -> SUN2000-450W-P2 | D32: ='ALL DATA & IT4PROFIT'!C35 -> OPTIMIZER | E32: 1 | F32: ='ALL DATA & IT4PROFIT'!F35 -> 36 | G32: =F32+$G$205 -> 39 | H32: =(G32*$E$204)+G32 -> 39.975 | I32: =(J32-H32)/J32 -> 0.1117 | J32: =H32/(1-M32) -> 45.001689 | K32: =SUM(E32*J32) -> 45.001689 | L32: =SUM(E32*H32) -> 39.975 | M32: 0.1117 | N32: ='ALL DATA & IT4PROFIT'!L35 -> 40 | P32: ='ALL DATA & IT4PROFIT'!H35 | Q32: ='ALL DATA & IT4PROFIT'!K35 -> 38.5 | R32: ='ALL DATA & IT4PROFIT'!D35 -> 41
B33: ='ALL DATA & IT4PROFIT'!A36 -> HUAWEI | C33: ='ALL DATA & IT4PROFIT'!B36 -> SUN2000-600W-P | D33: ='ALL DATA & IT4PROFIT'!C36 -> OPTIMIZER | E33: 1 | F33: ='ALL DATA & IT4PROFIT'!F36 -> 39 | G33: =F33+$G$205 -> 42 | H33: =(G33*$E$204)+G33 -> 43.05 | I33: =(J33-H33)/J33 -> 0.103 | J33: =H33/(1-M33) -> 47.993311 | K33: =SUM(E33*J33) -> 47.993311 | L33: =SUM(E33*H33) -> 43.05 | M33: 0.103 | N33: ='ALL DATA & IT4PROFIT'!L36 -> 40 | P33: ='ALL DATA & IT4PROFIT'!H36 | Q33: ='ALL DATA & IT4PROFIT'!K36 -> 39 | R33: ='ALL DATA & IT4PROFIT'!D36 -> 41
B34: ='ALL DATA & IT4PROFIT'!A37 | C34: ='ALL DATA & IT4PROFIT'!B37 | D34: ='ALL DATA & IT4PROFIT'!C37 | E34: 1 | F34: ='ALL DATA & IT4PROFIT'!F37 | G34: =F34+$G$204 -> 30 | H34: =(G34*$E$204)+G34 -> 30.75 | I34: =(J34-H34)/J34 -> 0.1 | J34: =H34/(1-M34) -> 34.166667 | K34: =SUM(E34*J34) -> 34.166667 | L34: =SUM(E34*H34) -> 30.75 | M34: 0.1 | N34: ='ALL DATA & IT4PROFIT'!L37 | P34: ='ALL DATA & IT4PROFIT'!H37 | Q34: ='ALL DATA & IT4PROFIT'!K37 | R34: ='ALL DATA & IT4PROFIT'!D37
B35: ='ALL DATA & IT4PROFIT'!A38 | C35: ='ALL DATA & IT4PROFIT'!B38 | D35: ='ALL DATA & IT4PROFIT'!C38 | E35: 1 | F35: ='ALL DATA & IT4PROFIT'!F38 | G35: =F35+$G$204 -> 30 | H35: =(G35*$E$204)+G35 -> 30.75 | I35: =(J35-H35)/J35 -> 0.1 | J35: =H35/(1-M35) -> 34.166667 | K35: =SUM(E35*J35) -> 34.166667 | L35: =SUM(E35*H35) -> 30.75 | M35: 0.1 | N35: ='ALL DATA & IT4PROFIT'!L38 | P35: ='ALL DATA & IT4PROFIT'!H38 | Q35: ='ALL DATA & IT4PROFIT'!K38 | R35: ='ALL DATA & IT4PROFIT'!D38
B36: ='ALL DATA & IT4PROFIT'!A39 -> SUNGROW | C36: ='ALL DATA & IT4PROFIT'!B39 -> IV SUNG SG2.0RS | D36: ='ALL DATA & IT4PROFIT'!C39 -> 1PH | E36: 1 | F36: ='ALL DATA & IT4PROFIT'!F39 -> 393 | G36: =F36+$G$204 -> 423 | H36: =(G36*$E$204)+G36 -> 433.575 | I36: =(J36-H36)/J36 -> 0.1 | J36: =H36/(1-M36) -> 481.75 | K36: =SUM(E36*J36) -> 481.75 | L36: =SUM(E36*H36) -> 433.575 | M36: 0.1 | N36: ='ALL DATA & IT4PROFIT'!L39 | P36: ='ALL DATA & IT4PROFIT'!H39 | Q36: ='ALL DATA & IT4PROFIT'!K39 | R36: ='ALL DATA & IT4PROFIT'!D39
B37: ='ALL DATA & IT4PROFIT'!A40 -> SUNGROW | C37: ='ALL DATA & IT4PROFIT'!B40 -> IV SUNG SG3.0RS | D37: ='ALL DATA & IT4PROFIT'!C40 -> 1PH | E37: 1 | F37: ='ALL DATA & IT4PROFIT'!F40 -> 462 | G37: =F37+$G$204 -> 492 | H37: =(G37*$E$204)+G37 -> 504.3 | I37: =(J37-H37)/J37 -> 0.1 | J37: =H37/(1-M37) -> 560.33333 | K37: =SUM(E37*J37) -> 560.33333 | L37: =SUM(E37*H37) -> 504.3 | M37: 0.1 | N37: ='ALL DATA & IT4PROFIT'!L40 | P37: ='ALL DATA & IT4PROFIT'!H40 | Q37: ='ALL DATA & IT4PROFIT'!K40 | R37: ='ALL DATA & IT4PROFIT'!D40
B38: ='ALL DATA & IT4PROFIT'!A41 -> SUNGROW | C38: ='ALL DATA & IT4PROFIT'!B41 -> IV SUNG SG4.0RS | D38: ='ALL DATA & IT4PROFIT'!C41 -> 1PH | E38: 1 | F38: ='ALL DATA & IT4PROFIT'!F41 -> 549.6 | G38: =F38+$G$204 -> 579.6 | H38: =(G38*$E$204)+G38 -> 594.09 | I38: =(J38-H38)/J38 -> 0.1 | J38: =H38/(1-M38) -> 660.1 | K38: =SUM(E38*J38) -> 660.1 | L38: =SUM(E38*H38) -> 594.09 | M38: 0.1 | N38: ='ALL DATA & IT4PROFIT'!L41 | P38: ='ALL DATA & IT4PROFIT'!H41 | Q38: ='ALL DATA & IT4PROFIT'!K41 | R38: ='ALL DATA & IT4PROFIT'!D41
B39: ='ALL DATA & IT4PROFIT'!A42 -> SUNGROW | C39: ='ALL DATA & IT4PROFIT'!B42 -> IV SUNG SG5.0RS | D39: ='ALL DATA & IT4PROFIT'!C42 -> 1PH | E39: 1 | F39: ='ALL DATA & IT4PROFIT'!F42 -> 593.4 | G39: =F39+$G$204 -> 623.4 | H39: =(G39*$E$204)+G39 -> 638.985 | I39: =(J39-H39)/J39 -> 0.1 | J39: =H39/(1-M39) -> 709.98333 | K39: =SUM(E39*J39) -> 709.98333 | L39: =SUM(E39*H39) -> 638.985 | M39: 0.1 | N39: ='ALL DATA & IT4PROFIT'!L42 | P39: ='ALL DATA & IT4PROFIT'!H42 | Q39: ='ALL DATA & IT4PROFIT'!K42 | R39: ='ALL DATA & IT4PROFIT'!D42
B40: ='ALL DATA & IT4PROFIT'!A43 -> SUNGROW | C40: ='ALL DATA & IT4PROFIT'!B43 -> IV SUNG SG3.0RT | D40: ='ALL DATA & IT4PROFIT'!C43 -> 3PH | E40: 1 | F40: ='ALL DATA & IT4PROFIT'!F43 -> 648 | G40: =F40+$G$204 -> 678 | H40: =(G40*$E$204)+G40 -> 694.95 | I40: =(J40-H40)/J40 -> 0.1 | J40: =H40/(1-M40) -> 772.16667 | K40: =SUM(E40*J40) -> 772.16667 | L40: =SUM(E40*H40) -> 694.95 | M40: 0.1 | N40: ='ALL DATA & IT4PROFIT'!L43 | P40: ='ALL DATA & IT4PROFIT'!H43 | Q40: ='ALL DATA & IT4PROFIT'!K43 | R40: ='ALL DATA & IT4PROFIT'!D43
B41: ='ALL DATA & IT4PROFIT'!A44 -> SUNGROW | C41: ='ALL DATA & IT4PROFIT'!B44 -> IV SUNG SG4.0RT | D41: ='ALL DATA & IT4PROFIT'!C44 -> 3PH | E41: 1 | F41: ='ALL DATA & IT4PROFIT'!F44 -> 683.4 | G41: =F41+$G$204 -> 713.4 | H41: =(G41*$E$204)+G41 -> 731.235 | I41: =(J41-H41)/J41 -> 0.1 | J41: =H41/(1-M41) -> 812.48333 | K41: =SUM(E41*J41) -> 812.48333 | L41: =SUM(E41*H41) -> 731.235 | M41: 0.1 | N41: ='ALL DATA & IT4PROFIT'!L44 | P41: ='ALL DATA & IT4PROFIT'!H44 | Q41: ='ALL DATA & IT4PROFIT'!K44 | R41: ='ALL DATA & IT4PROFIT'!D44
B42: ='ALL DATA & IT4PROFIT'!A45 -> SUNGROW | C42: ='ALL DATA & IT4PROFIT'!B45 -> IV SUNG SG5.0RT | D42: ='ALL DATA & IT4PROFIT'!C45 -> 3PH | E42: 1 | F42: ='ALL DATA & IT4PROFIT'!F45 -> 729 | G42: =F42+$G$204 -> 759 | H42: =(G42*$E$204)+G42 -> 777.975 | I42: =(J42-H42)/J42 -> 0.1 | J42: =H42/(1-M42) -> 864.41667 | K42: =SUM(E42*J42) -> 864.41667 | L42: =SUM(E42*H42) -> 777.975 | M42: 0.1 | N42: ='ALL DATA & IT4PROFIT'!L45 | P42: ='ALL DATA & IT4PROFIT'!H45 | Q42: ='ALL DATA & IT4PROFIT'!K45 | R42: ='ALL DATA & IT4PROFIT'!D45
B43: ='ALL DATA & IT4PROFIT'!A46 -> SUNGROW | C43: ='ALL DATA & IT4PROFIT'!B46 -> IV SUNG SG6.0RT | D43: ='ALL DATA & IT4PROFIT'!C46 -> 3PH | E43: 1 | F43: ='ALL DATA & IT4PROFIT'!F46 -> 747 | G43: =F43+$G$204 -> 777 | H43: =(G43*$E$204)+G43 -> 796.425 | I43: =(J43-H43)/J43 -> 0.1 | J43: =H43/(1-M43) -> 884.91667 | K43: =SUM(E43*J43) -> 884.91667 | L43: =SUM(E43*H43) -> 796.425 | M43: 0.1 | N43: ='ALL DATA & IT4PROFIT'!L46 | P43: ='ALL DATA & IT4PROFIT'!H46 | Q43: ='ALL DATA & IT4PROFIT'!K46 | R43: ='ALL DATA & IT4PROFIT'!D46
B44: ='ALL DATA & IT4PROFIT'!A47 -> SUNGROW | C44: ='ALL DATA & IT4PROFIT'!B47 -> IV SUNG SG8.0RT | D44: ='ALL DATA & IT4PROFIT'!C47 -> 3PH | E44: 1 | F44: ='ALL DATA & IT4PROFIT'!F47 -> 755.4 | G44: =F44+$G$204 -> 785.4 | H44: =(G44*$E$204)+G44 -> 805.035 | I44: =(J44-H44)/J44 -> 0.1 | J44: =H44/(1-M44) -> 894.48333 | K44: =SUM(E44*J44) -> 894.48333 | L44: =SUM(E44*H44) -> 805.035 | M44: 0.1 | N44: ='ALL DATA & IT4PROFIT'!L47 | P44: ='ALL DATA & IT4PROFIT'!H47 | Q44: ='ALL DATA & IT4PROFIT'!K47 | R44: ='ALL DATA & IT4PROFIT'!D47
B45: ='ALL DATA & IT4PROFIT'!A48 -> SUNGROW | C45: ='ALL DATA & IT4PROFIT'!B48 -> IV SUNG SG10.0RT | D45: ='ALL DATA & IT4PROFIT'!C48 -> 3PH | E45: 1 | F45: ='ALL DATA & IT4PROFIT'!F48 -> 870 | G45: =F45+$G$204 -> 900 | H45: =(G45*$E$204)+G45 -> 922.5 | I45: =(J45-H45)/J45 -> 0.1 | J45: =H45/(1-M45) -> 1025 | K45: =SUM(E45*J45) -> 1025 | L45: =SUM(E45*H45) -> 922.5 | M45: 0.1 | N45: ='ALL DATA & IT4PROFIT'!L48 | P45: ='ALL DATA & IT4PROFIT'!H48 | Q45: ='ALL DATA & IT4PROFIT'!K48 | R45: ='ALL DATA & IT4PROFIT'!D48
... B59: ='ALL DATA & IT4PROFIT'!A62 | C59: ='ALL DATA & IT4PROFIT'!B62 | D59: ='ALL DATA & IT4PROFIT'!C62 | E59: 1 | F59: ='ALL DATA & IT4PROFIT'!F62 | G59: =F59+$G$204 -> 30 | H59: =(G59*$E$204)+G59 -> 30.75 | I59: =(J59-H59)/J59 -> 0.1 | J59: =H59/(1-M59) -> 34.166667 | K59: =SUM(E59*J59) -> 34.166667 | L59: =SUM(E59*H59) -> 30.75 | M59: 0.1 | N59: ='ALL DATA & IT4PROFIT'!L62 | P59: ='ALL DATA & IT4PROFIT'!H62 | Q59: ='ALL DATA & IT4PROFIT'!K62 | R59: ='ALL DATA & IT4PROFIT'!D62
B60: ='ALL DATA & IT4PROFIT'!A63 -> FRONIUS | C60: ='ALL DATA & IT4PROFIT'!B63 -> PRIMO 3.0 | D60: ='ALL DATA & IT4PROFIT'!C63 -> 1PH | E60: 1 | F60: ='ALL DATA & IT4PROFIT'!F63 -> 814.2 | G60: =F60+$G$204 -> 844.2 | H60: =(G60*$E$204)+G60 -> 865.305 | I60: =(J60-H60)/J60 -> 0.1 | J60: =H60/(1-M60) -> 961.45 | K60: =SUM(E60*J60) -> 961.45 | L60: =SUM(E60*H60) -> 865.305 | M60: 0.1 | N60: ='ALL DATA & IT4PROFIT'!L63 | O60: =1570-1570*0.42 -> 910.6 | P60: ='ALL DATA & IT4PROFIT'!H63 -> 950 | Q60: ='ALL DATA & IT4PROFIT'!K63 | R60: ='ALL DATA & IT4PROFIT'!D63
B61: ='ALL DATA & IT4PROFIT'!A64 -> FRONIUS | C61: ='ALL DATA & IT4PROFIT'!B64 -> Fronius Primo 3.6-1 | D61: ='ALL DATA & IT4PROFIT'!C64 | E61: 1 | F61: ='ALL DATA & IT4PROFIT'!F64 -> 0 | G61: =F61+$G$204 -> 30 | H61: =(G61*$E$204)+G61 -> 30.75 | I61: =(J61-H61)/J61 -> 0.1 | J61: =H61/(1-M61) -> 34.166667 | K61: =SUM(E61*J61) -> 34.166667 | L61: =SUM(E61*H61) -> 30.75 | M61: 0.1 | N61: ='ALL DATA & IT4PROFIT'!L64 | P61: ='ALL DATA & IT4PROFIT'!H64 | Q61: ='ALL DATA & IT4PROFIT'!K64 | R61: ='ALL DATA & IT4PROFIT'!D64
...

Sheet Inverter price analysis Energy3
A1: BEU: | C1: Partner: | G1: Location: | P1: COMPETITION PRICES
G2: *distr.price+freight | J2: *devide (LCP CY)/(1-GM)
B3: Brand | C3: Description | D3: Type | E3: QTY | F3: Distributor Energy3000 Price | G3: LCP CY (€) | H3: Final LCP CY | I3: ASKY GM % | J3: Final Price to Customer | K3: Revenue | L3: LCP CY Revenue | M3: Desired GM | N3: CONERCON ENERGY | O3: BIG SOLAR | P3: DR. ENERGY | Q3: TRIKKIS ENERGY | R3: KAFKAS
B4: ='ALL DATA & IT4PROFIT'!A6 -> HUAWEI | C4: ='ALL DATA & IT4PROFIT'!B6 -> SUN2000-2KTL-L1 | D4: ='ALL DATA & IT4PROFIT'!C6 -> 1PH HYBRID | E4: 1 | F4: ='ALL DATA & IT4PROFIT'!R6 -> 449 | G4: =F4+$G$190 -> 539 | H4: =(G4*$E$190)+G4 -> 552.475 | I4: =(J4-H4)/J4 -> 0.07 | J4: =H4/(1-M4) -> 594.05914 | K4: =SUM(E4*J4) -> 594.05914 | L4: =SUM(E4*H4) -> 552.475 | M4: 0.07 | N4: ='ALL DATA & IT4PROFIT'!L6 -> 420 | P4: ='ALL DATA & IT4PROFIT'!H6 -> 557 | Q4: ='ALL DATA & IT4PROFIT'!K6 -> 344 | R4: ='ALL DATA & IT4PROFIT'!D6 -> 489
B5: ='ALL DATA & IT4PROFIT'!A7 -> HUAWEI | C5: ='ALL DATA & IT4PROFIT'!B7 -> SUN2000-3KTL-L1 | D5: ='ALL DATA & IT4PROFIT'!C7 -> 1PH HYBRID | E5: 1 | F5: ='ALL DATA & IT4PROFIT'!R7 -> 529 | G5: =F5+$G$190 -> 619 | H5: =(G5*$E$190)+G5 -> 634.475 | I5: =(J5-H5)/J5 -> 0.07 | J5: =H5/(1-M5) -> 682.23118 | K5: =SUM(E5*J5) -> 682.23118 | L5: =SUM(E5*H5) -> 634.475 | M5: 0.07 | N5: ='ALL DATA & IT4PROFIT'!L7 -> 510 | P5: ='ALL DATA & IT4PROFIT'!H7 -> 545 | Q5: ='ALL DATA & IT4PROFIT'!K7 -> 432 | R5: ='ALL DATA & IT4PROFIT'!D7 -> 575
B6: ='ALL DATA & IT4PROFIT'!A8 -> HUAWEI | C6: ='ALL DATA & IT4PROFIT'!B8 -> SUN2000-3.68KTL-L1 | D6: ='ALL DATA & IT4PROFIT'!C8 -> 1PH HYBRID | E6: 1 | F6: ='ALL DATA & IT4PROFIT'!R8 -> 523 | G6: =F6+$G$190 -> 613 | H6: =(G6*$E$190)+G6 -> 628.325 | I6: =(J6-H6)/J6 -> 0.07 | J6: =H6/(1-M6) -> 675.61828 | K6: =SUM(E6*J6) -> 675.61828 | L6: =SUM(E6*H6) -> 628.325 | M6: 0.07 | N6: ='ALL DATA & IT4PROFIT'!L8 -> 580 | P6: ='ALL DATA & IT4PROFIT'!H8 | Q6: ='ALL DATA & IT4PROFIT'!K8 | R6: ='ALL DATA & IT4PROFIT'!D8 -> 677
B7: ='ALL DATA & IT4PROFIT'!A9 -> HUAWEI | C7: ='ALL DATA & IT4PROFIT'!B9 -> SUN2000-4KTL-L1 | D7: ='ALL DATA & IT4PROFIT'!C9 -> 1PH HYBRID | E7: 1 | F7: ='ALL DATA & IT4PROFIT'!R9 -> 648 | G7: =F7+$G$190 -> 738 | H7: =(G7*$E$190)+G7 -> 756.45 | I7: =(J7-H7)/J7 -> 0.07 | J7: =H7/(1-M7) -> 813.3871 | K7: =SUM(E7*J7) -> 813.3871 | L7: =SUM(E7*H7) -> 756.45 | M7: 0.07 | N7: ='ALL DATA & IT4PROFIT'!L9 -> 620 | P7: ='ALL DATA & IT4PROFIT'!H9 -> 580 | Q7: ='ALL DATA & IT4PROFIT'!K9 -> 563 | R7: ='ALL DATA & IT4PROFIT'!D9 -> 705
B8: ='ALL DATA & IT4PROFIT'!A10 -> HUAWEI | C8: ='ALL DATA & IT4PROFIT'!B10 -> SUN2000-4.6KTL-L1 | D8: ='ALL DATA & IT4PROFIT'!C10 -> 1PH HYBRID | E8: 1 | F8: ='ALL DATA & IT4PROFIT'!R10 -> 696 | G8: =F8+$G$190 -> 786 | H8: =(G8*$E$190)+G8 -> 805.65 | I8: =(J8-H8)/J8 -> 0.07 | J8: =H8/(1-M8) -> 866.29032 | K8: =SUM(E8*J8) -> 866.29032 | L8: =SUM(E8*H8) -> 805.65 | M8: 0.07 | N8: ='ALL DATA & IT4PROFIT'!L10 -> 645 | P8: ='ALL DATA & IT4PROFIT'!H10 -> 595 | Q8: ='ALL DATA & IT4PROFIT'!K10 -> 616 | R8: ='ALL DATA & IT4PROFIT'!D10 -> 756
B9: ='ALL DATA & IT4PROFIT'!A11 -> HUAWEI | C9: ='ALL DATA & IT4PROFIT'!B11 -> SUN2000-5KTL-L1 | D9: ='ALL DATA & IT4PROFIT'!C11 -> 1PH HYBRID | E9: 1 | F9: ='ALL DATA & IT4PROFIT'!R11 -> 703 | G9: =F9+$G$190 -> 793 | H9: =(G9*$E$190)+G9 -> 812.825 | I9: =(J9-H9)/J9 -> 0.07 | J9: =H9/(1-M9) -> 874.00538 | K9: =SUM(E9*J9) -> 874.00538 | L9: =SUM(E9*H9) -> 812.825 | M9: 0.07 | N9: ='ALL DATA & IT4PROFIT'!L11 -> 660 | P9: ='ALL DATA & IT4PROFIT'!H11 -> 620 | Q9: ='ALL DATA & IT4PROFIT'!K11 -> 624 | R9: ='ALL DATA & IT4PROFIT'!D11 -> 764
B10: ='ALL DATA & IT4PROFIT'!A12 -> HUAWEI | C10: ='ALL DATA & IT4PROFIT'!B12 -> SUN2000-6KTL-L1 | D10: ='ALL DATA & IT4PROFIT'!C12 -> 1PH HYBRID | E10: 1 | F10: ='ALL DATA & IT4PROFIT'!R12 -> 799 | G10: =F10+$G$190 -> 889 | H10: =(G10*$E$190)+G10 -> 911.225 | I10: =(J10-H10)/J10 -> 0.07 | J10: =H10/(1-M10) -> 979.81183 | K10: =SUM(E10*J10) -> 979.81183 | L10: =SUM(E10*H10) -> 911.225 | M10: 0.07 | N10: ='ALL DATA & IT4PROFIT'!L12 | P10: ='ALL DATA & IT4PROFIT'!H12 | Q10: ='ALL DATA & IT4PROFIT'!K12 | R10: ='ALL DATA & IT4PROFIT'!D12 -> 868
B11: ='ALL DATA & IT4PROFIT'!A13 -> HUAWEI | C11: ='ALL DATA & IT4PROFIT'!B13 -> SUN2000-3KTL-M1 | D11: ='ALL DATA & IT4PROFIT'!C13 -> 3PH HYBRID | E11: 1 | F11: ='ALL DATA & IT4PROFIT'!R13 -> 794 | G11: =F11+$G$190 -> 884 | H11: =(G11*$E$190)+G11 -> 906.1 | I11: =(J11-H11)/J11 -> 0.07 | J11: =H11/(1-M11) -> 974.30108 | K11: =SUM(E11*J11) -> 974.30108 | L11: =SUM(E11*H11) -> 906.1 | M11: 0.07 | N11: ='ALL DATA & IT4PROFIT'!L13 -> 845 | P11: ='ALL DATA & IT4PROFIT'!H13 -> 907 | Q11: ='ALL DATA & IT4PROFIT'!K13 -> 832 | R11: ='ALL DATA & IT4PROFIT'!D13 -> 880
B12: ='ALL DATA & IT4PROFIT'!A14 -> HUAWEI | C12: ='ALL DATA & IT4PROFIT'!B14 -> SUN2000-4KTL-M1 | D12: ='ALL DATA & IT4PROFIT'!C14 -> 3PH HYBRID | E12: 1 | F12: ='ALL DATA & IT4PROFIT'!R14 -> 830 | G12: =F12+$G$190 -> 920 | H12: =(G12*$E$190)+G12 -> 943 | I12: =(J12-H12)/J12 -> 0.07 | J12: =H12/(1-M12) -> 1013.9785 | K12: =SUM(E12*J12) -> 1013.9785 | L12: =SUM(E12*H12) -> 943 | M12: 0.07 | N12: ='ALL DATA & IT4PROFIT'!L14 -> 880 | P12: ='ALL DATA & IT4PROFIT'!H14 -> 906 | Q12: ='ALL DATA & IT4PROFIT'!K14 -> 871 | R12: ='ALL DATA & IT4PROFIT'!D14 -> 920
B13: ='ALL DATA & IT4PROFIT'!A15 -> HUAWEI | C13: ='ALL DATA & IT4PROFIT'!B15 -> SUN2000-5KTL-M1 | D13: ='ALL DATA & IT4PROFIT'!C15 -> 3PH HYBRID | E13: 1 | F13: ='ALL DATA & IT4PROFIT'!R15 -> 876 | G13: =F13+$G$190 -> 966 | H13: =(G13*$E$190)+G13 -> 990.15 | I13: =(J13-H13)/J13 -> 0.07 | J13: =H13/(1-M13) -> 1064.6774 | K13: =SUM(E13*J13) -> 1064.6774 | L13: =SUM(E13*H13) -> 990.15 | M13: 0.07 | N13: ='ALL DATA & IT4PROFIT'!L15 -> 930 | P13: ='ALL DATA & IT4PROFIT'!H15 -> 930 | Q13: ='ALL DATA & IT4PROFIT'!K15 -> 919 | R13: ='ALL DATA & IT4PROFIT'!D15 -> 971
B14: ='ALL DATA & IT4PROFIT'!A16 -> HUAWEI | C14: ='ALL DATA & IT4PROFIT'!B16 -> SUN2000-6KTL-M1 | D14: ='ALL DATA & IT4PROFIT'!C16 -> 3PH HYBRID | E14: 1 | F14: ='ALL DATA & IT4PROFIT'!R16 -> 980 | G14: =F14+$G$190 -> 1070 | H14: =(G14*$E$190)+G14 -> 1096.75 | I14: =(J14-H14)/J14 -> 0.07 | J14: =H14/(1-M14) -> 1179.3011 | K14: =SUM(E14*J14) -> 1179.3011 | L14: =SUM(E14*H14) -> 1096.75 | M14: 0.07 | N14: ='ALL DATA & IT4PROFIT'!L16 -> 1040 | P14: ='ALL DATA & IT4PROFIT'!H16 -> 1090 | Q14: ='ALL DATA & IT4PROFIT'!K16 -> 1028 | R14: ='ALL DATA & IT4PROFIT'!D16 -> 1086
B15: ='ALL DATA & IT4PROFIT'!A17 -> HUAWEI | C15: ='ALL DATA & IT4PROFIT'!B17 -> SUN2000-8KTL-M1 | D15: ='ALL DATA & IT4PROFIT'!C17 -> 3PH HYBRID | E15: 1 | F15: ='ALL DATA & IT4PROFIT'!R17 -> 1162 | G15: =F15+$G$190 -> 1252 | H15: =(G15*$E$190)+G15 -> 1283.3 | I15: =(J15-H15)/J15 -> 0.07 | J15: =H15/(1-M15) -> 1379.8925 | K15: =SUM(E15*J15) -> 1379.8925 | L15: =SUM(E15*H15) -> 1283.3 | M15: 0.07 | N15: ='ALL DATA & IT4PROFIT'!L17 -> 1235 | P15: ='ALL DATA & IT4PROFIT'!H17 -> 1260 | Q15: ='ALL DATA & IT4PROFIT'!K17 -> 1219 | R15: ='ALL DATA & IT4PROFIT'!D17 -> 1289
... B30: ='ALL DATA & IT4PROFIT'!A32 -> HUAWEI | C30: ='ALL DATA & IT4PROFIT'!B32 -> IV HU SUN2000-330KTL-H1 (1500V) | D30: ='ALL DATA & IT4PROFIT'!C32 | E30: 1 | F30: ='ALL DATA & IT4PROFIT'!R32 | G30: =F30+$G$190 -> 90 | H30: =(G30*$E$190)+G30 -> 92.25 | I30: =(J30-H30)/J30 -> 0.07 | J30: =H30/(1-M30) -> 99.193548 | K30: =SUM(E30*J30) -> 99.193548 | L30: =SUM(E30*H30) -> 92.25 | M30: 0.07 | N30: ='ALL DATA & IT4PROFIT'!L32 | P30: ='ALL DATA & IT4PROFIT'!H32 | Q30: ='ALL DATA & IT4PROFIT'!K32 | R30: ='ALL DATA & IT4PROFIT'!D32
B31: ='ALL DATA & IT4PROFIT'!A34 | C31: ='ALL DATA & IT4PROFIT'!B34 | D31: ='ALL DATA & IT4PROFIT'!C34 | E31: 1 | F31: ='ALL DATA & IT4PROFIT'!R34 | G31: =F31+$G$190 -> 90 | H31: =(G31*$E$190)+G31 -> 92.25 | I31: =(J31-H31)/J31 -> 0.07 | J31: =H31/(1-M31) -> 99.193548 | K31: =SUM(E31*J31) -> 99.193548 | L31: =SUM(E31*H31) -> 92.25 | M31: 0.07 | N31: ='ALL DATA & IT4PROFIT'!L34 | P31: ='ALL DATA & IT4PROFIT'!H34 | Q31: ='ALL DATA & IT4PROFIT'!K34 | R31: ='ALL DATA & IT4PROFIT'!D34
B32: ='ALL DATA & IT4PROFIT'!A35 -> HUAWEI | C32: ='ALL DATA & IT4PROFIT'!B35 -> SUN2000-450W-P2 | D32: ='ALL DATA & IT4PROFIT'!C35 -> OPTIMIZER | E32: 1 | F32: ='ALL DATA & IT4PROFIT'!R35 -> 35 | G32: =F32+$G$191 -> 40 | H32: =(G32*$E$190)+G32 -> 41 | I32: =(J32-H32)/J32 -> 0.07 | J32: =H32/(1-M32) -> 44.086022 | K32: =SUM(E32*J32) -> 44.086022 | L32: =SUM(E32*H32) -> 41 | M32: 0.07 | N32: ='ALL DATA & IT4PROFIT'!L35 -> 40 | P32: ='ALL DATA & IT4PROFIT'!H35 | Q32: ='ALL DATA & IT4PROFIT'!K35 -> 38.5 | R32: ='ALL DATA & IT4PROFIT'!D35 -> 41
B33: ='ALL DATA & IT4PROFIT'!A36 -> HUAWEI | C33: ='ALL DATA & IT4PROFIT'!B36 -> SUN2000-600W-P | D33: ='ALL DATA & IT4PROFIT'!C36 -> OPTIMIZER | E33: 1 | F33: ='ALL DATA & IT4PROFIT'!R36 -> 36.4 | G33: =F33+$G$191 -> 41.4 | H33: =(G33*$E$190)+G33 -> 42.435 | I33: =(J33-H33)/J33 -> 0.07 | J33: =H33/(1-M33) -> 45.629032 | K33: =SUM(E33*J33) -> 45.629032 | L33: =SUM(E33*H33) -> 42.435 | M33: 0.07 | N33: ='ALL DATA & IT4PROFIT'!L36 -> 40 | P33: ='ALL DATA & IT4PROFIT'!H36 | Q33: ='ALL DATA & IT4PROFIT'!K36 -> 39 | R33: ='ALL DATA & IT4PROFIT'!D36 -> 41
B34: ='ALL DATA & IT4PROFIT'!A37 | C34: ='ALL DATA & IT4PROFIT'!B37 | D34: ='ALL DATA & IT4PROFIT'!C37 | E34: 1 | F34: ='ALL DATA & IT4PROFIT'!R37 | G34: =F34+$G$190 -> 90 | H34: =(G34*$E$190)+G34 -> 92.25 | I34: =(J34-H34)/J34 -> 0.07 | J34: =H34/(1-M34) -> 99.193548 | K34: =SUM(E34*J34) -> 99.193548 | L34: =SUM(E34*H34) -> 92.25 | M34: 0.07 | N34: ='ALL DATA & IT4PROFIT'!L37 | P34: ='ALL DATA & IT4PROFIT'!H37 | Q34: ='ALL DATA & IT4PROFIT'!K37 | R34: ='ALL DATA & IT4PROFIT'!D37
B35: ='ALL DATA & IT4PROFIT'!A38 | C35: ='ALL DATA & IT4PROFIT'!B38 | D35: ='ALL DATA & IT4PROFIT'!C38 | E35: 1 | F35: ='ALL DATA & IT4PROFIT'!R38 | G35: =F35+$G$190 -> 90 | H35: =(G35*$E$190)+G35 -> 92.25 | I35: =(J35-H35)/J35 -> 0.07 | J35: =H35/(1-M35) -> 99.193548 | K35: =SUM(E35*J35) -> 99.193548 | L35: =SUM(E35*H35) -> 92.25 | M35: 0.07 | N35: ='ALL DATA & IT4PROFIT'!L38 | P35: ='ALL DATA & IT4PROFIT'!H38 | Q35: ='ALL DATA & IT4PROFIT'!K38 | R35: ='ALL DATA & IT4PROFIT'!D38
B36: ='ALL DATA & IT4PROFIT'!A39 -> SUNGROW | C36: ='ALL DATA & IT4PROFIT'!B39 -> IV SUNG SG2.0RS | D36: ='ALL DATA & IT4PROFIT'!C39 -> 1PH | E36: 1 | F36: ='ALL DATA & IT4PROFIT'!R39 | G36: =F36+$G$190 -> 90 | H36: =(G36*$E$190)+G36 -> 92.25 | I36: =(J36-H36)/J36 -> 0.07 | J36: =H36/(1-M36) -> 99.193548 | K36: =SUM(E36*J36) -> 99.193548 | L36: =SUM(E36*H36) -> 92.25 | M36: 0.07 | N36: ='ALL DATA & IT4PROFIT'!L39 | P36: ='ALL DATA & IT4PROFIT'!H39 | Q36: ='ALL DATA & IT4PROFIT'!K39 | R36: ='ALL DATA & IT4PROFIT'!D39
B37: ='ALL DATA & IT4PROFIT'!A40 -> SUNGROW | C37: ='ALL DATA & IT4PROFIT'!B40 -> IV SUNG SG3.0RS | D37: ='ALL DATA & IT4PROFIT'!C40 -> 1PH | E37: 1 | F37: ='ALL DATA & IT4PROFIT'!R40 | G37: =F37+$G$190 -> 90 | H37: =(G37*$E$190)+G37 -> 92.25 | I37: =(J37-H37)/J37 -> 0.07 | J37: =H37/(1-M37) -> 99.193548 | K37: =SUM(E37*J37) -> 99.193548 | L37: =SUM(E37*H37) -> 92.25 | M37: 0.07 | N37: ='ALL DATA & IT4PROFIT'!L40 | P37: ='ALL DATA & IT4PROFIT'!H40 | Q37: ='ALL DATA & IT4PROFIT'!K40 | R37: ='ALL DATA & IT4PROFIT'!D40
B38: ='ALL DATA & IT4PROFIT'!A41 -> SUNGROW | C38: ='ALL DATA & IT4PROFIT'!B41 -> IV SUNG SG4.0RS | D38: ='ALL DATA & IT4PROFIT'!C41 -> 1PH | E38: 1 | F38: ='ALL DATA & IT4PROFIT'!R41 | G38: =F38+$G$190 -> 90 | H38: =(G38*$E$190)+G38 -> 92.25 | I38: =(J38-H38)/J38 -> 0.07 | J38: =H38/(1-M38) -> 99.193548 | K38: =SUM(E38*J38) -> 99.193548 | L38: =SUM(E38*H38) -> 92.25 | M38: 0.07 | N38: ='ALL DATA & IT4PROFIT'!L41 | P38: ='ALL DATA & IT4PROFIT'!H41 | Q38: ='ALL DATA & IT4PROFIT'!K41 | R38: ='ALL DATA & IT4PROFIT'!D41
B39: ='ALL DATA & IT4PROFIT'!A42 -> SUNGROW | C39: ='ALL DATA & IT4PROFIT'!B42 -> IV SUNG SG5.0RS | D39: ='ALL DATA & IT4PROFIT'!C42 -> 1PH | E39: 1 | F39: ='ALL DATA & IT4PROFIT'!R42 | G39: =F39+$G$190 -> 90 | H39: =(G39*$E$190)+G39 -> 92.25 | I39: =(J39-H39)/J39 -> 0.07 | J39: =H39/(1-M39) -> 99.193548 | K39: =SUM(E39*J39) -> 99.193548 | L39: =SUM(E39*H39) -> 92.25 | M39: 0.07 | N39: ='ALL DATA & IT4PROFIT'!L42 | P39: ='ALL DATA & IT4PROFIT'!H42 | Q39: ='ALL DATA & IT4PROFIT'!K42 | R39: ='ALL DATA & IT4PROFIT'!D42
B40: ='ALL DATA & IT4PROFIT'!A43 -> SUNGROW | C40: ='ALL DATA & IT4PROFIT'!B43 -> IV SUNG SG3.0RT | D40: ='ALL DATA & IT4PROFIT'!C43 -> 3PH | E40: 1 | F40: ='ALL DATA & IT4PROFIT'!R43 | G40: =F40+$G$190 -> 90 | H40: =(G40*$E$190)+G40 -> 92.25 | I40: =(J40-H40)/J40 -> 0.07 | J40: =H40/(1-M40) -> 99.193548 | K40: =SUM(E40*J40) -> 99.193548 | L40: =SUM(E40*H40) -> 92.25 | M40: 0.07 | N40: ='ALL DATA & IT4PROFIT'!L43 | P40: ='ALL DATA & IT4PROFIT'!H43 | Q40: ='ALL DATA & IT4PROFIT'!K43 | R40: ='ALL DATA & IT4PROFIT'!D43
B41: ='ALL DATA & IT4PROFIT'!A44 -> SUNGROW | C41: ='ALL DATA & IT4PROFIT'!B44 -> IV SUNG SG4.0RT | D41: ='ALL DATA & IT4PROFIT'!C44 -> 3PH | E41: 1 | F41: ='ALL DATA & IT4PROFIT'!R44 | G41: =F41+$G$190 -> 90 | H41: =(G41*$E$190)+G41 -> 92.25 | I41: =(J41-H41)/J41 -> 0.07 | J41: =H41/(1-M41) -> 99.193548 | K41: =SUM(E41*J41) -> 99.193548 | L41: =SUM(E41*H41) -> 92.25 | M41: 0.07 | N41: ='ALL DATA & IT4PROFIT'!L44 | P41: ='ALL DATA & IT4PROFIT'!H44 | Q41: ='ALL DATA & IT4PROFIT'!K44 | R41: ='ALL DATA & IT4PROFIT'!D44
B42: ='ALL DATA & IT4PROFIT'!A45 -> SUNGROW | C42: ='ALL DATA & IT4PROFIT'!B45 -> IV SUNG SG5.0RT | D42: ='ALL DATA & IT4PROFIT'!C45 -> 3PH | E42: 1 | F42: ='ALL DATA & IT4PROFIT'!R45 | G42: =F42+$G$190 -> 90 | H42: =(G42*$E$190)+G42 -> 92.25 | I42: =(J42-H42)/J42 -> 0.07 | J42: =H42/(1-M42) -> 99.193548 | K42: =SUM(E42*J42) -> 99.193548 | L42: =SUM(E42*H42) -> 92.25 | M42: 0.07 | N42: ='ALL DATA & IT4PROFIT'!L45 | P42: ='ALL DATA & IT4PROFIT'!H45 | Q42: ='ALL DATA & IT4PROFIT'!K45 | R42: ='ALL DATA & IT4PROFIT'!D45
B43: ='ALL DATA & IT4PROFIT'!A46 -> SUNGROW | C43: ='ALL DATA & IT4PROFIT'!B46 -> IV SUNG SG6.0RT | D43: ='ALL DATA & IT4PROFIT'!C46 -> 3PH | E43: 1 | F43: ='ALL DATA & IT4PROFIT'!R46 | G43: =F43+$G$190 -> 90 | H43: =(G43*$E$190)+G43 -> 92.25 | I43: =(J43-H43)/J43 -> 0.07 | J43: =H43/(1-M43) -> 99.193548 | K43: =SUM(E43*J43) -> 99.193548 | L43: =SUM(E43*H43) -> 92.25 | M43: 0.07 | N43: ='ALL DATA & IT4PROFIT'!L46 | P43: ='ALL DATA & IT4PROFIT'!H46 | Q43: ='ALL DATA & IT4PROFIT'!K46 | R43: ='ALL DATA & IT4PROFIT'!D46
B44: ='ALL DATA & IT4PROFIT'!A47 -> SUNGROW | C44: ='ALL DATA & IT4PROFIT'!B47 -> IV SUNG SG8.0RT | D44: ='ALL DATA & IT4PROFIT'!C47 -> 3PH | E44: 1 | F44: ='ALL DATA & IT4PROFIT'!R47 | G44: =F44+$G$190 -> 90 | H44: =(G44*$E$190)+G44 -> 92.25 | I44: =(J44-H44)/J44 -> 0.07 | J44: =H44/(1-M44) -> 99.193548 | K44: =SUM(E44*J44) -> 99.193548 | L44: =SUM(E44*H44) -> 92.25 | M44: 0.07 | N44: ='ALL DATA & IT4PROFIT'!L47 | P44: ='ALL DATA & IT4PROFIT'!H47 | Q44: ='ALL DATA & IT4PROFIT'!K47 | R44: ='ALL DATA & IT4PROFIT'!D47
B45: ='ALL DATA & IT4PROFIT'!A48 -> SUNGROW | C45: ='ALL DATA & IT4PROFIT'!B48 -> IV SUNG SG10.0RT | D45: ='ALL DATA & IT4PROFIT'!C48 -> 3PH | E45: 1 | F45: ='ALL DATA & IT4PROFIT'!R48 | G45: =F45+$G$190 -> 90 | H45: =(G45*$E$190)+G45 -> 92.25 | I45: =(J45-H45)/J45 -> 0.07 | J45: =H45/(1-M45) -> 99.193548 | K45: =SUM(E45*J45) -> 99.193548 | L45: =SUM(E45*H45) -> 92.25 | M45: 0.07 | N45: ='ALL DATA & IT4PROFIT'!L48 | P45: ='ALL DATA & IT4PROFIT'!H48 | Q45: ='ALL DATA & IT4PROFIT'!K48 | R45: ='ALL DATA & IT4PROFIT'!D48
... B59: ='ALL DATA & IT4PROFIT'!A62 | C59: ='ALL DATA & IT4PROFIT'!B62 | D59: ='ALL DATA & IT4PROFIT'!C62 | E59: 1 | F59: ='ALL DATA & IT4PROFIT'!R62 | G59: =F59+$G$190 -> 90 | H59: =(G59*$E$190)+G59 -> 92.25 | I59: =(J59-H59)/J59 -> 0.07 | J59: =H59/(1-M59) -> 99.193548 | K59: =SUM(E59*J59) -> 99.193548 | L59: =SUM(E59*H59) -> 92.25 | M59: 0.07 | N59: ='ALL DATA & IT4PROFIT'!L62 | P59: ='ALL DATA & IT4PROFIT'!H62 | Q59: ='ALL DATA & IT4PROFIT'!K62 | R59: ='ALL DATA & IT4PROFIT'!D62
B60: ='ALL DATA & IT4PROFIT'!A63 -> FRONIUS | C60: ='ALL DATA & IT4PROFIT'!B63 -> PRIMO 3.0 | D60: ='ALL DATA & IT4PROFIT'!C63 -> 1PH | E60: 1 | F60: ='ALL DATA & IT4PROFIT'!R63 | G60: =F60+$G$190 -> 90 | H60: =(G60*$E$190)+G60 -> 92.25 | I60: =(J60-H60)/J60 -> 0.07 | J60: =H60/(1-M60) -> 99.193548 | K60: =SUM(E60*J60) -> 99.193548 | L60: =SUM(E60*H60) -> 92.25 | M60: 0.07 | N60: ='ALL DATA & IT4PROFIT'!L63 | O60: =1570-1570*0.42 -> 910.6 | P60: ='ALL DATA & IT4PROFIT'!H63 -> 950 | Q60: ='ALL DATA & IT4PROFIT'!K63 | R60: ='ALL DATA & IT4PROFIT'!D63
B61: ='ALL DATA & IT4PROFIT'!A64 -> FRONIUS | C61: ='ALL DATA & IT4PROFIT'!B64 -> Fronius Primo 3.6-1 | D61: ='ALL DATA & IT4PROFIT'!C64 | E61: 1 | F61: ='ALL DATA & IT4PROFIT'!R64 | G61: =F61+$G$190 -> 90 | H61: =(G61*$E$190)+G61 -> 92.25 | I61: =(J61-H61)/J61 -> 0.07 | J61: =H61/(1-M61) -> 99.193548 | K61: =SUM(E61*J61) -> 99.193548 | L61: =SUM(E61*H61) -> 92.25 | M61: 0.07 | N61: ='ALL DATA & IT4PROFIT'!L64 | P61: ='ALL DATA & IT4PROFIT'!H64 | Q61: ='ALL DATA & IT4PROFIT'!K64 | R61: ='ALL DATA & IT4PROFIT'!D64
B62: ='ALL DATA & IT4PROFIT'!A65 -> FRONIUS | C62: ='ALL DATA & IT4PROFIT'!B65 -> PRIMO 4.0 | D62: ='ALL DATA & IT4PROFIT'!C65 -> 1PH | E62: 1 | F62: ='ALL DATA & IT4PROFIT'!R65 | G62: =F62+$G$190 -> 90 | H62: =(G62*$E$190)+G62 -> 92.25 | I62: =(J62-H62)/J62 -> 0.07 | J62: =H62/(1-M62) -> 99.193548 | K62: =SUM(E62*J62) -> 99.193548 | L62: =SUM(E62*H62) -> 92.25 | M62: 0.07 | N62: ='ALL DATA & IT4PROFIT'!L65 | O62: =1740-1740*0.42 -> 1009.2 | P62: ='ALL DATA & IT4PROFIT'!H65 -> 1026 | Q62: ='ALL DATA & IT4PROFIT'!K65 | R62: ='ALL DATA & IT4PROFIT'!D65
B63: ='ALL DATA & IT4PROFIT'!A66 -> FRONIUS | C63: ='ALL DATA & IT4PROFIT'!B66 -> Fronius Primo 4.6-1 | D63: ='ALL DATA & IT4PROFIT'!C66 | E63: 1 | F63: ='ALL DATA & IT4PROFIT'!R66 | G63: =F63+$G$190 -> 90 | H63: =(G63*$E$190)+G63 -> 92.25 | I63: =(J63-H63)/J63 -> 0.07 | J63: =H63/(1-M63) -> 99.193548 | K63: =SUM(E63*J63) -> 99.193548 | L63: =SUM(E63*H63) -> 92.25 | M63: 0.07 | N63: ='ALL DATA & IT4PROFIT'!L66 | P63: ='ALL DATA & IT4PROFIT'!H66 | Q63: ='ALL DATA & IT4PROFIT'!K66 | R63: ='ALL DATA & IT4PROFIT'!D66
B64: ='ALL DATA & IT4PROFIT'!A67 -> FRONIUS | C64: ='ALL DATA & IT4PROFIT'!B67 -> PRIMO 5.0 | D64: ='ALL DATA & IT4PROFIT'!C67 -> 1PH | E64: 1 | F64: ='ALL DATA & IT4PROFIT'!R67 | G64: =F64+$G$190 -> 90 | H64: =(G64*$E$190)+G64 -> 92.25 | I64: =(J64-H64)/J64 -> 0.07 | J64: =H64/(1-M64) -> 99.193548 | K64: =SUM(E64*J64) -> 99.193548 | L64: =SUM(E64*H64) -> 92.25 | M64: 0.07 | N64: ='ALL DATA & IT4PROFIT'!L67 | O64: =1905-1905*0.42 -> 1104.9 | P64: ='ALL DATA & IT4PROFIT'!H67 -> 1124 | Q64: ='ALL DATA & IT4PROFIT'!K67 | R64: ='ALL DATA & IT4PROFIT'!D67
B65: ='ALL DATA & IT4PROFIT'!A68 | C65: ='ALL DATA & IT4PROFIT'!B68 | D65: ='ALL DATA & IT4PROFIT'!C68 | E65: 1 | F65: ='ALL DATA & IT4PROFIT'!R68 | G65: =F65+$G$190 -> 90 | H65: =(G65*$E$190)+G65 -> 92.25 | I65: =(J65-H65)/J65 -> 0.07 | J65: =H65/(1-M65) -> 99.193548 | K65: =SUM(E65*J65) -> 99.193548 | L65: =SUM(E65*H65) -> 92.25 | M65: 0.07 | N65: ='ALL DATA & IT4PROFIT'!L68 | P65: ='ALL DATA & IT4PROFIT'!H68 | Q65: ='ALL DATA & IT4PROFIT'!K68 | R65: ='ALL DATA & IT4PROFIT'!D68
B66: ='ALL DATA & IT4PROFIT'!A69 -> FRONIUS | C66: ='ALL DATA & IT4PROFIT'!B69 -> SYMO 3.0-S | D66: ='ALL DATA & IT4PROFIT'!C69 -> 3PH | E66: 1 | F66: ='ALL DATA & IT4PROFIT'!R69 | G66: =F66+$G$190 -> 90 | H66: =(G66*$E$190)+G66 -> 92.25 | I66: =(J66-H66)/J66 -> 0.07 | J66: =H66/(1-M66) -> 99.193548 | K66: =SUM(E66*J66) -> 99.193548 | L66: =SUM(E66*H66) -> 92.25 | M66: 0.07 | N66: ='ALL DATA & IT4PROFIT'!L69 | O66: =1630-1630*0.42 -> 945.4 | P66: ='ALL DATA & IT4PROFIT'!H69 -> 955 | Q66: ='ALL DATA & IT4PROFIT'!K69 | R66: ='ALL DATA & IT4PROFIT'!D69
