Workbook

Sheet Assumptions
A1: 45.20 MW Solar Park – Cyprus
A2: Preliminary Financial Model – Assumptions
A4: PROJECT
A5: Installed capacity (MW) | B5: 45.2 | C5: MW
A6: Total CAPEX (EPC, BESS, project rights) | B6: 65.25 | C6: EUR mm | D6: Source: user-provided data (handwritten note)
A8: FINANCING STRUCTURE
A9: Equity share | B9: 0.3
A10: Debt share (bank) | B10: =1-B9 -> 0.7
A11: Equity amount | B11: =B6*B9 -> 19.575 | C11: EUR mm
A12: Debt amount (bank loan) | B12: =B6*B10 -> 45.675 | C12: EUR mm
A13: Loan interest rate | B13: 0.05
A14: Loan term | B14: 15 | C14: years
A16: REVENUE AND OPERATING COSTS (YEAR 1)
A17: Annual revenue (Year 1) | B17: 9.7 | C17: EUR mm
A18: O&M (Year 1) | B18: 0.7 | C18: EUR mm
A19: Land lease (Year 1) | B19: 0.12 | C19: EUR mm
A20: Insurance (Year 1) | B20: 0.1 | C20: EUR mm
A21: Total OPEX (Year 1) | B21: =SUM(B18:B20) -> 0.92 | C21: EUR mm
A23: ADDITIONAL ASSUMPTIONS (to be verified – not provided by user)
A24: Revenue degradation/escalation p.a. | B24: -0.004 | D24: ASSUMPTION: typical annual PV panel degradation ~0.4%/yr. Please verify against module datasheet / PPA terms.
A25: OPEX escalation p.a. (inflation) | B25: 0.02 | D25: ASSUMPTION: standard inflation on O&M/insurance/land lease costs, 2%/yr.
A26: Project operating life | B26: 25 | C26: years | D26: ASSUMPTION: typical PV+BESS asset life assumed in the model, 25 years.
A27: Depreciation period (straight-line) | B27: 25 | C27: years | D27: ASSUMPTION: straight-line depreciation of total CAPEX over project life (simplification – BESS may have a shorter useful life).
A28: Corporate tax rate (Cyprus) | B28: 0.125 | D28: Cyprus standard corporate income tax rate = 12.5%.
A29: Equity discount rate (required investor return) | B29: 0.1 | D29: ASSUMPTION: required equity return for a Cyprus RE project ~10%. Please adjust to your own return hurdle.
A30: Project discount rate (indicative WACC) | B30: 0.07

Sheet Debt Schedule
A1: Loan Amortization Schedule (fixed annuity)
A2: Loan amount, interest rate and term are pulled from the Assumptions sheet
A4: Year | B4: Opening balance | C4: Interest | D4: Principal repayment | E4: Annual payment (annuity) | F4: Closing balance
A5: 1 | B5: =Assumptions!$B$12 -> 45.675 | C5: =B5*Assumptions!$B$13 -> 2.28375 | D5: =E5-C5 -> 2.116684 | E5: =-PMT(Assumptions!$B$13,Assumptions!$B$14,Assumptions!$B$12) -> 4.400434 | F5: =B5-D5 -> 43.558316
A6: 2 | B6: =F5 -> 43.558316 | C6: =B6*Assumptions!$B$13 -> 2.1779158 | D6: =E6-C6 -> 2.2225182 | E6: =-PMT(Assumptions!$B$13,Assumptions!$B$14,Assumptions!$B$12) -> 4.400434 | F6: =B6-D6 -> 41.335798
A7: 3 | B7: =F6 -> 41.335798 | C7: =B7*Assumptions!$B$13 -> 2.0667899 | D7: =E7-C7 -> 2.3336441 | E7: =-PMT(Assumptions!$B$13,Assumptions!$B$14,Assumptions!$B$12) -> 4.400434 | F7: =B7-D7 -> 39.002154
A8: 4 | B8: =F7 -> 39.002154 | C8: =B8*Assumptions!$B$13 -> 1.9501077 | D8: =E8-C8 -> 2.4503263 | E8: =-PMT(Assumptions!$B$13,Assumptions!$B$14,Assumptions!$B$12) -> 4.400434 | F8: =B8-D8 -> 36.551827
A9: 5 | B9: =F8 -> 36.551827 | C9: =B9*Assumptions!$B$13 -> 1.8275914 | D9: =E9-C9 -> 2.5728426 | E9: =-PMT(Assumptions!$B$13,Assumptions!$B$14,Assumptions!$B$12) -> 4.400434 | F9: =B9-D9 -> 33.978985
A10: 6 | B10: =F9 -> 33.978985 | C10: =B10*Assumptions!$B$13 -> 1.6989492 | D10: =E10-C10 -> 2.7014847 | E10: =-PMT(Assumptions!$B$13,Assumptions!$B$14,Assumptions!$B$12) -> 4.400434 | F10: =B10-D10 -> 31.2775
A11: 7 | B11: =F10 -> 31.2775 | C11: =B11*Assumptions!$B$13 -> 1.563875 | D11: =E11-C11 -> 2.836559 | E11: =-PMT(Assumptions!$B$13,Assumptions!$B$14,Assumptions!$B$12) -> 4.400434 | F11: =B11-D11 -> 28.440941
A12: 8 | B12: =F11 -> 28.440941 | C12: =B12*Assumptions!$B$13 -> 1.4220471 | D12: =E12-C12 -> 2.9783869 | E12: =-PMT(Assumptions!$B$13,Assumptions!$B$14,Assumptions!$B$12) -> 4.400434 | F12: =B12-D12 -> 25.462554
A13: 9 | B13: =F12 -> 25.462554 | C13: =B13*Assumptions!$B$13 -> 1.2731277 | D13: =E13-C13 -> 3.1273063 | E13: =-PMT(Assumptions!$B$13,Assumptions!$B$14,Assumptions!$B$12) -> 4.400434 | F13: =B13-D13 -> 22.335248
A14: 10 | B14: =F13 -> 22.335248 | C14: =B14*Assumptions!$B$13 -> 1.1167624 | D14: =E14-C14 -> 3.2836716 | E14: =-PMT(Assumptions!$B$13,Assumptions!$B$14,Assumptions!$B$12) -> 4.400434 | F14: =B14-D14 -> 19.051576
A15: 11 | B15: =F14 -> 19.051576 | C15: =B15*Assumptions!$B$13 -> 0.95257881 | D15: =E15-C15 -> 3.4478552 | E15: =-PMT(Assumptions!$B$13,Assumptions!$B$14,Assumptions!$B$12) -> 4.400434 | F15: =B15-D15 -> 15.603721
A16: 12 | B16: =F15 -> 15.603721 | C16: =B16*Assumptions!$B$13 -> 0.78018606 | D16: =E16-C16 -> 3.6202479 | E16: =-PMT(Assumptions!$B$13,Assumptions!$B$14,Assumptions!$B$12) -> 4.400434 | F16: =B16-D16 -> 11.983473
A17: 13 | B17: =F16 -> 11.983473 | C17: =B17*Assumptions!$B$13 -> 0.59917366 | D17: =E17-C17 -> 3.8012603 | E17: =-PMT(Assumptions!$B$13,Assumptions!$B$14,Assumptions!$B$12) -> 4.400434 | F17: =B17-D17 -> 8.1822129
... A19: 15 | B19: =F18 -> 4.1908895 | C19: =B19*Assumptions!$B$13 -> 0.20954448 | D19: =E19-C19 -> 4.1908895 | E19: =-PMT(Assumptions!$B$13,Assumptions!$B$14,Assumptions!$B$12) -> 4.400434 | F19: =B19-D19 -> -3.4638958e-14
A21: Total interest | C21: =SUM(C5:C19) -> 20.33151
A22: Total principal (=loan amount) | D22: =SUM(D5:D19) -> 45.675
A23: Ending balance (check = 0) | F23: =F19 -> -3.4638958e-14

Sheet Cash Flow
A1: Cash Flow Statement – 25 Years (EUR mm)
A3: Year | C3: 0 | D3: 1 | E3: 2 | F3: 3 | G3: 4 | H3: 5 | I3: 6 | J3: 7 | K3: 8 | L3: 9 | M3: 10 | N3: 11 | O3: 12 | P3: 13 | Q3: 14 | R3: 15 | S3: 16 | T3: 17 | U3: 18 | V3: 19 | W3: 20 | X3: 21 | Y3: 22 | Z3: 23 | AA3: 24 | AB3: 25
A4: Revenue | D4: =Assumptions!$B$17*(1+Assumptions!$B$24)^(1-1) -> 9.7 | E4: =Assumptions!$B$17*(1+Assumptions!$B$24)^(2-1) -> 9.6612 | F4: =Assumptions!$B$17*(1+Assumptions!$B$24)^(3-1) -> 9.6225552 | G4: =Assumptions!$B$17*(1+Assumptions!$B$24)^(4-1) -> 9.584065 | H4: =Assumptions!$B$17*(1+Assumptions!$B$24)^(5-1) -> 9.5457287 | I4: =Assumptions!$B$17*(1+Assumptions!$B$24)^(6-1) -> 9.5075458 | J4: =Assumptions!$B$17*(1+Assumptions!$B$24)^(7-1) -> 9.4695156 | K4: =Assumptions!$B$17*(1+Assumptions!$B$24)^(8-1) -> 9.4316376 | L4: =Assumptions!$B$17*(1+Assumptions!$B$24)^(9-1) -> 9.393911 | M4: =Assumptions!$B$17*(1+Assumptions!$B$24)^(10-1) -> 9.3563354 | N4: =Assumptions!$B$17*(1+Assumptions!$B$24)^(11-1) -> 9.31891 | O4: =Assumptions!$B$17*(1+Assumptions!$B$24)^(12-1) -> 9.2816344 | P4: =Assumptions!$B$17*(1+Assumptions!$B$24)^(13-1) -> 9.2445078 | Q4: =Assumptions!$B$17*(1+Assumptions!$B$24)^(14-1) -> 9.2075298 | R4: =Assumptions!$B$17*(1+Assumptions!$B$24)^(15-1) -> 9.1706997 | S4: =Assumptions!$B$17*(1+Assumptions!$B$24)^(16-1) -> 9.1340169 | T4: =Assumptions!$B$17*(1+Assumptions!$B$24)^(17-1) -> 9.0974808 | U4: =Assumptions!$B$17*(1+Assumptions!$B$24)^(18-1) -> 9.0610909 | V4: =Assumptions!$B$17*(1+Assumptions!$B$24)^(19-1) -> 9.0248465 | W4: =Assumptions!$B$17*(1+Assumptions!$B$24)^(20-1) -> 8.9887472 | X4: =Assumptions!$B$17*(1+Assumptions!$B$24)^(21-1) -> 8.9527922 | Y4: =Assumptions!$B$17*(1+Assumptions!$B$24)^(22-1) -> 8.916981 | Z4: =Assumptions!$B$17*(1+Assumptions!$B$24)^(23-1) -> 8.8813131 | AA4: =Assumptions!$B$17*(1+Assumptions!$B$24)^(24-1) -> 8.8457878 | AB4: =Assumptions!$B$17*(1+Assumptions!$B$24)^(25-1) -> 8.8104047
A5: O&M | D5: =Assumptions!$B$18*(1+Assumptions!$B$25)^(1-1) -> 0.7 | E5: =Assumptions!$B$18*(1+Assumptions!$B$25)^(2-1) -> 0.714 | F5: =Assumptions!$B$18*(1+Assumptions!$B$25)^(3-1) -> 0.72828 | G5: =Assumptions!$B$18*(1+Assumptions!$B$25)^(4-1) -> 0.7428456 | H5: =Assumptions!$B$18*(1+Assumptions!$B$25)^(5-1) -> 0.75770251 | I5: =Assumptions!$B$18*(1+Assumptions!$B$25)^(6-1) -> 0.77285656 | J5: =Assumptions!$B$18*(1+Assumptions!$B$25)^(7-1) -> 0.78831369 | K5: =Assumptions!$B$18*(1+Assumptions!$B$25)^(8-1) -> 0.80407997 | L5: =Assumptions!$B$18*(1+Assumptions!$B$25)^(9-1) -> 0.82016157 | M5: =Assumptions!$B$18*(1+Assumptions!$B$25)^(10-1) -> 0.8365648 | N5: =Assumptions!$B$18*(1+Assumptions!$B$25)^(11-1) -> 0.85329609 | O5: =Assumptions!$B$18*(1+Assumptions!$B$25)^(12-1) -> 0.87036202 | P5: =Assumptions!$B$18*(1+Assumptions!$B$25)^(13-1) -> 0.88776926 | Q5: =Assumptions!$B$18*(1+Assumptions!$B$25)^(14-1) -> 0.90552464 | R5: =Assumptions!$B$18*(1+Assumptions!$B$25)^(15-1) -> 0.92363513 | S5: =Assumptions!$B$18*(1+Assumptions!$B$25)^(16-1) -> 0.94210784 | T5: =Assumptions!$B$18*(1+Assumptions!$B$25)^(17-1) -> 0.96094999 | U5: =Assumptions!$B$18*(1+Assumptions!$B$25)^(18-1) -> 0.98016899 | V5: =Assumptions!$B$18*(1+Assumptions!$B$25)^(19-1) -> 0.99977237 | W5: =Assumptions!$B$18*(1+Assumptions!$B$25)^(20-1) -> 1.0197678 | X5: =Assumptions!$B$18*(1+Assumptions!$B$25)^(21-1) -> 1.0401632 | Y5: =Assumptions!$B$18*(1+Assumptions!$B$25)^(22-1) -> 1.0609664 | Z5: =Assumptions!$B$18*(1+Assumptions!$B$25)^(23-1) -> 1.0821858 | AA5: =Assumptions!$B$18*(1+Assumptions!$B$25)^(24-1) -> 1.1038295 | AB5: =Assumptions!$B$18*(1+Assumptions!$B$25)^(25-1) -> 1.1259061
A6: Land lease | D6: =Assumptions!$B$19*(1+Assumptions!$B$25)^(1-1) -> 0.12 | E6: =Assumptions!$B$19*(1+Assumptions!$B$25)^(2-1) -> 0.1224 | F6: =Assumptions!$B$19*(1+Assumptions!$B$25)^(3-1) -> 0.124848 | G6: =Assumptions!$B$19*(1+Assumptions!$B$25)^(4-1) -> 0.12734496 | H6: =Assumptions!$B$19*(1+Assumptions!$B$25)^(5-1) -> 0.12989186 | I6: =Assumptions!$B$19*(1+Assumptions!$B$25)^(6-1) -> 0.1324897 | J6: =Assumptions!$B$19*(1+Assumptions!$B$25)^(7-1) -> 0.13513949 | K6: =Assumptions!$B$19*(1+Assumptions!$B$25)^(8-1) -> 0.13784228 | L6: =Assumptions!$B$19*(1+Assumptions!$B$25)^(9-1) -> 0.14059913 | M6: =Assumptions!$B$19*(1+Assumptions!$B$25)^(10-1) -> 0.14341111 | N6: =Assumptions!$B$19*(1+Assumptions!$B$25)^(11-1) -> 0.14627933 | O6: =Assumptions!$B$19*(1+Assumptions!$B$25)^(12-1) -> 0.14920492 | P6: =Assumptions!$B$19*(1+Assumptions!$B$25)^(13-1) -> 0.15218902 | Q6: =Assumptions!$B$19*(1+Assumptions!$B$25)^(14-1) -> 0.1552328 | R6: =Assumptions!$B$19*(1+Assumptions!$B$25)^(15-1) -> 0.15833745 | S6: =Assumptions!$B$19*(1+Assumptions!$B$25)^(16-1) -> 0.1615042 | T6: =Assumptions!$B$19*(1+Assumptions!$B$25)^(17-1) -> 0.16473428 | U6: =Assumptions!$B$19*(1+Assumptions!$B$25)^(18-1) -> 0.16802897 | V6: =Assumptions!$B$19*(1+Assumptions!$B$25)^(19-1) -> 0.17138955 | W6: =Assumptions!$B$19*(1+Assumptions!$B$25)^(20-1) -> 0.17481734 | X6: =Assumptions!$B$19*(1+Assumptions!$B$25)^(21-1) -> 0.17831369 | Y6: =Assumptions!$B$19*(1+Assumptions!$B$25)^(22-1) -> 0.18187996 | Z6: =Assumptions!$B$19*(1+Assumptions!$B$25)^(23-1) -> 0.18551756 | AA6: =Assumptions!$B$19*(1+Assumptions!$B$25)^(24-1) -> 0.18922791 | AB6: =Assumptions!$B$19*(1+Assumptions!$B$25)^(25-1) -> 0.19301247
A7: Insurance | D7: =Assumptions!$B$20*(1+Assumptions!$B$25)^(1-1) -> 0.1 | E7: =Assumptions!$B$20*(1+Assumptions!$B$25)^(2-1) -> 0.102 | F7: =Assumptions!$B$20*(1+Assumptions!$B$25)^(3-1) -> 0.10404 | G7: =Assumptions!$B$20*(1+Assumptions!$B$25)^(4-1) -> 0.1061208 | H7: =Assumptions!$B$20*(1+Assumptions!$B$25)^(5-1) -> 0.10824322 | I7: =Assumptions!$B$20*(1+Assumptions!$B$25)^(6-1) -> 0.11040808 | J7: =Assumptions!$B$20*(1+Assumptions!$B$25)^(7-1) -> 0.11261624 | K7: =Assumptions!$B$20*(1+Assumptions!$B$25)^(8-1) -> 0.11486857 | L7: =Assumptions!$B$20*(1+Assumptions!$B$25)^(9-1) -> 0.11716594 | M7: =Assumptions!$B$20*(1+Assumptions!$B$25)^(10-1) -> 0.11950926 | N7: =Assumptions!$B$20*(1+Assumptions!$B$25)^(11-1) -> 0.12189944 | O7: =Assumptions!$B$20*(1+Assumptions!$B$25)^(12-1) -> 0.12433743 | P7: =Assumptions!$B$20*(1+Assumptions!$B$25)^(13-1) -> 0.12682418 | Q7: =Assumptions!$B$20*(1+Assumptions!$B$25)^(14-1) -> 0.12936066 | R7: =Assumptions!$B$20*(1+Assumptions!$B$25)^(15-1) -> 0.13194788 | S7: =Assumptions!$B$20*(1+Assumptions!$B$25)^(16-1) -> 0.13458683 | T7: =Assumptions!$B$20*(1+Assumptions!$B$25)^(17-1) -> 0.13727857 | U7: =Assumptions!$B$20*(1+Assumptions!$B$25)^(18-1) -> 0.14002414 | V7: =Assumptions!$B$20*(1+Assumptions!$B$25)^(19-1) -> 0.14282462 | W7: =Assumptions!$B$20*(1+Assumptions!$B$25)^(20-1) -> 0.14568112 | X7: =Assumptions!$B$20*(1+Assumptions!$B$25)^(21-1) -> 0.14859474 | Y7: =Assumptions!$B$20*(1+Assumptions!$B$25)^(22-1) -> 0.15156663 | Z7: =Assumptions!$B$20*(1+Assumptions!$B$25)^(23-1) -> 0.15459797 | AA7: =Assumptions!$B$20*(1+Assumptions!$B$25)^(24-1) -> 0.15768993 | AB7: =Assumptions!$B$20*(1+Assumptions!$B$25)^(25-1) -> 0.16084372
A8: Total OPEX | D8: =SUM(D5:D7) -> 0.92 | E8: =SUM(E5:E7) -> 0.9384 | F8: =SUM(F5:F7) -> 0.957168 | G8: =SUM(G5:G7) -> 0.97631136 | H8: =SUM(H5:H7) -> 0.99583759 | I8: =SUM(I5:I7) -> 1.0157543 | J8: =SUM(J5:J7) -> 1.0360694 | K8: =SUM(K5:K7) -> 1.0567908 | ... AB8: =SUM(AB5:AB7) -> 1.4797623
A9: EBITDA | D9: =D4-D8 -> 8.78 | E9: =E4-E8 -> 8.7228 | F9: =F4-F8 -> 8.6653872 | G9: =G4-G8 -> 8.6077536 | H9: =H4-H8 -> 8.5498911 | I9: =I4-I8 -> 8.4917915 | J9: =J4-J8 -> 8.4334462 | K9: =K4-K8 -> 8.3748467 | ... AB9: =AB4-AB8 -> 7.3306424
A10: Depreciation | D10: =IF(1<=Assumptions!$B$27,Assumptions!$B$6/Assumptions!$B$27,0) -> 2.61 | E10: =IF(2<=Assumptions!$B$27,Assumptions!$B$6/Assumptions!$B$27,0) -> 2.61 | F10: =IF(3<=Assumptions!$B$27,Assumptions!$B$6/Assumptions!$B$27,0) -> 2.61 | G10: =IF(4<=Assumptions!$B$27,Assumptions!$B$6/Assumptions!$B$27,0) -> 2.61 | H10: =IF(5<=Assumptions!$B$27,Assumptions!$B$6/Assumptions!$B$27,0) -> 2.61 | I10: =IF(6<=Assumptions!$B$27,Assumptions!$B$6/Assumptions!$B$27,0) -> 2.61 | J10: =IF(7<=Assumptions!$B$27,Assumptions!$B$6/Assumptions!$B$27,0) -> 2.61 | K10: =IF(8<=Assumptions!$B$27,Assumptions!$B$6/Assumptions!$B$27,0) -> 2.61 | L10: =IF(9<=Assumptions!$B$27,Assumptions!$B$6/Assumptions!$B$27,0) -> 2.61 | M10: =IF(10<=Assumptions!$B$27,Assumptions!$B$6/Assumptions!$B$27,0) -> 2.61 | N10: =IF(11<=Assumptions!$B$27,Assumptions!$B$6/Assumptions!$B$27,0) -> 2.61 | O10: =IF(12<=Assumptions!$B$27,Assumptions!$B$6/Assumptions!$B$27,0) -> 2.61 | P10: =IF(13<=Assumptions!$B$27,Assumptions!$B$6/Assumptions!$B$27,0) -> 2.61 | Q10: =IF(14<=Assumptions!$B$27,Assumptions!$B$6/Assumptions!$B$27,0) -> 2.61 | R10: =IF(15<=Assumptions!$B$27,Assumptions!$B$6/Assumptions!$B$27,0) -> 2.61 | S10: =IF(16<=Assumptions!$B$27,Assumptions!$B$6/Assumptions!$B$27,0) -> 2.61 | T10: =IF(17<=Assumptions!$B$27,Assumptions!$B$6/Assumptions!$B$27,0) -> 2.61 | U10: =IF(18<=Assumptions!$B$27,Assumptions!$B$6/Assumptions!$B$27,0) -> 2.61 | V10: =IF(19<=Assumptions!$B$27,Assumptions!$B$6/Assumptions!$B$27,0) -> 2.61 | W10: =IF(20<=Assumptions!$B$27,Assumptions!$B$6/Assumptions!$B$27,0) -> 2.61 | X10: =IF(21<=Assumptions!$B$27,Assumptions!$B$6/Assumptions!$B$27,0) -> 2.61 | Y10: =IF(22<=Assumptions!$B$27,Assumptions!$B$6/Assumptions!$B$27,0) -> 2.61 | Z10: =IF(23<=Assumptions!$B$27,Assumptions!$B$6/Assumptions!$B$27,0) -> 2.61 | AA10: =IF(24<=Assumptions!$B$27,Assumptions!$B$6/Assumptions!$B$27,0) -> 2.61 | AB10: =IF(25<=Assumptions!$B$27,Assumptions!$B$6/Assumptions!$B$27,0) -> 2.61
A11: EBIT | D11: =D9-D10 -> 6.17 | E11: =E9-E10 -> 6.1128 | F11: =F9-F10 -> 6.0553872 | G11: =G9-G10 -> 5.9977536 | H11: =H9-H10 -> 5.9398911 | I11: =I9-I10 -> 5.8817915 | J11: =J9-J10 -> 5.8234462 | K11: =K9-K10 -> 5.7648467 | ... AB11: =AB9-AB10 -> 4.7206424
A12: Loan interest | D12: =IF(1<=Assumptions!$B$14,INDEX('Debt Schedule'!$C$5:$C$19,1),0) -> 2.28375 | E12: =IF(2<=Assumptions!$B$14,INDEX('Debt Schedule'!$C$5:$C$19,2),0) -> 2.1779158 | F12: =IF(3<=Assumptions!$B$14,INDEX('Debt Schedule'!$C$5:$C$19,3),0) -> 2.0667899 | G12: =IF(4<=Assumptions!$B$14,INDEX('Debt Schedule'!$C$5:$C$19,4),0) -> 1.9501077 | H12: =IF(5<=Assumptions!$B$14,INDEX('Debt Schedule'!$C$5:$C$19,5),0) -> 1.8275914 | I12: =IF(6<=Assumptions!$B$14,INDEX('Debt Schedule'!$C$5:$C$19,6),0) -> 1.6989492 | J12: =IF(7<=Assumptions!$B$14,INDEX('Debt Schedule'!$C$5:$C$19,7),0) -> 1.563875 | K12: =IF(8<=Assumptions!$B$14,INDEX('Debt Schedule'!$C$5:$C$19,8),0) -> 1.4220471 | L12: =IF(9<=Assumptions!$B$14,INDEX('Debt Schedule'!$C$5:$C$19,9),0) -> 1.2731277 | M12: =IF(10<=Assumptions!$B$14,INDEX('Debt Schedule'!$C$5:$C$19,10),0) -> 1.1167624 | N12: =IF(11<=Assumptions!$B$14,INDEX('Debt Schedule'!$C$5:$C$19,11),0) -> 0.95257881 | O12: =IF(12<=Assumptions!$B$14,INDEX('Debt Schedule'!$C$5:$C$19,12),0) -> 0.78018606 | P12: =IF(13<=Assumptions!$B$14,INDEX('Debt Schedule'!$C$5:$C$19,13),0) -> 0.59917366 | Q12: =IF(14<=Assumptions!$B$14,INDEX('Debt Schedule'!$C$5:$C$19,14),0) -> 0.40911064 | R12: =IF(15<=Assumptions!$B$14,INDEX('Debt Schedule'!$C$5:$C$19,15),0) -> 0.20954448 | S12: =IF(16<=Assumptions!$B$14,INDEX('Debt Schedule'!$C$5:$C$19,16),0) -> 0 | T12: =IF(17<=Assumptions!$B$14,INDEX('Debt Schedule'!$C$5:$C$19,17),0) -> 0 | U12: =IF(18<=Assumptions!$B$14,INDEX('Debt Schedule'!$C$5:$C$19,18),0) -> 0 | V12: =IF(19<=Assumptions!$B$14,INDEX('Debt Schedule'!$C$5:$C$19,19),0) -> 0 | W12: =IF(20<=Assumptions!$B$14,INDEX('Debt Schedule'!$C$5:$C$19,20),0) -> 0 | X12: =IF(21<=Assumptions!$B$14,INDEX('Debt Schedule'!$C$5:$C$19,21),0) -> 0 | Y12: =IF(22<=Assumptions!$B$14,INDEX('Debt Schedule'!$C$5:$C$19,22),0) -> 0 | Z12: =IF(23<=Assumptions!$B$14,INDEX('Debt Schedule'!$C$5:$C$19,23),0) -> 0 | AA12: =IF(24<=Assumptions!$B$14,INDEX('Debt Schedule'!$C$5:$C$19,24),0) -> 0 | AB12: =IF(25<=Assumptions!$B$14,INDEX('Debt Schedule'!$C$5:$C$19,25),0) -> 0
A13: EBT (pre-tax profit) | D13: =D11-D12 -> 3.88625 | E13: =E11-E12 -> 3.9348842 | F13: =F11-F12 -> 3.9885973 | G13: =G11-G12 -> 4.0476459 | H13: =H11-H12 -> 4.1122998 | I13: =I11-I12 -> 4.1828422 | J13: =J11-J12 -> 4.2595712 | K13: =K11-K12 -> 4.3427997 | ... AB13: =AB11-AB12 -> 4.7206424
A14: Corporate tax | D14: =MAX(D13,0)*Assumptions!$B$28 -> 0.48578125 | E14: =MAX(E13,0)*Assumptions!$B$28 -> 0.49186052 | F14: =MAX(F13,0)*Assumptions!$B$28 -> 0.49857466 | G14: =MAX(G13,0)*Assumptions!$B$28 -> 0.50595574 | H14: =MAX(H13,0)*Assumptions!$B$28 -> 0.51403747 | I14: =MAX(I13,0)*Assumptions!$B$28 -> 0.52285528 | J14: =MAX(J13,0)*Assumptions!$B$28 -> 0.5324464 | K14: =MAX(K13,0)*Assumptions!$B$28 -> 0.54284996 | ... AB14: =MAX(AB13,0)*Assumptions!$B$28 -> 0.5900803
A15: Net income | D15: =D13-D14 -> 3.4004687 | E15: =E13-E14 -> 3.4430237 | F15: =F13-F14 -> 3.4900226 | G15: =G13-G14 -> 3.5416902 | H15: =H13-H14 -> 3.5982623 | I15: =I13-I14 -> 3.6599869 | J15: =J13-J14 -> 3.7271248 | K15: =K13-K14 -> 3.7999497 | ... AB15: =AB13-AB14 -> 4.1305621
A16: Loan principal repayment | D16: =IF(1<=Assumptions!$B$14,INDEX('Debt Schedule'!$D$5:$D$19,1),0) -> 2.116684 | E16: =IF(2<=Assumptions!$B$14,INDEX('Debt Schedule'!$D$5:$D$19,2),0) -> 2.2225182 | F16: =IF(3<=Assumptions!$B$14,INDEX('Debt Schedule'!$D$5:$D$19,3),0) -> 2.3336441 | G16: =IF(4<=Assumptions!$B$14,INDEX('Debt Schedule'!$D$5:$D$19,4),0) -> 2.4503263 | H16: =IF(5<=Assumptions!$B$14,INDEX('Debt Schedule'!$D$5:$D$19,5),0) -> 2.5728426 | I16: =IF(6<=Assumptions!$B$14,INDEX('Debt Schedule'!$D$5:$D$19,6),0) -> 2.7014847 | J16: =IF(7<=Assumptions!$B$14,INDEX('Debt Schedule'!$D$5:$D$19,7),0) -> 2.836559 | K16: =IF(8<=Assumptions!$B$14,INDEX('Debt Schedule'!$D$5:$D$19,8),0) -> 2.9783869 | L16: =IF(9<=Assumptions!$B$14,INDEX('Debt Schedule'!$D$5:$D$19,9),0) -> 3.1273063 | M16: =IF(10<=Assumptions!$B$14,INDEX('Debt Schedule'!$D$5:$D$19,10),0) -> 3.2836716 | N16: =IF(11<=Assumptions!$B$14,INDEX('Debt Schedule'!$D$5:$D$19,11),0) -> 3.4478552 | O16: =IF(12<=Assumptions!$B$14,INDEX('Debt Schedule'!$D$5:$D$19,12),0) -> 3.6202479 | P16: =IF(13<=Assumptions!$B$14,INDEX('Debt Schedule'!$D$5:$D$19,13),0) -> 3.8012603 | Q16: =IF(14<=Assumptions!$B$14,INDEX('Debt Schedule'!$D$5:$D$19,14),0) -> 3.9913233 | R16: =IF(15<=Assumptions!$B$14,INDEX('Debt Schedule'!$D$5:$D$19,15),0) -> 4.1908895 | S16: =IF(16<=Assumptions!$B$14,INDEX('Debt Schedule'!$D$5:$D$19,16),0) -> 0 | T16: =IF(17<=Assumptions!$B$14,INDEX('Debt Schedule'!$D$5:$D$19,17),0) -> 0 | U16: =IF(18<=Assumptions!$B$14,INDEX('Debt Schedule'!$D$5:$D$19,18),0) -> 0 | V16: =IF(19<=Assumptions!$B$14,INDEX('Debt Schedule'!$D$5:$D$19,19),0) -> 0 | W16: =IF(20<=Assumptions!$B$14,INDEX('Debt Schedule'!$D$5:$D$19,20),0) -> 0 | X16: =IF(21<=Assumptions!$B$14,INDEX('Debt Schedule'!$D$5:$D$19,21),0) -> 0 | Y16: =IF(22<=Assumptions!$B$14,INDEX('Debt Schedule'!$D$5:$D$19,22),0) -> 0 | Z16: =IF(23<=Assumptions!$B$14,INDEX('Debt Schedule'!$D$5:$D$19,23),0) -> 0 | AA16: =IF(24<=Assumptions!$B$14,INDEX('Debt Schedule'!$D$5:$D$19,24),0) -> 0 | AB16: =IF(25<=Assumptions!$B$14,INDEX('Debt Schedule'!$D$5:$D$19,25),0) -> 0
A17: Equity Cash Flow | C17: =-Assumptions!$B$11 -> -19.575 | D17: =D15+D10-D16 -> 3.8937848 | E17: =E15+E10-E16 -> 3.8305055 | F17: =F15+F10-F16 -> 3.7663785 | G17: =G15+G10-G16 -> 3.7013639 | H17: =H15+H10-H16 -> 3.6354197 | I17: =I15+I10-I16 -> 3.5685022 | J17: =J15+J10-J16 -> 3.5005658 | K17: =K15+K10-K16 -> 3.4315628 | ... AB17: =AB15+AB10-AB16 -> 6.7405621
A18: Project Cash Flow (unlevered, Project FCF) | C18: =-Assumptions!$B$6 -> -65.25 | D18: =(D11-MAX(D11,0)*Assumptions!$B$28)+D10 -> 8.00875 | E18: =(E11-MAX(E11,0)*Assumptions!$B$28)+E10 -> 7.9587 | F18: =(F11-MAX(F11,0)*Assumptions!$B$28)+F10 -> 7.9084638 | G18: =(G11-MAX(G11,0)*Assumptions!$B$28)+G10 -> 7.8580344 | H18: =(H11-MAX(H11,0)*Assumptions!$B$28)+H10 -> 7.8074047 | I18: =(I11-MAX(I11,0)*Assumptions!$B$28)+I10 -> 7.7565675 | J18: =(J11-MAX(J11,0)*Assumptions!$B$28)+J10 -> 7.7055154 | K18: =(K11-MAX(K11,0)*Assumptions!$B$28)+K10 -> 7.6542409 | ... AB18: =(AB11-MAX(AB11,0)*Assumptions!$B$28)+AB10 -> 6.7405621
A19: DSCR (EBITDA / debt service) | D19: =IF((D12+D16)=0,"n/d",D9/(D12+D16)) -> 1.9952577 | E19: =IF((E12+E16)=0,"n/d",E9/(E12+E16)) -> 1.982259 | F19: =IF((F12+F16)=0,"n/d",F9/(F12+F16)) -> 1.969212 | G19: =IF((G12+G16)=0,"n/d",G9/(G12+G16)) -> 1.9561147 | H19: =IF((H12+H16)=0,"n/d",H9/(H12+H16)) -> 1.9429654 | I19: =IF((I12+I16)=0,"n/d",I9/(I12+I16)) -> 1.9297623 | J19: =IF((J12+J16)=0,"n/d",J9/(J12+J16)) -> 1.9165033 | K19: =IF((K12+K16)=0,"n/d",K9/(K12+K16)) -> 1.9031865 | ... AB19: =IF((AB12+AB16)=0,"n/d",AB9/(AB12+AB16)) -> n/d
A20: Cumulative equity cash flow | C20: =C17 -> -19.575 | D20: =C20+D17 -> -15.681215 | E20: =D20+E17 -> -11.85071 | F20: =E20+F17 -> -8.0843312 | G20: =F20+G17 -> -4.3829673 | H20: =G20+H17 -> -0.74754763 | I20: =H20+I17 -> 2.8209546 | J20: =I20+J17 -> 6.3215204 | K20: =J20+K17 -> 9.7530832 | ... AB20: =AA20+AB17 -> 101.63987

Sheet Returns
A1: Results – Project Viability
A3: EQUITY RETURNS (INVESTOR)
A4: Equity IRR (levered) | B4: =IRR('Cash Flow'!C17:AB17) -> 0.19329756
A5: Equity NPV @ equity discount rate | B5: ='Cash Flow'!C17+NPV(Assumptions!$B$29,'Cash Flow'!D17:AB17) -> 17.69954 | C5: EUR mm
A6: Equity multiple (sum of FCFE / equity invested) | B6: =SUM('Cash Flow'!D17:AB17)/Assumptions!$B$11 -> 6.1923305
A7: Simple equity payback (undiscounted) | B7: =SUMPRODUCT(--('Cash Flow'!C20:AB20<0)) -> 6 | C7: years (approx.)
A9: PROJECT RETURNS (UNLEVERED)
A10: Project IRR (unlevered) | B10: =IRR('Cash Flow'!C18:AB18) -> 0.10810387
A11: Project NPV @ WACC | B11: ='Cash Flow'!C18+NPV(Assumptions!$B$30,'Cash Flow'!D18:AB18) -> 22.896877 | C11: EUR mm
A13: LOAN SECURITY (BANK)
A14: Average DSCR (Years 1-15) | B14: =AVERAGE('Cash Flow'!D19:R19) -> 1.902628
A15: Minimum DSCR (Years 1-15) | B15: =MIN('Cash Flow'!D19:R19) -> 1.8081806 | C15: Lenders financing PV/BESS projects typically require min. DSCR of ~1.20-1.35x
A16: Annual loan payment (annuity) | B16: ='Debt Schedule'!$E$5 -> 4.400434 | C16: EUR mm/yr
A18: KEY YEAR 1 FIGURES (sanity check)
A19: EBITDA Year 1 | B19: ='Cash Flow'!D9 -> 8.78 | C19: EUR mm
A20: EBITDA margin Year 1 | B20: ='Cash Flow'!D9/'Cash Flow'!D4 -> 0.90515464
A21: FCFE Year 1 | B21: ='Cash Flow'!D17 -> 3.8937848 | C21: EUR mm

Sheet Sensitivity
A1: Sensitivity Analysis – Equity IRR
A2: Impact of revenue change (rows) and CAPEX change (columns) on equity IRR. Financing structure (30/70) and interest rate held as in the base case.
A4: Revenue \ CAPEX | B4: -0.1 | C4: 0 | D4: 0.1
A5: -0.2 | B5: =C$65 -> 0.14376275 | C5: =D$65 -> 0.11398186 | D5: =E$65 -> 0.090307413
A6: -0.1 | B6: =F$65 -> 0.18842856 | C6: =G$65 -> 0.15299269 | D6: =H$65 -> 0.12490865
A7: 0 | B7: =I$65 -> 0.2345058 | C7: =J$65 -> 0.19329756 | D7: =K$65 -> 0.16055359
A8: 0.1 | B8: =L$65 -> 0.28162491 | C8: =M$65 -> 0.23474125 | D8: =N$65 -> 0.19727537
A9: 0.2 | B9: =O$65 -> 0.32941099 | C9: =P$65 -> 0.27704493 | D9: =Q$65 -> 0.23493324
A12: Note: base scenario (0%/0%) highlighted in yellow = matches the Cash Flow sheet.
A28: Helper equity cash flows per scenario (EUR mm) - do not delete, feeds the table above
A30: Scenario # | C30: 1 | D30: 2 | E30: 3 | F30: 4 | G30: 5 | H30: 6 | I30: 7 | J30: 8 | K30: 9 | L30: 10 | M30: 11 | N30: 12 | O30: 13 | P30: 14 | Q30: 15
A31: Revenue delta | C31: -0.2 | D31: -0.2 | E31: -0.2 | F31: -0.1 | G31: -0.1 | H31: -0.1 | I31: 0 | J31: 0 | K31: 0 | L31: 0.1 | M31: 0.1 | N31: 0.1 | O31: 0.2 | P31: 0.2 | Q31: 0.2
A32: CAPEX delta | C32: -0.1 | D32: 0 | E32: 0.1 | F32: -0.1 | G32: 0 | H32: 0.1 | I32: -0.1 | J32: 0 | K32: 0.1 | L32: -0.1 | M32: 0 | N32: 0.1 | O32: -0.1 | P32: 0 | Q32: 0.1
A33: Scenario CAPEX (EUR mm) | C33: =Assumptions!$B$6*(1+C$32) -> 58.725 | D33: =Assumptions!$B$6*(1+D$32) -> 65.25 | E33: =Assumptions!$B$6*(1+E$32) -> 71.775 | F33: =Assumptions!$B$6*(1+F$32) -> 58.725 | G33: =Assumptions!$B$6*(1+G$32) -> 65.25 | H33: =Assumptions!$B$6*(1+H$32) -> 71.775 | I33: =Assumptions!$B$6*(1+I$32) -> 58.725 | J33: =Assumptions!$B$6*(1+J$32) -> 65.25 | ... Q33: =Assumptions!$B$6*(1+Q$32) -> 71.775
A34: Scenario equity (EUR mm) | C34: =C$33*Assumptions!$B$9 -> 17.6175 | D34: =D$33*Assumptions!$B$9 -> 19.575 | E34: =E$33*Assumptions!$B$9 -> 21.5325 | F34: =F$33*Assumptions!$B$9 -> 17.6175 | G34: =G$33*Assumptions!$B$9 -> 19.575 | H34: =H$33*Assumptions!$B$9 -> 21.5325 | I34: =I$33*Assumptions!$B$9 -> 17.6175 | J34: =J$33*Assumptions!$B$9 -> 19.575 | ... Q34: =Q$33*Assumptions!$B$9 -> 21.5325
A35: Scenario debt (EUR mm) | C35: =C$33*Assumptions!$B$10 -> 41.1075 | D35: =D$33*Assumptions!$B$10 -> 45.675 | E35: =E$33*Assumptions!$B$10 -> 50.2425 | F35: =F$33*Assumptions!$B$10 -> 41.1075 | G35: =G$33*Assumptions!$B$10 -> 45.675 | H35: =H$33*Assumptions!$B$10 -> 50.2425 | I35: =I$33*Assumptions!$B$10 -> 41.1075 | J35: =J$33*Assumptions!$B$10 -> 45.675 | ... Q35: =Q$33*Assumptions!$B$10 -> 50.2425
A36: Scenario annual loan payment | C36: =-PMT(Assumptions!$B$13,Assumptions!$B$14,C$35) -> 3.9603906 | D36: =-PMT(Assumptions!$B$13,Assumptions!$B$14,D$35) -> 4.400434 | E36: =-PMT(Assumptions!$B$13,Assumptions!$B$14,E$35) -> 4.8404774 | F36: =-PMT(Assumptions!$B$13,Assumptions!$B$14,F$35) -> 3.9603906 | G36: =-PMT(Assumptions!$B$13,Assumptions!$B$14,G$35) -> 4.400434 | H36: =-PMT(Assumptions!$B$13,Assumptions!$B$14,H$35) -> 4.8404774 | I36: =-PMT(Assumptions!$B$13,Assumptions!$B$14,I$35) -> 3.9603906 | J36: =-PMT(Assumptions!$B$13,Assumptions!$B$14,J$35) -> 4.400434 | ... Q36: =-PMT(Assumptions!$B$13,Assumptions!$B$14,Q$35) -> 4.8404774
A37: Year (0-25) / Equity CF
A38: 0 | C38: =-C$34 -> -17.6175 | D38: =-D$34 -> -19.575 | E38: =-E$34 -> -21.5325 | F38: =-F$34 -> -17.6175 | G38: =-G$34 -> -19.575 | H38: =-H$34 -> -21.5325 | I38: =-I$34 -> -17.6175 | J38: =-J$34 -> -19.575 | ... Q38: =-Q$34 -> -21.5325
A39: 1 | C39: =(((((Assumptions!$B$17*(1+C$31)*(1+Assumptions!$B$24)^(1-1))-(Assumptions!$B$21*(1+Assumptions!$B$25)^(1-1)))-(IF(1<=Assumptions!$B$27,C$33/Assumptions!$B$27,0)))-((C$35*(1+Assumptions!$B$13)^(1-1)-C$36*(((1+Assumptions!$B$13)^(1-1)-1)/Assumptions!$B$13))*Assumptions!$B$13))-(MAX(((((Assumptions!$B$17*(1+C$31)*(1+Assumptions!$B$24)^(1-1))-(Assumptions!$B$21*(1+Assumptions!$B$25)^(1-1)))-(IF(1<=Assumptions!$B$27,C$33/Assumptions!$B$27,0)))-((C$35*(1+Assumptions!$B$13)^(1-1)-C$36*(((1+Assumptions!$B$13)^(1-1)-1)/Assumptions!$B$13))*Assumptions!$B$13)),0)*Assumptions!$B$28))+(IF(1<=Assumptions!$B$27,C$33/Assumptions!$B$27,0))-(C$36-((C$35*(1+Assumptions!$B$13)^(1-1)-C$36*(((1+Assumptions!$B$13)^(1-1)-1)/Assumptions!$B$13))*Assumptions!$B$13)) -> 2.5751563 | D39: =(((((Assumptions!$B$17*(1+D$31)*(1+Assumptions!$B$24)^(1-1))-(Assumptions!$B$21*(1+Assumptions!$B$25)^(1-1)))-(IF(1<=Assumptions!$B$27,D$33/Assumptions!$B$27,0)))-((D$35*(1+Assumptions!$B$13)^(1-1)-D$36*(((1+Assumptions!$B$13)^(1-1)-1)/Assumptions!$B$13))*Assumptions!$B$13))-(MAX(((((Assumptions!$B$17*(1+D$31)*(1+Assumptions!$B$24)^(1-1))-(Assumptions!$B$21*(1+Assumptions!$B$25)^(1-1)))-(IF(1<=Assumptions!$B$27,D$33/Assumptions!$B$27,0)))-((D$35*(1+Assumptions!$B$13)^(1-1)-D$36*(((1+Assumptions!$B$13)^(1-1)-1)/Assumptions!$B$13))*Assumptions!$B$13)),0)*Assumptions!$B$28))+(IF(1<=Assumptions!$B$27,D$33/Assumptions!$B$27,0))-(D$36-((D$35*(1+Assumptions!$B$13)^(1-1)-D$36*(((1+Assumptions!$B$13)^(1-1)-1)/Assumptions!$B$13))*Assumptions!$B$13)) -> 2.1962848 | E39: =(((((Assumptions!$B$17*(1+E$31)*(1+Assumptions!$B$24)^(1-1))-(Assumptions!$B$21*(1+Assumptions!$B$25)^(1-1)))-(IF(1<=Assumptions!$B$27,E$33/Assumptions!$B$27,0)))-((E$35*(1+Assumptions!$B$13)^(1-1)-E$36*(((1+Assumptions!$B$13)^(1-1)-1)/Assumptions!$B$13))*Assumptions!$B$13))-(MAX(((((Assumptions!$B$17*(1+E$31)*(1+Assumptions!$B$24)^(1-1))-(Assumptions!$B$21*(1+Assumptions!$B$25)^(1-1)))-(IF(1<=Assumptions!$B$27,E$33/Assumptions!$B$27,0)))-((E$35*(1+Assumptions!$B$13)^(1-1)-E$36*(((1+Assumptions!$B$13)^(1-1)-1)/Assumptions!$B$13))*Assumptions!$B$13)),0)*Assumptions!$B$28))+(IF(1<=Assumptions!$B$27,E$33/Assumptions!$B$27,0))-(E$36-((E$35*(1+Assumptions!$B$13)^(1-1)-E$36*(((1+Assumptions!$B$13)^(1-1)-1)/Assumptions!$B$13))*Assumptions!$B$13)) -> 1.8174132 | F39: =(((((Assumptions!$B$17*(1+F$31)*(1+Assumptions!$B$24)^(1-1))-(Assumptions!$B$21*(1+Assumptions!$B$25)^(1-1)))-(IF(1<=Assumptions!$B$27,F$33/Assumptions!$B$27,0)))-((F$35*(1+Assumptions!$B$13)^(1-1)-F$36*(((1+Assumptions!$B$13)^(1-1)-1)/Assumptions!$B$13))*Assumptions!$B$13))-(MAX(((((Assumptions!$B$17*(1+F$31)*(1+Assumptions!$B$24)^(1-1))-(Assumptions!$B$21*(1+Assumptions!$B$25)^(1-1)))-(IF(1<=Assumptions!$B$27,F$33/Assumptions!$B$27,0)))-((F$35*(1+Assumptions!$B$13)^(1-1)-F$36*(((1+Assumptions!$B$13)^(1-1)-1)/Assumptions!$B$13))*Assumptions!$B$13)),0)*Assumptions!$B$28))+(IF(1<=Assumptions!$B$27,F$33/Assumptions!$B$27,0))-(F$36-((F$35*(1+Assumptions!$B$13)^(1-1)-F$36*(((1+Assumptions!$B$13)^(1-1)-1)/Assumptions!$B$13))*Assumptions!$B$13)) -> 3.4239063 | G39: =(((((Assumptions!$B$17*(1+G$31)*(1+Assumptions!$B$24)^(1-1))-(Assumptions!$B$21*(1+Assumptions!$B$25)^(1-1)))-(IF(1<=Assumptions!$B$27,G$33/Assumptions!$B$27,0)))-((G$35*(1+Assumptions!$B$13)^(1-1)-G$36*(((1+Assumptions!$B$13)^(1-1)-1)/Assumptions!$B$13))*Assumptions!$B$13))-(MAX(((((Assumptions!$B$17*(1+G$31)*(1+Assumptions!$B$24)^(1-1))-(Assumptions!$B$21*(1+Assumptions!$B$25)^(1-1)))-(IF(1<=Assumptions!$B$27,G$33/Assumptions!$B$27,0)))-((G$35*(1+Assumptions!$B$13)^(1-1)-G$36*(((1+Assumptions!$B$13)^(1-1)-1)/Assumptions!$B$13))*Assumptions!$B$13)),0)*Assumptions!$B$28))+(IF(1<=Assumptions!$B$27,G$33/Assumptions!$B$27,0))-(G$36-((G$35*(1+Assumptions!$B$13)^(1-1)-G$36*(((1+Assumptions!$B$13)^(1-1)-1)/Assumptions!$B$13))*Assumptions!$B$13)) -> 3.0450348 | H39: =(((((Assumptions!$B$17*(1+H$31)*(1+Assumptions!$B$24)^(1-1))-(Assumptions!$B$21*(1+Assumptions!$B$25)^(1-1)))-(IF(1<=Assumptions!$B$27,H$33/Assumptions!$B$27,0)))-((H$35*(1+Assumptions!$B$13)^(1-1)-H$36*(((1+Assumptions!$B$13)^(1-1)-1)/Assumptions!$B$13))*Assumptions!$B$13))-(MAX(((((Assumptions!$B$17*(1+H$31)*(1+Assumptions!$B$24)^(1-1))-(Assumptions!$B$21*(1+Assumptions!$B$25)^(1-1)))-(IF(1<=Assumptions!$B$27,H$33/Assumptions!$B$27,0)))-((H$35*(1+Assumptions!$B$13)^(1-1)-H$36*(((1+Assumptions!$B$13)^(1-1)-1)/Assumptions!$B$13))*Assumptions!$B$13)),0)*Assumptions!$B$28))+(IF(1<=Assumptions!$B$27,H$33/Assumptions!$B$27,0))-(H$36-((H$35*(1+Assumptions!$B$13)^(1-1)-H$36*(((1+Assumptions!$B$13)^(1-1)-1)/Assumptions!$B$13))*Assumptions!$B$13)) -> 2.6661632 | I39: =(((((Assumptions!$B$17*(1+I$31)*(1+Assumptions!$B$24)^(1-1))-(Assumptions!$B$21*(1+Assumptions!$B$25)^(1-1)))-(IF(1<=Assumptions!$B$27,I$33/Assumptions!$B$27,0)))-((I$35*(1+Assumptions!$B$13)^(1-1)-I$36*(((1+Assumptions!$B$13)^(1-1)-1)/Assumptions!$B$13))*Assumptions!$B$13))-(MAX(((((Assumptions!$B$17*(1+I$31)*(1+Assumptions!$B$24)^(1-1))-(Assumptions!$B$21*(1+Assumptions!$B$25)^(1-1)))-(IF(1<=Assumptions!$B$27,I$33/Assumptions!$B$27,0)))-((I$35*(1+Assumptions!$B$13)^(1-1)-I$36*(((1+Assumptions!$B$13)^(1-1)-1)/Assumptions!$B$13))*Assumptions!$B$13)),0)*Assumptions!$B$28))+(IF(1<=Assumptions!$B$27,I$33/Assumptions!$B$27,0))-(I$36-((I$35*(1+Assumptions!$B$13)^(1-1)-I$36*(((1+Assumptions!$B$13)^(1-1)-1)/Assumptions!$B$13))*Assumptions!$B$13)) -> 4.2726563 | J39: =(((((Assumptions!$B$17*(1+J$31)*(1+Assumptions!$B$24)^(1-1))-(Assumptions!$B$21*(1+Assumptions!$B$25)^(1-1)))-(IF(1<=Assumptions!$B$27,J$33/Assumptions!$B$27,0)))-((J$35*(1+Assumptions!$B$13)^(1-1)-J$36*(((1+Assumptions!$B$13)^(1-1)-1)/Assumptions!$B$13))*Assumptions!$B$13))-(MAX(((((Assumptions!$B$17*(1+J$31)*(1+Assumptions!$B$24)^(1-1))-(Assumptions!$B$21*(1+Assumptions!$B$25)^(1-1)))-(IF(1<=Assumptions!$B$27,J$33/Assumptions!$B$27,0)))-((J$35*(1+Assumptions!$B$13)^(1-1)-J$36*(((1+Assumptions!$B$13)^(1-1)-1)/Assumptions!$B$13))*Assumptions!$B$13)),0)*Assumptions!$B$28))+(IF(1<=Assumptions!$B$27,J$33/Assumptions!$B$27,0))-(J$36-((J$35*(1+Assumptions!$B$13)^(1-1)-J$36*(((1+Assumptions!$B$13)^(1-1)-1)/Assumptions!$B$13))*Assumptions!$B$13)) -> 3.8937848 | ... Q39: =(((((Assumptions!$B$17*(1+Q$31)*(1+Assumptions!$B$24)^(1-1))-(Assumptions!$B$21*(1+Assumptions!$B$25)^(1-1)))-(IF(1<=Assumptions!$B$27,Q$33/Assumptions!$B$27,0)))-((Q$35*(1+Assumptions!$B$13)^(1-1)-Q$36*(((1+Assumptions!$B$13)^(1-1)-1)/Assumptions!$B$13))*Assumptions!$B$13))-(MAX(((((Assumptions!$B$17*(1+Q$31)*(1+Assumptions!$B$24)^(1-1))-(Assumptions!$B$21*(1+Assumptions!$B$25)^(1-1)))-(IF(1<=Assumptions!$B$27,Q$33/Assumptions!$B$27,0)))-((Q$35*(1+Assumptions!$B$13)^(1-1)-Q$36*(((1+Assumptions!$B$13)^(1-1)-1)/Assumptions!$B$13))*Assumptions!$B$13)),0)*Assumptions!$B$28))+(IF(1<=Assumptions!$B$27,Q$33/Assumptions!$B$27,0))-(Q$36-((Q$35*(1+Assumptions!$B$13)^(1-1)-Q$36*(((1+Assumptions!$B$13)^(1-1)-1)/Assumptions!$B$13))*Assumptions!$B$13)) -> 5.2124132
A40: 2 | C40: =(((((Assumptions!$B$17*(1+C$31)*(1+Assumptions!$B$24)^(2-1))-(Assumptions!$B$21*(1+Assumptions!$B$25)^(2-1)))-(IF(2<=Assumptions!$B$27,C$33/Assumptions!$B$27,0)))-((C$35*(1+Assumptions!$B$13)^(2-1)-C$36*(((1+Assumptions!$B$13)^(2-1)-1)/Assumptions!$B$13))*Assumptions!$B$13))-(MAX(((((Assumptions!$B$17*(1+C$31)*(1+Assumptions!$B$24)^(2-1))-(Assumptions!$B$21*(1+Assumptions!$B$25)^(2-1)))-(IF(2<=Assumptions!$B$27,C$33/Assumptions!$B$27,0)))-((C$35*(1+Assumptions!$B$13)^(2-1)-C$36*(((1+Assumptions!$B$13)^(2-1)-1)/Assumptions!$B$13))*Assumptions!$B$13)),0)*Assumptions!$B$28))+(IF(2<=Assumptions!$B$27,C$33/Assumptions!$B$27,0))-(C$36-((C$35*(1+Assumptions!$B$13)^(2-1)-C$36*(((1+Assumptions!$B$13)^(2-1)-1)/Assumptions!$B$13))*Assumptions!$B$13)) -> 2.5199899 | D40: =(((((Assumptions!$B$17*(1+D$31)*(1+Assumptions!$B$24)^(2-1))-(Assumptions!$B$21*(1+Assumptions!$B$25)^(2-1)))-(IF(2<=Assumptions!$B$27,D$33/Assumptions!$B$27,0)))-((D$35*(1+Assumptions!$B$13)^(2-1)-D$36*(((1+Assumptions!$B$13)^(2-1)-1)/Assumptions!$B$13))*Assumptions!$B$13))-(MAX(((((Assumptions!$B$17*(1+D$31)*(1+Assumptions!$B$24)^(2-1))-(Assumptions!$B$21*(1+Assumptions!$B$25)^(2-1)))-(IF(2<=Assumptions!$B$27,D$33/Assumptions!$B$27,0)))-((D$35*(1+Assumptions!$B$13)^(2-1)-D$36*(((1+Assumptions!$B$13)^(2-1)-1)/Assumptions!$B$13))*Assumptions!$B$13)),0)*Assumptions!$B$28))+(IF(2<=Assumptions!$B$27,D$33/Assumptions!$B$27,0))-(D$36-((D$35*(1+Assumptions!$B$13)^(2-1)-D$36*(((1+Assumptions!$B$13)^(2-1)-1)/Assumptions!$B$13))*Assumptions!$B$13)) -> 2.1397955 | E40: =(((((Assumptions!$B$17*(1+E$31)*(1+Assumptions!$B$24)^(2-1))-(Assumptions!$B$21*(1+Assumptions!$B$25)^(2-1)))-(IF(2<=Assumptions!$B$27,E$33/Assumptions!$B$27,0)))-((E$35*(1+Assumptions!$B$13)^(2-1)-E$36*(((1+Assumptions!$B$13)^(2-1)-1)/Assumptions!$B$13))*Assumptions!$B$13))-(MAX(((((Assumptions!$B$17*(1+E$31)*(1+Assumptions!$B$24)^(2-1))-(Assumptions!$B$21*(1+Assumptions!$B$25)^(2-1)))-(IF(2<=Assumptions!$B$27,E$33/Assumptions!$B$27,0)))-((E$35*(1+Assumptions!$B$13)^(2-1)-E$36*(((1+Assumptions!$B$13)^(2-1)-1)/Assumptions!$B$13))*Assumptions!$B$13)),0)*Assumptions!$B$28))+(IF(2<=Assumptions!$B$27,E$33/Assumptions!$B$27,0))-(E$36-((E$35*(1+Assumptions!$B$13)^(2-1)-E$36*(((1+Assumptions!$B$13)^(2-1)-1)/Assumptions!$B$13))*Assumptions!$B$13)) -> 1.759601 | F40: =(((((Assumptions!$B$17*(1+F$31)*(1+Assumptions!$B$24)^(2-1))-(Assumptions!$B$21*(1+Assumptions!$B$25)^(2-1)))-(IF(2<=Assumptions!$B$27,F$33/Assumptions!$B$27,0)))-((F$35*(1+Assumptions!$B$13)^(2-1)-F$36*(((1+Assumptions!$B$13)^(2-1)-1)/Assumptions!$B$13))*Assumptions!$B$13))-(MAX(((((Assumptions!$B$17*(1+F$31)*(1+Assumptions!$B$24)^(2-1))-(Assumptions!$B$21*(1+Assumptions!$B$25)^(2-1)))-(IF(2<=Assumptions!$B$27,F$33/Assumptions!$B$27,0)))-((F$35*(1+Assumptions!$B$13)^(2-1)-F$36*(((1+Assumptions!$B$13)^(2-1)-1)/Assumptions!$B$13))*Assumptions!$B$13)),0)*Assumptions!$B$28))+(IF(2<=Assumptions!$B$27,F$33/Assumptions!$B$27,0))-(F$36-((F$35*(1+Assumptions!$B$13)^(2-1)-F$36*(((1+Assumptions!$B$13)^(2-1)-1)/Assumptions!$B$13))*Assumptions!$B$13)) -> 3.3653449 | G40: =(((((Assumptions!$B$17*(1+G$31)*(1+Assumptions!$B$24)^(2-1))-(Assumptions!$B$21*(1+Assumptions!$B$25)^(2-1)))-(IF(2<=Assumptions!$B$27,G$33/Assumptions!$B$27,0)))-((G$35*(1+Assumptions!$B$13)^(2-1)-G$36*(((1+Assumptions!$B$13)^(2-1)-1)/Assumptions!$B$13))*Assumptions!$B$13))-(MAX(((((Assumptions!$B$17*(1+G$31)*(1+Assumptions!$B$24)^(2-1))-(Assumptions!$B$21*(1+Assumptions!$B$25)^(2-1)))-(IF(2<=Assumptions!$B$27,G$33/Assumptions!$B$27,0)))-((G$35*(1+Assumptions!$B$13)^(2-1)-G$36*(((1+Assumptions!$B$13)^(2-1)-1)/Assumptions!$B$13))*Assumptions!$B$13)),0)*Assumptions!$B$28))+(IF(2<=Assumptions!$B$27,G$33/Assumptions!$B$27,0))-(G$36-((G$35*(1+Assumptions!$B$13)^(2-1)-G$36*(((1+Assumptions!$B$13)^(2-1)-1)/Assumptions!$B$13))*Assumptions!$B$13)) -> 2.9851505 | H40: =(((((Assumptions!$B$17*(1+H$31)*(1+Assumptions!$B$24)^(2-1))-(Assumptions!$B$21*(1+Assumptions!$B$25)^(2-1)))-(IF(2<=Assumptions!$B$27,H$33/Assumptions!$B$27,0)))-((H$35*(1+Assumptions!$B$13)^(2-1)-H$36*(((1+Assumptions!$B$13)^(2-1)-1)/Assumptions!$B$13))*Assumptions!$B$13))-(MAX(((((Assumptions!$B$17*(1+H$31)*(1+Assumptions!$B$24)^(2-1))-(Assumptions!$B$21*(1+Assumptions!$B$25)^(2-1)))-(IF(2<=Assumptions!$B$27,H$33/Assumptions!$B$27,0)))-((H$35*(1+Assumptions!$B$13)^(2-1)-H$36*(((1+Assumptions!$B$13)^(2-1)-1)/Assumptions!$B$13))*Assumptions!$B$13)),0)*Assumptions!$B$28))+(IF(2<=Assumptions!$B$27,H$33/Assumptions!$B$27,0))-(H$36-((H$35*(1+Assumptions!$B$13)^(2-1)-H$36*(((1+Assumptions!$B$13)^(2-1)-1)/Assumptions!$B$13))*Assumptions!$B$13)) -> 2.604956 | I40: =(((((Assumptions!$B$17*(1+I$31)*(1+Assumptions!$B$24)^(2-1))-(Assumptions!$B$21*(1+Assumptions!$B$25)^(2-1)))-(IF(2<=Assumptions!$B$27,I$33/Assumptions!$B$27,0)))-((I$35*(1+Assumptions!$B$13)^(2-1)-I$36*(((1+Assumptions!$B$13)^(2-1)-1)/Assumptions!$B$13))*Assumptions!$B$13))-(MAX(((((Assumptions!$B$17*(1+I$31)*(1+Assumptions!$B$24)^(2-1))-(Assumptions!$B$21*(1+Assumptions!$B$25)^(2-1)))-(IF(2<=Assumptions!$B$27,I$33/Assumptions!$B$27,0)))-((I$35*(1+Assumptions!$B$13)^(2-1)-I$36*(((1+Assumptions!$B$13)^(2-1)-1)/Assumptions!$B$13))*Assumptions!$B$13)),0)*Assumptions!$B$28))+(IF(2<=Assumptions!$B$27,I$33/Assumptions!$B$27,0))-(I$36-((I$35*(1+Assumptions!$B$13)^(2-1)-I$36*(((1+Assumptions!$B$13)^(2-1)-1)/Assumptions!$B$13))*Assumptions!$B$13)) -> 4.2106999 | J40: =(((((Assumptions!$B$17*(1+J$31)*(1+Assumptions!$B$24)^(2-1))-(Assumptions!$B$21*(1+Assumptions!$B$25)^(2-1)))-(IF(2<=Assumptions!$B$27,J$33/Assumptions!$B$27,0)))-((J$35*(1+Assumptions!$B$13)^(2-1)-J$36*(((1+Assumptions!$B$13)^(2-1)-1)/Assumptions!$B$13))*Assumptions!$B$13))-(MAX(((((Assumptions!$B$17*(1+J$31)*(1+Assumptions!$B$24)^(2-1))-(Assumptions!$B$21*(1+Assumptions!$B$25)^(2-1)))-(IF(2<=Assumptions!$B$27,J$33/Assumptions!$B$27,0)))-((J$35*(1+Assumptions!$B$13)^(2-1)-J$36*(((1+Assumptions!$B$13)^(2-1)-1)/Assumptions!$B$13))*Assumptions!$B$13)),0)*Assumptions!$B$28))+(IF(2<=Assumptions!$B$27,J$33/Assumptions!$B$27,0))-(J$36-((J$35*(1+Assumptions!$B$13)^(2-1)-J$36*(((1+Assumptions!$B$13)^(2-1)-1)/Assumptions!$B$13))*Assumptions!$B$13)) -> 3.8305055 | ... Q40: =(((((Assumptions!$B$17*(1+Q$31)*(1+Assumptions!$B$24)^(2-1))-(Assumptions!$B$21*(1+Assumptions!$B$25)^(2-1)))-(IF(2<=Assumptions!$B$27,Q$33/Assumptions!$B$27,0)))-((Q$35*(1+Assumptions!$B$13)^(2-1)-Q$36*(((1+Assumptions!$B$13)^(2-1)-1)/Assumptions!$B$13))*Assumptions!$B$13))-(MAX(((((Assumptions!$B$17*(1+Q$31)*(1+Assumptions!$B$24)^(2-1))-(Assumptions!$B$21*(1+Assumptions!$B$25)^(2-1)))-(IF(2<=Assumptions!$B$27,Q$33/Assumptions!$B$27,0)))-((Q$35*(1+Assumptions!$B$13)^(2-1)-Q$36*(((1+Assumptions!$B$13)^(2-1)-1)/Assumptions!$B$13))*Assumptions!$B$13)),0)*Assumptions!$B$28))+(IF(2<=Assumptions!$B$27,Q$33/Assumptions!$B$27,0))-(Q$36-((Q$35*(1+Assumptions!$B$13)^(2-1)-Q$36*(((1+Assumptions!$B$13)^(2-1)-1)/Assumptions!$B$13))*Assumptions!$B$13)) -> 5.141021
A41: 3 | C41: =(((((Assumptions!$B$17*(1+C$31)*(1+Assumptions!$B$24)^(3-1))-(Assumptions!$B$21*(1+Assumptions!$B$25)^(3-1)))-(IF(3<=Assumptions!$B$27,C$33/Assumptions!$B$27,0)))-((C$35*(1+Assumptions!$B$13)^(3-1)-C$36*(((1+Assumptions!$B$13)^(3-1)-1)/Assumptions!$B$13))*Assumptions!$B$13))-(MAX(((((Assumptions!$B$17*(1+C$31)*(1+Assumptions!$B$24)^(3-1))-(Assumptions!$B$21*(1+Assumptions!$B$25)^(3-1)))-(IF(3<=Assumptions!$B$27,C$33/Assumptions!$B$27,0)))-((C$35*(1+Assumptions!$B$13)^(3-1)-C$36*(((1+Assumptions!$B$13)^(3-1)-1)/Assumptions!$B$13))*Assumptions!$B$13)),0)*Assumptions!$B$28))+(IF(3<=Assumptions!$B$27,C$33/Assumptions!$B$27,0))-(C$36-((C$35*(1+Assumptions!$B$13)^(3-1)-C$36*(((1+Assumptions!$B$13)^(3-1)-1)/Assumptions!$B$13))*Assumptions!$B$13)) -> 2.4640149 | D41: =(((((Assumptions!$B$17*(1+D$31)*(1+Assumptions!$B$24)^(3-1))-(Assumptions!$B$21*(1+Assumptions!$B$25)^(3-1)))-(IF(3<=Assumptions!$B$27,D$33/Assumptions!$B$27,0)))-((D$35*(1+Assumptions!$B$13)^(3-1)-D$36*(((1+Assumptions!$B$13)^(3-1)-1)/Assumptions!$B$13))*Assumptions!$B$13))-(MAX(((((Assumptions!$B$17*(1+D$31)*(1+Assumptions!$B$24)^(3-1))-(Assumptions!$B$21*(1+Assumptions!$B$25)^(3-1)))-(IF(3<=Assumptions!$B$27,D$33/Assumptions!$B$27,0)))-((D$35*(1+Assumptions!$B$13)^(3-1)-D$36*(((1+Assumptions!$B$13)^(3-1)-1)/Assumptions!$B$13))*Assumptions!$B$13)),0)*Assumptions!$B$28))+(IF(3<=Assumptions!$B$27,D$33/Assumptions!$B$27,0))-(D$36-((D$35*(1+Assumptions!$B$13)^(3-1)-D$36*(((1+Assumptions!$B$13)^(3-1)-1)/Assumptions!$B$13))*Assumptions!$B$13)) -> 2.0824314 | E41: =(((((Assumptions!$B$17*(1+E$31)*(1+Assumptions!$B$24)^(3-1))-(Assumptions!$B$21*(1+Assumptions!$B$25)^(3-1)))-(IF(3<=Assumptions!$B$27,E$33/Assumptions!$B$27,0)))-((E$35*(1+Assumptions!$B$13)^(3-1)-E$36*(((1+Assumptions!$B$13)^(3-1)-1)/Assumptions!$B$13))*Assumptions!$B$13))-(MAX(((((Assumptions!$B$17*(1+E$31)*(1+Assumptions!$B$24)^(3-1))-(Assumptions!$B$21*(1+Assumptions!$B$25)^(3-1)))-(IF(3<=Assumptions!$B$27,E$33/Assumptions!$B$27,0)))-((E$35*(1+Assumptions!$B$13)^(3-1)-E$36*(((1+Assumptions!$B$13)^(3-1)-1)/Assumptions!$B$13))*Assumptions!$B$13)),0)*Assumptions!$B$28))+(IF(3<=Assumptions!$B$27,E$33/Assumptions!$B$27,0))-(E$36-((E$35*(1+Assumptions!$B$13)^(3-1)-E$36*(((1+Assumptions!$B$13)^(3-1)-1)/Assumptions!$B$13))*Assumptions!$B$13)) -> 1.7008479 | F41: =(((((Assumptions!$B$17*(1+F$31)*(1+Assumptions!$B$24)^(3-1))-(Assumptions!$B$21*(1+Assumptions!$B$25)^(3-1)))-(IF(3<=Assumptions!$B$27,F$33/Assumptions!$B$27,0)))-((F$35*(1+Assumptions!$B$13)^(3-1)-F$36*(((1+Assumptions!$B$13)^(3-1)-1)/Assumptions!$B$13))*Assumptions!$B$13))-(MAX(((((Assumptions!$B$17*(1+F$31)*(1+Assumptions!$B$24)^(3-1))-(Assumptions!$B$21*(1+Assumptions!$B$25)^(3-1)))-(IF(3<=Assumptions!$B$27,F$33/Assumptions!$B$27,0)))-((F$35*(1+Assumptions!$B$13)^(3-1)-F$36*(((1+Assumptions!$B$13)^(3-1)-1)/Assumptions!$B$13))*Assumptions!$B$13)),0)*Assumptions!$B$28))+(IF(3<=Assumptions!$B$27,F$33/Assumptions!$B$27,0))-(F$36-((F$35*(1+Assumptions!$B$13)^(3-1)-F$36*(((1+Assumptions!$B$13)^(3-1)-1)/Assumptions!$B$13))*Assumptions!$B$13)) -> 3.3059885 | G41: =(((((Assumptions!$B$17*(1+G$31)*(1+Assumptions!$B$24)^(3-1))-(Assumptions!$B$21*(1+Assumptions!$B$25)^(3-1)))-(IF(3<=Assumptions!$B$27,G$33/Assumptions!$B$27,0)))-((G$35*(1+Assumptions!$B$13)^(3-1)-G$36*(((1+Assumptions!$B$13)^(3-1)-1)/Assumptions!$B$13))*Assumptions!$B$13))-(MAX(((((Assumptions!$B$17*(1+G$31)*(1+Assumptions!$B$24)^(3-1))-(Assumptions!$B$21*(1+Assumptions!$B$25)^(3-1)))-(IF(3<=Assumptions!$B$27,G$33/Assumptions!$B$27,0)))-((G$35*(1+Assumptions!$B$13)^(3-1)-G$36*(((1+Assumptions!$B$13)^(3-1)-1)/Assumptions!$B$13))*Assumptions!$B$13)),0)*Assumptions!$B$28))+(IF(3<=Assumptions!$B$27,G$33/Assumptions!$B$27,0))-(G$36-((G$35*(1+Assumptions!$B$13)^(3-1)-G$36*(((1+Assumptions!$B$13)^(3-1)-1)/Assumptions!$B$13))*Assumptions!$B$13)) -> 2.924405 | H41: =(((((Assumptions!$B$17*(1+H$31)*(1+Assumptions!$B$24)^(3-1))-(Assumptions!$B$21*(1+Assumptions!$B$25)^(3-1)))-(IF(3<=Assumptions!$B$27,H$33/Assumptions!$B$27,0)))-((H$35*(1+Assumptions!$B$13)^(3-1)-H$36*(((1+Assumptions!$B$13)^(3-1)-1)/Assumptions!$B$13))*Assumptions!$B$13))-(MAX(((((Assumptions!$B$17*(1+H$31)*(1+Assumptions!$B$24)^(3-1))-(Assumptions!$B$21*(1+Assumptions!$B$25)^(3-1)))-(IF(3<=Assumptions!$B$27,H$33/Assumptions!$B$27,0)))-((H$35*(1+Assumptions!$B$13)^(3-1)-H$36*(((1+Assumptions!$B$13)^(3-1)-1)/Assumptions!$B$13))*Assumptions!$B$13)),0)*Assumptions!$B$28))+(IF(3<=Assumptions!$B$27,H$33/Assumptions!$B$27,0))-(H$36-((H$35*(1+Assumptions!$B$13)^(3-1)-H$36*(((1+Assumptions!$B$13)^(3-1)-1)/Assumptions!$B$13))*Assumptions!$B$13)) -> 2.5428214 | I41: =(((((Assumptions!$B$17*(1+I$31)*(1+Assumptions!$B$24)^(3-1))-(Assumptions!$B$21*(1+Assumptions!$B$25)^(3-1)))-(IF(3<=Assumptions!$B$27,I$33/Assumptions!$B$27,0)))-((I$35*(1+Assumptions!$B$13)^(3-1)-I$36*(((1+Assumptions!$B$13)^(3-1)-1)/Assumptions!$B$13))*Assumptions!$B$13))-(MAX(((((Assumptions!$B$17*(1+I$31)*(1+Assumptions!$B$24)^(3-1))-(Assumptions!$B$21*(1+Assumptions!$B$25)^(3-1)))-(IF(3<=Assumptions!$B$27,I$33/Assumptions!$B$27,0)))-((I$35*(1+Assumptions!$B$13)^(3-1)-I$36*(((1+Assumptions!$B$13)^(3-1)-1)/Assumptions!$B$13))*Assumptions!$B$13)),0)*Assumptions!$B$28))+(IF(3<=Assumptions!$B$27,I$33/Assumptions!$B$27,0))-(I$36-((I$35*(1+Assumptions!$B$13)^(3-1)-I$36*(((1+Assumptions!$B$13)^(3-1)-1)/Assumptions!$B$13))*Assumptions!$B$13)) -> 4.1479621 | J41: =(((((Assumptions!$B$17*(1+J$31)*(1+Assumptions!$B$24)^(3-1))-(Assumptions!$B$21*(1+Assumptions!$B$25)^(3-1)))-(IF(3<=Assumptions!$B$27,J$33/Assumptions!$B$27,0)))-((J$35*(1+Assumptions!$B$13)^(3-1)-J$36*(((1+Assumptions!$B$13)^(3-1)-1)/Assumptions!$B$13))*Assumptions!$B$13))-(MAX(((((Assumptions!$B$17*(1+J$31)*(1+Assumptions!$B$24)^(3-1))-(Assumptions!$B$21*(1+Assumptions!$B$25)^(3-1)))-(IF(3<=Assumptions!$B$27,J$33/Assumptions!$B$27,0)))-((J$35*(1+Assumptions!$B$13)^(3-1)-J$36*(((1+Assumptions!$B$13)^(3-1)-1)/Assumptions!$B$13))*Assumptions!$B$13)),0)*Assumptions!$B$28))+(IF(3<=Assumptions!$B$27,J$33/Assumptions!$B$27,0))-(J$36-((J$35*(1+Assumptions!$B$13)^(3-1)-J$36*(((1+Assumptions!$B$13)^(3-1)-1)/Assumptions!$B$13))*Assumptions!$B$13)) -> 3.7663785 | ... Q41: =(((((Assumptions!$B$17*(1+Q$31)*(1+Assumptions!$B$24)^(3-1))-(Assumptions!$B$21*(1+Assumptions!$B$25)^(3-1)))-(IF(3<=Assumptions!$B$27,Q$33/Assumptions!$B$27,0)))-((Q$35*(1+Assumptions!$B$13)^(3-1)-Q$36*(((1+Assumptions!$B$13)^(3-1)-1)/Assumptions!$B$13))*Assumptions!$B$13))-(MAX(((((Assumptions!$B$17*(1+Q$31)*(1+Assumptions!$B$24)^(3-1))-(Assumptions!$B$21*(1+Assumptions!$B$25)^(3-1)))-(IF(3<=Assumptions!$B$27,Q$33/Assumptions!$B$27,0)))-((Q$35*(1+Assumptions!$B$13)^(3-1)-Q$36*(((1+Assumptions!$B$13)^(3-1)-1)/Assumptions!$B$13))*Assumptions!$B$13)),0)*Assumptions!$B$28))+(IF(3<=Assumptions!$B$27,Q$33/Assumptions!$B$27,0))-(Q$36-((Q$35*(1+Assumptions!$B$13)^(3-1)-Q$36*(((1+Assumptions!$B$13)^(3-1)-1)/Assumptions!$B$13))*Assumptions!$B$13)) -> 5.0687422
A42: 4 | C42: =(((((Assumptions!$B$17*(1+C$31)*(1+Assumptions!$B$24)^(4-1))-(Assumptions!$B$21*(1+Assumptions!$B$25)^(4-1)))-(IF(4<=Assumptions!$B$27,C$33/Assumptions!$B$27,0)))-((C$35*(1+Assumptions!$B$13)^(4-1)-C$36*(((1+Assumptions!$B$13)^(4-1)-1)/Assumptions!$B$13))*Assumptions!$B$13))-(MAX(((((Assumptions!$B$17*(1+C$31)*(1+Assumptions!$B$24)^(4-1))-(Assumptions!$B$21*(1+Assumptions!$B$25)^(4-1)))-(IF(4<=Assumptions!$B$27,C$33/Assumptions!$B$27,0)))-((C$35*(1+Assumptions!$B$13)^(4-1)-C$36*(((1+Assumptions!$B$13)^(4-1)-1)/Assumptions!$B$13))*Assumptions!$B$13)),0)*Assumptions!$B$28))+(IF(4<=Assumptions!$B$27,C$33/Assumptions!$B$27,0))-(C$36-((C$35*(1+Assumptions!$B$13)^(4-1)-C$36*(((1+Assumptions!$B$13)^(4-1)-1)/Assumptions!$B$13))*Assumptions!$B$13)) -> 2.4071946 | D42: =(((((Assumptions!$B$17*(1+D$31)*(1+Assumptions!$B$24)^(4-1))-(Assumptions!$B$21*(1+Assumptions!$B$25)^(4-1)))-(IF(4<=Assumptions!$B$27,D$33/Assumptions!$B$27,0)))-((D$35*(1+Assumptions!$B$13)^(4-1)-D$36*(((1+Assumptions!$B$13)^(4-1)-1)/Assumptions!$B$13))*Assumptions!$B$13))-(MAX(((((Assumptions!$B$17*(1+D$31)*(1+Assumptions!$B$24)^(4-1))-(Assumptions!$B$21*(1+Assumptions!$B$25)^(4-1)))-(IF(4<=Assumptions!$B$27,D$33/Assumptions!$B$27,0)))-((D$35*(1+Assumptions!$B$13)^(4-1)-D$36*(((1+Assumptions!$B$13)^(4-1)-1)/Assumptions!$B$13))*Assumptions!$B$13)),0)*Assumptions!$B$28))+(IF(4<=Assumptions!$B$27,D$33/Assumptions!$B$27,0))-(D$36-((D$35*(1+Assumptions!$B$13)^(4-1)-D$36*(((1+Assumptions!$B$13)^(4-1)-1)/Assumptions!$B$13))*Assumptions!$B$13)) -> 2.0241525 | E42: =(((((Assumptions!$B$17*(1+E$31)*(1+Assumptions!$B$24)^(4-1))-(Assumptions!$B$21*(1+Assumptions!$B$25)^(4-1)))-(IF(4<=Assumptions!$B$27,E$33/Assumptions!$B$27,0)))-((E$35*(1+Assumptions!$B$13)^(4-1)-E$36*(((1+Assumptions!$B$13)^(4-1)-1)/Assumptions!$B$13))*Assumptions!$B$13))-(MAX(((((Assumptions!$B$17*(1+E$31)*(1+Assumptions!$B$24)^(4-1))-(Assumptions!$B$21*(1+Assumptions!$B$25)^(4-1)))-(IF(4<=Assumptions!$B$27,E$33/Assumptions!$B$27,0)))-((E$35*(1+Assumptions!$B$13)^(4-1)-E$36*(((1+Assumptions!$B$13)^(4-1)-1)/Assumptions!$B$13))*Assumptions!$B$13)),0)*Assumptions!$B$28))+(IF(4<=Assumptions!$B$27,E$33/Assumptions!$B$27,0))-(E$36-((E$35*(1+Assumptions!$B$13)^(4-1)-E$36*(((1+Assumptions!$B$13)^(4-1)-1)/Assumptions!$B$13))*Assumptions!$B$13)) -> 1.6411105 | F42: =(((((Assumptions!$B$17*(1+F$31)*(1+Assumptions!$B$24)^(4-1))-(Assumptions!$B$21*(1+Assumptions!$B$25)^(4-1)))-(IF(4<=Assumptions!$B$27,F$33/Assumptions!$B$27,0)))-((F$35*(1+Assumptions!$B$13)^(4-1)-F$36*(((1+Assumptions!$B$13)^(4-1)-1)/Assumptions!$B$13))*Assumptions!$B$13))-(MAX(((((Assumptions!$B$17*(1+F$31)*(1+Assumptions!$B$24)^(4-1))-(Assumptions!$B$21*(1+Assumptions!$B$25)^(4-1)))-(IF(4<=Assumptions!$B$27,F$33/Assumptions!$B$27,0)))-((F$35*(1+Assumptions!$B$13)^(4-1)-F$36*(((1+Assumptions!$B$13)^(4-1)-1)/Assumptions!$B$13))*Assumptions!$B$13)),0)*Assumptions!$B$28))+(IF(4<=Assumptions!$B$27,F$33/Assumptions!$B$27,0))-(F$36-((F$35*(1+Assumptions!$B$13)^(4-1)-F$36*(((1+Assumptions!$B$13)^(4-1)-1)/Assumptions!$B$13))*Assumptions!$B$13)) -> 3.2458003 | G42: =(((((Assumptions!$B$17*(1+G$31)*(1+Assumptions!$B$24)^(4-1))-(Assumptions!$B$21*(1+Assumptions!$B$25)^(4-1)))-(IF(4<=Assumptions!$B$27,G$33/Assumptions!$B$27,0)))-((G$35*(1+Assumptions!$B$13)^(4-1)-G$36*(((1+Assumptions!$B$13)^(4-1)-1)/Assumptions!$B$13))*Assumptions!$B$13))-(MAX(((((Assumptions!$B$17*(1+G$31)*(1+Assumptions!$B$24)^(4-1))-(Assumptions!$B$21*(1+Assumptions!$B$25)^(4-1)))-(IF(4<=Assumptions!$B$27,G$33/Assumptions!$B$27,0)))-((G$35*(1+Assumptions!$B$13)^(4-1)-G$36*(((1+Assumptions!$B$13)^(4-1)-1)/Assumptions!$B$13))*Assumptions!$B$13)),0)*Assumptions!$B$28))+(IF(4<=Assumptions!$B$27,G$33/Assumptions!$B$27,0))-(G$36-((G$35*(1+Assumptions!$B$13)^(4-1)-G$36*(((1+Assumptions!$B$13)^(4-1)-1)/Assumptions!$B$13))*Assumptions!$B$13)) -> 2.8627582 | H42: =(((((Assumptions!$B$17*(1+H$31)*(1+Assumptions!$B$24)^(4-1))-(Assumptions!$B$21*(1+Assumptions!$B$25)^(4-1)))-(IF(4<=Assumptions!$B$27,H$33/Assumptions!$B$27,0)))-((H$35*(1+Assumptions!$B$13)^(4-1)-H$36*(((1+Assumptions!$B$13)^(4-1)-1)/Assumptions!$B$13))*Assumptions!$B$13))-(MAX(((((Assumptions!$B$17*(1+H$31)*(1+Assumptions!$B$24)^(4-1))-(Assumptions!$B$21*(1+Assumptions!$B$25)^(4-1)))-(IF(4<=Assumptions!$B$27,H$33/Assumptions!$B$27,0)))-((H$35*(1+Assumptions!$B$13)^(4-1)-H$36*(((1+Assumptions!$B$13)^(4-1)-1)/Assumptions!$B$13))*Assumptions!$B$13)),0)*Assumptions!$B$28))+(IF(4<=Assumptions!$B$27,H$33/Assumptions!$B$27,0))-(H$36-((H$35*(1+Assumptions!$B$13)^(4-1)-H$36*(((1+Assumptions!$B$13)^(4-1)-1)/Assumptions!$B$13))*Assumptions!$B$13)) -> 2.4797162 | I42: =(((((Assumptions!$B$17*(1+I$31)*(1+Assumptions!$B$24)^(4-1))-(Assumptions!$B$21*(1+Assumptions!$B$25)^(4-1)))-(IF(4<=Assumptions!$B$27,I$33/Assumptions!$B$27,0)))-((I$35*(1+Assumptions!$B$13)^(4-1)-I$36*(((1+Assumptions!$B$13)^(4-1)-1)/Assumptions!$B$13))*Assumptions!$B$13))-(MAX(((((Assumptions!$B$17*(1+I$31)*(1+Assumptions!$B$24)^(4-1))-(Assumptions!$B$21*(1+Assumptions!$B$25)^(4-1)))-(IF(4<=Assumptions!$B$27,I$33/Assumptions!$B$27,0)))-((I$35*(1+Assumptions!$B$13)^(4-1)-I$36*(((1+Assumptions!$B$13)^(4-1)-1)/Assumptions!$B$13))*Assumptions!$B$13)),0)*Assumptions!$B$28))+(IF(4<=Assumptions!$B$27,I$33/Assumptions!$B$27,0))-(I$36-((I$35*(1+Assumptions!$B$13)^(4-1)-I$36*(((1+Assumptions!$B$13)^(4-1)-1)/Assumptions!$B$13))*Assumptions!$B$13)) -> 4.0844059 | J42: =(((((Assumptions!$B$17*(1+J$31)*(1+Assumptions!$B$24)^(4-1))-(Assumptions!$B$21*(1+Assumptions!$B$25)^(4-1)))-(IF(4<=Assumptions!$B$27,J$33/Assumptions!$B$27,0)))-((J$35*(1+Assumptions!$B$13)^(4-1)-J$36*(((1+Assumptions!$B$13)^(4-1)-1)/Assumptions!$B$13))*Assumptions!$B$13))-(MAX(((((Assumptions!$B$17*(1+J$31)*(1+Assumptions!$B$24)^(4-1))-(Assumptions!$B$21*(1+Assumptions!$B$25)^(4-1)))-(IF(4<=Assumptions!$B$27,J$33/Assumptions!$B$27,0)))-((J$35*(1+Assumptions!$B$13)^(4-1)-J$36*(((1+Assumptions!$B$13)^(4-1)-1)/Assumptions!$B$13))*Assumptions!$B$13)),0)*Assumptions!$B$28))+(IF(4<=Assumptions!$B$27,J$33/Assumptions!$B$27,0))-(J$36-((J$35*(1+Assumptions!$B$13)^(4-1)-J$36*(((1+Assumptions!$B$13)^(4-1)-1)/Assumptions!$B$13))*Assumptions!$B$13)) -> 3.7013639 | ... Q42: =(((((Assumptions!$B$17*(1+Q$31)*(1+Assumptions!$B$24)^(4-1))-(Assumptions!$B$21*(1+Assumptions!$B$25)^(4-1)))-(IF(4<=Assumptions!$B$27,Q$33/Assumptions!$B$27,0)))-((Q$35*(1+Assumptions!$B$13)^(4-1)-Q$36*(((1+Assumptions!$B$13)^(4-1)-1)/Assumptions!$B$13))*Assumptions!$B$13))-(MAX(((((Assumptions!$B$17*(1+Q$31)*(1+Assumptions!$B$24)^(4-1))-(Assumptions!$B$21*(1+Assumptions!$B$25)^(4-1)))-(IF(4<=Assumptions!$B$27,Q$33/Assumptions!$B$27,0)))-((Q$35*(1+Assumptions!$B$13)^(4-1)-Q$36*(((1+Assumptions!$B$13)^(4-1)-1)/Assumptions!$B$13))*Assumptions!$B$13)),0)*Assumptions!$B$28))+(IF(4<=Assumptions!$B$27,Q$33/Assumptions!$B$27,0))-(Q$36-((Q$35*(1+Assumptions!$B$13)^(4-1)-Q$36*(((1+Assumptions!$B$13)^(4-1)-1)/Assumptions!$B$13))*Assumptions!$B$13)) -> 4.9955332
