Workbook

Sheet Inputs
A1: Cyprus PV + 4h BESS — Assumptions (YELLOW = editable)
A2: INV-CY-PVBESS-1-5-10-2026 · September 2026 · Lighthief Cyprus Ltd · Non-binding indicative model
A3: Edit any yellow cell — Detail_* sheets recalc via live formulas. Re-run script to refresh Summary/Cashflow.
A5: Parameter | B5: Value | C5: Unit | D5: Source / Note
A6: PV CONFIGURATION A — FIXED BIFACIAL
A7: Fixed — specific yield | B7: 1800 | C7: kWh/kWp/yr | D7: Public SSOT — fixed bifacial
A8: Fixed — PV EPC turnkey | B8: 600000 | C8: €/MWp | D8: Public turnkey EPC
A9: Fixed — PV O&M | B9: 9000 | C9: €/MW/yr | D9: Public PV O&M
A10: PV CONFIGURATION B — TRACKER + BIFACIAL + WHITE ALBEDO
A11: Tracker — specific yield | B11: 2200 | C11: kWh/kWp/yr | D11: Public SSOT — 2P tracker bifacial
A12: Tracker — PV EPC turnkey | B12: 780000 | C12: €/MWp | D12: Public turnkey EPC
A13: Tracker — PV O&M | B13: 9000 | C13: €/MW/yr | D13: Public PV O&M
A14: BESS & TECHNICAL
A15: BESS duration | B15: 4 | C15: hours | D15: 4-hour system (MW = MWh/4)
A16: Curtailment baseline | B16: 0.5 | C16: % | D16: BESS_DEFAULTS 2027 baseline
A17: BESS capture of curtailment | B17: 0.95 | C17: % | D17: Avdellero public capture 95%
A18: RTE AC–AC | B18: 0.8632 | C18: % | D18: BESS_DEFAULTS.rteAcAc
A19: Full-cycle days / year | B19: 280 | C19: days | D19: Curtailment-active days Cyprus
A20: PRICES (market data)
A21: DAM daytime (uncurtailed PV) | B21: 151.38 | C21: €/MWh | D21: TSOC DAM 339-day sample 06–17h (to 4 Sep 2026)
A22: Evening discharge (BESS) | B22: 212.42 | C22: €/MWh | D22: TSOC DAM 339-day sample evening peak
A23: CAPEX (shared) & OPEX
A24: BESS EPC installed | B24: 125000 | C24: €/MWh | D24: 4h LFP installed
A25: RTB / development | B25: 450000 | C25: €/MW | D25: Public RTB acquisition
A26: EAC connection terms | B26: 150000 | C26: €/MW | D26: Indicative EAC connection
A27: Other CAPEX (flat) | B27: 0 | C27: € | D27: MV cable / permitting / contingency
A28: BESS LTSA | B28: 2200 | C28: €/MWh/yr | D28: Public LTSA — all years (no OEM extended warranty in model)
A29: SCADA / EMS | B29: 5000 | C29: €/yr
A30: Admin | B30: 10000 | C30: €/yr
A31: Land lease — 1 MW | B31: 8000 | C31: €/yr | D31: Indicative; site-specific
A32: Land lease — 5 MW | B32: 25000 | C32: €/yr | D32: Indicative; site-specific
A33: Land lease — 10 MW | B33: 45000 | C33: €/yr | D33: Indicative; site-specific
A34: Insurance | B34: 0.005 | C34: % of CAPEX | D34: 0.5% CAPEX
A35: FINANCE
A36: Aggregator / market access | B36: 0.1 | C36: % | D36: PV_DEFAULTS.aggregatorFeePct
A37: Cyprus CIT | B37: 0.15 | C37: % | D37: From 1 Jan 2026
A38: LTV (senior debt) | B38: 0 | C38: % of CAPEX | D38: 0 = 100% equity base; try 65%
A39: Loan interest rate | B39: 0.055 | C39: % | D39: Indicative Cyprus commercial
A40: Loan tenor | B40: 12 | C40: years
A41: DA — EPC years | B41: 20 | C41: years | D41: Tax depreciation
...

Sheet Summary
A1: Indicative Comparison — 1 / 5 / 10 MW PV + 4-hour BESS (Cyprus merchant hybrid)
A2: Base case = 100% equity. Evening discharge from live market data. Two PV configs.
A4: ■ Configuration: Fixed Bifacial
A5: Metric | B5: 1 MW + 4 MWh | C5: 5 MW + 20 MWh | D5: 10 MW + 40 MWh
A6: PV specific yield (kWh/kWp) | B6: 1800 | C6: 1800 | D6: 1800
A7: BESS energy (MWh) | B7: 4 | C7: 20 | D7: 40
A8: Total CAPEX (€) | B8: 1700000 | C8: 8500000 | D8: 17000000
A9: PV EPC | B9: 600000 | C9: 3000000 | D9: 6000000
A10: BESS EPC | B10: 500000 | C10: 2500000 | D10: 5000000
A11: RTB / development | B11: 450000 | C11: 2250000 | D11: 4500000
A12: Annual PV production (MWh) | B12: 1800 | C12: 9000 | D12: 18000
A13: Gross Y1 revenue (€) | B13: 293015.61 | C13: 1465078 | D13: 2930156.1
A14: Uncurtailed solar | B14: 136242 | C14: 681210 | D14: 1362420
A15: BESS discharge | B15: 156773.61 | C15: 783868.04 | D15: 1567736.1
A16: OPEX Y1 (€) | B16: 49300 | C16: 171500 | D16: 323000
A17: EBITDA Y1 (€) | B17: 214414.05 | C17: 1147070.2 | D17: 2314140.5
... A23: NPV @ 8% (€) | B23: 11191.272 | C23: 681863.26 | D23: 1530635
A26: ■ Configuration: Single-Axis Tracker · Bifacial 2P
A27: Metric | B27: 1 MW + 4 MWh | C27: 5 MW + 20 MWh | D27: 10 MW + 40 MWh
A28: PV specific yield (kWh/kWp) | B28: 2200 | C28: 2200 | D28: 2200
A29: BESS energy (MWh) | B29: 4 | C29: 20 | D29: 40
A30: Total CAPEX (€) | B30: 1880000 | C30: 9400000 | D30: 18800000
A31: PV EPC | B31: 780000 | C31: 3900000 | D31: 7800000
A32: BESS EPC | B32: 500000 | C32: 2500000 | D32: 5000000
A33: RTB / development | B33: 450000 | C33: 2250000 | D33: 4500000
A34: Annual PV production (MWh) | B34: 2200 | C34: 11000 | D34: 22000
A35: Gross Y1 revenue (€) | B35: 358130.19 | C35: 1790650.9 | D35: 3581301.9
A36: Uncurtailed solar | B36: 166518 | C36: 832590 | D36: 1665180
A37: BESS discharge | B37: 191612.19 | C37: 958060.93 | D37: 1916121.9
A38: OPEX Y1 (€) | B38: 50200 | C38: 176000 | D38: 332000
A39: EBITDA Y1 (€) | B39: 272117.17 | C39: 1435585.8 | D39: 2891171.7
... A45: NPV @ 8% (€) | B45: 277537.59 | C45: 2013594.8 | D45: 4194098.2
A48: Notes
A49: Revenue = uncurtailed PV at DAM daytime + curtailed energy stored (charge €0) and discharged at evening price.
A50: Evening discharge €212.42/MWh = TSOC DAM 339-day sample evening peak (1 Oct 2025–4 Sep 2026).
A51: Fixed PV EPC €600k/MWp. Tracker €780k/MWp. RTB €450k/MW. EAC connection €150k/MW.
A52: BESS EPC €125k/MWh installed 4h. LTSA €2,200/MWh/yr. PV O&M €9k/MW/yr.
A53: Cyprus rule: BESS cannot yet buy from DAM — no arbitrage. Capacity/ancillary = €0 (upside).
A54: 20y IRR/NPV include PV & BESS degradation. OPEX is PV O&M + BESS LTSA only (no OEM extended warranty). Indicative, non-binding, ex-VAT.
A55: Contact: Alexander Papacosta, Cyprus Director · +357 99 164 158 · office@lighthief.com

Sheet D_1MW_Fixed
A1: 1 MW + 4 MWh · Fixed Bifacial — live formulas (reads Inputs)
A2: PV capacity (MWp) | B2: =Inputs!$B$44
A3: BESS energy (MWh) | B3: =Inputs!$B$45
A4: BESS power (MW) | B4: =B3/Inputs!$B$15
A5: Specific yield (kWh/kWp) | B5: =Inputs!$B$7
A7: CAPEX
A8: PV EPC | B8: =B2*Inputs!$B$8
A9: BESS EPC | B9: =B3*Inputs!$B$24
A10: RTB / development | B10: =B2*Inputs!$B$25
A11: EAC connection | B11: =B2*Inputs!$B$26
A12: Other CAPEX | B12: =Inputs!$B$27
A13: Total CAPEX | B13: =B8+B9+B10+B11+B12
A14: Senior debt | B14: =B13*Inputs!$B$38
A15: Equity | B15: =B13-B14
A17: ENERGY & REVENUE Y1
A18: Annual PV production (MWh) | B18: =B2*B5
A19: Uncurtailed (MWh) | B19: =B18*(1-Inputs!$B$16)
A20: Curtailed (MWh) | B20: =B18*Inputs!$B$16
A21: BESS charged (MWh) | B21: =MIN(B20*Inputs!$B$17,B3*Inputs!$B$19)
A22: BESS discharged (MWh) | B22: =B21*Inputs!$B$18
A23: Solar revenue (€) | B23: =B19*Inputs!$B$21
A24: BESS revenue (€) | B24: =B22*Inputs!$B$22
A25: Gross revenue (€) | B25: =B23+B24
A26: Aggregator fee (€) | B26: =B25*Inputs!$B$36
A27: Net revenue (€) | B27: =B25-B26
A29: OPEX & RETURNS Y1
A30: PV O&M | B30: =B2*Inputs!$B$9
A31: BESS LTSA | B31: =B3*Inputs!$B$28
A32: SCADA | B32: =Inputs!$B$29
A33: Admin | B33: =Inputs!$B$30
A34: Land lease | B34: =Inputs!$B$31
A35: Insurance | B35: =B13*Inputs!$B$34
A36: Total OPEX | B36: =B30+B31+B32+B33+B34+B35
A37: EBITDA | B37: =B27-B36
A38: Debt service | B38: =IF(B14=0,0,B14*(Inputs!$B$39*(1+Inputs!$B$39)^Inputs!$B$40/((1+Inputs!$B$39)^Inputs!$B$40-1)))
A39: D&A | B39: =(B8+B9)/Inputs!$B$41+(B10+B11)/Inputs!$B$42
A40: Taxable income | B40: =MAX(0,B37-B38-B39)
A41: CIT | B41: =B40*Inputs!$B$37
A42: After-tax FCF | B42: =B37-B38-B41
A43: Cash yield on equity | B43: =IF(B15=0,0,B42/B15)
...

Sheet D_5MW_Fixed
A1: 5 MW + 20 MWh · Fixed Bifacial — live formulas (reads Inputs)
A2: PV capacity (MWp) | B2: =Inputs!$B$46
A3: BESS energy (MWh) | B3: =Inputs!$B$47
A4: BESS power (MW) | B4: =B3/Inputs!$B$15
A5: Specific yield (kWh/kWp) | B5: =Inputs!$B$7
A7: CAPEX
A8: PV EPC | B8: =B2*Inputs!$B$8
A9: BESS EPC | B9: =B3*Inputs!$B$24
A10: RTB / development | B10: =B2*Inputs!$B$25
A11: EAC connection | B11: =B2*Inputs!$B$26
A12: Other CAPEX | B12: =Inputs!$B$27
A13: Total CAPEX | B13: =B8+B9+B10+B11+B12
A14: Senior debt | B14: =B13*Inputs!$B$38
A15: Equity | B15: =B13-B14
A17: ENERGY & REVENUE Y1
A18: Annual PV production (MWh) | B18: =B2*B5
A19: Uncurtailed (MWh) | B19: =B18*(1-Inputs!$B$16)
A20: Curtailed (MWh) | B20: =B18*Inputs!$B$16
A21: BESS charged (MWh) | B21: =MIN(B20*Inputs!$B$17,B3*Inputs!$B$19)
A22: BESS discharged (MWh) | B22: =B21*Inputs!$B$18
A23: Solar revenue (€) | B23: =B19*Inputs!$B$21
A24: BESS revenue (€) | B24: =B22*Inputs!$B$22
A25: Gross revenue (€) | B25: =B23+B24
A26: Aggregator fee (€) | B26: =B25*Inputs!$B$36
A27: Net revenue (€) | B27: =B25-B26
A29: OPEX & RETURNS Y1
A30: PV O&M | B30: =B2*Inputs!$B$9
A31: BESS LTSA | B31: =B3*Inputs!$B$28
A32: SCADA | B32: =Inputs!$B$29
A33: Admin | B33: =Inputs!$B$30
A34: Land lease | B34: =Inputs!$B$32
A35: Insurance | B35: =B13*Inputs!$B$34
A36: Total OPEX | B36: =B30+B31+B32+B33+B34+B35
A37: EBITDA | B37: =B27-B36
A38: Debt service | B38: =IF(B14=0,0,B14*(Inputs!$B$39*(1+Inputs!$B$39)^Inputs!$B$40/((1+Inputs!$B$39)^Inputs!$B$40-1)))
A39: D&A | B39: =(B8+B9)/Inputs!$B$41+(B10+B11)/Inputs!$B$42
A40: Taxable income | B40: =MAX(0,B37-B38-B39)
A41: CIT | B41: =B40*Inputs!$B$37
A42: After-tax FCF | B42: =B37-B38-B41
A43: Cash yield on equity | B43: =IF(B15=0,0,B42/B15)
...

Sheet D_10MW_Fixed
A1: 10 MW + 40 MWh · Fixed Bifacial — live formulas (reads Inputs)
A2: PV capacity (MWp) | B2: =Inputs!$B$48
A3: BESS energy (MWh) | B3: =Inputs!$B$49
A4: BESS power (MW) | B4: =B3/Inputs!$B$15
A5: Specific yield (kWh/kWp) | B5: =Inputs!$B$7
A7: CAPEX
A8: PV EPC | B8: =B2*Inputs!$B$8
A9: BESS EPC | B9: =B3*Inputs!$B$24
A10: RTB / development | B10: =B2*Inputs!$B$25
A11: EAC connection | B11: =B2*Inputs!$B$26
A12: Other CAPEX | B12: =Inputs!$B$27
A13: Total CAPEX | B13: =B8+B9+B10+B11+B12
A14: Senior debt | B14: =B13*Inputs!$B$38
A15: Equity | B15: =B13-B14
A17: ENERGY & REVENUE Y1
A18: Annual PV production (MWh) | B18: =B2*B5
A19: Uncurtailed (MWh) | B19: =B18*(1-Inputs!$B$16)
A20: Curtailed (MWh) | B20: =B18*Inputs!$B$16
A21: BESS charged (MWh) | B21: =MIN(B20*Inputs!$B$17,B3*Inputs!$B$19)
A22: BESS discharged (MWh) | B22: =B21*Inputs!$B$18
A23: Solar revenue (€) | B23: =B19*Inputs!$B$21
A24: BESS revenue (€) | B24: =B22*Inputs!$B$22
A25: Gross revenue (€) | B25: =B23+B24
A26: Aggregator fee (€) | B26: =B25*Inputs!$B$36
A27: Net revenue (€) | B27: =B25-B26
A29: OPEX & RETURNS Y1
A30: PV O&M | B30: =B2*Inputs!$B$9
A31: BESS LTSA | B31: =B3*Inputs!$B$28
A32: SCADA | B32: =Inputs!$B$29
A33: Admin | B33: =Inputs!$B$30
A34: Land lease | B34: =Inputs!$B$33
A35: Insurance | B35: =B13*Inputs!$B$34
A36: Total OPEX | B36: =B30+B31+B32+B33+B34+B35
A37: EBITDA | B37: =B27-B36
A38: Debt service | B38: =IF(B14=0,0,B14*(Inputs!$B$39*(1+Inputs!$B$39)^Inputs!$B$40/((1+Inputs!$B$39)^Inputs!$B$40-1)))
A39: D&A | B39: =(B8+B9)/Inputs!$B$41+(B10+B11)/Inputs!$B$42
A40: Taxable income | B40: =MAX(0,B37-B38-B39)
A41: CIT | B41: =B40*Inputs!$B$37
A42: After-tax FCF | B42: =B37-B38-B41
A43: Cash yield on equity | B43: =IF(B15=0,0,B42/B15)
...

Sheet D_1MW_Tracker
A1: 1 MW + 4 MWh · Single-Axis Tracker · Bifacial 2P — live formulas (reads Inputs)
A2: PV capacity (MWp) | B2: =Inputs!$B$44
A3: BESS energy (MWh) | B3: =Inputs!$B$45
A4: BESS power (MW) | B4: =B3/Inputs!$B$15
A5: Specific yield (kWh/kWp) | B5: =Inputs!$B$11
A7: CAPEX
A8: PV EPC | B8: =B2*Inputs!$B$12
A9: BESS EPC | B9: =B3*Inputs!$B$24
A10: RTB / development | B10: =B2*Inputs!$B$25
A11: EAC connection | B11: =B2*Inputs!$B$26
A12: Other CAPEX | B12: =Inputs!$B$27
A13: Total CAPEX | B13: =B8+B9+B10+B11+B12
A14: Senior debt | B14: =B13*Inputs!$B$38
A15: Equity | B15: =B13-B14
A17: ENERGY & REVENUE Y1
A18: Annual PV production (MWh) | B18: =B2*B5
A19: Uncurtailed (MWh) | B19: =B18*(1-Inputs!$B$16)
A20: Curtailed (MWh) | B20: =B18*Inputs!$B$16
A21: BESS charged (MWh) | B21: =MIN(B20*Inputs!$B$17,B3*Inputs!$B$19)
A22: BESS discharged (MWh) | B22: =B21*Inputs!$B$18
A23: Solar revenue (€) | B23: =B19*Inputs!$B$21
A24: BESS revenue (€) | B24: =B22*Inputs!$B$22
A25: Gross revenue (€) | B25: =B23+B24
A26: Aggregator fee (€) | B26: =B25*Inputs!$B$36
A27: Net revenue (€) | B27: =B25-B26
A29: OPEX & RETURNS Y1
A30: PV O&M | B30: =B2*Inputs!$B$13
A31: BESS LTSA | B31: =B3*Inputs!$B$28
A32: SCADA | B32: =Inputs!$B$29
A33: Admin | B33: =Inputs!$B$30
A34: Land lease | B34: =Inputs!$B$31
A35: Insurance | B35: =B13*Inputs!$B$34
A36: Total OPEX | B36: =B30+B31+B32+B33+B34+B35
A37: EBITDA | B37: =B27-B36
A38: Debt service | B38: =IF(B14=0,0,B14*(Inputs!$B$39*(1+Inputs!$B$39)^Inputs!$B$40/((1+Inputs!$B$39)^Inputs!$B$40-1)))
A39: D&A | B39: =(B8+B9)/Inputs!$B$41+(B10+B11)/Inputs!$B$42
A40: Taxable income | B40: =MAX(0,B37-B38-B39)
A41: CIT | B41: =B40*Inputs!$B$37
A42: After-tax FCF | B42: =B37-B38-B41
A43: Cash yield on equity | B43: =IF(B15=0,0,B42/B15)
...

Sheet D_5MW_Tracker
A1: 5 MW + 20 MWh · Single-Axis Tracker · Bifacial 2P — live formulas (reads Inputs)
A2: PV capacity (MWp) | B2: =Inputs!$B$46
A3: BESS energy (MWh) | B3: =Inputs!$B$47
A4: BESS power (MW) | B4: =B3/Inputs!$B$15
A5: Specific yield (kWh/kWp) | B5: =Inputs!$B$11
A7: CAPEX
A8: PV EPC | B8: =B2*Inputs!$B$12
A9: BESS EPC | B9: =B3*Inputs!$B$24
A10: RTB / development | B10: =B2*Inputs!$B$25
A11: EAC connection | B11: =B2*Inputs!$B$26
A12: Other CAPEX | B12: =Inputs!$B$27
A13: Total CAPEX | B13: =B8+B9+B10+B11+B12
A14: Senior debt | B14: =B13*Inputs!$B$38
A15: Equity | B15: =B13-B14
A17: ENERGY & REVENUE Y1
A18: Annual PV production (MWh) | B18: =B2*B5
A19: Uncurtailed (MWh) | B19: =B18*(1-Inputs!$B$16)
A20: Curtailed (MWh) | B20: =B18*Inputs!$B$16
A21: BESS charged (MWh) | B21: =MIN(B20*Inputs!$B$17,B3*Inputs!$B$19)
A22: BESS discharged (MWh) | B22: =B21*Inputs!$B$18
A23: Solar revenue (€) | B23: =B19*Inputs!$B$21
A24: BESS revenue (€) | B24: =B22*Inputs!$B$22
A25: Gross revenue (€) | B25: =B23+B24
A26: Aggregator fee (€) | B26: =B25*Inputs!$B$36
A27: Net revenue (€) | B27: =B25-B26
A29: OPEX & RETURNS Y1
A30: PV O&M | B30: =B2*Inputs!$B$13
A31: BESS LTSA | B31: =B3*Inputs!$B$28
A32: SCADA | B32: =Inputs!$B$29
A33: Admin | B33: =Inputs!$B$30
A34: Land lease | B34: =Inputs!$B$32
A35: Insurance | B35: =B13*Inputs!$B$34
A36: Total OPEX | B36: =B30+B31+B32+B33+B34+B35
A37: EBITDA | B37: =B27-B36
A38: Debt service | B38: =IF(B14=0,0,B14*(Inputs!$B$39*(1+Inputs!$B$39)^Inputs!$B$40/((1+Inputs!$B$39)^Inputs!$B$40-1)))
A39: D&A | B39: =(B8+B9)/Inputs!$B$41+(B10+B11)/Inputs!$B$42
A40: Taxable income | B40: =MAX(0,B37-B38-B39)
A41: CIT | B41: =B40*Inputs!$B$37
A42: After-tax FCF | B42: =B37-B38-B41
A43: Cash yield on equity | B43: =IF(B15=0,0,B42/B15)
...

Sheet D_10MW_Tracker
A1: 10 MW + 40 MWh · Single-Axis Tracker · Bifacial 2P — live formulas (reads Inputs)
A2: PV capacity (MWp) | B2: =Inputs!$B$48
A3: BESS energy (MWh) | B3: =Inputs!$B$49
A4: BESS power (MW) | B4: =B3/Inputs!$B$15
A5: Specific yield (kWh/kWp) | B5: =Inputs!$B$11
A7: CAPEX
A8: PV EPC | B8: =B2*Inputs!$B$12
A9: BESS EPC | B9: =B3*Inputs!$B$24
A10: RTB / development | B10: =B2*Inputs!$B$25
A11: EAC connection | B11: =B2*Inputs!$B$26
A12: Other CAPEX | B12: =Inputs!$B$27
A13: Total CAPEX | B13: =B8+B9+B10+B11+B12
A14: Senior debt | B14: =B13*Inputs!$B$38
A15: Equity | B15: =B13-B14
A17: ENERGY & REVENUE Y1
A18: Annual PV production (MWh) | B18: =B2*B5
A19: Uncurtailed (MWh) | B19: =B18*(1-Inputs!$B$16)
A20: Curtailed (MWh) | B20: =B18*Inputs!$B$16
A21: BESS charged (MWh) | B21: =MIN(B20*Inputs!$B$17,B3*Inputs!$B$19)
A22: BESS discharged (MWh) | B22: =B21*Inputs!$B$18
A23: Solar revenue (€) | B23: =B19*Inputs!$B$21
A24: BESS revenue (€) | B24: =B22*Inputs!$B$22
A25: Gross revenue (€) | B25: =B23+B24
A26: Aggregator fee (€) | B26: =B25*Inputs!$B$36
A27: Net revenue (€) | B27: =B25-B26
A29: OPEX & RETURNS Y1
A30: PV O&M | B30: =B2*Inputs!$B$13
A31: BESS LTSA | B31: =B3*Inputs!$B$28
A32: SCADA | B32: =Inputs!$B$29
A33: Admin | B33: =Inputs!$B$30
A34: Land lease | B34: =Inputs!$B$33
A35: Insurance | B35: =B13*Inputs!$B$34
A36: Total OPEX | B36: =B30+B31+B32+B33+B34+B35
A37: EBITDA | B37: =B27-B36
A38: Debt service | B38: =IF(B14=0,0,B14*(Inputs!$B$39*(1+Inputs!$B$39)^Inputs!$B$40/((1+Inputs!$B$39)^Inputs!$B$40-1)))
A39: D&A | B39: =(B8+B9)/Inputs!$B$41+(B10+B11)/Inputs!$B$42
A40: Taxable income | B40: =MAX(0,B37-B38-B39)
A41: CIT | B41: =B40*Inputs!$B$37
A42: After-tax FCF | B42: =B37-B38-B41
A43: Cash yield on equity | B43: =IF(B15=0,0,B42/B15)
...

Sheet Cashflow_20y
A1: 20-Year Equity Cashflow (computed from Inputs defaults; re-run script to refresh)
A2: Includes PV & BESS degradation. Recurring OPEX is PV O&M + BESS LTSA only (OEM extended warranty excluded).
A4: Year | B4: 1 MW + 4 MWh · Fixed | C4: 5 MW + 20 MWh · Fixed | D4: 10 MW + 40 MWh · Fixed | E4: 1 MW + 4 MWh · Tracker | F4: 5 MW + 20 MWh · Tracker | G4: 10 MW + 40 MWh · Tracker
A5: 0 (invest) | B5: -1700000 | C5: -8500000 | D5: -17000000 | E5: -1880000 | F5: -9400000 | G5: -18800000
A6: 1 | B6: 196501.94 | C6: 1046259.7 | D6: 2109519.4 | E6: 246899.59 | F6: 1298248 | G6: 2613495.9
A7: 2 | B7: 192982.52 | C7: 1028662.6 | D7: 2074325.2 | E7: 242598.08 | F7: 1276740.4 | G7: 2570480.8
A8: 3 | B8: 189540.66 | C8: 1011453.3 | D8: 2039906.6 | E8: 238391.36 | F8: 1255706.8 | G8: 2528413.6
A9: 4 | B9: 186174.48 | C9: 994622.39 | D9: 2006244.8 | E9: 234277.14 | F9: 1235135.7 | G9: 2487271.4
A10: 5 | B10: 182882.13 | C10: 978160.67 | D10: 1973321.3 | E10: 230253.16 | F10: 1215015.8 | G10: 2447031.6
A11: 6 | B11: 179661.83 | C11: 962059.14 | D11: 1941118.3 | E11: 226317.24 | F11: 1195336.2 | G11: 2407672.4
A12: 7 | B12: 176511.82 | C12: 946309.08 | D12: 1909618.2 | E12: 222467.22 | F12: 1176086.1 | G12: 2369172.2
A13: 8 | B13: 173430.39 | C13: 930901.95 | D13: 1878803.9 | E13: 218701.03 | F13: 1157255.2 | G13: 2331510.3
A14: 9 | B14: 170415.89 | C14: 915829.43 | D14: 1848658.9 | E14: 215016.64 | F14: 1138833.2 | G14: 2294666.4
A15: 10 | B15: 167466.68 | C15: 901083.4 | D15: 1819166.8 | E15: 211412.05 | F15: 1120810.3 | G15: 2258620.5
A16: 11 | B16: 164581.19 | C16: 886655.97 | D16: 1790311.9 | E16: 207885.35 | F16: 1103176.7 | G16: 2223353.5
A17: 12 | B17: 161757.88 | C17: 872539.4 | D17: 1762078.8 | E17: 204434.63 | F17: 1085923.2 | G17: 2188846.3
... A25: 20 | B25: 141236.72 | C25: 769933.62 | D25: 1556867.2 | E25: 179353.22 | F25: 960516.09 | G25: 1938032.2
A27: Equity IRR | B27: 0.080942726 | C27: 0.091286931 | D27: 0.092640174 | E27: 0.10059899 | F27: 0.10948337 | G27: 0.11065175
A28: NPV @ 8% | B28: 11191.272 | C28: 681863.26 | D28: 1530635 | E28: 277537.59 | F28: 2013594.8 | G28: 4194098.2
A29: Simple payback (yr) | B29: 8.6513141 | C29: 8.124178 | D29: 8.0587076 | E29: 7.6144314 | F29: 7.2405274 | G29: 7.19343

Sheet Sources
A1: Single Source of Truth — validation map
A3: Item | B3: File | C3: Value / note
A4: Evening discharge €212.42 | B4: lib/market/cyprus-tsoc-dam-sample.ts | C4: 339 TSOC DAM days to 4 Sep 2026
A5: DAM daytime €151.38 | B5: lib/market/cyprus-tsoc-dam-sample.ts | C5: 06:00–17:00 average
A6: RTE / capture / curtailment | B6: lib/public-hybrid-ssot.ts | C6: 86.32% / 95% / 50%
A7: Fixed PV EPC €600k/MWp | B7: lib/public-hybrid-ssot.ts | C7: Public turnkey EPC
A8: Tracker PV EPC €780k/MWp | B8: lib/public-hybrid-ssot.ts | C8: Public turnkey EPC
A9: BESS EPC €125k/MWh | B9: lib/public-hybrid-ssot.ts | C9: 4h LFP installed
A10: PV O&M €9k/MW/yr | B10: lib/public-hybrid-ssot.ts | C10: Public O&M
A11: BESS LTSA €2,200/MWh/yr | B11: lib/public-hybrid-ssot.ts | C11: Public LTSA
A12: RTB €450k/MW + connection €150k/MW | B12: lib/public-hybrid-ssot.ts
A13: CIT 15% / aggregator 10% | B13: PV_DEFAULTS | C13: From 1 Jan 2026
A14: Yields 1,850 / 2,450 | B14: Client-tested Year-1 | C14: Fixed bifacial / tracker+bifacial+albedo
A15: Contact | B15: lib/constants.ts → COMPANY_DATA | C15: office@lighthief.com / +357 99 164 158
A17: Lighthief Cyprus Ltd · HE 477423 · solarfarms.cy · Alexander Papacosta · +357 99 164 158 · office@lighthief.com
