Workbook
Name Yield_kWh_per_kWp: Assumptions!$B$5
Name DAM_Day_EUR_per_MWh: Assumptions!$B$6
Name DAM_Eve_EUR_per_MWh: Assumptions!$B$7
Name RTE_AC_AC: Assumptions!$B$8
Name Capture_Pct: Assumptions!$B$9
Name Full_Cycle_Days: Assumptions!$B$10
Name Aggregator_Fee_Pct: Assumptions!$B$11
Name CIT_Pct: Assumptions!$B$12
Name LTV_Pct: Assumptions!$B$13
Name Equity_Pct: Assumptions!$B$14
Name Loan_Rate: Assumptions!$B$15
Name Loan_Years: Assumptions!$B$16
Name DA_Years: Assumptions!$B$17
Name PV_OM_EUR_per_MW: Assumptions!$B$18
Name BESS_LTSA_EUR_per_MWh: Assumptions!$B$19
Name Land_EUR_per_MW: Assumptions!$B$20
Name Other_Fixed_EUR: Assumptions!$B$21
Name Other_Pct_of_Capex: Assumptions!$B$22
Name RTB_EUR_per_MW: Assumptions!$B$23
Name EAC_EUR_per_MW: Assumptions!$B$24
Name Tracker_Premium_EUR_per_MW: Assumptions!$B$25
Name Permitting_EUR: Assumptions!$B$26
Name MV_Cable_EUR: Assumptions!$B$27
Name Curtailment_Base_Pct: Assumptions!$B$28
Name Curtailment_Stress_Pct: Assumptions!$B$29
Name Annuity_Factor: Assumptions!$B$39

Sheet Summary
A1: INVESTOR SUMMARY — CYPRUS PV TRACKERS + 4h BESS
A2: Values linked to Model sheet (50% curtailment base case). Edit Assumptions to refresh.
A4: KPI (50% curtailment) | B4: 1 MWp + 4 MWh | C4: 5 MWp + 20 MWh | D4: 10 MWp + 40 MWh
A5: Total CAPEX | B5: =Model!B15 | C5: =Model!C15 | D5: =Model!D15
A6: EBITDA Y1 | B6: =Model!B34 | C6: =Model!C34 | D6: =Model!D34
A7: Net cash to equity Y1 | B7: =Model!B43 | C7: =Model!C43 | D7: =Model!D43
A8: Unlevered payback (yr) | B8: =Model!B44 | C8: =Model!C44 | D8: =Model!D44
A9: Equity payback (yr) | B9: =Model!B45 | C9: =Model!C45 | D9: =Model!D45
A10: Equity cash yield | B10: =Model!B46 | C10: =Model!C46 | D10: =Model!D46
A11: DSCR | B11: =Model!B40 | C11: =Model!C40 | D11: =Model!D40
A14: KPI (65% curtailment stress) | B14: 1 MWp + 4 MWh | C14: 5 MWp + 20 MWh | D14: 10 MWp + 40 MWh
A15: Total CAPEX | B15: =Model!E15 | C15: =Model!F15 | D15: =Model!G15
A16: EBITDA Y1 | B16: =Model!E34 | C16: =Model!F34 | D16: =Model!G34
A17: Net cash to equity Y1 | B17: =Model!E43 | C17: =Model!F43 | D17: =Model!G43
A18: Unlevered payback (yr) | B18: =Model!E44 | C18: =Model!F44 | D18: =Model!G44
A19: Equity payback (yr) | B19: =Model!E45 | C19: =Model!F45 | D19: =Model!G45
A20: Equity cash yield | B20: =Model!E46 | C20: =Model!F46 | D20: =Model!G46
A21: DSCR | B21: =Model!E40 | C21: =Model!F40 | D21: =Model!G40
A24: Contact
A25: Alexander Papacosta · Cyprus Director · +357 99 164 158 · office@lighthief.com
A26: Lighthief Cyprus Ltd · HE 477423 · solarfarms.cy

Sheet Assumptions
A1: LIGHTHIEF CYPRUS — PV TRACKERS + 4h BESS INVESTOR MODEL
A2: Yellow cells = INPUTS (edit these). Green cells on Model sheets = FORMULAS. Ref: LH-CY-PVBESS-TRK-JUL2026 · July 2026 · Confidential
A4: GLOBAL MARKET & TECHNOLOGY INPUTS
A5: Yield kWh per kWp | B5: 2400 | E5: Single-axis + 700 Wp bifacial + white albedo
A6: DAM Day EUR per MWh | B6: 140.88 | E6: TSOC daytime 06–17h sample
A7: DAM Eve EUR per MWh | B7: 182.99 | E7: TSOC evening peak sample
A8: RTE AC AC | B8: 0.8632 | E8: Linyang full-system AC–AC
A9: Capture Pct | B9: 0.874 | E9: Share of curtailed energy captured (pre capacity cap)
A10: Full Cycle Days | B10: 280 | E10: Max BESS full cycles / year
A11: Aggregator Fee Pct | B11: 0.1 | E11: Market access / aggregator
A12: CIT Pct | B12: 0.15 | E12: Cyprus CIT from 1 Jan 2026
A13: LTV Pct | B13: 0.65 | E13: Senior debt / total CapEx
A14: Equity Pct | B14: 0.35 | E14: Must equal 1 − LTV
A15: Loan Rate | B15: 0.055 | E15: Nominal p.a.
A16: Loan Years | B16: 12 | E16: Annuity term
... A29: Curtailment Stress Pct | B29: 0.65 | E29: Case B
A32: SCENARIO SIZING & UNIT CAPEX (PER COLUMN)
A33: Parameter | B33: 1 MWp | C33: 5 MWp | D33: 10 MWp | E33: Note
A34: PV capacity (MWp) | B34: 1 | C34: 5 | D34: 10 | E34: Edit to resize parks
A35: BESS energy (MWh) | B35: 4 | C35: 20 | D35: 40 | E35: 4h duration = 4 × MWp
A36: PV base EPC € (fixed-tilt client) | B36: 730077 | C36: 3200385 | D36: 6100770 | E36: solarpark-epc client schedule
A37: BESS client €/MWh | B37: 168584 | C37: 111900 | D37: 109797 | E37: 4 MWh tier / confirmed 20 MWh / 40 MWh schedule
A39: Annuity factor (loan) | B39: =$B$15*(1+$B$15)^$B$16/((1+$B$15)^$B$16-1)
A41: Legend
A42: INPUT | B42: Editable assumption
A43: FORMULA | B43: Calculated — do not overwrite

Sheet Model
A1: FULL PROJECT MODEL — FORMULA DRIVEN FROM Assumptions
A3: Metric | B3: 1 MWp · 50% | C3: 5 MWp · 50% | D3: 10 MWp · 50% | E3: 1 MWp · 65% | F3: 5 MWp · 65% | G3: 10 MWp · 65%
A4: CAPACITY
A5: PV capacity (MWp) | B5: =Assumptions!B34 | C5: =Assumptions!C34 | D5: =Assumptions!D34 | E5: =Assumptions!B34 | F5: =Assumptions!C34 | G5: =Assumptions!D34
A6: BESS energy (MWh) | B6: =Assumptions!B35 | C6: =Assumptions!C35 | D6: =Assumptions!D35 | E6: =Assumptions!B35 | F6: =Assumptions!C35 | G6: =Assumptions!D35
A7: Curtailment % | B7: =Assumptions!$B$28 | C7: =Assumptions!$B$28 | D7: =Assumptions!$B$28 | E7: =Assumptions!$B$29 | F7: =Assumptions!$B$29 | G7: =Assumptions!$B$29
A9: CAPITAL EXPENDITURE
A10: PV EPC (base + tracker premium) | B10: =Assumptions!B36+Assumptions!B34*Assumptions!$B$25 | C10: =Assumptions!C36+Assumptions!C34*Assumptions!$B$25 | D10: =Assumptions!D36+Assumptions!D34*Assumptions!$B$25 | E10: =Assumptions!B36+Assumptions!B34*Assumptions!$B$25 | F10: =Assumptions!C36+Assumptions!C34*Assumptions!$B$25 | G10: =Assumptions!D36+Assumptions!D34*Assumptions!$B$25
A11: BESS EPC | B11: =Assumptions!B35*Assumptions!B37 | C11: =Assumptions!C35*Assumptions!C37 | D11: =Assumptions!D35*Assumptions!D37 | E11: =Assumptions!B35*Assumptions!B37 | F11: =Assumptions!C35*Assumptions!C37 | G11: =Assumptions!D35*Assumptions!D37
A12: RTB acquisition | B12: =Assumptions!B34*Assumptions!$B$23 | C12: =Assumptions!C34*Assumptions!$B$23 | D12: =Assumptions!D34*Assumptions!$B$23 | E12: =Assumptions!B34*Assumptions!$B$23 | F12: =Assumptions!C34*Assumptions!$B$23 | G12: =Assumptions!D34*Assumptions!$B$23
A13: EAC connection terms | B13: =Assumptions!B34*Assumptions!$B$24 | C13: =Assumptions!C34*Assumptions!$B$24 | D13: =Assumptions!D34*Assumptions!$B$24 | E13: =Assumptions!B34*Assumptions!$B$24 | F13: =Assumptions!C34*Assumptions!$B$24 | G13: =Assumptions!D34*Assumptions!$B$24
A14: Permitting + MV cable | B14: =Assumptions!$B$26+Assumptions!$B$27 | C14: =Assumptions!$B$26+Assumptions!$B$27 | D14: =Assumptions!$B$26+Assumptions!$B$27 | E14: =Assumptions!$B$26+Assumptions!$B$27 | F14: =Assumptions!$B$26+Assumptions!$B$27 | G14: =Assumptions!$B$26+Assumptions!$B$27
A15: Total CAPEX | B15: =B10+B11+B12+B13+B14 | C15: =C10+C11+C12+C13+C14 | D15: =D10+D11+D12+D13+D14 | E15: =E10+E11+E12+E13+E14 | F15: =F10+F11+F12+F13+F14 | G15: =G10+G11+G12+G13+G14
A17: PRODUCTION & REVENUE (YEAR 1)
A18: Gross PV production (MWh) | B18: =B5*1000*Assumptions!$B$5/1000 | C18: =C5*1000*Assumptions!$B$5/1000 | D18: =D5*1000*Assumptions!$B$5/1000 | E18: =E5*1000*Assumptions!$B$5/1000 | F18: =F5*1000*Assumptions!$B$5/1000 | G18: =G5*1000*Assumptions!$B$5/1000
A19: Uncurtailed solar (MWh) | B19: =B18*(1-B7) | C19: =C18*(1-C7) | D19: =D18*(1-D7) | E19: =E18*(1-E7) | F19: =F18*(1-F7) | G19: =G18*(1-G7)
A20: Curtailed energy (MWh) | B20: =B18*B7 | C20: =C18*C7 | D20: =D18*D7 | E20: =E18*E7 | F20: =F18*F7 | G20: =G18*G7
A21: BESS charged (MWh) — min(ideal, capacity) | B21: =MIN(B20*Assumptions!$B$9,B6*Assumptions!$B$10) | C21: =MIN(C20*Assumptions!$B$9,C6*Assumptions!$B$10) | D21: =MIN(D20*Assumptions!$B$9,D6*Assumptions!$B$10) | E21: =MIN(E20*Assumptions!$B$9,E6*Assumptions!$B$10) | F21: =MIN(F20*Assumptions!$B$9,F6*Assumptions!$B$10) | G21: =MIN(G20*Assumptions!$B$9,G6*Assumptions!$B$10)
A22: BESS discharged (MWh) | B22: =B21*Assumptions!$B$8 | C22: =C21*Assumptions!$B$8 | D22: =D21*Assumptions!$B$8 | E22: =E21*Assumptions!$B$8 | F22: =F21*Assumptions!$B$8 | G22: =G21*Assumptions!$B$8
A23: Solar revenue (€) | B23: =B19*Assumptions!$B$6 | C23: =C19*Assumptions!$B$6 | D23: =D19*Assumptions!$B$6 | E23: =E19*Assumptions!$B$6 | F23: =F19*Assumptions!$B$6 | G23: =G19*Assumptions!$B$6
A24: BESS revenue (€) | B24: =B22*Assumptions!$B$7 | C24: =C22*Assumptions!$B$7 | D24: =D22*Assumptions!$B$7 | E24: =E22*Assumptions!$B$7 | F24: =F22*Assumptions!$B$7 | G24: =G22*Assumptions!$B$7
A25: Gross energy revenue | B25: =B23+B24 | C25: =C23+C24 | D25: =D23+D24 | E25: =E23+E24 | F25: =F23+F24 | G25: =G23+G24
A26: Net revenue (after aggregator) | B26: =B25*(1-Assumptions!$B$11) | C26: =C25*(1-Assumptions!$B$11) | D26: =D25*(1-Assumptions!$B$11) | E26: =E25*(1-Assumptions!$B$11) | F26: =F25*(1-Assumptions!$B$11) | G26: =G25*(1-Assumptions!$B$11)
A28: OPEX & EBITDA
A29: PV O&M | B29: =B5*Assumptions!$B$18 | C29: =C5*Assumptions!$B$18 | D29: =D5*Assumptions!$B$18 | E29: =E5*Assumptions!$B$18 | F29: =F5*Assumptions!$B$18 | G29: =G5*Assumptions!$B$18
A30: BESS LTSA | B30: =B6*Assumptions!$B$19 | C30: =C6*Assumptions!$B$19 | D30: =D6*Assumptions!$B$19 | E30: =E6*Assumptions!$B$19 | F30: =F6*Assumptions!$B$19 | G30: =G6*Assumptions!$B$19
A31: Land lease | B31: =B5*Assumptions!$B$20 | C31: =C5*Assumptions!$B$20 | D31: =D5*Assumptions!$B$20 | E31: =E5*Assumptions!$B$20 | F31: =F5*Assumptions!$B$20 | G31: =G5*Assumptions!$B$20
A32: Insurance + admin | B32: =Assumptions!$B$21+B15*Assumptions!$B$22 | C32: =Assumptions!$B$21+C15*Assumptions!$B$22 | D32: =Assumptions!$B$21+D15*Assumptions!$B$22 | E32: =Assumptions!$B$21+E15*Assumptions!$B$22 | F32: =Assumptions!$B$21+F15*Assumptions!$B$22 | G32: =Assumptions!$B$21+G15*Assumptions!$B$22
A33: Total OPEX | B33: =B29+B30+B31+B32 | C33: =C29+C30+C31+C32 | D33: =D29+D30+D31+D32 | E33: =E29+E30+E31+E32 | F33: =F29+F30+F31+F32 | G33: =G29+G30+G31+G32
A34: EBITDA | B34: =B26-B33 | C34: =C26-C33 | D34: =D26-D33 | E34: =E26-E33 | F34: =F26-F33 | G34: =G26-G33
A36: RETURNS (LEVERED)
A37: Equity required | B37: =B15*Assumptions!$B$14 | C37: =C15*Assumptions!$B$14 | D37: =D15*Assumptions!$B$14 | E37: =E15*Assumptions!$B$14 | F37: =F15*Assumptions!$B$14 | G37: =G15*Assumptions!$B$14
A38: Senior debt | B38: =B15*Assumptions!$B$13 | C38: =C15*Assumptions!$B$13 | D38: =D15*Assumptions!$B$13 | E38: =E15*Assumptions!$B$13 | F38: =F15*Assumptions!$B$13 | G38: =G15*Assumptions!$B$13
A39: Annual debt service | B39: =B38*Annuity_Factor | C39: =C38*Annuity_Factor | D39: =D38*Annuity_Factor | E39: =E38*Annuity_Factor | F39: =F38*Annuity_Factor | G39: =G38*Annuity_Factor
A40: DSCR | B40: =IF(B39=0,0,B34/B39) | C40: =IF(C39=0,0,C34/C39) | D40: =IF(D39=0,0,D34/D39) | E40: =IF(E39=0,0,E34/E39) | F40: =IF(F39=0,0,F34/F39) | G40: =IF(G39=0,0,G34/G39)
A41: Depreciation | B41: =B15/Assumptions!$B$17 | C41: =C15/Assumptions!$B$17 | D41: =D15/Assumptions!$B$17 | E41: =E15/Assumptions!$B$17 | F41: =F15/Assumptions!$B$17 | G41: =G15/Assumptions!$B$17
A42: Tax (15% CIT on EBT) | B42: =MAX(0,(B34-B39-B41)*Assumptions!$B$12) | C42: =MAX(0,(C34-C39-C41)*Assumptions!$B$12) | D42: =MAX(0,(D34-D39-D41)*Assumptions!$B$12) | E42: =MAX(0,(E34-E39-E41)*Assumptions!$B$12) | F42: =MAX(0,(F34-F39-F41)*Assumptions!$B$12) | G42: =MAX(0,(G34-G39-G41)*Assumptions!$B$12)
A43: Net cash to equity | B43: =B34-B39-B42 | C43: =C34-C39-C42 | D43: =D34-D39-D42 | E43: =E34-E39-E42 | F43: =F34-F39-F42 | G43: =G34-G39-G42
A44: Unlevered payback (years) | B44: =IF(B34<=0,99,B15/B34) | C44: =IF(C34<=0,99,C15/C34) | D44: =IF(D34<=0,99,D15/D34) | E44: =IF(E34<=0,99,E15/E34) | F44: =IF(F34<=0,99,F15/F34) | G44: =IF(G34<=0,99,G15/G34)
A45: Equity payback (years) | B45: =IF(B43<=0,99,B37/B43) | C45: =IF(C43<=0,99,C37/C43) | D45: =IF(D43<=0,99,D37/D43) | E45: =IF(E43<=0,99,E37/E43) | F45: =IF(F43<=0,99,F37/F43) | G45: =IF(G43<=0,99,G37/G43)
...

Sheet Sources
A1: Data sources (internal SSOT)
A3: PV / BESS client EPC | B3: docs/internal/solarpark-epc.md
A4: Confirmed 5MW/20MWh BESS | B4: lib/portfolio-data.ts CLIENT_PRICING €111,900/MWh
A5: RTE / LTSA | B5: lib/portfolio-data.ts — 86.32% RTE · LTSA Tier C €1,740/MWh
A6: DAM prices | B6: lib/market/cyprus-tsoc-dam-sample.ts / rtb-deal-types DAM
A7: Capture & cycle days | B7: lib/deals/rtb-deal-types.ts BESS_DEFAULTS
A8: Tracker premium | B8: solarpark-epc.md §7.3 — €80–120k/MW (model uses €100k)
A9: Yield | B9: Investor assumption — 2,400 kWh/kWp trackers + white albedo
A10: RTB + connection | B10: Investor assumption — €550k/MW RTB + €80k/MW EAC
