Workbook

Sheet Inputs
A1: ANARITA 10 MW BESS — FINANCIAL MODEL (4-HOUR, 2×5/20)
A2: Prepared for: Muminjon (Spanercom) | Lighthief Cyprus Ltd | 24 March 2026 — matches commercial offer €119k/MWh turnkey (€4.76M, 40 MWh total)
A3: ⚡ Yellow cells are modifiable inputs — change them to run your own scenarios
A5: INPUT PARAMETERS
A6: Parameter | B6: Value | C6: Unit | D6: Source / Notes
A7: PV Installed Capacity | B7: 10 | C7: MW | D7: Client
A8: Annual Specific Yield | B8: 1932 | C8: kWh/kWp | D8: PVSyst verified (May-24 to Oct-25)
A9: Annual PV Production | B9: =B7*B8 | C9: MWh | D9: Calculated: capacity × yield
A10: Park Configuration | B10: Fixed Tilt (EAST + WEST) | D10: Client confirmed
A11: PV Annual Degradation | B11: 0.005 | D11: Industry standard (0.5%/yr)
A12: Peak Discharge Price | B12: 182.99 | C12: €/MWh | D12: TSOC DAM 134-day avg (17:00-21:00)
A13: Round-Trip Efficiency | B13: 0.8632 | D13: Linyang AC-AC full system
A14: Net Revenue per MWh Stored | B14: =B12*B13 | C14: €/MWh | D14: Calculated: peak price × RTE
A15: BESS Availability | B15: 0.97 | D15: Guaranteed LTSA Tier C (97%)
A16: LTSA Cost Rate | B16: 2469.59 | C16: €/MWh/yr | D16: Confirmed Linyang RFI V3
A17: Insurance (annual) | B17: 15000 | C17: €/yr | D17: Budget estimate
A18: Cycles per Day | B18: 1 | D18: Annual average (conservative)
A19: BESS EOL Definition | B19: 0.7 | D19: SOH threshold (70%)
A22: BESS OPTIONS
A23: Option | B23: Power (MW) | C23: Energy (MWh) | D23: Price (€) | E23: EUR/kWh | F23: Configuration
A24: Option A | B24: 10 | C24: 20 | D24: 3033000 | E24: =D24/(C24*1000) | F24: 4 x 5 MWh (2 per park)
A25: Option B | B25: 10 | C25: 30 | D25: 4440000 | E25: 148 | F25: 6 x 5 MWh (3 per park)
A26: Selected offer (this workbook) | B26: 10 | C26: 40 | D26: 4760000 | E26: =D26/(C26*1000) | F26: 8 x 5 MWh (4 per park)

Sheet Scenario Matrix
A1: YEAR 1 SCENARIO ANALYSIS
A2: Primary curtailment cases: B=50%, C=60%, D=70%. E and F repeat 50% and 70% so legacy option-block formulas stay valid.
A4: Curtailment Rate | B4: 0.5 | C4: 0.6 | D4: 0.7 | E4: 0.5 | F4: 0.7
A5: Annual Curtailed (MWh) | B5: =Inputs!B9*B4 | C5: =Inputs!B9*C4 | D5: =Inputs!B9*D4 | E5: =Inputs!B9*E4 | F5: =Inputs!B9*F4
A6: Avg Daily Curtailed (MWh) | B6: =B5/365 | C6: =C5/365 | D6: =D5/365 | E6: =E5/365 | F6: =F5/365
A8: OPTION A: 10 MW / 20 MWh
A9: BESS Price (€) | B9: =Inputs!D24
A10: Annual O&M + Insurance (€) | B10: =Inputs!C24*Inputs!B16+Inputs!B17
A11: Max Annual Throughput (MWh) | B11: =Inputs!C24*365*Inputs!B15 | C11: =Inputs!C24*365*Inputs!B15 | D11: =Inputs!C24*365*Inputs!B15 | E11: =Inputs!C24*365*Inputs!B15 | F11: =Inputs!C24*365*Inputs!B15
A12: Ratio (daily curt / BESS MWh) | B12: =B6/Inputs!C24 | C12: =C6/Inputs!C24 | D12: =D6/Inputs!C24 | E12: =E6/Inputs!C24 | F12: =F6/Inputs!C24
A13: Capture Efficiency | B13: =IF(B12>1.5,0.97,IF(B12>1.2,0.95,IF(B12>1.0,0.92,IF(B12>0.8,0.88,IF(B12>0.6,0.82,0.72))))) | C13: =IF(C12>1.5,0.97,IF(C12>1.2,0.95,IF(C12>1.0,0.92,IF(C12>0.8,0.88,IF(C12>0.6,0.82,0.72))))) | D13: =IF(D12>1.5,0.97,IF(D12>1.2,0.95,IF(D12>1.0,0.92,IF(D12>0.8,0.88,IF(D12>0.6,0.82,0.72))))) | E13: =IF(E12>1.5,0.97,IF(E12>1.2,0.95,IF(E12>1.0,0.92,IF(E12>0.8,0.88,IF(E12>0.6,0.82,0.72))))) | F13: =IF(F12>1.5,0.97,IF(F12>1.2,0.95,IF(F12>1.0,0.92,IF(F12>0.8,0.88,IF(F12>0.6,0.82,0.72)))))
A14: Annual Captured (MWh) | B14: =MIN(B11,B5*B13*Inputs!B15) | C14: =MIN(C11,C5*C13*Inputs!B15) | D14: =MIN(D11,D5*D13*Inputs!B15) | E14: =MIN(E11,E5*E13*Inputs!B15) | F14: =MIN(F11,F5*F13*Inputs!B15)
A15: Annual Discharged (MWh) | B15: =B14*Inputs!B13 | C15: =C14*Inputs!B13 | D15: =D14*Inputs!B13 | E15: =E14*Inputs!B13 | F15: =F14*Inputs!B13
A16: Gross Revenue (€) | B16: =B15*Inputs!B12 | C16: =C15*Inputs!B12 | D16: =D15*Inputs!B12 | E16: =E15*Inputs!B12 | F16: =F15*Inputs!B12
A17: Net Income (€) | B17: =B16-$B$10 | C17: =C16-$B$10 | D17: =D16-$B$10 | E17: =E16-$B$10 | F17: =F16-$B$10
A18: ROI (%) | B18: =B17/$B$9 | C18: =C17/$B$9 | D18: =D17/$B$9 | E18: =E17/$B$9 | F18: =F17/$B$9
A19: Simple Payback (years) | B19: =$B$9/B17 | C19: =$B$9/C17 | D19: =$B$9/D17 | E19: =$B$9/E17 | F19: =$B$9/F17
A22: OPTION B: 2 × 5 MW / 15 MWh (30 MWh total)
A23: BESS Price (€) | B23: =Inputs!D25
A24: Annual O&M + Insurance (€) | B24: =Inputs!C25*Inputs!B16+Inputs!B17
A25: Max Annual Throughput (MWh) | B25: =Inputs!C25*365*Inputs!B15 | C25: =Inputs!C25*365*Inputs!B15 | D25: =Inputs!C25*365*Inputs!B15 | E25: =Inputs!C25*365*Inputs!B15 | F25: =Inputs!C25*365*Inputs!B15
A26: Ratio (daily curt / BESS MWh) | B26: =B6/Inputs!C25 | C26: =C6/Inputs!C25 | D26: =D6/Inputs!C25 | E26: =E6/Inputs!C25 | F26: =F6/Inputs!C25
A27: Capture Efficiency | B27: =IF(B26>1.5,0.97,IF(B26>1.2,0.95,IF(B26>1.0,0.92,IF(B26>0.8,0.88,IF(B26>0.6,0.82,0.72))))) | C27: =IF(C26>1.5,0.97,IF(C26>1.2,0.95,IF(C26>1.0,0.92,IF(C26>0.8,0.88,IF(C26>0.6,0.82,0.72))))) | D27: =IF(D26>1.5,0.97,IF(D26>1.2,0.95,IF(D26>1.0,0.92,IF(D26>0.8,0.88,IF(D26>0.6,0.82,0.72))))) | E27: =IF(E26>1.5,0.97,IF(E26>1.2,0.95,IF(E26>1.0,0.92,IF(E26>0.8,0.88,IF(E26>0.6,0.82,0.72))))) | F27: =IF(F26>1.5,0.97,IF(F26>1.2,0.95,IF(F26>1.0,0.92,IF(F26>0.8,0.88,IF(F26>0.6,0.82,0.72)))))
A28: Annual Captured (MWh) | B28: =MIN(B25,B5*B27*Inputs!B15) | C28: =MIN(C25,C5*C27*Inputs!B15) | D28: =MIN(D25,D5*D27*Inputs!B15) | E28: =MIN(E25,E5*E27*Inputs!B15) | F28: =MIN(F25,F5*F27*Inputs!B15)
A29: Annual Discharged (MWh) | B29: =B28*Inputs!B13 | C29: =C28*Inputs!B13 | D29: =D28*Inputs!B13 | E29: =E28*Inputs!B13 | F29: =F28*Inputs!B13
A30: Gross Revenue (€) | B30: =B29*Inputs!B12 | C30: =C29*Inputs!B12 | D30: =D29*Inputs!B12 | E30: =E29*Inputs!B12 | F30: =F29*Inputs!B12
A31: Net Income (€) | B31: =B30-$B$24 | C31: =C30-$B$24 | D31: =D30-$B$24 | E31: =E30-$B$24 | F31: =F30-$B$24
A32: ROI (%) | B32: =B31/$B$23 | C32: =C31/$B$23 | D32: =D31/$B$23 | E32: =E31/$B$23 | F32: =F31/$B$23
A33: Simple Payback (years) | B33: =$B$23/B31 | C33: =$B$23/C31 | D33: =$B$23/D31 | E33: =$B$23/E31 | F33: =$B$23/F31
A36: OPTION: 2 × 5 MW / 20 MWh (40 MWh total, 4-hour)
A37: BESS Price (€) | B37: =Inputs!D26
A38: Annual O&M + Insurance (€) | B38: =Inputs!C26*Inputs!B16+Inputs!B17
A39: Max Annual Throughput (MWh) | B39: =Inputs!C26*365*Inputs!B15 | C39: =Inputs!C26*365*Inputs!B15 | D39: =Inputs!C26*365*Inputs!B15 | E39: =Inputs!C26*365*Inputs!B15 | F39: =Inputs!C26*365*Inputs!B15
A40: Ratio (daily curt / BESS MWh) | B40: =B6/Inputs!C26 | C40: =C6/Inputs!C26 | D40: =D6/Inputs!C26 | E40: =E6/Inputs!C26 | F40: =F6/Inputs!C26
A41: Capture Efficiency | B41: =IF(B40>1.5,0.97,IF(B40>1.2,0.95,IF(B40>1.0,0.92,IF(B40>0.8,0.88,IF(B40>0.6,0.82,0.72))))) | C41: =IF(C40>1.5,0.97,IF(C40>1.2,0.95,IF(C40>1.0,0.92,IF(C40>0.8,0.88,IF(C40>0.6,0.82,0.72))))) | D41: =IF(D40>1.5,0.97,IF(D40>1.2,0.95,IF(D40>1.0,0.92,IF(D40>0.8,0.88,IF(D40>0.6,0.82,0.72))))) | E41: =IF(E40>1.5,0.97,IF(E40>1.2,0.95,IF(E40>1.0,0.92,IF(E40>0.8,0.88,IF(E40>0.6,0.82,0.72))))) | F41: =IF(F40>1.5,0.97,IF(F40>1.2,0.95,IF(F40>1.0,0.92,IF(F40>0.8,0.88,IF(F40>0.6,0.82,0.72)))))
A42: Annual Captured (MWh) | B42: =MIN(B39,B5*B41*Inputs!B15) | C42: =MIN(C39,C5*C41*Inputs!B15) | D42: =MIN(D39,D5*D41*Inputs!B15) | E42: =MIN(E39,E5*E41*Inputs!B15) | F42: =MIN(F39,F5*F41*Inputs!B15)
A43: Annual Discharged (MWh) | B43: =B42*Inputs!B13 | C43: =C42*Inputs!B13 | D43: =D42*Inputs!B13 | E43: =E42*Inputs!B13 | F43: =F42*Inputs!B13
A44: Gross Revenue (€) | B44: =B43*Inputs!B12 | C44: =C43*Inputs!B12 | D44: =D43*Inputs!B12 | E44: =E43*Inputs!B12 | F44: =F43*Inputs!B12
A45: Net Income (€) | B45: =B44-$B$38 | C45: =C44-$B$38 | D45: =D44-$B$38 | E45: =E44-$B$38 | F45: =F44-$B$38
A46: ROI (%) | B46: =B45/$B$37 | C46: =C45/$B$37 | D46: =D45/$B$37 | E46: =E45/$B$37 | F46: =F45/$B$37
...

Sheet 15-Year Projection
A1: 15-YEAR PROJECTION — OPTION B (30 MWh)
A3: Curtailment Rate: | B3: 0.5 | C3: ← Change this to model different scenarios
A4: BESS Option: | B4: B (30 MWh)
A6: Year | B6: PV (MWh) | C6: SOH % | D6: Eff BESS (MWh) | E6: Curtailed (MWh) | F6: Ratio | G6: CE | H6: Captured (MWh) | I6: Dischgd (MWh) | J6: Revenue (€) | K6: O&M (€) | L6: Net (€) | M6: Cumul. (€) | O6: SOH Data
A7: 1 | B7: =Inputs!B9*(1-Inputs!B11)^(1-1) | C7: =$O$8 | D7: =Inputs!C25*$O$8 | E7: =B7*$B$3 | F7: =(E7/365)/D7 | G7: =IF(F7>1.5,0.97,IF(F7>1.2,0.95,IF(F7>1.0,0.92,IF(F7>0.8,0.88,IF(F7>0.6,0.82,0.72))))) | H7: =MIN(D7*365*Inputs!B15, E7*G7*Inputs!B15) | I7: =H7*Inputs!B13 | J7: =I7*Inputs!B12 | K7: =Inputs!C25*Inputs!B16+Inputs!B17 | L7: =J7-K7 | M7: =L7 | O7: 1
A8: 2 | B8: =Inputs!B9*(1-Inputs!B11)^(2-1) | C8: =$O$9 | D8: =Inputs!C25*$O$9 | E8: =B8*$B$3 | F8: =(E8/365)/D8 | G8: =IF(F8>1.5,0.97,IF(F8>1.2,0.95,IF(F8>1.0,0.92,IF(F8>0.8,0.88,IF(F8>0.6,0.82,0.72))))) | H8: =MIN(D8*365*Inputs!B15, E8*G8*Inputs!B15) | I8: =H8*Inputs!B13 | J8: =I8*Inputs!B12 | K8: =Inputs!C25*Inputs!B16+Inputs!B17 | L8: =J8-K8 | M8: =M7+L8 | O8: 0.9462
A9: 3 | B9: =Inputs!B9*(1-Inputs!B11)^(3-1) | C9: =$O$10 | D9: =Inputs!C25*$O$10 | E9: =B9*$B$3 | F9: =(E9/365)/D9 | G9: =IF(F9>1.5,0.97,IF(F9>1.2,0.95,IF(F9>1.0,0.92,IF(F9>0.8,0.88,IF(F9>0.6,0.82,0.72))))) | H9: =MIN(D9*365*Inputs!B15, E9*G9*Inputs!B15) | I9: =H9*Inputs!B13 | J9: =I9*Inputs!B12 | K9: =Inputs!C25*Inputs!B16+Inputs!B17 | L9: =J9-K9 | M9: =M8+L9 | O9: 0.9266
A10: 4 | B10: =Inputs!B9*(1-Inputs!B11)^(4-1) | C10: =$O$11 | D10: =Inputs!C25*$O$11 | E10: =B10*$B$3 | F10: =(E10/365)/D10 | G10: =IF(F10>1.5,0.97,IF(F10>1.2,0.95,IF(F10>1.0,0.92,IF(F10>0.8,0.88,IF(F10>0.6,0.82,0.72))))) | H10: =MIN(D10*365*Inputs!B15, E10*G10*Inputs!B15) | I10: =H10*Inputs!B13 | J10: =I10*Inputs!B12 | K10: =Inputs!C25*Inputs!B16+Inputs!B17 | L10: =J10-K10 | M10: =M9+L10 | O10: 0.907
A11: 5 | B11: =Inputs!B9*(1-Inputs!B11)^(5-1) | C11: =$O$12 | D11: =Inputs!C25*$O$12 | E11: =B11*$B$3 | F11: =(E11/365)/D11 | G11: =IF(F11>1.5,0.97,IF(F11>1.2,0.95,IF(F11>1.0,0.92,IF(F11>0.8,0.88,IF(F11>0.6,0.82,0.72))))) | H11: =MIN(D11*365*Inputs!B15, E11*G11*Inputs!B15) | I11: =H11*Inputs!B13 | J11: =I11*Inputs!B12 | K11: =Inputs!C25*Inputs!B16+Inputs!B17 | L11: =J11-K11 | M11: =M10+L11 | O11: 0.8874
A12: 6 | B12: =Inputs!B9*(1-Inputs!B11)^(6-1) | C12: =$O$13 | D12: =Inputs!C25*$O$13 | E12: =B12*$B$3 | F12: =(E12/365)/D12 | G12: =IF(F12>1.5,0.97,IF(F12>1.2,0.95,IF(F12>1.0,0.92,IF(F12>0.8,0.88,IF(F12>0.6,0.82,0.72))))) | H12: =MIN(D12*365*Inputs!B15, E12*G12*Inputs!B15) | I12: =H12*Inputs!B13 | J12: =I12*Inputs!B12 | K12: =Inputs!C25*Inputs!B16+Inputs!B17 | L12: =J12-K12 | M12: =M11+L12 | O12: 0.8678
A13: 7 | B13: =Inputs!B9*(1-Inputs!B11)^(7-1) | C13: =$O$14 | D13: =Inputs!C25*$O$14 | E13: =B13*$B$3 | F13: =(E13/365)/D13 | G13: =IF(F13>1.5,0.97,IF(F13>1.2,0.95,IF(F13>1.0,0.92,IF(F13>0.8,0.88,IF(F13>0.6,0.82,0.72))))) | H13: =MIN(D13*365*Inputs!B15, E13*G13*Inputs!B15) | I13: =H13*Inputs!B13 | J13: =I13*Inputs!B12 | K13: =Inputs!C25*Inputs!B16+Inputs!B17 | L13: =J13-K13 | M13: =M12+L13 | O13: 0.8534
A14: 8 | B14: =Inputs!B9*(1-Inputs!B11)^(8-1) | C14: =$O$15 | D14: =Inputs!C25*$O$15 | E14: =B14*$B$3 | F14: =(E14/365)/D14 | G14: =IF(F14>1.5,0.97,IF(F14>1.2,0.95,IF(F14>1.0,0.92,IF(F14>0.8,0.88,IF(F14>0.6,0.82,0.72))))) | H14: =MIN(D14*365*Inputs!B15, E14*G14*Inputs!B15) | I14: =H14*Inputs!B13 | J14: =I14*Inputs!B12 | K14: =Inputs!C25*Inputs!B16+Inputs!B17 | L14: =J14-K14 | M14: =M13+L14 | O14: 0.839
A15: 9 | B15: =Inputs!B9*(1-Inputs!B11)^(9-1) | C15: =$O$16 | D15: =Inputs!C25*$O$16 | E15: =B15*$B$3 | F15: =(E15/365)/D15 | G15: =IF(F15>1.5,0.97,IF(F15>1.2,0.95,IF(F15>1.0,0.92,IF(F15>0.8,0.88,IF(F15>0.6,0.82,0.72))))) | H15: =MIN(D15*365*Inputs!B15, E15*G15*Inputs!B15) | I15: =H15*Inputs!B13 | J15: =I15*Inputs!B12 | K15: =Inputs!C25*Inputs!B16+Inputs!B17 | L15: =J15-K15 | M15: =M14+L15 | O15: 0.8246
A16: 10 | B16: =Inputs!B9*(1-Inputs!B11)^(10-1) | C16: =$O$17 | D16: =Inputs!C25*$O$17 | E16: =B16*$B$3 | F16: =(E16/365)/D16 | G16: =IF(F16>1.5,0.97,IF(F16>1.2,0.95,IF(F16>1.0,0.92,IF(F16>0.8,0.88,IF(F16>0.6,0.82,0.72))))) | H16: =MIN(D16*365*Inputs!B15, E16*G16*Inputs!B15) | I16: =H16*Inputs!B13 | J16: =I16*Inputs!B12 | K16: =Inputs!C25*Inputs!B16+Inputs!B17 | L16: =J16-K16 | M16: =M15+L16 | O16: 0.8102
A17: 11 | B17: =Inputs!B9*(1-Inputs!B11)^(11-1) | C17: =$O$18 | D17: =Inputs!C25*$O$18 | E17: =B17*$B$3 | F17: =(E17/365)/D17 | G17: =IF(F17>1.5,0.97,IF(F17>1.2,0.95,IF(F17>1.0,0.92,IF(F17>0.8,0.88,IF(F17>0.6,0.82,0.72))))) | H17: =MIN(D17*365*Inputs!B15, E17*G17*Inputs!B15) | I17: =H17*Inputs!B13 | J17: =I17*Inputs!B12 | K17: =Inputs!C25*Inputs!B16+Inputs!B17 | L17: =J17-K17 | M17: =M16+L17 | O17: 0.7958
A18: 12 | B18: =Inputs!B9*(1-Inputs!B11)^(12-1) | C18: =$O$19 | D18: =Inputs!C25*$O$19 | E18: =B18*$B$3 | F18: =(E18/365)/D18 | G18: =IF(F18>1.5,0.97,IF(F18>1.2,0.95,IF(F18>1.0,0.92,IF(F18>0.8,0.88,IF(F18>0.6,0.82,0.72))))) | H18: =MIN(D18*365*Inputs!B15, E18*G18*Inputs!B15) | I18: =H18*Inputs!B13 | J18: =I18*Inputs!B12 | K18: =Inputs!C25*Inputs!B16+Inputs!B17 | L18: =J18-K18 | M18: =M17+L18 | O18: 0.7839
A19: 13 | B19: =Inputs!B9*(1-Inputs!B11)^(13-1) | C19: =$O$20 | D19: =Inputs!C25*$O$20 | E19: =B19*$B$3 | F19: =(E19/365)/D19 | G19: =IF(F19>1.5,0.97,IF(F19>1.2,0.95,IF(F19>1.0,0.92,IF(F19>0.8,0.88,IF(F19>0.6,0.82,0.72))))) | H19: =MIN(D19*365*Inputs!B15, E19*G19*Inputs!B15) | I19: =H19*Inputs!B13 | J19: =I19*Inputs!B12 | K19: =Inputs!C25*Inputs!B16+Inputs!B17 | L19: =J19-K19 | M19: =M18+L19 | O19: 0.772
A20: 14 | B20: =Inputs!B9*(1-Inputs!B11)^(14-1) | C20: =$O$21 | D20: =Inputs!C25*$O$21 | E20: =B20*$B$3 | F20: =(E20/365)/D20 | G20: =IF(F20>1.5,0.97,IF(F20>1.2,0.95,IF(F20>1.0,0.92,IF(F20>0.8,0.88,IF(F20>0.6,0.82,0.72))))) | H20: =MIN(D20*365*Inputs!B15, E20*G20*Inputs!B15) | I20: =H20*Inputs!B13 | J20: =I20*Inputs!B12 | K20: =Inputs!C25*Inputs!B16+Inputs!B17 | L20: =J20-K20 | M20: =M19+L20 | O20: 0.7601
A21: 15 | B21: =Inputs!B9*(1-Inputs!B11)^(15-1) | C21: =$O$22 | D21: =Inputs!C25*$O$22 | E21: =B21*$B$3 | F21: =(E21/365)/D21 | G21: =IF(F21>1.5,0.97,IF(F21>1.2,0.95,IF(F21>1.0,0.92,IF(F21>0.8,0.88,IF(F21>0.6,0.82,0.72))))) | H21: =MIN(D21*365*Inputs!B15, E21*G21*Inputs!B15) | I21: =H21*Inputs!B13 | J21: =I21*Inputs!B12 | K21: =Inputs!C25*Inputs!B16+Inputs!B17 | L21: =J21-K21 | M21: =M20+L21 | O21: 0.7482
L22: 0.7361 | O22: 0.7361
A23: SUMMARY
A24: Total Revenue (€) | B24: =SUM(J7:J21)
A25: Total O&M (€) | B25: =SUM(K7:K21)
A26: Total Net Income (€) | B26: =SUM(L7:L21)
A27: BESS Investment (€) | B27: =Inputs!D25
A28: Return Multiple | B28: =B26/B27
A29: Annualised ROI | B29: =B26/(B27*15)

Sheet LCOS
A1: LEVELIZED COST OF STORAGE
A3: Cost Component | B3: Option A (20 MWh) | C3: Option B (30 MWh) | D3: Option C (40 MWh)
A4: Capital (BESS EPC) | B4: =Inputs!D24 | C4: =Inputs!D25 | D4: =Inputs!D26
A5: O&M — LTSA 15 years | B5: =(Inputs!C24*Inputs!B16+Inputs!B17)*15 | C5: =(Inputs!C25*Inputs!B16+Inputs!B17)*15 | D5: =(Inputs!C26*Inputs!B16+Inputs!B17)*15
A6: Ext. Warranty Yr 6-10 (€1,661.68/MWh×5) | B6: =1661.68*Inputs!C24*5 | C6: =1661.68*Inputs!C25*5 | D6: =1661.68*Inputs!C26*5
A7: Ext. Warranty Yr 11-15 (€2,083.72/MWh×5) | B7: =2083.72*Inputs!C24*5 | C7: =2083.72*Inputs!C25*5 | D7: =2083.72*Inputs!C26*5
A8: TOTAL 15-YEAR COST | B8: =SUM(B4:B7) | C8: =SUM(C4:C7) | D8: =SUM(D4:D7)
A10: SYSTEM LCOS (full utilisation)
A11: 15-Year Discharged (MWh) | B11: =20*365*Inputs!B15*Inputs!B13*SUM('15-Year Projection'!O8:O22) | C11: =30*365*Inputs!B15*Inputs!B13*SUM('15-Year Projection'!O8:O22) | D11: =40*365*Inputs!B15*Inputs!B13*SUM('15-Year Projection'!O8:O22)
A12: System LCOS (€/MWh) | B12: =B8/B11 | C12: =C8/C11 | D12: =D8/D11
A14: REVENUE MARGIN
A15: Revenue per MWh Discharged | B15: =Inputs!B12 | C15: =Inputs!B12 | D15: =Inputs!B12
A16: System LCOS | B16: =B12 | C16: =C12 | D16: =D12
A17: Margin per MWh (€) | B17: =B15-B16 | C17: =C15-C16 | D17: =D15-D16
A18: Margin % | B18: =B17/B15 | C18: =C17/C15 | D18: =D17/D15
A21: DISCOUNTED LCOS (8% WACC)
A22: Discount Rate | B22: 0.08 | C22: ← Modifiable
A23: NPV of Total Costs (€) | B23: =Inputs!D24+SUMPRODUCT((Inputs!C24*Inputs!B16+Inputs!B17)/(1+$B$22)^ROW(INDIRECT("1:15")))+SUMPRODUCT((1661.68*Inputs!C24)/(1+$B$22)^{6,7,8,9,10})+SUMPRODUCT((2083.72*Inputs!C24)/(1+$B$22)^{11,12,13,14,15}) | C23: =Inputs!D25+SUMPRODUCT((Inputs!C25*Inputs!B16+Inputs!B17)/(1+$B$22)^ROW(INDIRECT("1:15")))+SUMPRODUCT((1661.68*Inputs!C25)/(1+$B$22)^{6,7,8,9,10})+SUMPRODUCT((2083.72*Inputs!C25)/(1+$B$22)^{11,12,13,14,15}) | D23: =Inputs!D26+SUMPRODUCT((Inputs!C26*Inputs!B16+Inputs!B17)/(1+$B$22)^ROW(INDIRECT("1:15")))+SUMPRODUCT((1661.68*Inputs!C26)/(1+$B$22)^{6,7,8,9,10})+SUMPRODUCT((2083.72*Inputs!C26)/(1+$B$22)^{11,12,13,14,15})
A24: NPV of Energy Discharged (MWh) | B24: =(20*0.9462*365*Inputs!B15*Inputs!B13)/(1+$B$22)^1+(20*0.9266*365*Inputs!B15*Inputs!B13)/(1+$B$22)^2+(20*0.907*365*Inputs!B15*Inputs!B13)/(1+$B$22)^3+(20*0.8874*365*Inputs!B15*Inputs!B13)/(1+$B$22)^4+(20*0.8678*365*Inputs!B15*Inputs!B13)/(1+$B$22)^5+(20*0.8534*365*Inputs!B15*Inputs!B13)/(1+$B$22)^6+(20*0.839*365*Inputs!B15*Inputs!B13)/(1+$B$22)^7+(20*0.8246*365*Inputs!B15*Inputs!B13)/(1+$B$22)^8+(20*0.8102*365*Inputs!B15*Inputs!B13)/(1+$B$22)^9+(20*0.7958*365*Inputs!B15*Inputs!B13)/(1+$B$22)^10+(20*0.7839*365*Inputs!B15*Inputs!B13)/(1+$B$22)^11+(20*0.772*365*Inputs!B15*Inputs!B13)/(1+$B$22)^12+(20*0.7601*365*Inputs!B15*Inputs!B13)/(1+$B$22)^13+(20*0.7482*365*Inputs!B15*Inputs!B13)/(1+$B$22)^14+(20*0.7361*365*Inputs!B15*Inputs!B13)/(1+$B$22)^15 | C24: =(30*0.9462*365*Inputs!B15*Inputs!B13)/(1+$B$22)^1+(30*0.9266*365*Inputs!B15*Inputs!B13)/(1+$B$22)^2+(30*0.907*365*Inputs!B15*Inputs!B13)/(1+$B$22)^3+(30*0.8874*365*Inputs!B15*Inputs!B13)/(1+$B$22)^4+(30*0.8678*365*Inputs!B15*Inputs!B13)/(1+$B$22)^5+(30*0.8534*365*Inputs!B15*Inputs!B13)/(1+$B$22)^6+(30*0.839*365*Inputs!B15*Inputs!B13)/(1+$B$22)^7+(30*0.8246*365*Inputs!B15*Inputs!B13)/(1+$B$22)^8+(30*0.8102*365*Inputs!B15*Inputs!B13)/(1+$B$22)^9+(30*0.7958*365*Inputs!B15*Inputs!B13)/(1+$B$22)^10+(30*0.7839*365*Inputs!B15*Inputs!B13)/(1+$B$22)^11+(30*0.772*365*Inputs!B15*Inputs!B13)/(1+$B$22)^12+(30*0.7601*365*Inputs!B15*Inputs!B13)/(1+$B$22)^13+(30*0.7482*365*Inputs!B15*Inputs!B13)/(1+$B$22)^14+(30*0.7361*365*Inputs!B15*Inputs!B13)/(1+$B$22)^15 | D24: =(40*0.9462*365*Inputs!B15*Inputs!B13)/(1+$B$22)^1+(40*0.9266*365*Inputs!B15*Inputs!B13)/(1+$B$22)^2+(40*0.907*365*Inputs!B15*Inputs!B13)/(1+$B$22)^3+(40*0.8874*365*Inputs!B15*Inputs!B13)/(1+$B$22)^4+(40*0.8678*365*Inputs!B15*Inputs!B13)/(1+$B$22)^5+(40*0.8534*365*Inputs!B15*Inputs!B13)/(1+$B$22)^6+(40*0.839*365*Inputs!B15*Inputs!B13)/(1+$B$22)^7+(40*0.8246*365*Inputs!B15*Inputs!B13)/(1+$B$22)^8+(40*0.8102*365*Inputs!B15*Inputs!B13)/(1+$B$22)^9+(40*0.7958*365*Inputs!B15*Inputs!B13)/(1+$B$22)^10+(40*0.7839*365*Inputs!B15*Inputs!B13)/(1+$B$22)^11+(40*0.772*365*Inputs!B15*Inputs!B13)/(1+$B$22)^12+(40*0.7601*365*Inputs!B15*Inputs!B13)/(1+$B$22)^13+(40*0.7482*365*Inputs!B15*Inputs!B13)/(1+$B$22)^14+(40*0.7361*365*Inputs!B15*Inputs!B13)/(1+$B$22)^15
A25: Discounted LCOS (€/MWh) | B25: =B23/B24 | C25: =C23/C24 | D25: =D23/D24
A26: Discounted Margin per MWh (€) | B26: =Inputs!B12-B25 | C26: =Inputs!B12-C25 | D26: =Inputs!B12-D25
A27: Discounted Margin % | B27: =B26/Inputs!B12 | C27: =C26/Inputs!B12 | D27: =D26/Inputs!B12

Sheet Park Data
A1: ACTUAL PARK CURTAILMENT DATA — Spanercom Anarita
A2: Source: energy_production_Oct2025.xlsx | EAST + WEST combined | Fixed tilt
A4: Month | B4: Energy Yield (MWh) | C4: Est. Potential (MWh) | D4: PVSyst (MWh) | E4: Curtailment %
A5: May-24 | B5: 1023 | C5: 1854 | D5: 1921 | E5: 0.45
A6: Jun-24 | B6: 1670 | C6: 1888 | D6: 1987 | E6: 0.12
A7: Jul-24 | B7: 1791 | C7: 1916 | D7: 2034 | E7: 0.07
A8: Aug-24 | B8: 1703 | C8: 1788 | D8: 1944 | E8: 0.05
A9: Sep-24 | B9: 1225 | C9: 1589 | D9: 1724 | E9: 0.23
A10: Oct-24 | B10: 941 | C10: 1617 | D10: 1461 | E10: 0.42
A11: Nov-24 | B11: 645 | C11: 1160 | D11: 1108 | E11: 0.44
A12: Dec-24 | B12: 694 | C12: 951 | D12: 922 | E12: 0.27
A13: Jan-25 | B13: 600 | C13: 1179 | D13: 955 | E13: 0.49
A14: Feb-25 | B14: 655 | C14: 1198 | D14: 1086 | E14: 0.45
A15: Mar-25 | B15: 566 | C15: 1648 | D15: 1513 | E15: 0.66
A16: Apr-25 | B16: 578 | C16: 1731 | D16: 1669 | E16: 0.67
... A22: Oct-25 | B22: 467 | C22: 1139 | D22: 1461 | E22: 0.59
A24: CURTAILMENT TREND
A25: Period | B25: Avg Curtailment | C25: Notes
A26: May-Aug 2024 | B26: 18% | C26: Low — early market
A27: Sep-Dec 2024 | B27: 34% | C27: Increasing
A28: Jan-Apr 2025 | B28: 57% | C28: High — spring peak
A29: May-Oct 2025 | B29: 42% | C29: Summer lower, still elevated
A30: Full 2025 (Jan-Oct) | B30: 48% | C30: Current baseline

Sheet Formula Reference
A1: FORMULA REFERENCE & METHODOLOGY
A2: All formulas used in this model, with descriptions and cell references
A4: INPUT CALCULATIONS
A5: Calculation | B5: Formula (text representation) | C5: Description
A6: Annual PV Production (MWh) | B6: PV_MW × Specific_Yield [Inputs!B9] = B7 × B8 | C6: 10 MW × 1,932 kWh/kWp = 19,320 MWh. Units: MW × kWh/kWp = MWh (since 1 MW = 1000 kWp).
A7: Net Revenue per MWh Stored | B7: Peak_Price × RTE [Inputs!B14] = B12 × B13 | C7: €182.99 × 86.32% = €157.96/MWh. Revenue after round-trip losses on each MWh stored.
A8: Annual O&M Cost | B8: BESS_MWh × LTSA_Rate + Insurance [Scenario Matrix] = Inputs!C24 × Inputs!B16 + Inputs!B17 | C8: e.g. 30 MWh × €2,469.59 + €15,000 = €89,088/yr. LTSA rate is OEM-confirmed (Linyang RFI V3).
A10: SCENARIO MATRIX FORMULAS
A11: Calculation | B11: Formula (text representation) | C11: Description
A12: Annual Curtailed Energy | B12: Annual_PV_Production × Curtailment_Rate [Row 5] = Inputs!B9 × [curtailment %] | C12: Total energy the DSO orders curtailed per year. e.g. 19,320 MWh × 50% = 9,660 MWh
A13: Avg Daily Curtailed | B13: Annual_Curtailed / 365 [Row 6] = [Row 5] / 365 | C13: Average daily curtailment in MWh. Used to calculate the ratio for CE lookup.
A14: Max Annual Throughput | B14: BESS_MWh × 365 × Availability [Row 11/25/39] = Inputs!C[option] × 365 × Inputs!B15 | C14: Maximum energy the BESS can cycle in a year. e.g. 20 MWh × 365 × 97% = 7,081 MWh
A15: Ratio | B15: Avg_Daily_Curtailed / BESS_MWh [Row 12/26/40] = [Row 6] / Inputs!C[option] | C15: How much daily curtailment vs BESS capacity. Ratio > 1 = more curtailment than battery can absorb.
A16: Capture Efficiency (CE) | B16: IF(Ratio>1.5, 0.97, IF(Ratio>1.2, 0.95, IF(Ratio>1.0, 0.92, IF(Ratio>0.8, 0.88, IF(Ratio>0.6, 0.82, 0.72))))) | C16: Accounts for temporal mismatch: not all curtailment occurs when BESS is available. Higher ratio = more days the BESS fills = higher efficiency.
A17: Annual Captured | B17: MIN( Max_Throughput, Annual_Curtailed × CE × Availability ) [Row 14/28/42] = MIN([throughput], [curtailed] × [CE] × Inputs!B15) | C17: The lesser of: BESS cycling limit OR available curtailed energy adjusted for capture efficiency and ~11 days/yr downtime.
A18: Annual Discharged | B18: Annual_Captured × RTE [Row 15/29/43] = [captured] × Inputs!B13 | C18: Energy actually delivered to grid after round-trip losses. RTE = 86.32% AC-AC full system.
A19: Gross Revenue | B19: Annual_Discharged × Peak_Price [Row 16/30/44] = [discharged] × Inputs!B12 | C19: Total revenue from selling discharged energy at evening peak prices. €182.99/MWh avg (17:00-21:00).
A20: Net Income | B20: Gross_Revenue − Annual_O&M [Row 17/31/45] = [revenue] − $B$[O&M row] | C20: Revenue minus operating costs. O&M referenced with absolute $ to column B.
A21: ROI (%) | B21: Net_Income / BESS_Price [Row 18/32/46] = [net] / $B$[price row] | C21: Simple annual return on investment. e.g. €1,054,101 / €3,033,000 = 34.8%
A22: Simple Payback (years) | B22: BESS_Price / Net_Income [Row 19/33/47] = $B$[price row] / [net income] | C22: Years to recover the initial investment. e.g. €3,033,000 / €1,054,101 = 2.9 years
A24: 15-YEAR PROJECTION FORMULAS
A25: Calculation | B25: Formula (text representation) | C25: Description
A26: PV Production (Year N) | B26: Base_PV × (1 − Degradation)^(N−1) [Col B] = Inputs!B9 × (1 − Inputs!B11)^(year−1) | C26: PV output declines 0.5%/yr. Year 1 = 19,320 MWh → Year 15 ≈ 17,996 MWh.
A27: SOH % (Year N) | B27: Hardcoded from Linyang degradation curve [Col C] = $O$[row] (lookup to SOH data column) | C27: State of Health at 1 cycle/day, 0.25P rate. Year 1: 94.62%, Year 5: 86.78%, Year 10: 79.58%, Year 15: 73.61%. Source: Linyang cycle-life test data.
A28: Effective BESS (MWh) | B28: Nominal_BESS_MWh × SOH% [Col D] = Inputs!C25 × $O$[row] | C28: Usable capacity decreases as cells degrade. e.g. 30 MWh × 86.78% = 26.03 MWh at Year 5.
A29: Annual Curtailed | B29: PV_Production × Curtailment_Rate [Col E] = B[row] × $B$3 | C29: Curtailment rate held constant (modifiable in cell B3). PV degradation reduces available curtailment each year.
A30: Captured | B30: MIN( Eff_BESS × 365 × Avail, Curtailed × CE × Avail ) [Col H] = MIN(D[row]×365×Inputs!B15, E[row]×G[row]×Inputs!B15) | C30: Same formula as scenario matrix but using year-specific effective BESS capacity and PV production.
A31: Cumulative Net | B31: Previous_Cumulative + Current_Year_Net [Col M] = M[prev] + L[row] | C31: Running total. Payback year is when cumulative net exceeds BESS investment.
A33: LCOS FORMULAS
A34: Calculation | B34: Formula (text representation) | C34: Description
A35: Total 15-Year Cost | B35: CAPEX + (O&M × 15) + Ext_Warranty_6to10 + Ext_Warranty_11to15 [LCOS sheet Row 8] = SUM(rows 4:7) | C35: Sum of capital, operating, and warranty costs over 15 years.
A36: 15-Year Discharged (System) | B36: BESS_MWh × 365 × Avail × RTE × SUM(SOH_yr1..yr15) [LCOS Row 11] = [MWh] × 365 × B15 × B13 × SUM('15-Year Projection'!O8:O22) | C36: Total energy delivered assuming 1 full cycle per available day, declining with SOH.
A37: System LCOS | B37: Total_15yr_Cost / Total_15yr_Discharged [LCOS Row 12] = [Row 8] / [Row 11] | C37: Cost per MWh delivered at full utilisation. Intrinsic cost of the storage technology.
A38: Margin per MWh | B38: Peak_Discharge_Price − LCOS [LCOS Row 17] = Inputs!B12 − [LCOS] | C38: Profit per MWh discharged. Driven by €0 charge cost under curtailment recovery.
A39: Discounted LCOS | B39: NPV(All_Costs) / NPV(All_Energy_Discharged) [LCOS Row 25] = [NPV costs] / [NPV energy] | C39: Levelized cost with time-value-of-money. Discount rate (default 8%) weights early costs more heavily. More rigorous for investor analysis.
A40: NPV of Costs | B40: CAPEX + SUMPRODUCT(Annual_Cost / (1+r)^{1..15}) [LCOS Row 23] = CAPEX + discounted O&M + discounted warranties | C40: Present value of all future costs discounted at WACC. Includes O&M (yr 1-15) + ext warranty (yr 6-15).
A41: NPV of Energy | B41: SUM( Discharged_yr_n / (1+r)^n ) for n=1..15 [LCOS Row 24] = sum of SOH-adjusted discharged per year, each discounted | C41: Present value of energy delivered, using SOH-adjusted capacity for each year.
A43: KEY ASSUMPTIONS & DATA SOURCES
A44: Parameter | B44: Value | C44: Source
A45: Peak Discharge Price | B45: €182.99/MWh | C45: TSOC DAM 134-day verified avg (Oct 2025 – Feb 2026), 17:00-21:00. Summer not yet available.
...
