Workbook

Sheet Inputs
A1: ANARITA BESS — MONTHLY MODEL WITH SCENARIOS
A2: 2 × 5 MW / 20 MWh | €4,760,000 | Muminjon (Spanercom)
A3: Yellow cells are modifiable — change to run your own scenarios
A5: PV PARK
A6: Parameter | B6: Value | C6: Unit | D6: Notes
A7: PV Installed Capacity | B7: 10 | C7: MW | D7: Client
A8: Total PV Panels | B8: 15178 | D8: 7,586 East + 7,592 West (ASTRO 660Wp)
A9: Panels Removed for BESS | B9: 90 | D9: Lost to BESS foundation area
A10: Panel Wattage | B10: 660 | C10: Wp | D10: ASTROENERGY ASTRO 6 CHSM66M-HC
A11: Effective PV Capacity | B11: =(B7*1000)-(B9*B10/1000) | C11: kWp | D11: =(B7*1000)-(B9*B10/1000)
A12: Annual Specific Yield | B12: 1932 | C12: kWh/kWp | D12: PVSyst verified
A13: Effective Annual Production | B13: =B11*B12/1000 | C13: MWh | D13: =B11*B12/1000
A14: PV Revenue Price (solar-hour avg) | B14: 140.88 | C14: EUR/MWh | D14: TSOC DAM 134-day (06:00-17:00)
A15: PV Annual Degradation | B15: 0.005 | D15: 0.5%/yr
A16: Annual PV Revenue Loss (panels) | B16: =(B9*B10/1000)*B12/1000*B14 | C16: EUR/yr | D16: Revenue lost per year from removing 90 panels
A18: BESS SYSTEM
A19: BESS Energy (Total) | B19: 40 | C19: MWh | D19: 2 × 20 MWh (4 × 5 MWh containers per park)
A20: BESS Power | B20: 10 | C20: MW | D20: 2 × 5 MW
A21: BESS EPC Price | B21: 4760000 | C21: EUR | D21: €119/kWh | 2 × €2,380,000
A22: Round-Trip Efficiency (RTE) | B22: 0.8632 | D22: Linyang AC-AC full system
A23: BESS Availability | B23: 0.97 | D23: 97% guaranteed (LTSA)
A24: LTSA Cost Rate | B24: 2469.59 | C24: EUR/MWh/yr | D24: Confirmed Linyang RFI V3
A25: BESS Insurance | B25: 15000 | C25: EUR/yr | D25: Budget estimate
A26: Annual O&M + Insurance | B26: =B19*B24+B25 | C26: EUR/yr | D26: =B19*B24+B25
A28: SCENARIO CONTROL
A29: Curtailment Scenario Multiplier | B29: 1 | D29: 1.0 = actual data. Set 1.1 = +10% curtailment across all months. Set 1.3 = +30% etc.
A30: Effective curtailment = Base × Multiplier (capped at 95%)
A32: SOH DATA
A33: Year 0 | B33: 1
A34: Year 1 | B34: 0.9462
A35: Year 2 | B35: 0.9266
A36: Year 3 | B36: 0.907
A37: Year 4 | B37: 0.8874
A38: Year 5 | B38: 0.8678
A39: Year 6 | B39: 0.8534
A40: Year 7 | B40: 0.839
A41: Year 8 | B41: 0.8246
A42: Year 9 | B42: 0.8102
A43: Year 10 | B43: 0.7958
A44: Year 11 | B44: 0.7839
...

Sheet Monthly Model
A1: MONTHLY BESS REVENUE MODEL — YEAR 1
A2: Based on actual Anarita monthly curtailment profile × scenario multiplier
A4: Month | B4: Days | C4: PVSyst (MWh) | D4: Base Curt % | E4: Eff Curt % | F4: Curtailed (MWh) | G4: Daily Curt (MWh) | H4: BESS Eff (MWh) | I4: Daily Capture | J4: Monthly Cap (MWh) | K4: Dischgd (MWh) | L4: Peak Price | M4: Revenue (€) | N4: O&M (€) | O4: Net (€) | P4: Charge Rate (MW) | Q4: Rate Check
A5: Jan | B5: 31 | C5: 955 | D5: 0.49 | E5: =MIN(D5*Inputs!B29,0.95) | F5: =C5*E5 | G5: =F5/B5 | H5: =Inputs!B19*0.9462 | I5: =MIN(H5,G5)*Inputs!B23 | J5: =I5*B5 | K5: =J5*Inputs!B22 | L5: 188.26 | M5: =K5*L5 | N5: =Inputs!B26/12 | O5: =M5-N5 | P5: =G5/Inputs!B52 | Q5: =IF(P5>Inputs!B20,"EXCEEDS","OK")
A6: Feb | B6: 28 | C6: 1086 | D6: 0.45 | E6: =MIN(D6*Inputs!B29,0.95) | F6: =C6*E6 | G6: =F6/B6 | H6: =Inputs!B19*0.9462 | I6: =MIN(H6,G6)*Inputs!B23 | J6: =I6*B6 | K6: =J6*Inputs!B22 | L6: 191.88 | M6: =K6*L6 | N6: =Inputs!B26/12 | O6: =M6-N6 | P6: =G6/Inputs!B52 | Q6: =IF(P6>Inputs!B20,"EXCEEDS","OK")
A7: Mar | B7: 31 | C7: 1513 | D7: 0.66 | E7: =MIN(D7*Inputs!B29,0.95) | F7: =C7*E7 | G7: =F7/B7 | H7: =Inputs!B19*0.9462 | I7: =MIN(H7,G7)*Inputs!B23 | J7: =I7*B7 | K7: =J7*Inputs!B22 | L7: 182.99 | M7: =K7*L7 | N7: =Inputs!B26/12 | O7: =M7-N7 | P7: =G7/Inputs!B52 | Q7: =IF(P7>Inputs!B20,"EXCEEDS","OK")
A8: Apr | B8: 30 | C8: 1669 | D8: 0.67 | E8: =MIN(D8*Inputs!B29,0.95) | F8: =C8*E8 | G8: =F8/B8 | H8: =Inputs!B19*0.9462 | I8: =MIN(H8,G8)*Inputs!B23 | J8: =I8*B8 | K8: =J8*Inputs!B22 | L8: 182.99 | M8: =K8*L8 | N8: =Inputs!B26/12 | O8: =M8-N8 | P8: =G8/Inputs!B52 | Q8: =IF(P8>Inputs!B20,"EXCEEDS","OK")
A9: May | B9: 31 | C9: 1921 | D9: 0.52 | E9: =MIN(D9*Inputs!B29,0.95) | F9: =C9*E9 | G9: =F9/B9 | H9: =Inputs!B19*0.9462 | I9: =MIN(H9,G9)*Inputs!B23 | J9: =I9*B9 | K9: =J9*Inputs!B22 | L9: 182.99 | M9: =K9*L9 | N9: =Inputs!B26/12 | O9: =M9-N9 | P9: =G9/Inputs!B52 | Q9: =IF(P9>Inputs!B20,"EXCEEDS","OK")
A10: Jun | B10: 30 | C10: 1987 | D10: 0.28 | E10: =MIN(D10*Inputs!B29,0.95) | F10: =C10*E10 | G10: =F10/B10 | H10: =Inputs!B19*0.9462 | I10: =MIN(H10,G10)*Inputs!B23 | J10: =I10*B10 | K10: =J10*Inputs!B22 | L10: 182.99 | M10: =K10*L10 | N10: =Inputs!B26/12 | O10: =M10-N10 | P10: =G10/Inputs!B52 | Q10: =IF(P10>Inputs!B20,"EXCEEDS","OK")
A11: Jul | B11: 31 | C11: 2034 | D11: 0.27 | E11: =MIN(D11*Inputs!B29,0.95) | F11: =C11*E11 | G11: =F11/B11 | H11: =Inputs!B19*0.9462 | I11: =MIN(H11,G11)*Inputs!B23 | J11: =I11*B11 | K11: =J11*Inputs!B22 | L11: 182.99 | M11: =K11*L11 | N11: =Inputs!B26/12 | O11: =M11-N11 | P11: =G11/Inputs!B52 | Q11: =IF(P11>Inputs!B20,"EXCEEDS","OK")
A12: Aug | B12: 31 | C12: 1944 | D12: 0.39 | E12: =MIN(D12*Inputs!B29,0.95) | F12: =C12*E12 | G12: =F12/B12 | H12: =Inputs!B19*0.9462 | I12: =MIN(H12,G12)*Inputs!B23 | J12: =I12*B12 | K12: =J12*Inputs!B22 | L12: 182.99 | M12: =K12*L12 | N12: =Inputs!B26/12 | O12: =M12-N12 | P12: =G12/Inputs!B52 | Q12: =IF(P12>Inputs!B20,"EXCEEDS","OK")
A13: Sep | B13: 30 | C13: 1724 | D13: 0.44 | E13: =MIN(D13*Inputs!B29,0.95) | F13: =C13*E13 | G13: =F13/B13 | H13: =Inputs!B19*0.9462 | I13: =MIN(H13,G13)*Inputs!B23 | J13: =I13*B13 | K13: =J13*Inputs!B22 | L13: 182.99 | M13: =K13*L13 | N13: =Inputs!B26/12 | O13: =M13-N13 | P13: =G13/Inputs!B52 | Q13: =IF(P13>Inputs!B20,"EXCEEDS","OK")
A14: Oct | B14: 31 | C14: 1461 | D14: 0.59 | E14: =MIN(D14*Inputs!B29,0.95) | F14: =C14*E14 | G14: =F14/B14 | H14: =Inputs!B19*0.9462 | I14: =MIN(H14,G14)*Inputs!B23 | J14: =I14*B14 | K14: =J14*Inputs!B22 | L14: 177.69 | M14: =K14*L14 | N14: =Inputs!B26/12 | O14: =M14-N14 | P14: =G14/Inputs!B52 | Q14: =IF(P14>Inputs!B20,"EXCEEDS","OK")
A15: Nov | B15: 30 | C15: 1108 | D15: 0.44 | E15: =MIN(D15*Inputs!B29,0.95) | F15: =C15*E15 | G15: =F15/B15 | H15: =Inputs!B19*0.9462 | I15: =MIN(H15,G15)*Inputs!B23 | J15: =I15*B15 | K15: =J15*Inputs!B22 | L15: 184.77 | M15: =K15*L15 | N15: =Inputs!B26/12 | O15: =M15-N15 | P15: =G15/Inputs!B52 | Q15: =IF(P15>Inputs!B20,"EXCEEDS","OK")
A16: Dec | B16: 31 | C16: 922 | D16: 0.27 | E16: =MIN(D16*Inputs!B29,0.95) | F16: =C16*E16 | G16: =F16/B16 | H16: =Inputs!B19*0.9462 | I16: =MIN(H16,G16)*Inputs!B23 | J16: =I16*B16 | K16: =J16*Inputs!B22 | L16: 147.55 | M16: =K16*L16 | N16: =Inputs!B26/12 | O16: =M16-N16 | P16: =G16/Inputs!B52 | Q16: =IF(P16>Inputs!B20,"EXCEEDS","OK")
A17: TOTAL | C17: =SUM(C5:C16) | F17: =SUM(F5:F16) | J17: =SUM(J5:J16) | K17: =SUM(K5:K16) | M17: =SUM(M5:M16) | N17: =SUM(N5:N16) | O17: =SUM(O5:O16)
A19: YEAR 1 SUMMARY
A20: Gross Revenue | B20: =M17
A21: Total O&M | B21: =N17
A22: Net BESS Income | B22: =O17
A23: Panel Loss Revenue Impact | B23: =Inputs!B16
A24: Net Income After Panel Loss | B24: =B22-B23
A25: ROI (after panel loss) | B25: =B24/Inputs!B21
A26: Simple Payback | B26: =Inputs!B21/B24
A27: UTILISATION METRICS
A28: Max Annual Throughput (MWh) | B28: =Inputs!B19*Inputs!B34*365*Inputs!B23 | D28: =BESS_MWh × SOH_Year1 × 365 × Availability
A29: Annual Captured (MWh) | B29: =J17
A30: BESS Utilisation | B30: =B29/B28 | D30: =Annual_Captured / Max_Annual_Throughput (standard definition)

Sheet Scenarios
A1: SCENARIO COMPARISON — CURTAILMENT MULTIPLIERS
A2: Shows impact of different curtailment levels on returns
A4: Metric | B4: Baseline (1.0×) | C4: Moderate (+20%) | D4: High (+40%) | E4: Very High (+55%)
A5: Weighted Avg Curtailment | B5: 0.45258077 | C5: 0.54309692 | D5: 0.63361308 | E5: 0.68741181
A6: Annual Curtailed (MWh) | B6: 8293.09 | C6: 9951.708 | D6: 11610.326 | E6: 12596.134
A7: Annual Captured (MWh) | B7: 8044.2973 | C7: 9404.0026 | D7: 10375.917 | E7: 10962.881
A8: Annual Discharged (MWh) | B8: 6943.8374 | C8: 8117.535 | D8: 8956.4918 | E8: 9463.1592
A9: BESS Utilisation | B9: 0.60031691 | C9: 0.70178682 | D9: 0.77431731 | E9: 0.81812032
A10: Gross Revenue (EUR) | B10: 1265869.7 | C10: 1479688 | D10: 1632400.7 | E10: 1724972.1
A11: O&M + Insurance | B11: 113783.6 | C11: 113783.6 | D11: 113783.6 | E11: 113783.6
A12: Panel Loss (90 panels) | B12: 16167.502 | C12: 16167.502 | D12: 16167.502 | E12: 16167.502
A13: Net Income (after panel loss) | B13: 1135918.6 | C13: 1349736.9 | D13: 1502449.6 | E13: 1595021
A14: ROI | B14: 0.23863835 | C14: 0.28355816 | D14: 0.31564067 | E14: 0.33508844
A15: Simple Payback (years) | B15: 4.1904412 | C15: 3.5266133 | D15: 3.1681595 | E15: 2.9842868
A17: SCENARIO DEFINITIONS
A18: Baseline (1.0×) | B18: Actual 2024-2025 monthly curtailment data as recorded
A19: Moderate (+20%) | B19: Each month's curtailment increased by 20% — reflects near-term trend
A20: High (+40%) | B20: Each month +40% — reflects 1-2 year outlook with more PV online
A21: Very High (+55%) | B21: Each month +55% — reflects 2-3 year outlook, high solar penetration

Sheet 15-Year Projection
A1: 15-YEAR PROJECTION (Monthly-Based)
A3: Uses monthly model results for Year 1, then degrades PV and SOH
A5: Year | B5: PV Prod | C5: SOH % | D5: BESS Rev | E5: O&M | F5: Panel Loss | G5: Net Income | H5: Cumulative
A6: 1 | B6: =Inputs!B13 | C6: 0.9462 | D6: ='Monthly Model'!M17 | E6: =Inputs!B26 | F6: =Inputs!B16 | G6: =D6-E6-F6 | H6: =G6
A7: 2 | B7: =Inputs!B13*(1-Inputs!B15)^(2-1) | C7: 0.9266 | D7: =D6*C7/C6*(1-Inputs!B15)^(2-1) | E7: =Inputs!B26 | F7: =Inputs!B16*(1-Inputs!B15)^(2-1) | G7: =D7-E7-F7 | H7: =H6+G7
A8: 3 | B8: =Inputs!B13*(1-Inputs!B15)^(3-1) | C8: 0.907 | D8: =D6*C8/C6*(1-Inputs!B15)^(3-1) | E8: =Inputs!B26 | F8: =Inputs!B16*(1-Inputs!B15)^(3-1) | G8: =D8-E8-F8 | H8: =H7+G8
A9: 4 | B9: =Inputs!B13*(1-Inputs!B15)^(4-1) | C9: 0.8874 | D9: =D6*C9/C6*(1-Inputs!B15)^(4-1) | E9: =Inputs!B26 | F9: =Inputs!B16*(1-Inputs!B15)^(4-1) | G9: =D9-E9-F9 | H9: =H8+G9
A10: 5 | B10: =Inputs!B13*(1-Inputs!B15)^(5-1) | C10: 0.8678 | D10: =D6*C10/C6*(1-Inputs!B15)^(5-1) | E10: =Inputs!B26 | F10: =Inputs!B16*(1-Inputs!B15)^(5-1) | G10: =D10-E10-F10 | H10: =H9+G10
A11: 6 | B11: =Inputs!B13*(1-Inputs!B15)^(6-1) | C11: 0.8534 | D11: =D6*C11/C6*(1-Inputs!B15)^(6-1) | E11: =Inputs!B26 | F11: =Inputs!B16*(1-Inputs!B15)^(6-1) | G11: =D11-E11-F11 | H11: =H10+G11
A12: 7 | B12: =Inputs!B13*(1-Inputs!B15)^(7-1) | C12: 0.839 | D12: =D6*C12/C6*(1-Inputs!B15)^(7-1) | E12: =Inputs!B26 | F12: =Inputs!B16*(1-Inputs!B15)^(7-1) | G12: =D12-E12-F12 | H12: =H11+G12
A13: 8 | B13: =Inputs!B13*(1-Inputs!B15)^(8-1) | C13: 0.8246 | D13: =D6*C13/C6*(1-Inputs!B15)^(8-1) | E13: =Inputs!B26 | F13: =Inputs!B16*(1-Inputs!B15)^(8-1) | G13: =D13-E13-F13 | H13: =H12+G13
A14: 9 | B14: =Inputs!B13*(1-Inputs!B15)^(9-1) | C14: 0.8102 | D14: =D6*C14/C6*(1-Inputs!B15)^(9-1) | E14: =Inputs!B26 | F14: =Inputs!B16*(1-Inputs!B15)^(9-1) | G14: =D14-E14-F14 | H14: =H13+G14
A15: 10 | B15: =Inputs!B13*(1-Inputs!B15)^(10-1) | C15: 0.7958 | D15: =D6*C15/C6*(1-Inputs!B15)^(10-1) | E15: =Inputs!B26 | F15: =Inputs!B16*(1-Inputs!B15)^(10-1) | G15: =D15-E15-F15 | H15: =H14+G15
A16: 11 | B16: =Inputs!B13*(1-Inputs!B15)^(11-1) | C16: 0.7839 | D16: =D6*C16/C6*(1-Inputs!B15)^(11-1) | E16: =Inputs!B26 | F16: =Inputs!B16*(1-Inputs!B15)^(11-1) | G16: =D16-E16-F16 | H16: =H15+G16
A17: 12 | B17: =Inputs!B13*(1-Inputs!B15)^(12-1) | C17: 0.772 | D17: =D6*C17/C6*(1-Inputs!B15)^(12-1) | E17: =Inputs!B26 | F17: =Inputs!B16*(1-Inputs!B15)^(12-1) | G17: =D17-E17-F17 | H17: =H16+G17
A18: 13 | B18: =Inputs!B13*(1-Inputs!B15)^(13-1) | C18: 0.7601 | D18: =D6*C18/C6*(1-Inputs!B15)^(13-1) | E18: =Inputs!B26 | F18: =Inputs!B16*(1-Inputs!B15)^(13-1) | G18: =D18-E18-F18 | H18: =H17+G18
A19: 14 | B19: =Inputs!B13*(1-Inputs!B15)^(14-1) | C19: 0.7482 | D19: =D6*C19/C6*(1-Inputs!B15)^(14-1) | E19: =Inputs!B26 | F19: =Inputs!B16*(1-Inputs!B15)^(14-1) | G19: =D19-E19-F19 | H19: =H18+G19
A20: 15 | B20: =Inputs!B13*(1-Inputs!B15)^(15-1) | C20: 0.7361 | D20: =D6*C20/C6*(1-Inputs!B15)^(15-1) | E20: =Inputs!B26 | F20: =Inputs!B16*(1-Inputs!B15)^(15-1) | G20: =D20-E20-F20 | H20: =H19+G20
A22: SUMMARY
A23: Total Net Income | B23: =SUM(G6:G20)
A24: BESS Investment | B24: =Inputs!B21
A25: Return Multiple | B25: =B23/B24
A26: Total Panel Loss (15yr) | B26: =SUM(F6:F20)

Sheet Park Data
A1: ACTUAL PARK DATA — Spanercom Anarita
A3: Month | B3: Yield (MWh) | C3: Potential (MWh) | D3: PVSyst (MWh) | E3: Curtailment %
A4: May-24 | B4: 1023 | C4: 1854 | D4: 1921 | E4: 0.45
A5: Jun-24 | B5: 1670 | C5: 1888 | D5: 1987 | E5: 0.12
A6: Jul-24 | B6: 1791 | C6: 1916 | D6: 2034 | E6: 0.07
A7: Aug-24 | B7: 1703 | C7: 1788 | D7: 1944 | E7: 0.05
A8: Sep-24 | B8: 1225 | C8: 1589 | D8: 1724 | E8: 0.23
A9: Oct-24 | B9: 941 | C9: 1617 | D9: 1461 | E9: 0.42
A10: Nov-24 | B10: 645 | C10: 1160 | D10: 1108 | E10: 0.44
A11: Dec-24 | B11: 694 | C11: 951 | D11: 922 | E11: 0.27
A12: Jan-25 | B12: 600 | C12: 1179 | D12: 955 | E12: 0.49
A13: Feb-25 | B13: 655 | C13: 1198 | D13: 1086 | E13: 0.45
A14: Mar-25 | B14: 566 | C14: 1648 | D14: 1513 | E14: 0.66
A15: Apr-25 | B15: 578 | C15: 1731 | D15: 1669 | E15: 0.67
... A21: Oct-25 | B21: 467 | C21: 1139 | D21: 1461 | E21: 0.59

Sheet NPV & IRR
A1: NPV & IRR ANALYSIS
A2: Discounted cashflow with price decline adjustment
A4: Year | B4: Net Income | C4: Price Adj Factor | D4: Adj Net Income | E4: Discount Factor | F4: PV of Cashflow | G4: Cumul PV
A5: 0 | B5: =-Inputs!B21 | C5: 1 | D5: =B5 | E5: 1 | F5: =D5*E5 | G5: =F5
A6: 1 | B6: ='15-Year Projection'!G6 | C6: =(1-Inputs!B51)^1 | D6: =B6*C6 | E6: =1/(1+Inputs!B53)^1 | F6: =D6*E6 | G6: =G5+F6
A7: 2 | B7: ='15-Year Projection'!G7 | C7: =(1-Inputs!B51)^2 | D7: =B7*C7 | E7: =1/(1+Inputs!B53)^2 | F7: =D7*E7 | G7: =G6+F7
A8: 3 | B8: ='15-Year Projection'!G8 | C8: =(1-Inputs!B51)^3 | D8: =B8*C8 | E8: =1/(1+Inputs!B53)^3 | F8: =D8*E8 | G8: =G7+F8
A9: 4 | B9: ='15-Year Projection'!G9 | C9: =(1-Inputs!B51)^4 | D9: =B9*C9 | E9: =1/(1+Inputs!B53)^4 | F9: =D9*E9 | G9: =G8+F9
A10: 5 | B10: ='15-Year Projection'!G10 | C10: =(1-Inputs!B51)^5 | D10: =B10*C10 | E10: =1/(1+Inputs!B53)^5 | F10: =D10*E10 | G10: =G9+F10
A11: 6 | B11: ='15-Year Projection'!G11 | C11: =(1-Inputs!B51)^6 | D11: =B11*C11 | E11: =1/(1+Inputs!B53)^6 | F11: =D11*E11 | G11: =G10+F11
A12: 7 | B12: ='15-Year Projection'!G12 | C12: =(1-Inputs!B51)^7 | D12: =B12*C12 | E12: =1/(1+Inputs!B53)^7 | F12: =D12*E12 | G12: =G11+F12
A13: 8 | B13: ='15-Year Projection'!G13 | C13: =(1-Inputs!B51)^8 | D13: =B13*C13 | E13: =1/(1+Inputs!B53)^8 | F13: =D13*E13 | G13: =G12+F13
A14: 9 | B14: ='15-Year Projection'!G14 | C14: =(1-Inputs!B51)^9 | D14: =B14*C14 | E14: =1/(1+Inputs!B53)^9 | F14: =D14*E14 | G14: =G13+F14
A15: 10 | B15: ='15-Year Projection'!G15 | C15: =(1-Inputs!B51)^10 | D15: =B15*C15 | E15: =1/(1+Inputs!B53)^10 | F15: =D15*E15 | G15: =G14+F15
A16: 11 | B16: ='15-Year Projection'!G16 | C16: =(1-Inputs!B51)^11 | D16: =B16*C16 | E16: =1/(1+Inputs!B53)^11 | F16: =D16*E16 | G16: =G15+F16
A17: 12 | B17: ='15-Year Projection'!G17 | C17: =(1-Inputs!B51)^12 | D17: =B17*C17 | E17: =1/(1+Inputs!B53)^12 | F17: =D17*E17 | G17: =G16+F17
A18: 13 | B18: ='15-Year Projection'!G18 | C18: =(1-Inputs!B51)^13 | D18: =B18*C18 | E18: =1/(1+Inputs!B53)^13 | F18: =D18*E18 | G18: =G17+F18
A19: 14 | B19: ='15-Year Projection'!G19 | C19: =(1-Inputs!B51)^14 | D19: =B19*C19 | E19: =1/(1+Inputs!B53)^14 | F19: =D19*E19 | G19: =G18+F19
A20: 15 | B20: ='15-Year Projection'!G20 | C20: =(1-Inputs!B51)^15 | D20: =B20*C20 | E20: =1/(1+Inputs!B53)^15 | F20: =D20*E20 | G20: =G19+F20
A22: RESULTS
A23: NPV | B23: =SUM(F5:F20) | D23: Net Present Value at WACC discount rate
A24: IRR | B24: =IRR(D5:D20) | D24: Internal Rate of Return (project IRR)
A25: Discount Rate | B25: =Inputs!B53 | D25: From Inputs sheet (modifiable)
A26: Price Decline | B26: =Inputs!B51 | D26: Annual peak price compression assumption
A27: Investment | B27: =Inputs!B21
A28: Discounted Payback | B28: =MATCH(TRUE,INDEX(G5:G20>0,0),0)-1 | D28: Year when cumulative discounted cashflow turns positive
A31: NPV SENSITIVITY
B32: 0% decline | C32: 1% decline | D32: 2% decline
A33: WACC 6% | B33: 2110459.4 | C33: 1680439.4 | D33: 1283963
A34: WACC 8% | B34: 1340699.1 | C34: 977097.88 | D34: 640894.46
A35: WACC 10% | B35: 700091.39 | C35: 390099.02 | D35: 102647.93
A36: WACC 12% | B36: 162442.65 | C36: -103944.14 | D36: -351654.16

Sheet Model Notes
A1: MODEL NOTES & ASSUMPTIONS
A4: CURTAILMENT DATA
A5: Monthly curtailment rates use the most recent available data per calendar month (2025 preferred over 2024).
A6: For May-Oct, only 2025 data is used. This reflects the latest (and higher) curtailment trend.
A7: If you prefer a 2-year average, modify the Base Curt % cells on the Monthly Model sheet.
A8: The Scenario Multiplier on the Inputs sheet scales all months uniformly. Set 1.0 for baseline, 1.2 for +20%, etc.
A10: PEAK PRICE COMPRESSION
A11: Base case assumes constant peak prices (0% annual decline).
A12: The Annual Peak Price Decline input (Inputs sheet) applies a compounding reduction to the 15-year projection.
A13: As more BESS enters the Cyprus market, peak-to-off-peak spreads may compress. 1-2%/yr is a reasonable stress test.
A14: Summer peak prices not yet available from TSOC DAM (dataset is Oct-Feb only). Summer months use €182.99 as placeholder.
A16: CHARGE-RATE CONSTRAINT
... A48: LTSA Rates: OEM-confirmed (Linyang RFI V3, February 2026)
