Workbook

Sheet Summary
B1: BESS PROFITABILITY - GALASCOPE (ESPERIA ENERGY)
B2: Lighthief Cyprus Ltd - Data-Validated Model (Feb 2026) | E2: Change parameters on the Inputs sheet
B4: KEY FINANCIAL METRICS
B5: Investment (EUR) | C5: =Inputs!C16
B6: Simple Payback (years) | C6: =IF(CashFlow!J18<0,"Never",SUMPRODUCT((CashFlow!J4:J18<0)*1)+1+ABS(INDEX(CashFlow!J3:J18,SUMPRODUCT((CashFlow!J4:J18<0)*1)+1))/INDEX(CashFlow!I4:I18,SUMPRODUCT((CashFlow!J4:J18<0)*1)+1))
B7: 15-Year Net Profit (EUR) | C7: =CashFlow!J18
B8: 15-Year ROI (%) | C8: =CashFlow!J18/Inputs!C16
B9: 15-Year Gross Revenue (EUR) | C9: =SUM(CashFlow!G4:G18)
B10: 15-Year Operating Costs (EUR) | C10: =SUM(CashFlow!H4:H18)
B11: Year 1 Net Cash Flow (EUR) | C11: =CashFlow!I4
B12: Year 15 Net Cash Flow (EUR) | C12: =CashFlow!I18
B14: BESS PERFORMANCE
B15: BESS Capture Efficiency | C15: =SUM(DailyAnalysis!G2:G366)/SUM(DailyAnalysis!D2:D366)
B16: Average Daily Fill | C16: =AVERAGE(DailyAnalysis!H2:H366)
B17: Days at 100% Fill | C17: =COUNTIF(DailyAnalysis!H2:H366,">=0.9999")
B18: Days Zero Curtailment | C18: =COUNTIF(CurtailmentData!D2:D366,"<=0")
B19: 15-Year Total Cycles | C19: =CashFlow!E18
B20: Cycle Headroom vs 7000 | C20: =1-CashFlow!E18/Inputs!C13
B21: Average Daily Cycles | C21: =SUM(CashFlow!L4:L18)/(Inputs!C30*365)
B23: CURTAILMENT DATA SUMMARY
B24: Data Source | C24: Galascope 2.5MW, 365 days (Jan-Dec 2025)
B25: Annual PV Potential (MWh, ref) | C25: =SUM(CurtailmentData!F2:F366)/1000
B26: Annual Curtailed (MWh, ref) | C26: =SUM(CurtailmentData!D2:D366)/1000
B27: Curtailment Rate | C27: =C26/C25
B28: Days with Curtailment | C28: =COUNTIF(CurtailmentData!D2:D366,">0")
B30: MARKET DATA VALIDATION
B31: DAM Data Source | C31: 137 TSOC files, Oct 2025 - Feb 2026
B32: Peak Evening Avg (17-21) | C32: EUR 184.13/MWh
B33: Model Discharge Price | C33: =Inputs!C27
B34: Model vs Actual | C34: Conservative by EUR 9.13 (+5.2%)
B35: Midday Trough Avg (09-14) | C35: EUR 102.40/MWh
B37: MONTHLY BREAKDOWN
B38: Month | C38: PV Yield (MWh) | D38: Curtailed (MWh) | E38: Curt % | F38: BESS Captured (MWh) | G38: Avg Fill
B39: Jan | C39: 128 | D39: 117.6 | E39: 0.479 | F39: 235.3 | G39: 0.446
B40: Feb | C40: 162.1 | D40: 107.2 | E40: 0.398 | F40: 209.7 | G40: 0.44
B41: Mar | C41: 150.6 | D41: 286 | E41: 0.655 | F41: 470.9 | G41: 0.892
B42: Apr | C42: 175.8 | D42: 276.1 | E42: 0.611 | F42: 393.9 | G42: 0.771
B43: May | C43: 298.1 | D43: 297.6 | E43: 0.5 | F43: 463 | G43: 0.877
B44: Jun | C44: 432.7 | D44: 188.3 | E44: 0.303 | F44: 313.3 | G44: 0.613
B45: Jul | C45: 486.8 | D45: 127.2 | E45: 0.207 | F45: 232.7 | G45: 0.441
...

Sheet Inputs
B1: BESS Profitability Calculator - Galascope (Esperia Energy)
B2: Lighthief Cyprus Ltd - Yellow cells are editable inputs
B4: BESS SYSTEM
B5: PV Park Capacity (MW) | C5: 5 | D5: MW | E5: Galascope 1 target - change for different park sizes
B6: Reference Park Capacity (MW) | C6: 2.5 | D6: MW | E6: Galascope 2.5MW - source of actual curtailment data
B7: Scaling Factor | C7: =C5/C6 | D7: x | E7: Auto-calculated: Target / Reference
B8: BESS Power Rating (MW) | C8: 5 | D8: MW | E8: Linyang system power rating
B9: BESS Energy Capacity (MWh) | C9: 20 | D9: MWh | E9: 4x 5.015 MWh containers = 20.06 MWh nameplate
B10: BESS Duration (hours) | C10: =C9/C8 | D10: hrs
B11: Depth of Discharge (%) | C11: 90 | D11: % | E11: Linyang operating specification
B12: Round-Trip Efficiency (%) | C12: 87.8 | D12: % | E12: Linyang confirmed AC-AC RTE
B13: Cycle Life (@ 90% DOD, 70% EOL) | C13: 7000 | D13: cycles
B15: INVESTMENT & COSTS
B16: Turnkey EPC Price (EUR) | C16: 2258900 | D16: EUR | E16: Confirmed Esperia 5MW/20MWh price
B17: Cost per kWh (EUR/kWh) | C17: =C16/(C9*1000) | D17: EUR/kWh
B18: LTSA Tier C - Yr 1-5 (EUR/yr) | C18: 34800 | D18: EUR/yr
B19: Extended Warranty - Yr 6-10 add-on (EUR/yr) | C19: 33234 | D19: EUR/yr
B20: Extended Warranty - Yr 11-15 add-on (EUR/yr) | C20: 41674 | D20: EUR/yr
B21: SCADA/EMS Annual (EUR/yr) | C21: 5000 | D21: EUR/yr
B22: Total OpCost Yr 1-5 (EUR/yr) | C22: =C18+C21
B23: Total OpCost Yr 6-10 (EUR/yr) | C23: =C18+C19+C21
B24: Total OpCost Yr 11-15 (EUR/yr) | C24: =C18+C20+C21
B26: REVENUE ASSUMPTIONS
B27: Blended Discharge Price (EUR/MWh) | C27: 175 | D27: EUR/MWh | E27: Conservative - actual DAM peak 17-21 avg = EUR 184.13
B28: Charge Cost (EUR/MWh) | C28: 0 | D28: EUR/MWh | E28: Curtailed energy = zero opportunity cost
B29: Annual Price Escalation (%) | C29: 0 | D29: % | E29: Conservative - no escalation assumed
B30: Project Life (years) | C30: 15 | D30: years
B32: CURTAILMENT SUMMARY (from actual data)
B33: Annual Curtailed - Ref Park (MWh) | C33: =SUM(CurtailmentData!D2:D366)/1000
B34: Annual Curtailed - Scaled (MWh) | C34: =C33*C7
B35: Annual BESS Captured Yr1 - Scaled (MWh) | C35: =SUM(DailyAnalysis!G2:G366)/1000
B36: Capture Efficiency (%) | C36: =C35/C34
B37: Average Daily BESS Fill (%) | C37: =AVERAGE(DailyAnalysis!H2:H366)

Sheet CurtailmentData
A1: Date | B1: Month | C1: Sun Hours | D1: Curtailed (kWh) | E1: PV Yield (kWh) | F1: Total Potential (kWh) | G1: Curtailment %
A2: 2025-01-01 | B2: 1 | C2: 8.75 | D2: 5641.47 | E2: 2138.17 | F2: 7779.64 | G2: =IF(F2>0, D2/F2, 0)
A3: 2025-01-02 | B3: 1 | C3: 8.75 | D3: 5407.44 | E3: 3351.33 | F3: 8758.77 | G3: =IF(F3>0, D3/F3, 0)
A4: 2025-01-03 | B4: 1 | C4: 8.83 | D4: 2117.06 | E4: 6520.83 | F4: 8637.89 | G4: =IF(F4>0, D4/F4, 0)
A5: 2025-01-04 | B5: 1 | C5: 8.25 | D5: 5.83 | E5: 4942.21 | F5: 4948.04 | G5: =IF(F5>0, D5/F5, 0)
A6: 2025-01-05 | B6: 1 | C6: 7.33 | D6: 0 | E6: 3751.49 | F6: 3751.49 | G6: =IF(F6>0, D6/F6, 0)
A7: 2025-01-06 | B7: 1 | C7: 8.67 | D7: 5370.38 | E7: 2336.04 | F7: 7706.42 | G7: =IF(F7>0, D7/F7, 0)
A8: 2025-01-07 | B8: 1 | C8: 8.75 | D8: 2225.36 | E8: 5943.77 | F8: 8169.13 | G8: =IF(F8>0, D8/F8, 0)
A9: 2025-01-08 | B9: 1 | C9: 8.33 | D9: 653.62 | E9: 5578.62 | F9: 6232.24 | G9: =IF(F9>0, D9/F9, 0)
A10: 2025-01-09 | B10: 1 | C10: 8.5 | D10: 4418.52 | E10: 3671.6 | F10: 8090.12 | G10: =IF(F10>0, D10/F10, 0)
A11: 2025-01-10 | B11: 1 | C11: 8.83 | D11: 1868.59 | E11: 6382.54 | F11: 8251.12 | G11: =IF(F11>0, D11/F11, 0)
A12: 2025-01-11 | B12: 1 | C12: 8.75 | D12: 2929.18 | E12: 5319.32 | F12: 8248.5 | G12: =IF(F12>0, D12/F12, 0)
A13: 2025-01-12 | B13: 1 | C13: 8.67 | D13: 4573.96 | E13: 3737.31 | F13: 8311.27 | G13: =IF(F13>0, D13/F13, 0)
... A366: 2025-12-31 | B366: 12 | C366: 6.17 | D366: 1189.85 | E366: 1641.24 | F366: 2831.09 | G366: =IF(F366>0, D366/F366, 0)

Sheet MarketData
A1: TSOC DAM Hourly Price Profile (Oct 2025 - Feb 2026, 6576 records)
A2: Hour | B2: Avg EUR/MWh | C2: Median | D2: P10 | E2: P90 | F2: Min | G2: Max | H2: Zero-Price % | I2: Count | J2: Band
A3: 00:00 | B3: 173.15 | C3: 174 | D3: 157.5 | E3: 187 | F3: 150 | G3: 194 | H3: 0 | I3: 274 | J3: Night
A4: 01:00 | B4: 170.28 | C4: 171 | D4: 155.5 | E4: 184 | F4: 150 | G4: 192.5 | H4: 0 | I4: 274 | J4: Night
A5: 02:00 | B5: 169.56 | C5: 170 | D5: 155 | E5: 183 | F5: 150 | G5: 192 | H5: 0 | I5: 274 | J5: Night
A6: 03:00 | B6: 169.25 | C6: 169 | D6: 155 | E6: 182 | F6: 150 | G6: 192 | H6: 0 | I6: 274 | J6: Night
A7: 04:00 | B7: 169.37 | C7: 169 | D7: 155 | E7: 182 | F7: 150 | G7: 193 | H7: 0 | I7: 274 | J7: Night
A8: 05:00 | B8: 171.31 | C8: 171 | D8: 157 | E8: 185 | F8: 150 | G8: 194.5 | H8: 0 | I8: 274 | J8: Night
A9: 06:00 | B9: 174.6 | C9: 175.5 | D9: 157.5 | E9: 188.2 | F9: 152 | G9: 198 | H9: 0 | I9: 274 | J9: Morning
A10: 07:00 | B10: 174.76 | C10: 175 | D10: 160 | E10: 188 | F10: 153 | G10: 200 | H10: 0 | I10: 274 | J10: Morning
A11: 08:00 | B11: 166.98 | C11: 169 | D11: 154 | E11: 185 | F11: 0 | G11: 195 | H11: 0.0146 | I11: 274 | J11: Morning
A12: 09:00 | B12: 146.09 | C12: 159 | D12: 69 | E12: 179 | F12: 0 | G12: 192 | H12: 0.0584 | I12: 274 | J12: Midday Trough
A13: 10:00 | B13: 102.79 | C13: 152 | D13: 0 | E13: 171 | F13: 0 | G13: 193.5 | H13: 0.2153 | I13: 274 | J13: Midday Trough
A14: 11:00 | B14: 80.43 | C14: 38.5 | D14: 0 | E14: 170 | F14: 0 | G14: 193.5 | H14: 0.3358 | I14: 274 | J14: Midday Trough
... A26: 23:00 | B26: 173.86 | C26: 175 | D26: 157 | E26: 188 | F26: 150 | G26: 195 | H26: 0 | I26: 274 | J26: Late Evening
A28: Band Summary
A29: Band | B29: Hours | C29: Avg EUR/MWh | D29: Zero % | E29: <=EUR50 %
A30: Night (00-06) | B30: 00:00-06:00 | C30: 170.49 | D30: 0 | E30: 0
A31: Morning (06-09) | B31: 06:00-09:00 | C31: 172.11 | D31: 0.0049 | E31: 0.0049
A32: Midday Trough (09-14) | B32: 09:00-14:00 | C32: 102.4 | D32: 0.2372 | E32: 0.3759
A33: Afternoon (14-17) | B33: 14:00-17:00 | C33: 161.35 | D33: 0.0219 | E33: 0.0596
A34: Peak Evening (17-21) | B34: 17:00-21:00 | C34: 184.13 | D34: 0 | E34: 0
A35: Late Evening (21-24) | B35: 21:00-24:00 | C35: 176.61 | D35: 0 | E35: 0
A37: Peak Evening Avg (17-21): | B37: 184.13

Sheet SOH_Degradation
A1: Linyang SOH Degradation Curve (0.5P, 1 cycle/day, 25 +/- 2C)
A2: Year | B2: SOH % | C2: Usable Capacity (MWh) | D2: Max Daily Charge (kWh) | E2: Cumulative Cycles | F2: Cycle Headroom vs 7000
A3: 1 | B3: 0.9462 | C3: =Inputs!C9*B3*Inputs!C11/100 | D3: =C3*1000 | E3: =CashFlow!E4 | F3: =1-E3/Inputs!C13
A4: 2 | B4: 0.9177 | C4: =Inputs!C9*B4*Inputs!C11/100 | D4: =C4*1000 | E4: =CashFlow!E5 | F4: =1-E4/Inputs!C13
A5: 3 | B5: 0.8991 | C5: =Inputs!C9*B5*Inputs!C11/100 | D5: =C5*1000 | E5: =CashFlow!E6 | F5: =1-E5/Inputs!C13
A6: 4 | B6: 0.8835 | C6: =Inputs!C9*B6*Inputs!C11/100 | D6: =C6*1000 | E6: =CashFlow!E7 | F6: =1-E6/Inputs!C13
A7: 5 | B7: 0.8678 | C7: =Inputs!C9*B7*Inputs!C11/100 | D7: =C7*1000 | E7: =CashFlow!E8 | F7: =1-E7/Inputs!C13
A8: 6 | B8: 0.8534 | C8: =Inputs!C9*B8*Inputs!C11/100 | D8: =C8*1000 | E8: =CashFlow!E9 | F8: =1-E8/Inputs!C13
A9: 7 | B9: 0.839 | C9: =Inputs!C9*B9*Inputs!C11/100 | D9: =C9*1000 | E9: =CashFlow!E10 | F9: =1-E9/Inputs!C13
A10: 8 | B10: 0.8246 | C10: =Inputs!C9*B10*Inputs!C11/100 | D10: =C10*1000 | E10: =CashFlow!E11 | F10: =1-E10/Inputs!C13
A11: 9 | B11: 0.8102 | C11: =Inputs!C9*B11*Inputs!C11/100 | D11: =C11*1000 | E11: =CashFlow!E12 | F11: =1-E11/Inputs!C13
A12: 10 | B12: 0.7958 | C12: =Inputs!C9*B12*Inputs!C11/100 | D12: =C12*1000 | E12: =CashFlow!E13 | F12: =1-E12/Inputs!C13
A13: 11 | B13: 0.7839 | C13: =Inputs!C9*B13*Inputs!C11/100 | D13: =C13*1000 | E13: =CashFlow!E14 | F13: =1-E13/Inputs!C13
A14: 12 | B14: 0.772 | C14: =Inputs!C9*B14*Inputs!C11/100 | D14: =C14*1000 | E14: =CashFlow!E15 | F14: =1-E14/Inputs!C13
A15: 13 | B15: 0.7601 | C15: =Inputs!C9*B15*Inputs!C11/100 | D15: =C15*1000 | E15: =CashFlow!E16 | F15: =1-E15/Inputs!C13
A16: 14 | B16: 0.7481 | C16: =Inputs!C9*B16*Inputs!C11/100 | D16: =C16*1000 | E16: =CashFlow!E17 | F16: =1-E16/Inputs!C13
A17: 15 | B17: 0.7361 | C17: =Inputs!C9*B17*Inputs!C11/100 | D17: =C17*1000 | E17: =CashFlow!E18 | F17: =1-E17/Inputs!C13

Sheet DailyAnalysis
A1: Date | B1: Month | C1: Curtailed Ref (kWh) | D1: Curtailed Scaled (kWh) | E1: BESS Usable Cap Yr1 (kWh) | F1: Overflow (kWh) | G1: Captured (kWh) | H1: Fill % | I1: Discharged (kWh) | J1: Revenue (EUR)
A2: 2025-01-01 | B2: 1 | C2: =CurtailmentData!D2 | D2: =C2*Inputs!C7 | E2: =SOH_Degradation!D3 | F2: =MAX(0, D2-E2) | G2: =MIN(D2, E2) | H2: =IF(E2>0, G2/E2, 0) | I2: =G2*Inputs!C12/100 | J2: =(I2/1000)*(Inputs!C27-Inputs!C28)
A3: 2025-01-02 | B3: 1 | C3: =CurtailmentData!D3 | D3: =C3*Inputs!C7 | E3: =SOH_Degradation!D3 | F3: =MAX(0, D3-E3) | G3: =MIN(D3, E3) | H3: =IF(E3>0, G3/E3, 0) | I3: =G3*Inputs!C12/100 | J3: =(I3/1000)*(Inputs!C27-Inputs!C28)
A4: 2025-01-03 | B4: 1 | C4: =CurtailmentData!D4 | D4: =C4*Inputs!C7 | E4: =SOH_Degradation!D3 | F4: =MAX(0, D4-E4) | G4: =MIN(D4, E4) | H4: =IF(E4>0, G4/E4, 0) | I4: =G4*Inputs!C12/100 | J4: =(I4/1000)*(Inputs!C27-Inputs!C28)
A5: 2025-01-04 | B5: 1 | C5: =CurtailmentData!D5 | D5: =C5*Inputs!C7 | E5: =SOH_Degradation!D3 | F5: =MAX(0, D5-E5) | G5: =MIN(D5, E5) | H5: =IF(E5>0, G5/E5, 0) | I5: =G5*Inputs!C12/100 | J5: =(I5/1000)*(Inputs!C27-Inputs!C28)
A6: 2025-01-05 | B6: 1 | C6: =CurtailmentData!D6 | D6: =C6*Inputs!C7 | E6: =SOH_Degradation!D3 | F6: =MAX(0, D6-E6) | G6: =MIN(D6, E6) | H6: =IF(E6>0, G6/E6, 0) | I6: =G6*Inputs!C12/100 | J6: =(I6/1000)*(Inputs!C27-Inputs!C28)
A7: 2025-01-06 | B7: 1 | C7: =CurtailmentData!D7 | D7: =C7*Inputs!C7 | E7: =SOH_Degradation!D3 | F7: =MAX(0, D7-E7) | G7: =MIN(D7, E7) | H7: =IF(E7>0, G7/E7, 0) | I7: =G7*Inputs!C12/100 | J7: =(I7/1000)*(Inputs!C27-Inputs!C28)
A8: 2025-01-07 | B8: 1 | C8: =CurtailmentData!D8 | D8: =C8*Inputs!C7 | E8: =SOH_Degradation!D3 | F8: =MAX(0, D8-E8) | G8: =MIN(D8, E8) | H8: =IF(E8>0, G8/E8, 0) | I8: =G8*Inputs!C12/100 | J8: =(I8/1000)*(Inputs!C27-Inputs!C28)
A9: 2025-01-08 | B9: 1 | C9: =CurtailmentData!D9 | D9: =C9*Inputs!C7 | E9: =SOH_Degradation!D3 | F9: =MAX(0, D9-E9) | G9: =MIN(D9, E9) | H9: =IF(E9>0, G9/E9, 0) | I9: =G9*Inputs!C12/100 | J9: =(I9/1000)*(Inputs!C27-Inputs!C28)
A10: 2025-01-09 | B10: 1 | C10: =CurtailmentData!D10 | D10: =C10*Inputs!C7 | E10: =SOH_Degradation!D3 | F10: =MAX(0, D10-E10) | G10: =MIN(D10, E10) | H10: =IF(E10>0, G10/E10, 0) | I10: =G10*Inputs!C12/100 | J10: =(I10/1000)*(Inputs!C27-Inputs!C28)
A11: 2025-01-10 | B11: 1 | C11: =CurtailmentData!D11 | D11: =C11*Inputs!C7 | E11: =SOH_Degradation!D3 | F11: =MAX(0, D11-E11) | G11: =MIN(D11, E11) | H11: =IF(E11>0, G11/E11, 0) | I11: =G11*Inputs!C12/100 | J11: =(I11/1000)*(Inputs!C27-Inputs!C28)
A12: 2025-01-11 | B12: 1 | C12: =CurtailmentData!D12 | D12: =C12*Inputs!C7 | E12: =SOH_Degradation!D3 | F12: =MAX(0, D12-E12) | G12: =MIN(D12, E12) | H12: =IF(E12>0, G12/E12, 0) | I12: =G12*Inputs!C12/100 | J12: =(I12/1000)*(Inputs!C27-Inputs!C28)
A13: 2025-01-12 | B13: 1 | C13: =CurtailmentData!D13 | D13: =C13*Inputs!C7 | E13: =SOH_Degradation!D3 | F13: =MAX(0, D13-E13) | G13: =MIN(D13, E13) | H13: =IF(E13>0, G13/E13, 0) | I13: =G13*Inputs!C12/100 | J13: =(I13/1000)*(Inputs!C27-Inputs!C28)
A14: 2025-01-13 | B14: 1 | C14: =CurtailmentData!D14 | D14: =C14*Inputs!C7 | E14: =SOH_Degradation!D3 | F14: =MAX(0, D14-E14) | G14: =MIN(D14, E14) | H14: =IF(E14>0, G14/E14, 0) | I14: =G14*Inputs!C12/100 | J14: =(I14/1000)*(Inputs!C27-Inputs!C28)
A15: 2025-01-14 | B15: 1 | C15: =CurtailmentData!D15 | D15: =C15*Inputs!C7 | E15: =SOH_Degradation!D3 | F15: =MAX(0, D15-E15) | G15: =MIN(D15, E15) | H15: =IF(E15>0, G15/E15, 0) | I15: =G15*Inputs!C12/100 | J15: =(I15/1000)*(Inputs!C27-Inputs!C28)
A16: 2025-01-15 | B16: 1 | C16: =CurtailmentData!D16 | D16: =C16*Inputs!C7 | E16: =SOH_Degradation!D3 | F16: =MAX(0, D16-E16) | G16: =MIN(D16, E16) | H16: =IF(E16>0, G16/E16, 0) | I16: =G16*Inputs!C12/100 | J16: =(I16/1000)*(Inputs!C27-Inputs!C28)
A17: 2025-01-16 | B17: 1 | C17: =CurtailmentData!D17 | D17: =C17*Inputs!C7 | E17: =SOH_Degradation!D3 | F17: =MAX(0, D17-E17) | G17: =MIN(D17, E17) | H17: =IF(E17>0, G17/E17, 0) | I17: =G17*Inputs!C12/100 | J17: =(I17/1000)*(Inputs!C27-Inputs!C28)
A18: 2025-01-17 | B18: 1 | C18: =CurtailmentData!D18 | D18: =C18*Inputs!C7 | E18: =SOH_Degradation!D3 | F18: =MAX(0, D18-E18) | G18: =MIN(D18, E18) | H18: =IF(E18>0, G18/E18, 0) | I18: =G18*Inputs!C12/100 | J18: =(I18/1000)*(Inputs!C27-Inputs!C28)
A19: 2025-01-18 | B19: 1 | C19: =CurtailmentData!D19 | D19: =C19*Inputs!C7 | E19: =SOH_Degradation!D3 | F19: =MAX(0, D19-E19) | G19: =MIN(D19, E19) | H19: =IF(E19>0, G19/E19, 0) | I19: =G19*Inputs!C12/100 | J19: =(I19/1000)*(Inputs!C27-Inputs!C28)
A20: 2025-01-19 | B20: 1 | C20: =CurtailmentData!D20 | D20: =C20*Inputs!C7 | E20: =SOH_Degradation!D3 | F20: =MAX(0, D20-E20) | G20: =MIN(D20, E20) | H20: =IF(E20>0, G20/E20, 0) | I20: =G20*Inputs!C12/100 | J20: =(I20/1000)*(Inputs!C27-Inputs!C28)
A21: 2025-01-20 | B21: 1 | C21: =CurtailmentData!D21 | D21: =C21*Inputs!C7 | E21: =SOH_Degradation!D3 | F21: =MAX(0, D21-E21) | G21: =MIN(D21, E21) | H21: =IF(E21>0, G21/E21, 0) | I21: =G21*Inputs!C12/100 | J21: =(I21/1000)*(Inputs!C27-Inputs!C28)
A22: 2025-01-21 | B22: 1 | C22: =CurtailmentData!D22 | D22: =C22*Inputs!C7 | E22: =SOH_Degradation!D3 | F22: =MAX(0, D22-E22) | G22: =MIN(D22, E22) | H22: =IF(E22>0, G22/E22, 0) | I22: =G22*Inputs!C12/100 | J22: =(I22/1000)*(Inputs!C27-Inputs!C28)
A23: 2025-01-22 | B23: 1 | C23: =CurtailmentData!D23 | D23: =C23*Inputs!C7 | E23: =SOH_Degradation!D3 | F23: =MAX(0, D23-E23) | G23: =MIN(D23, E23) | H23: =IF(E23>0, G23/E23, 0) | I23: =G23*Inputs!C12/100 | J23: =(I23/1000)*(Inputs!C27-Inputs!C28)
A24: 2025-01-23 | B24: 1 | C24: =CurtailmentData!D24 | D24: =C24*Inputs!C7 | E24: =SOH_Degradation!D3 | F24: =MAX(0, D24-E24) | G24: =MIN(D24, E24) | H24: =IF(E24>0, G24/E24, 0) | I24: =G24*Inputs!C12/100 | J24: =(I24/1000)*(Inputs!C27-Inputs!C28)
A25: 2025-01-24 | B25: 1 | C25: =CurtailmentData!D25 | D25: =C25*Inputs!C7 | E25: =SOH_Degradation!D3 | F25: =MAX(0, D25-E25) | G25: =MIN(D25, E25) | H25: =IF(E25>0, G25/E25, 0) | I25: =G25*Inputs!C12/100 | J25: =(I25/1000)*(Inputs!C27-Inputs!C28)
A26: 2025-01-25 | B26: 1 | C26: =CurtailmentData!D26 | D26: =C26*Inputs!C7 | E26: =SOH_Degradation!D3 | F26: =MAX(0, D26-E26) | G26: =MIN(D26, E26) | H26: =IF(E26>0, G26/E26, 0) | I26: =G26*Inputs!C12/100 | J26: =(I26/1000)*(Inputs!C27-Inputs!C28)
A27: 2025-01-26 | B27: 1 | C27: =CurtailmentData!D27 | D27: =C27*Inputs!C7 | E27: =SOH_Degradation!D3 | F27: =MAX(0, D27-E27) | G27: =MIN(D27, E27) | H27: =IF(E27>0, G27/E27, 0) | I27: =G27*Inputs!C12/100 | J27: =(I27/1000)*(Inputs!C27-Inputs!C28)
A28: 2025-01-27 | B28: 1 | C28: =CurtailmentData!D28 | D28: =C28*Inputs!C7 | E28: =SOH_Degradation!D3 | F28: =MAX(0, D28-E28) | G28: =MIN(D28, E28) | H28: =IF(E28>0, G28/E28, 0) | I28: =G28*Inputs!C12/100 | J28: =(I28/1000)*(Inputs!C27-Inputs!C28)
A29: 2025-01-28 | B29: 1 | C29: =CurtailmentData!D29 | D29: =C29*Inputs!C7 | E29: =SOH_Degradation!D3 | F29: =MAX(0, D29-E29) | G29: =MIN(D29, E29) | H29: =IF(E29>0, G29/E29, 0) | I29: =G29*Inputs!C12/100 | J29: =(I29/1000)*(Inputs!C27-Inputs!C28)
A30: 2025-01-29 | B30: 1 | C30: =CurtailmentData!D30 | D30: =C30*Inputs!C7 | E30: =SOH_Degradation!D3 | F30: =MAX(0, D30-E30) | G30: =MIN(D30, E30) | H30: =IF(E30>0, G30/E30, 0) | I30: =G30*Inputs!C12/100 | J30: =(I30/1000)*(Inputs!C27-Inputs!C28)
A31: 2025-01-30 | B31: 1 | C31: =CurtailmentData!D31 | D31: =C31*Inputs!C7 | E31: =SOH_Degradation!D3 | F31: =MAX(0, D31-E31) | G31: =MIN(D31, E31) | H31: =IF(E31>0, G31/E31, 0) | I31: =G31*Inputs!C12/100 | J31: =(I31/1000)*(Inputs!C27-Inputs!C28)
A32: 2025-01-31 | B32: 1 | C32: =CurtailmentData!D32 | D32: =C32*Inputs!C7 | E32: =SOH_Degradation!D3 | F32: =MAX(0, D32-E32) | G32: =MIN(D32, E32) | H32: =IF(E32>0, G32/E32, 0) | I32: =G32*Inputs!C12/100 | J32: =(I32/1000)*(Inputs!C27-Inputs!C28)
A33: 2025-02-01 | B33: 2 | C33: =CurtailmentData!D33 | D33: =C33*Inputs!C7 | E33: =SOH_Degradation!D3 | F33: =MAX(0, D33-E33) | G33: =MIN(D33, E33) | H33: =IF(E33>0, G33/E33, 0) | I33: =G33*Inputs!C12/100 | J33: =(I33/1000)*(Inputs!C27-Inputs!C28)
A34: 2025-02-02 | B34: 2 | C34: =CurtailmentData!D34 | D34: =C34*Inputs!C7 | E34: =SOH_Degradation!D3 | F34: =MAX(0, D34-E34) | G34: =MIN(D34, E34) | H34: =IF(E34>0, G34/E34, 0) | I34: =G34*Inputs!C12/100 | J34: =(I34/1000)*(Inputs!C27-Inputs!C28)
A35: 2025-02-03 | B35: 2 | C35: =CurtailmentData!D35 | D35: =C35*Inputs!C7 | E35: =SOH_Degradation!D3 | F35: =MAX(0, D35-E35) | G35: =MIN(D35, E35) | H35: =IF(E35>0, G35/E35, 0) | I35: =G35*Inputs!C12/100 | J35: =(I35/1000)*(Inputs!C27-Inputs!C28)
A36: 2025-02-04 | B36: 2 | C36: =CurtailmentData!D36 | D36: =C36*Inputs!C7 | E36: =SOH_Degradation!D3 | F36: =MAX(0, D36-E36) | G36: =MIN(D36, E36) | H36: =IF(E36>0, G36/E36, 0) | I36: =G36*Inputs!C12/100 | J36: =(I36/1000)*(Inputs!C27-Inputs!C28)
A37: 2025-02-05 | B37: 2 | C37: =CurtailmentData!D37 | D37: =C37*Inputs!C7 | E37: =SOH_Degradation!D3 | F37: =MAX(0, D37-E37) | G37: =MIN(D37, E37) | H37: =IF(E37>0, G37/E37, 0) | I37: =G37*Inputs!C12/100 | J37: =(I37/1000)*(Inputs!C27-Inputs!C28)
A38: 2025-02-06 | B38: 2 | C38: =CurtailmentData!D38 | D38: =C38*Inputs!C7 | E38: =SOH_Degradation!D3 | F38: =MAX(0, D38-E38) | G38: =MIN(D38, E38) | H38: =IF(E38>0, G38/E38, 0) | I38: =G38*Inputs!C12/100 | J38: =(I38/1000)*(Inputs!C27-Inputs!C28)
A39: 2025-02-07 | B39: 2 | C39: =CurtailmentData!D39 | D39: =C39*Inputs!C7 | E39: =SOH_Degradation!D3 | F39: =MAX(0, D39-E39) | G39: =MIN(D39, E39) | H39: =IF(E39>0, G39/E39, 0) | I39: =G39*Inputs!C12/100 | J39: =(I39/1000)*(Inputs!C27-Inputs!C28)
A40: 2025-02-08 | B40: 2 | C40: =CurtailmentData!D40 | D40: =C40*Inputs!C7 | E40: =SOH_Degradation!D3 | F40: =MAX(0, D40-E40) | G40: =MIN(D40, E40) | H40: =IF(E40>0, G40/E40, 0) | I40: =G40*Inputs!C12/100 | J40: =(I40/1000)*(Inputs!C27-Inputs!C28)
...

Sheet CashFlow
A1: 15-Year Cash Flow Projection - Data-Validated Model
A2: Year | B2: SOH % | C2: Usable MWh | D2: Captured (MWh) | E2: Cumul Cycles | F2: Discharged (MWh) | G2: Gross Revenue (EUR) | H2: Operating Cost (EUR) | I2: Net Cash Flow (EUR) | J2: Cumulative (EUR) | K2: BESS Fill % | L2: Cycles This Year
A3: 0 | G3: Investment: | I3: =-Inputs!C16 | J3: =I3
A4: 1 | B4: =SOH_Degradation!B3 | C4: =SOH_Degradation!C3 | D4: 3755 | E4: 209 | F4: =D4*Inputs!C12/100 | G4: =F4*(Inputs!C27-Inputs!C28)*(1+Inputs!C29/100)^(A4-1) | H4: =Inputs!C22 | I4: =G4-H4 | J4: =J3+I4 | K4: =D4*1000/(C4*1000*365) | L4: =D4/(Inputs!C9*Inputs!C11/100)
A5: 2 | B5: =SOH_Degradation!B4 | C5: =SOH_Degradation!C4 | D5: 3708.4 | E5: 415 | F5: =D5*Inputs!C12/100 | G5: =F5*(Inputs!C27-Inputs!C28)*(1+Inputs!C29/100)^(A5-1) | H5: =Inputs!C22 | I5: =G5-H5 | J5: =J4+I5 | K5: =D5*1000/(C5*1000*365) | L5: =D5/(Inputs!C9*Inputs!C11/100)
A6: 3 | B6: =SOH_Degradation!B5 | C6: =SOH_Degradation!C5 | D6: 3676.5 | E6: 619 | F6: =D6*Inputs!C12/100 | G6: =F6*(Inputs!C27-Inputs!C28)*(1+Inputs!C29/100)^(A6-1) | H6: =Inputs!C22 | I6: =G6-H6 | J6: =J5+I6 | K6: =D6*1000/(C6*1000*365) | L6: =D6/(Inputs!C9*Inputs!C11/100)
A7: 4 | B7: =SOH_Degradation!B6 | C7: =SOH_Degradation!C6 | D7: 3648.5 | E7: 822 | F7: =D7*Inputs!C12/100 | G7: =F7*(Inputs!C27-Inputs!C28)*(1+Inputs!C29/100)^(A7-1) | H7: =Inputs!C22 | I7: =G7-H7 | J7: =J6+I7 | K7: =D7*1000/(C7*1000*365) | L7: =D7/(Inputs!C9*Inputs!C11/100)
A8: 5 | B8: =SOH_Degradation!B7 | C8: =SOH_Degradation!C7 | D8: 3619.8 | E8: 1023 | F8: =D8*Inputs!C12/100 | G8: =F8*(Inputs!C27-Inputs!C28)*(1+Inputs!C29/100)^(A8-1) | H8: =Inputs!C22 | I8: =G8-H8 | J8: =J7+I8 | K8: =D8*1000/(C8*1000*365) | L8: =D8/(Inputs!C9*Inputs!C11/100)
A9: 6 | B9: =SOH_Degradation!B8 | C9: =SOH_Degradation!C8 | D9: 3592.9 | E9: 1222 | F9: =D9*Inputs!C12/100 | G9: =F9*(Inputs!C27-Inputs!C28)*(1+Inputs!C29/100)^(A9-1) | H9: =Inputs!C23 | I9: =G9-H9 | J9: =J8+I9 | K9: =D9*1000/(C9*1000*365) | L9: =D9/(Inputs!C9*Inputs!C11/100)
A10: 7 | B10: =SOH_Degradation!B9 | C10: =SOH_Degradation!C9 | D10: 3565.2 | E10: 1420 | F10: =D10*Inputs!C12/100 | G10: =F10*(Inputs!C27-Inputs!C28)*(1+Inputs!C29/100)^(A10-1) | H10: =Inputs!C23 | I10: =G10-H10 | J10: =J9+I10 | K10: =D10*1000/(C10*1000*365) | L10: =D10/(Inputs!C9*Inputs!C11/100)
A11: 8 | B11: =SOH_Degradation!B10 | C11: =SOH_Degradation!C10 | D11: 3536.3 | E11: 1617 | F11: =D11*Inputs!C12/100 | G11: =F11*(Inputs!C27-Inputs!C28)*(1+Inputs!C29/100)^(A11-1) | H11: =Inputs!C23 | I11: =G11-H11 | J11: =J10+I11 | K11: =D11*1000/(C11*1000*365) | L11: =D11/(Inputs!C9*Inputs!C11/100)
A12: 9 | B12: =SOH_Degradation!B11 | C12: =SOH_Degradation!C11 | D12: 3506.2 | E12: 1812 | F12: =D12*Inputs!C12/100 | G12: =F12*(Inputs!C27-Inputs!C28)*(1+Inputs!C29/100)^(A12-1) | H12: =Inputs!C23 | I12: =G12-H12 | J12: =J11+I12 | K12: =D12*1000/(C12*1000*365) | L12: =D12/(Inputs!C9*Inputs!C11/100)
A13: 10 | B13: =SOH_Degradation!B12 | C13: =SOH_Degradation!C12 | D13: 3475.3 | E13: 2005 | F13: =D13*Inputs!C12/100 | G13: =F13*(Inputs!C27-Inputs!C28)*(1+Inputs!C29/100)^(A13-1) | H13: =Inputs!C23 | I13: =G13-H13 | J13: =J12+I13 | K13: =D13*1000/(C13*1000*365) | L13: =D13/(Inputs!C9*Inputs!C11/100)
A14: 11 | B14: =SOH_Degradation!B13 | C14: =SOH_Degradation!C13 | D14: 3448.1 | E14: 2196 | F14: =D14*Inputs!C12/100 | G14: =F14*(Inputs!C27-Inputs!C28)*(1+Inputs!C29/100)^(A14-1) | H14: =Inputs!C24 | I14: =G14-H14 | J14: =J13+I14 | K14: =D14*1000/(C14*1000*365) | L14: =D14/(Inputs!C9*Inputs!C11/100)
A15: 12 | B15: =SOH_Degradation!B14 | C15: =SOH_Degradation!C14 | D15: 3420.4 | E15: 2386 | F15: =D15*Inputs!C12/100 | G15: =F15*(Inputs!C27-Inputs!C28)*(1+Inputs!C29/100)^(A15-1) | H15: =Inputs!C24 | I15: =G15-H15 | J15: =J14+I15 | K15: =D15*1000/(C15*1000*365) | L15: =D15/(Inputs!C9*Inputs!C11/100)
A16: 13 | B16: =SOH_Degradation!B15 | C16: =SOH_Degradation!C15 | D16: 3391.8 | E16: 2575 | F16: =D16*Inputs!C12/100 | G16: =F16*(Inputs!C27-Inputs!C28)*(1+Inputs!C29/100)^(A16-1) | H16: =Inputs!C24 | I16: =G16-H16 | J16: =J15+I16 | K16: =D16*1000/(C16*1000*365) | L16: =D16/(Inputs!C9*Inputs!C11/100)
A17: 14 | B17: =SOH_Degradation!B16 | C17: =SOH_Degradation!C16 | D17: 3362.7 | E17: 2761 | F17: =D17*Inputs!C12/100 | G17: =F17*(Inputs!C27-Inputs!C28)*(1+Inputs!C29/100)^(A17-1) | H17: =Inputs!C24 | I17: =G17-H17 | J17: =J16+I17 | K17: =D17*1000/(C17*1000*365) | L17: =D17/(Inputs!C9*Inputs!C11/100)
A18: 15 | B18: =SOH_Degradation!B17 | C18: =SOH_Degradation!C17 | D18: 3333 | E18: 2947 | F18: =D18*Inputs!C12/100 | G18: =F18*(Inputs!C27-Inputs!C28)*(1+Inputs!C29/100)^(A18-1) | H18: =Inputs!C24 | I18: =G18-H18 | J18: =J17+I18 | K18: =D18*1000/(C18*1000*365) | L18: =D18/(Inputs!C9*Inputs!C11/100)
A20: TOTALS | D20: =SUM(D4:D18) | F20: =SUM(F4:F18) | G20: =SUM(G4:G18) | H20: =SUM(H4:H18) | I20: =SUM(I4:I18) | L20: =SUM(L4:L18)
