Workbook

Sheet Summary
A1: SHARK FUND
A2: Shapiro & Arkadiusz Renewable Hybrid Assets in Kypros
A3: Financial Plan — Hybrid PV + BESS Investments in Cyprus
A5: FUND OVERVIEW
A6: Target Equity Investment (EUR) | B6: ='Type A - 10MWp'!$B$12*'Type A - 10MWp'!$B$16+'Type B - 5MWp'!$B$12*'Type B - 5MWp'!$B$16+'Type C - 3MWp'!$B$12*'Type C - 3MWp'!$B$16 -> 50074389
A7: Total Debt (EUR) | B7: ='Type A - 10MWp'!$B$13*'Type A - 10MWp'!$B$16+'Type B - 5MWp'!$B$13*'Type B - 5MWp'!$B$16+'Type C - 3MWp'!$B$13*'Type C - 3MWp'!$B$16 -> 22578534
A8: Total CAPEX (EUR) | B8: =B6+B7 -> 72652923
A9: Project Lifetime | B9: =Assumptions!$B$7 -> 20
A10: PV Financing | B10: 100% Equity
A11: BESS Financing | B11: 100% Debt (LTV)
A12: Loan Interest Rate | B12: =Assumptions!$B$38 -> 0.05
A13: Loan Term (years) | B13: =Assumptions!$B$39 -> 15
A14: Corporate Tax Rate | B14: =Assumptions!$B$35 -> 0.125
A16: PORTFOLIO COMPOSITION
A17: Asset Type | B17: Size | C17: Units | D17: Equity/Unit | E17: Debt/Unit | F17: Total Equity | G17: Total Debt | H17: Total CAPEX
A18: Type A: Large Hybrid Park | B18: 10 MWp + 40 MWh | C18: ='Type A - 10MWp'!$B$16 -> 3 | D18: ='Type A - 10MWp'!$B$12 -> 8600770 | E18: ='Type A - 10MWp'!$B$13 -> 3740967 | F18: ='Type A - 10MWp'!$B$12*'Type A - 10MWp'!$B$16 -> 25802310 | G18: ='Type A - 10MWp'!$B$13*'Type A - 10MWp'!$B$16 -> 11222901 | H18: =('Type A - 10MWp'!$B$12+'Type A - 10MWp'!$B$13)*'Type A - 10MWp'!$B$16 -> 37025211
A19: Type B: Medium Hybrid Park | B19: 5 MWp + 20 MWh | C19: ='Type B - 5MWp'!$B$16 -> 3 | D19: ='Type B - 5MWp'!$B$12 -> 4450385 | E19: ='Type B - 5MWp'!$B$13 -> 1919179 | F19: ='Type B - 5MWp'!$B$12*'Type B - 5MWp'!$B$16 -> 13351155 | G19: ='Type B - 5MWp'!$B$13*'Type B - 5MWp'!$B$16 -> 5757537 | H19: =('Type B - 5MWp'!$B$12+'Type B - 5MWp'!$B$13)*'Type B - 5MWp'!$B$16 -> 19108692
A20: Type C: Small Hybrid Park | B20: 3 MWp + 12 MWh | C20: ='Type C - 3MWp'!$B$16 -> 4 | D20: ='Type C - 3MWp'!$B$12 -> 2730231 | E20: ='Type C - 3MWp'!$B$13 -> 1399524 | F20: ='Type C - 3MWp'!$B$12*'Type C - 3MWp'!$B$16 -> 10920924 | G20: ='Type C - 3MWp'!$B$13*'Type C - 3MWp'!$B$16 -> 5598096 | H20: =('Type C - 3MWp'!$B$12+'Type C - 3MWp'!$B$13)*'Type C - 3MWp'!$B$16 -> 16519020
A21: TOTAL PORTFOLIO | C21: =SUM(C18:C20) -> 10 | F21: =SUM(F18:F20) -> 50074389 | G21: =SUM(G18:G20) -> 22578534 | H21: =SUM(H18:H20) -> 72652923
A23: FUND RETURNS BY SCENARIO
A24: Metric | B24: Low (EUR 110/MWh) | C24: Base (EUR 150/MWh) | D24: High (EUR 175/MWh)
A25: Fund Equity IRR | B25: ='Fund Portfolio'!B$36 -> 0.15343254 | C25: ='Fund Portfolio'!C$36 -> 0.19992856 | D25: ='Fund Portfolio'!D$36 -> 0.22836614
A26: Fund Equity NPV (@ 8%) | B26: ='Fund Portfolio'!B$37 -> 28742746 | C26: ='Fund Portfolio'!C$37 -> 48115675 | D26: ='Fund Portfolio'!D$37 -> 60223755
A27: Fund Equity Multiple | B27: ='Fund Portfolio'!B$38 -> 3.1665199 | C27: ='Fund Portfolio'!C$38 -> 3.9251737 | D27: ='Fund Portfolio'!D$38 -> 4.3993322
A28: Fund Total FCFE | B28: ='Fund Portfolio'!B$39 -> 1.5856155e+08 | C28: ='Fund Portfolio'!C$39 -> 1.9655067e+08 | D28: ='Fund Portfolio'!D$39 -> 2.2029387e+08

Sheet Assumptions
A1: SHARK Fund — Assumptions & Inputs
A2: Change the blue-highlighted cells to update the entire model automatically.
A4: GENERAL ASSUMPTIONS
A5: RTB Acquisition Cost (EUR/MWp) | B5: 350000 | C5: Ready-to-build permit cost
A6: BESS Duration (hours) | B6: 4 | C6: 4-hour BESS sizing
A7: Project Lifetime (years) | B7: 20 | C7: Operational years
A9: PV ASSUMPTIONS
A10: PV Annual Yield (MWh/MWp) | B10: 1750 | C10: Cyprus fixed-tilt
A11: PV Degradation — Year 1 | B11: 0.025 | C11: 2.5% first year
A12: PV Degradation — Year 2 onwards | B12: 0.005 | C12: 0.5% per year
A13: PV Curtailment Rate | B13: 0.5 | C13: 50% of PV output curtailed / used by BESS
A14: PV Direct Sale Price (EUR/MWh) | B14: 160 | C14: PPA or market rate
A15: GoO Price (EUR/MWh) | B15: 1 | C15: Guarantees of Origin
A16: PV OPEX — all-in (EUR/MWp/year) | B16: 15000 | C16: O&M, insurance, admin, CERA PV, rent
A18: BESS ASSUMPTIONS
A19: BESS Round-Trip Efficiency (RTE) | B19: 0.863 | C19: DC RTE incl. losses
A20: BESS Initial State of Health | B20: 0.985 | C20: BOL capacity
A21: BESS Annual SOH Degradation | B21: 0.0135 | C21: Linear approx.
A22: BESS Depth of Discharge (DoD) | B22: 0.9
A23: BESS System Availability | B23: 0.98 | C23: Warranted
A24: BESS Cycles Per Day | B24: 1
A25: BESS Grid Purchase Price (EUR/MWh) | B25: 50 | C25: Cost to charge from grid
A26: BESS O&M (EUR/MWh installed/yr) | B26: 1750 | C26: Includes CERA, grounds, monitoring
A27: BESS Management Fee (EUR/MWh installed/yr) | B27: 1500 | C27: Asset management
A28: CERA BESS License (EUR/MW/yr) | B28: 700
A29: BESS Grounds Maintenance (EUR/site/yr) | B29: 4000 | C29: Security, landscaping
A30: Warranty Extension Yr 6-10 (EUR/MWh/yr) | B30: 1800
A31: Warranty Extension Yr 11-15 (EUR/MWh/yr) | B31: 2100
A32: Warranty Extension Yr 16-20 (EUR/MWh/yr) | B32: 2450
A34: FINANCIAL ASSUMPTIONS
A35: Corporate Tax Rate (Cyprus) | B35: 0.125 | C35: 12.5%
A36: Annual OPEX Inflation | B36: 0.01 | C36: 1%
A37: Discount Rate (for NPV) | B37: 0.08 | C37: 8% WACC
A38: Loan Interest Rate | B38: 0.05 | C38: Cyprus commercial
A39: Loan Term (years) | B39: 15 | C39: Senior debt
A41: REVENUE SCENARIOS ASSUMPTIONS
A42: BESS Arbitrage Price — Low (EUR/MWh) | B42: 110 | C42: Conservative
A43: BESS Arbitrage Price — Base (EUR/MWh) | B43: 150 | C43: Blended average
A44: BESS Arbitrage Price — High (EUR/MWh) | B44: 175 | C44: Strong prediction
A46: EPC SELF-COST REFERENCE (from Solarfarms.cy model)
...

Sheet Type A - 10MWp
A1: SHARK — Type A: Large Hybrid Park
A2: 10 MWp + 40 MWh Hybrid Park — Per-Unit Financial Model
A4: CAPEX & FINANCING
A5: PV Capacity (MWp) | B5: 10
A6: BESS Capacity (MWh) | B6: 40
A7: BESS Power (MW) | B7: =B6/Assumptions!$B$6 -> 10
A8: PV EPC Self-Cost (EUR) | B8: 5100770
A9: RTB Acquisition (EUR) | B9: =B5*Assumptions!$B$5 -> 3500000
A10: BESS Installed Cost (EUR) | B10: 3740967
A11: Total CAPEX (EUR) | B11: =B8+B9+B10 -> 12341737
A12: Equity (PV + RTB) | B12: =B8+B9 -> 8600770
A13: Debt (BESS — 100% LTV) | B13: =B10 -> 3740967
A14: Annual Debt Service | B14: =-PMT(Assumptions!$B$38,Assumptions!$B$39,B13) -> 360413.32
A15: Annual Depreciation (SL) | B15: =B11/Assumptions!$B$7 -> 617086.85
A16: Units in Portfolio | B16: 3
A18: ANNUAL PRODUCTION & TECHNICAL DATA
A19: Year # | C19: 1 | D19: 2 | E19: 3 | F19: 4 | G19: 5 | H19: 6 | I19: 7 | J19: 8 | K19: 9 | L19: 10 | M19: 11 | N19: 12 | O19: 13 | P19: 14 | Q19: 15 | R19: 16 | S19: 17 | T19: 18 | U19: 19 | V19: 20 | W19: Total/Avg
A20: Calendar | C20: 2026 | D20: 2027 | E20: 2028 | F20: 2029 | G20: 2030 | H20: 2031 | I20: 2032 | J20: 2033 | K20: 2034 | L20: 2035 | M20: 2036 | N20: 2037 | O20: 2038 | P20: 2039 | Q20: 2040 | R20: 2041 | S20: 2042 | T20: 2043 | U20: 2044 | V20: 2045
A21: PV Production (MWh) | C21: =IF(C$19=1,$B$5*Assumptions!$B$10*(1-Assumptions!$B$11),$B$5*Assumptions!$B$10*(1-Assumptions!$B$11)*(1-Assumptions!$B$12)^(C$19-1)) -> 17062.5 | D21: =IF(D$19=1,$B$5*Assumptions!$B$10*(1-Assumptions!$B$11),$B$5*Assumptions!$B$10*(1-Assumptions!$B$11)*(1-Assumptions!$B$12)^(D$19-1)) -> 16977.188 | E21: =IF(E$19=1,$B$5*Assumptions!$B$10*(1-Assumptions!$B$11),$B$5*Assumptions!$B$10*(1-Assumptions!$B$11)*(1-Assumptions!$B$12)^(E$19-1)) -> 16892.302 | F21: =IF(F$19=1,$B$5*Assumptions!$B$10*(1-Assumptions!$B$11),$B$5*Assumptions!$B$10*(1-Assumptions!$B$11)*(1-Assumptions!$B$12)^(F$19-1)) -> 16807.84 | G21: =IF(G$19=1,$B$5*Assumptions!$B$10*(1-Assumptions!$B$11),$B$5*Assumptions!$B$10*(1-Assumptions!$B$11)*(1-Assumptions!$B$12)^(G$19-1)) -> 16723.801 | H21: =IF(H$19=1,$B$5*Assumptions!$B$10*(1-Assumptions!$B$11),$B$5*Assumptions!$B$10*(1-Assumptions!$B$11)*(1-Assumptions!$B$12)^(H$19-1)) -> 16640.182 | I21: =IF(I$19=1,$B$5*Assumptions!$B$10*(1-Assumptions!$B$11),$B$5*Assumptions!$B$10*(1-Assumptions!$B$11)*(1-Assumptions!$B$12)^(I$19-1)) -> 16556.981 | J21: =IF(J$19=1,$B$5*Assumptions!$B$10*(1-Assumptions!$B$11),$B$5*Assumptions!$B$10*(1-Assumptions!$B$11)*(1-Assumptions!$B$12)^(J$19-1)) -> 16474.196 | ... V21: =IF(V$19=1,$B$5*Assumptions!$B$10*(1-Assumptions!$B$11),$B$5*Assumptions!$B$10*(1-Assumptions!$B$11)*(1-Assumptions!$B$12)^(V$19-1)) -> 15512.479 | W21: =SUM(C$21:V$21) -> 325516.74
A22: PV Direct Sales (MWh) | C22: =C$21*(1-Assumptions!$B$13) -> 8531.25 | D22: =D$21*(1-Assumptions!$B$13) -> 8488.5938 | E22: =E$21*(1-Assumptions!$B$13) -> 8446.1508 | F22: =F$21*(1-Assumptions!$B$13) -> 8403.92 | G22: =G$21*(1-Assumptions!$B$13) -> 8361.9004 | H22: =H$21*(1-Assumptions!$B$13) -> 8320.0909 | I22: =I$21*(1-Assumptions!$B$13) -> 8278.4905 | J22: =J$21*(1-Assumptions!$B$13) -> 8237.098 | ... V22: =V$21*(1-Assumptions!$B$13) -> 7756.2394 | W22: =SUM(C$22:V$22) -> 162758.37
A23: PV Curtailed → BESS (MWh) | C23: =C$21*Assumptions!$B$13 -> 8531.25 | D23: =D$21*Assumptions!$B$13 -> 8488.5938 | E23: =E$21*Assumptions!$B$13 -> 8446.1508 | F23: =F$21*Assumptions!$B$13 -> 8403.92 | G23: =G$21*Assumptions!$B$13 -> 8361.9004 | H23: =H$21*Assumptions!$B$13 -> 8320.0909 | I23: =I$21*Assumptions!$B$13 -> 8278.4905 | J23: =J$21*Assumptions!$B$13 -> 8237.098 | ... V23: =V$21*Assumptions!$B$13 -> 7756.2394 | W23: =SUM(C$23:V$23) -> 162758.37
A24: BESS State of Health (%) | C24: =MAX(0.6,Assumptions!$B$20-Assumptions!$B$21*(C$19-1)) -> 0.985 | D24: =MAX(0.6,Assumptions!$B$20-Assumptions!$B$21*(D$19-1)) -> 0.9715 | E24: =MAX(0.6,Assumptions!$B$20-Assumptions!$B$21*(E$19-1)) -> 0.958 | F24: =MAX(0.6,Assumptions!$B$20-Assumptions!$B$21*(F$19-1)) -> 0.9445 | G24: =MAX(0.6,Assumptions!$B$20-Assumptions!$B$21*(G$19-1)) -> 0.931 | H24: =MAX(0.6,Assumptions!$B$20-Assumptions!$B$21*(H$19-1)) -> 0.9175 | I24: =MAX(0.6,Assumptions!$B$20-Assumptions!$B$21*(I$19-1)) -> 0.904 | J24: =MAX(0.6,Assumptions!$B$20-Assumptions!$B$21*(J$19-1)) -> 0.8905 | ... V24: =MAX(0.6,Assumptions!$B$20-Assumptions!$B$21*(V$19-1)) -> 0.7285 | W24: =AVERAGE(C$24:V$24) -> 0.85675
A25: BESS Sellable Energy (MWh) | C25: =$B$6*C$24*Assumptions!$B$22*Assumptions!$B$19*Assumptions!$B$24*365*Assumptions!$B$23 -> 10946.328 | D25: =$B$6*D$24*Assumptions!$B$22*Assumptions!$B$19*Assumptions!$B$24*365*Assumptions!$B$23 -> 10796.302 | E25: =$B$6*E$24*Assumptions!$B$22*Assumptions!$B$19*Assumptions!$B$24*365*Assumptions!$B$23 -> 10646.277 | F25: =$B$6*F$24*Assumptions!$B$22*Assumptions!$B$19*Assumptions!$B$24*365*Assumptions!$B$23 -> 10496.251 | G25: =$B$6*G$24*Assumptions!$B$22*Assumptions!$B$19*Assumptions!$B$24*365*Assumptions!$B$23 -> 10346.225 | H25: =$B$6*H$24*Assumptions!$B$22*Assumptions!$B$19*Assumptions!$B$24*365*Assumptions!$B$23 -> 10196.199 | I25: =$B$6*I$24*Assumptions!$B$22*Assumptions!$B$19*Assumptions!$B$24*365*Assumptions!$B$23 -> 10046.173 | J25: =$B$6*J$24*Assumptions!$B$22*Assumptions!$B$19*Assumptions!$B$24*365*Assumptions!$B$23 -> 9896.1475 | ... V25: =$B$6*V$24*Assumptions!$B$22*Assumptions!$B$19*Assumptions!$B$24*365*Assumptions!$B$23 -> 8095.8377 | W25: =SUM(C$25:V$25) -> 190421.66
A26: BESS Charging Needed (MWh) | C26: =$B$6*C$24*Assumptions!$B$22*Assumptions!$B$24*365*Assumptions!$B$23 -> 12684.042 | D26: =$B$6*D$24*Assumptions!$B$22*Assumptions!$B$24*365*Assumptions!$B$23 -> 12510.2 | E26: =$B$6*E$24*Assumptions!$B$22*Assumptions!$B$24*365*Assumptions!$B$23 -> 12336.358 | F26: =$B$6*F$24*Assumptions!$B$22*Assumptions!$B$24*365*Assumptions!$B$23 -> 12162.515 | G26: =$B$6*G$24*Assumptions!$B$22*Assumptions!$B$24*365*Assumptions!$B$23 -> 11988.673 | H26: =$B$6*H$24*Assumptions!$B$22*Assumptions!$B$24*365*Assumptions!$B$23 -> 11814.831 | I26: =$B$6*I$24*Assumptions!$B$22*Assumptions!$B$24*365*Assumptions!$B$23 -> 11640.989 | J26: =$B$6*J$24*Assumptions!$B$22*Assumptions!$B$24*365*Assumptions!$B$23 -> 11467.147 | ... V26: =$B$6*V$24*Assumptions!$B$22*Assumptions!$B$24*365*Assumptions!$B$23 -> 9381.0402 | W26: =SUM(C$26:V$26) -> 220650.82
A27: Grid Purchases for BESS (MWh) | C27: =MAX(0,C$26-C$23) -> 4152.792 | D27: =MAX(0,D$26-D$23) -> 4021.606 | E27: =MAX(0,E$26-E$23) -> 3890.2068 | F27: =MAX(0,F$26-F$23) -> 3758.5954 | G27: =MAX(0,G$26-G$23) -> 3626.7728 | H27: =MAX(0,H$26-H$23) -> 3494.7401 | I27: =MAX(0,I$26-I$23) -> 3362.4983 | J27: =MAX(0,J$26-J$23) -> 3230.0486 | ... V27: =MAX(0,V$26-V$23) -> 1624.8008 | W27: =SUM(C$27:V$27) -> 57892.454
A29: SCENARIO: LOW CASE (EUR 110/MWh)
A30: PV Direct Revenue | C30: =C$22*Assumptions!$B$14 -> 1365000 | D30: =D$22*Assumptions!$B$14 -> 1358175 | E30: =E$22*Assumptions!$B$14 -> 1351384.1 | F30: =F$22*Assumptions!$B$14 -> 1344627.2 | G30: =G$22*Assumptions!$B$14 -> 1337904.1 | H30: =H$22*Assumptions!$B$14 -> 1331214.5 | I30: =I$22*Assumptions!$B$14 -> 1324558.5 | J30: =J$22*Assumptions!$B$14 -> 1317935.7 | ... V30: =V$22*Assumptions!$B$14 -> 1240998.3 | W30: =SUM(C$30:V$30) -> 26041339
A31: GoO Revenue | C31: =C$21*Assumptions!$B$15 -> 17062.5 | D31: =D$21*Assumptions!$B$15 -> 16977.188 | E31: =E$21*Assumptions!$B$15 -> 16892.302 | F31: =F$21*Assumptions!$B$15 -> 16807.84 | G31: =G$21*Assumptions!$B$15 -> 16723.801 | H31: =H$21*Assumptions!$B$15 -> 16640.182 | I31: =I$21*Assumptions!$B$15 -> 16556.981 | J31: =J$21*Assumptions!$B$15 -> 16474.196 | ... V31: =V$21*Assumptions!$B$15 -> 15512.479 | W31: =SUM(C$31:V$31) -> 325516.74
A32: BESS Arbitrage Revenue | C32: =C$25*Assumptions!$B$42 -> 1204096.1 | D32: =D$25*Assumptions!$B$42 -> 1187593.3 | E32: =E$25*Assumptions!$B$42 -> 1171090.4 | F32: =F$25*Assumptions!$B$42 -> 1154587.6 | G32: =G$25*Assumptions!$B$42 -> 1138084.7 | H32: =H$25*Assumptions!$B$42 -> 1121581.9 | I32: =I$25*Assumptions!$B$42 -> 1105079.1 | J32: =J$25*Assumptions!$B$42 -> 1088576.2 | ... V32: =V$25*Assumptions!$B$42 -> 890542.15 | W32: =SUM(C$32:V$32) -> 20946383
A33: Total Revenue | C33: =C$30+C$31+C$32 -> 2586158.6 | D33: =D$30+D$31+D$32 -> 2562745.5 | E33: =E$30+E$31+E$32 -> 2539366.9 | F33: =F$30+F$31+F$32 -> 2516022.6 | G33: =G$30+G$31+G$32 -> 2492712.6 | H33: =H$30+H$31+H$32 -> 2469436.6 | I33: =I$30+I$31+I$32 -> 2446194.5 | J33: =J$30+J$31+J$32 -> 2422986.1 | ... V33: =V$30+V$31+V$32 -> 2147052.9 | W33: =SUM(C$33:V$33) -> 47313238
A34: Energy Purchase Cost | C34: =C$27*Assumptions!$B$25*(1+Assumptions!$B$36)^(C$19-1) -> 207639.6 | D34: =D$27*Assumptions!$B$25*(1+Assumptions!$B$36)^(D$19-1) -> 203091.11 | E34: =E$27*Assumptions!$B$25*(1+Assumptions!$B$36)^(E$19-1) -> 198420 | F34: =F$27*Assumptions!$B$25*(1+Assumptions!$B$36)^(F$19-1) -> 193624.23 | G34: =G$27*Assumptions!$B$25*(1+Assumptions!$B$36)^(G$19-1) -> 188701.71 | H34: =H$27*Assumptions!$B$25*(1+Assumptions!$B$36)^(H$19-1) -> 183650.35 | I34: =I$27*Assumptions!$B$25*(1+Assumptions!$B$36)^(I$19-1) -> 178467.99 | J34: =J$27*Assumptions!$B$25*(1+Assumptions!$B$36)^(J$19-1) -> 173152.46 | ... V34: =V$27*Assumptions!$B$25*(1+Assumptions!$B$36)^(V$19-1) -> 98146.822 | W34: =SUM(C$34:V$34) -> 3138396.7
A35: PV OPEX | C35: =$B$5*Assumptions!$B$16*(1+Assumptions!$B$36)^(C$19-1) -> 150000 | D35: =$B$5*Assumptions!$B$16*(1+Assumptions!$B$36)^(D$19-1) -> 151500 | E35: =$B$5*Assumptions!$B$16*(1+Assumptions!$B$36)^(E$19-1) -> 153015 | F35: =$B$5*Assumptions!$B$16*(1+Assumptions!$B$36)^(F$19-1) -> 154545.15 | G35: =$B$5*Assumptions!$B$16*(1+Assumptions!$B$36)^(G$19-1) -> 156090.6 | H35: =$B$5*Assumptions!$B$16*(1+Assumptions!$B$36)^(H$19-1) -> 157651.51 | I35: =$B$5*Assumptions!$B$16*(1+Assumptions!$B$36)^(I$19-1) -> 159228.02 | J35: =$B$5*Assumptions!$B$16*(1+Assumptions!$B$36)^(J$19-1) -> 160820.3 | ... V35: =$B$5*Assumptions!$B$16*(1+Assumptions!$B$36)^(V$19-1) -> 181216.34 | W35: =SUM(C$35:V$35) -> 3302850.6
A36: BESS OPEX (O&M+Mgmt+CERA+Grounds) | C36: =($B$6*Assumptions!$B$26+$B$6*Assumptions!$B$27+$B$7*Assumptions!$B$28+Assumptions!$B$29)*(1+Assumptions!$B$36)^(C$19-1) -> 141000 | D36: =($B$6*Assumptions!$B$26+$B$6*Assumptions!$B$27+$B$7*Assumptions!$B$28+Assumptions!$B$29)*(1+Assumptions!$B$36)^(D$19-1) -> 142410 | E36: =($B$6*Assumptions!$B$26+$B$6*Assumptions!$B$27+$B$7*Assumptions!$B$28+Assumptions!$B$29)*(1+Assumptions!$B$36)^(E$19-1) -> 143834.1 | F36: =($B$6*Assumptions!$B$26+$B$6*Assumptions!$B$27+$B$7*Assumptions!$B$28+Assumptions!$B$29)*(1+Assumptions!$B$36)^(F$19-1) -> 145272.44 | G36: =($B$6*Assumptions!$B$26+$B$6*Assumptions!$B$27+$B$7*Assumptions!$B$28+Assumptions!$B$29)*(1+Assumptions!$B$36)^(G$19-1) -> 146725.17 | H36: =($B$6*Assumptions!$B$26+$B$6*Assumptions!$B$27+$B$7*Assumptions!$B$28+Assumptions!$B$29)*(1+Assumptions!$B$36)^(H$19-1) -> 148192.42 | I36: =($B$6*Assumptions!$B$26+$B$6*Assumptions!$B$27+$B$7*Assumptions!$B$28+Assumptions!$B$29)*(1+Assumptions!$B$36)^(I$19-1) -> 149674.34 | J36: =($B$6*Assumptions!$B$26+$B$6*Assumptions!$B$27+$B$7*Assumptions!$B$28+Assumptions!$B$29)*(1+Assumptions!$B$36)^(J$19-1) -> 151171.08 | ... V36: =($B$6*Assumptions!$B$26+$B$6*Assumptions!$B$27+$B$7*Assumptions!$B$28+Assumptions!$B$29)*(1+Assumptions!$B$36)^(V$19-1) -> 170343.36 | W36: =SUM(C$36:V$36) -> 3104679.6
A37: BESS Warranty Extension | C37: =IF(C$19<=5,0,IF(C$19<=10,Assumptions!$B$30,IF(C$19<=15,Assumptions!$B$31,Assumptions!$B$32)))*$B$6*(1+Assumptions!$B$36)^(C$19-1) -> 0 | D37: =IF(D$19<=5,0,IF(D$19<=10,Assumptions!$B$30,IF(D$19<=15,Assumptions!$B$31,Assumptions!$B$32)))*$B$6*(1+Assumptions!$B$36)^(D$19-1) -> 0 | E37: =IF(E$19<=5,0,IF(E$19<=10,Assumptions!$B$30,IF(E$19<=15,Assumptions!$B$31,Assumptions!$B$32)))*$B$6*(1+Assumptions!$B$36)^(E$19-1) -> 0 | F37: =IF(F$19<=5,0,IF(F$19<=10,Assumptions!$B$30,IF(F$19<=15,Assumptions!$B$31,Assumptions!$B$32)))*$B$6*(1+Assumptions!$B$36)^(F$19-1) -> 0 | G37: =IF(G$19<=5,0,IF(G$19<=10,Assumptions!$B$30,IF(G$19<=15,Assumptions!$B$31,Assumptions!$B$32)))*$B$6*(1+Assumptions!$B$36)^(G$19-1) -> 0 | H37: =IF(H$19<=5,0,IF(H$19<=10,Assumptions!$B$30,IF(H$19<=15,Assumptions!$B$31,Assumptions!$B$32)))*$B$6*(1+Assumptions!$B$36)^(H$19-1) -> 75672.724 | I37: =IF(I$19<=5,0,IF(I$19<=10,Assumptions!$B$30,IF(I$19<=15,Assumptions!$B$31,Assumptions!$B$32)))*$B$6*(1+Assumptions!$B$36)^(I$19-1) -> 76429.451 | J37: =IF(J$19<=5,0,IF(J$19<=10,Assumptions!$B$30,IF(J$19<=15,Assumptions!$B$31,Assumptions!$B$32)))*$B$6*(1+Assumptions!$B$36)^(J$19-1) -> 77193.745 | ... V37: =IF(V$19<=5,0,IF(V$19<=10,Assumptions!$B$30,IF(V$19<=15,Assumptions!$B$31,Assumptions!$B$32)))*$B$6*(1+Assumptions!$B$36)^(V$19-1) -> 118394.68 | W37: =SUM(C$37:V$37) -> 1439686.9
A38: Total Operating Costs | C38: =C$34+C$35+C$36+C$37 -> 498639.6 | D38: =D$34+D$35+D$36+D$37 -> 497001.11 | E38: =E$34+E$35+E$36+E$37 -> 495269.1 | F38: =F$34+F$35+F$36+F$37 -> 493441.82 | G38: =G$34+G$35+G$36+G$37 -> 491517.48 | H38: =H$34+H$35+H$36+H$37 -> 565167 | I38: =I$34+I$35+I$36+I$37 -> 563799.8 | J38: =J$34+J$35+J$36+J$37 -> 562337.6 | ... V38: =V$34+V$35+V$36+V$37 -> 568101.2 | W38: =SUM(C$38:V$38) -> 10985614
A39: EBITDA | C39: =C$33-C$38 -> 2087519 | D39: =D$33-D$38 -> 2065744.3 | E39: =E$33-E$38 -> 2044097.8 | F39: =F$33-F$38 -> 2022580.8 | G39: =G$33-G$38 -> 2001195.1 | H39: =H$33-H$38 -> 1904269.6 | I39: =I$33-I$38 -> 1882394.7 | J39: =J$33-J$38 -> 1860648.5 | ... V39: =V$33-V$38 -> 1578951.7 | W39: =SUM(C$39:V$39) -> 36327624
A40: Depreciation | C40: =$B$15 -> 617086.85 | D40: =$B$15 -> 617086.85 | E40: =$B$15 -> 617086.85 | F40: =$B$15 -> 617086.85 | G40: =$B$15 -> 617086.85 | H40: =$B$15 -> 617086.85 | I40: =$B$15 -> 617086.85 | J40: =$B$15 -> 617086.85 | ... V40: =$B$15 -> 617086.85 | W40: =SUM(C$40:V$40) -> 12341737
A41: Interest Expense | C41: =IF(C$19<=Assumptions!$B$39,-IPMT(Assumptions!$B$38,C$19,Assumptions!$B$39,$B$13),0) -> 187048.35 | D41: =IF(D$19<=Assumptions!$B$39,-IPMT(Assumptions!$B$38,D$19,Assumptions!$B$39,$B$13),0) -> 178380.1 | E41: =IF(E$19<=Assumptions!$B$39,-IPMT(Assumptions!$B$38,E$19,Assumptions!$B$39,$B$13),0) -> 169278.44 | F41: =IF(F$19<=Assumptions!$B$39,-IPMT(Assumptions!$B$38,F$19,Assumptions!$B$39,$B$13),0) -> 159721.7 | G41: =IF(G$19<=Assumptions!$B$39,-IPMT(Assumptions!$B$38,G$19,Assumptions!$B$39,$B$13),0) -> 149687.12 | H41: =IF(H$19<=Assumptions!$B$39,-IPMT(Assumptions!$B$38,H$19,Assumptions!$B$39,$B$13),0) -> 139150.81 | I41: =IF(I$19<=Assumptions!$B$39,-IPMT(Assumptions!$B$38,I$19,Assumptions!$B$39,$B$13),0) -> 128087.68 | J41: =IF(J$19<=Assumptions!$B$39,-IPMT(Assumptions!$B$38,J$19,Assumptions!$B$39,$B$13),0) -> 116471.4 | ... V41: =IF(V$19<=Assumptions!$B$39,-IPMT(Assumptions!$B$38,V$19,Assumptions!$B$39,$B$13),0) -> 0 | W41: =SUM(C$41:V$41) -> 1665232.8
A42: Earnings Before Tax | C42: =C$39-C$40-C$41 -> 1283383.8 | D42: =D$39-D$40-D$41 -> 1270277.4 | E42: =E$39-E$40-E$41 -> 1257732.5 | F42: =F$39-F$40-F$41 -> 1245772.3 | G42: =G$39-G$40-G$41 -> 1234421.2 | H42: =H$39-H$40-H$41 -> 1148032 | I42: =I$39-I$40-I$41 -> 1137220.2 | J42: =J$39-J$40-J$41 -> 1127090.3 | ... V42: =V$39-V$40-V$41 -> 961864.87 | W42: =SUM(C$42:V$42) -> 22320655
A43: Corporate Tax (12.5%) | C43: =MAX(0,C$42*Assumptions!$B$35) -> 160422.98 | D43: =MAX(0,D$42*Assumptions!$B$35) -> 158784.67 | E43: =MAX(0,E$42*Assumptions!$B$35) -> 157216.56 | F43: =MAX(0,F$42*Assumptions!$B$35) -> 155721.53 | G43: =MAX(0,G$42*Assumptions!$B$35) -> 154302.65 | H43: =MAX(0,H$42*Assumptions!$B$35) -> 143504 | I43: =MAX(0,I$42*Assumptions!$B$35) -> 142152.52 | J43: =MAX(0,J$42*Assumptions!$B$35) -> 140886.28 | ... V43: =MAX(0,V$42*Assumptions!$B$35) -> 120233.11 | W43: =SUM(C$43:V$43) -> 2790081.8
...

Sheet Type B - 5MWp
A1: SHARK — Type B: Medium Hybrid Park
A2: 5 MWp + 20 MWh Hybrid Park — Per-Unit Financial Model
A4: CAPEX & FINANCING
A5: PV Capacity (MWp) | B5: 5
A6: BESS Capacity (MWh) | B6: 20
A7: BESS Power (MW) | B7: =B6/Assumptions!$B$6 -> 5
A8: PV EPC Self-Cost (EUR) | B8: 2700385
A9: RTB Acquisition (EUR) | B9: =B5*Assumptions!$B$5 -> 1750000
A10: BESS Installed Cost (EUR) | B10: 1919179
A11: Total CAPEX (EUR) | B11: =B8+B9+B10 -> 6369564
A12: Equity (PV + RTB) | B12: =B8+B9 -> 4450385
A13: Debt (BESS — 100% LTV) | B13: =B10 -> 1919179
A14: Annual Debt Service | B14: =-PMT(Assumptions!$B$38,Assumptions!$B$39,B13) -> 184898.1
A15: Annual Depreciation (SL) | B15: =B11/Assumptions!$B$7 -> 318478.2
A16: Units in Portfolio | B16: 3
A18: ANNUAL PRODUCTION & TECHNICAL DATA
A19: Year # | C19: 1 | D19: 2 | E19: 3 | F19: 4 | G19: 5 | H19: 6 | I19: 7 | J19: 8 | K19: 9 | L19: 10 | M19: 11 | N19: 12 | O19: 13 | P19: 14 | Q19: 15 | R19: 16 | S19: 17 | T19: 18 | U19: 19 | V19: 20 | W19: Total/Avg
A20: Calendar | C20: 2026 | D20: 2027 | E20: 2028 | F20: 2029 | G20: 2030 | H20: 2031 | I20: 2032 | J20: 2033 | K20: 2034 | L20: 2035 | M20: 2036 | N20: 2037 | O20: 2038 | P20: 2039 | Q20: 2040 | R20: 2041 | S20: 2042 | T20: 2043 | U20: 2044 | V20: 2045
A21: PV Production (MWh) | C21: =IF(C$19=1,$B$5*Assumptions!$B$10*(1-Assumptions!$B$11),$B$5*Assumptions!$B$10*(1-Assumptions!$B$11)*(1-Assumptions!$B$12)^(C$19-1)) -> 8531.25 | D21: =IF(D$19=1,$B$5*Assumptions!$B$10*(1-Assumptions!$B$11),$B$5*Assumptions!$B$10*(1-Assumptions!$B$11)*(1-Assumptions!$B$12)^(D$19-1)) -> 8488.5938 | E21: =IF(E$19=1,$B$5*Assumptions!$B$10*(1-Assumptions!$B$11),$B$5*Assumptions!$B$10*(1-Assumptions!$B$11)*(1-Assumptions!$B$12)^(E$19-1)) -> 8446.1508 | F21: =IF(F$19=1,$B$5*Assumptions!$B$10*(1-Assumptions!$B$11),$B$5*Assumptions!$B$10*(1-Assumptions!$B$11)*(1-Assumptions!$B$12)^(F$19-1)) -> 8403.92 | G21: =IF(G$19=1,$B$5*Assumptions!$B$10*(1-Assumptions!$B$11),$B$5*Assumptions!$B$10*(1-Assumptions!$B$11)*(1-Assumptions!$B$12)^(G$19-1)) -> 8361.9004 | H21: =IF(H$19=1,$B$5*Assumptions!$B$10*(1-Assumptions!$B$11),$B$5*Assumptions!$B$10*(1-Assumptions!$B$11)*(1-Assumptions!$B$12)^(H$19-1)) -> 8320.0909 | I21: =IF(I$19=1,$B$5*Assumptions!$B$10*(1-Assumptions!$B$11),$B$5*Assumptions!$B$10*(1-Assumptions!$B$11)*(1-Assumptions!$B$12)^(I$19-1)) -> 8278.4905 | J21: =IF(J$19=1,$B$5*Assumptions!$B$10*(1-Assumptions!$B$11),$B$5*Assumptions!$B$10*(1-Assumptions!$B$11)*(1-Assumptions!$B$12)^(J$19-1)) -> 8237.098 | ... V21: =IF(V$19=1,$B$5*Assumptions!$B$10*(1-Assumptions!$B$11),$B$5*Assumptions!$B$10*(1-Assumptions!$B$11)*(1-Assumptions!$B$12)^(V$19-1)) -> 7756.2394 | W21: =SUM(C$21:V$21) -> 162758.37
A22: PV Direct Sales (MWh) | C22: =C$21*(1-Assumptions!$B$13) -> 4265.625 | D22: =D$21*(1-Assumptions!$B$13) -> 4244.2969 | E22: =E$21*(1-Assumptions!$B$13) -> 4223.0754 | F22: =F$21*(1-Assumptions!$B$13) -> 4201.96 | G22: =G$21*(1-Assumptions!$B$13) -> 4180.9502 | H22: =H$21*(1-Assumptions!$B$13) -> 4160.0455 | I22: =I$21*(1-Assumptions!$B$13) -> 4139.2452 | J22: =J$21*(1-Assumptions!$B$13) -> 4118.549 | ... V22: =V$21*(1-Assumptions!$B$13) -> 3878.1197 | W22: =SUM(C$22:V$22) -> 81379.184
A23: PV Curtailed → BESS (MWh) | C23: =C$21*Assumptions!$B$13 -> 4265.625 | D23: =D$21*Assumptions!$B$13 -> 4244.2969 | E23: =E$21*Assumptions!$B$13 -> 4223.0754 | F23: =F$21*Assumptions!$B$13 -> 4201.96 | G23: =G$21*Assumptions!$B$13 -> 4180.9502 | H23: =H$21*Assumptions!$B$13 -> 4160.0455 | I23: =I$21*Assumptions!$B$13 -> 4139.2452 | J23: =J$21*Assumptions!$B$13 -> 4118.549 | ... V23: =V$21*Assumptions!$B$13 -> 3878.1197 | W23: =SUM(C$23:V$23) -> 81379.184
A24: BESS State of Health (%) | C24: =MAX(0.6,Assumptions!$B$20-Assumptions!$B$21*(C$19-1)) -> 0.985 | D24: =MAX(0.6,Assumptions!$B$20-Assumptions!$B$21*(D$19-1)) -> 0.9715 | E24: =MAX(0.6,Assumptions!$B$20-Assumptions!$B$21*(E$19-1)) -> 0.958 | F24: =MAX(0.6,Assumptions!$B$20-Assumptions!$B$21*(F$19-1)) -> 0.9445 | G24: =MAX(0.6,Assumptions!$B$20-Assumptions!$B$21*(G$19-1)) -> 0.931 | H24: =MAX(0.6,Assumptions!$B$20-Assumptions!$B$21*(H$19-1)) -> 0.9175 | I24: =MAX(0.6,Assumptions!$B$20-Assumptions!$B$21*(I$19-1)) -> 0.904 | J24: =MAX(0.6,Assumptions!$B$20-Assumptions!$B$21*(J$19-1)) -> 0.8905 | ... V24: =MAX(0.6,Assumptions!$B$20-Assumptions!$B$21*(V$19-1)) -> 0.7285 | W24: =AVERAGE(C$24:V$24) -> 0.85675
A25: BESS Sellable Energy (MWh) | C25: =$B$6*C$24*Assumptions!$B$22*Assumptions!$B$19*Assumptions!$B$24*365*Assumptions!$B$23 -> 5473.1641 | D25: =$B$6*D$24*Assumptions!$B$22*Assumptions!$B$19*Assumptions!$B$24*365*Assumptions!$B$23 -> 5398.1512 | E25: =$B$6*E$24*Assumptions!$B$22*Assumptions!$B$19*Assumptions!$B$24*365*Assumptions!$B$23 -> 5323.1383 | F25: =$B$6*F$24*Assumptions!$B$22*Assumptions!$B$19*Assumptions!$B$24*365*Assumptions!$B$23 -> 5248.1254 | G25: =$B$6*G$24*Assumptions!$B$22*Assumptions!$B$19*Assumptions!$B$24*365*Assumptions!$B$23 -> 5173.1125 | H25: =$B$6*H$24*Assumptions!$B$22*Assumptions!$B$19*Assumptions!$B$24*365*Assumptions!$B$23 -> 5098.0996 | I25: =$B$6*I$24*Assumptions!$B$22*Assumptions!$B$19*Assumptions!$B$24*365*Assumptions!$B$23 -> 5023.0867 | J25: =$B$6*J$24*Assumptions!$B$22*Assumptions!$B$19*Assumptions!$B$24*365*Assumptions!$B$23 -> 4948.0738 | ... V25: =$B$6*V$24*Assumptions!$B$22*Assumptions!$B$19*Assumptions!$B$24*365*Assumptions!$B$23 -> 4047.9188 | W25: =SUM(C$25:V$25) -> 95210.83
A26: BESS Charging Needed (MWh) | C26: =$B$6*C$24*Assumptions!$B$22*Assumptions!$B$24*365*Assumptions!$B$23 -> 6342.021 | D26: =$B$6*D$24*Assumptions!$B$22*Assumptions!$B$24*365*Assumptions!$B$23 -> 6255.0999 | E26: =$B$6*E$24*Assumptions!$B$22*Assumptions!$B$24*365*Assumptions!$B$23 -> 6168.1788 | F26: =$B$6*F$24*Assumptions!$B$22*Assumptions!$B$24*365*Assumptions!$B$23 -> 6081.2577 | G26: =$B$6*G$24*Assumptions!$B$22*Assumptions!$B$24*365*Assumptions!$B$23 -> 5994.3366 | H26: =$B$6*H$24*Assumptions!$B$22*Assumptions!$B$24*365*Assumptions!$B$23 -> 5907.4155 | I26: =$B$6*I$24*Assumptions!$B$22*Assumptions!$B$24*365*Assumptions!$B$23 -> 5820.4944 | J26: =$B$6*J$24*Assumptions!$B$22*Assumptions!$B$24*365*Assumptions!$B$23 -> 5733.5733 | ... V26: =$B$6*V$24*Assumptions!$B$22*Assumptions!$B$24*365*Assumptions!$B$23 -> 4690.5201 | W26: =SUM(C$26:V$26) -> 110325.41
A27: Grid Purchases for BESS (MWh) | C27: =MAX(0,C$26-C$23) -> 2076.396 | D27: =MAX(0,D$26-D$23) -> 2010.803 | E27: =MAX(0,E$26-E$23) -> 1945.1034 | F27: =MAX(0,F$26-F$23) -> 1879.2977 | G27: =MAX(0,G$26-G$23) -> 1813.3864 | H27: =MAX(0,H$26-H$23) -> 1747.37 | I27: =MAX(0,I$26-I$23) -> 1681.2492 | J27: =MAX(0,J$26-J$23) -> 1615.0243 | ... V27: =MAX(0,V$26-V$23) -> 812.40042 | W27: =SUM(C$27:V$27) -> 28946.227
A29: SCENARIO: LOW CASE (EUR 110/MWh)
A30: PV Direct Revenue | C30: =C$22*Assumptions!$B$14 -> 682500 | D30: =D$22*Assumptions!$B$14 -> 679087.5 | E30: =E$22*Assumptions!$B$14 -> 675692.06 | F30: =F$22*Assumptions!$B$14 -> 672313.6 | G30: =G$22*Assumptions!$B$14 -> 668952.03 | H30: =H$22*Assumptions!$B$14 -> 665607.27 | I30: =I$22*Assumptions!$B$14 -> 662279.24 | J30: =J$22*Assumptions!$B$14 -> 658967.84 | ... V30: =V$22*Assumptions!$B$14 -> 620499.15 | W30: =SUM(C$30:V$30) -> 13020669
A31: GoO Revenue | C31: =C$21*Assumptions!$B$15 -> 8531.25 | D31: =D$21*Assumptions!$B$15 -> 8488.5938 | E31: =E$21*Assumptions!$B$15 -> 8446.1508 | F31: =F$21*Assumptions!$B$15 -> 8403.92 | G31: =G$21*Assumptions!$B$15 -> 8361.9004 | H31: =H$21*Assumptions!$B$15 -> 8320.0909 | I31: =I$21*Assumptions!$B$15 -> 8278.4905 | J31: =J$21*Assumptions!$B$15 -> 8237.098 | ... V31: =V$21*Assumptions!$B$15 -> 7756.2394 | W31: =SUM(C$31:V$31) -> 162758.37
A32: BESS Arbitrage Revenue | C32: =C$25*Assumptions!$B$42 -> 602048.05 | D32: =D$25*Assumptions!$B$42 -> 593796.63 | E32: =E$25*Assumptions!$B$42 -> 585545.21 | F32: =F$25*Assumptions!$B$42 -> 577293.79 | G32: =G$25*Assumptions!$B$42 -> 569042.37 | H32: =H$25*Assumptions!$B$42 -> 560790.95 | I32: =I$25*Assumptions!$B$42 -> 552539.53 | J32: =J$25*Assumptions!$B$42 -> 544288.11 | ... V32: =V$25*Assumptions!$B$42 -> 445271.07 | W32: =SUM(C$32:V$32) -> 10473191
A33: Total Revenue | C33: =C$30+C$31+C$32 -> 1293079.3 | D33: =D$30+D$31+D$32 -> 1281372.7 | E33: =E$30+E$31+E$32 -> 1269683.4 | F33: =F$30+F$31+F$32 -> 1258011.3 | G33: =G$30+G$31+G$32 -> 1246356.3 | H33: =H$30+H$31+H$32 -> 1234718.3 | I33: =I$30+I$31+I$32 -> 1223097.3 | J33: =J$30+J$31+J$32 -> 1211493.1 | ... V33: =V$30+V$31+V$32 -> 1073526.5 | W33: =SUM(C$33:V$33) -> 23656619
A34: Energy Purchase Cost | C34: =C$27*Assumptions!$B$25*(1+Assumptions!$B$36)^(C$19-1) -> 103819.8 | D34: =D$27*Assumptions!$B$25*(1+Assumptions!$B$36)^(D$19-1) -> 101545.55 | E34: =E$27*Assumptions!$B$25*(1+Assumptions!$B$36)^(E$19-1) -> 99209.999 | F34: =F$27*Assumptions!$B$25*(1+Assumptions!$B$36)^(F$19-1) -> 96812.114 | G34: =G$27*Assumptions!$B$25*(1+Assumptions!$B$36)^(G$19-1) -> 94350.857 | H34: =H$27*Assumptions!$B$25*(1+Assumptions!$B$36)^(H$19-1) -> 91825.174 | I34: =I$27*Assumptions!$B$25*(1+Assumptions!$B$36)^(I$19-1) -> 89233.993 | J34: =J$27*Assumptions!$B$25*(1+Assumptions!$B$36)^(J$19-1) -> 86576.232 | ... V34: =V$27*Assumptions!$B$25*(1+Assumptions!$B$36)^(V$19-1) -> 49073.411 | W34: =SUM(C$34:V$34) -> 1569198.4
A35: PV OPEX | C35: =$B$5*Assumptions!$B$16*(1+Assumptions!$B$36)^(C$19-1) -> 75000 | D35: =$B$5*Assumptions!$B$16*(1+Assumptions!$B$36)^(D$19-1) -> 75750 | E35: =$B$5*Assumptions!$B$16*(1+Assumptions!$B$36)^(E$19-1) -> 76507.5 | F35: =$B$5*Assumptions!$B$16*(1+Assumptions!$B$36)^(F$19-1) -> 77272.575 | G35: =$B$5*Assumptions!$B$16*(1+Assumptions!$B$36)^(G$19-1) -> 78045.301 | H35: =$B$5*Assumptions!$B$16*(1+Assumptions!$B$36)^(H$19-1) -> 78825.754 | I35: =$B$5*Assumptions!$B$16*(1+Assumptions!$B$36)^(I$19-1) -> 79614.011 | J35: =$B$5*Assumptions!$B$16*(1+Assumptions!$B$36)^(J$19-1) -> 80410.151 | ... V35: =$B$5*Assumptions!$B$16*(1+Assumptions!$B$36)^(V$19-1) -> 90608.171 | W35: =SUM(C$35:V$35) -> 1651425.3
A36: BESS OPEX (O&M+Mgmt+CERA+Grounds) | C36: =($B$6*Assumptions!$B$26+$B$6*Assumptions!$B$27+$B$7*Assumptions!$B$28+Assumptions!$B$29)*(1+Assumptions!$B$36)^(C$19-1) -> 72500 | D36: =($B$6*Assumptions!$B$26+$B$6*Assumptions!$B$27+$B$7*Assumptions!$B$28+Assumptions!$B$29)*(1+Assumptions!$B$36)^(D$19-1) -> 73225 | E36: =($B$6*Assumptions!$B$26+$B$6*Assumptions!$B$27+$B$7*Assumptions!$B$28+Assumptions!$B$29)*(1+Assumptions!$B$36)^(E$19-1) -> 73957.25 | F36: =($B$6*Assumptions!$B$26+$B$6*Assumptions!$B$27+$B$7*Assumptions!$B$28+Assumptions!$B$29)*(1+Assumptions!$B$36)^(F$19-1) -> 74696.822 | G36: =($B$6*Assumptions!$B$26+$B$6*Assumptions!$B$27+$B$7*Assumptions!$B$28+Assumptions!$B$29)*(1+Assumptions!$B$36)^(G$19-1) -> 75443.791 | H36: =($B$6*Assumptions!$B$26+$B$6*Assumptions!$B$27+$B$7*Assumptions!$B$28+Assumptions!$B$29)*(1+Assumptions!$B$36)^(H$19-1) -> 76198.229 | I36: =($B$6*Assumptions!$B$26+$B$6*Assumptions!$B$27+$B$7*Assumptions!$B$28+Assumptions!$B$29)*(1+Assumptions!$B$36)^(I$19-1) -> 76960.211 | J36: =($B$6*Assumptions!$B$26+$B$6*Assumptions!$B$27+$B$7*Assumptions!$B$28+Assumptions!$B$29)*(1+Assumptions!$B$36)^(J$19-1) -> 77729.813 | ... V36: =($B$6*Assumptions!$B$26+$B$6*Assumptions!$B$27+$B$7*Assumptions!$B$28+Assumptions!$B$29)*(1+Assumptions!$B$36)^(V$19-1) -> 87587.899 | W36: =SUM(C$36:V$36) -> 1596377.8
A37: BESS Warranty Extension | C37: =IF(C$19<=5,0,IF(C$19<=10,Assumptions!$B$30,IF(C$19<=15,Assumptions!$B$31,Assumptions!$B$32)))*$B$6*(1+Assumptions!$B$36)^(C$19-1) -> 0 | D37: =IF(D$19<=5,0,IF(D$19<=10,Assumptions!$B$30,IF(D$19<=15,Assumptions!$B$31,Assumptions!$B$32)))*$B$6*(1+Assumptions!$B$36)^(D$19-1) -> 0 | E37: =IF(E$19<=5,0,IF(E$19<=10,Assumptions!$B$30,IF(E$19<=15,Assumptions!$B$31,Assumptions!$B$32)))*$B$6*(1+Assumptions!$B$36)^(E$19-1) -> 0 | F37: =IF(F$19<=5,0,IF(F$19<=10,Assumptions!$B$30,IF(F$19<=15,Assumptions!$B$31,Assumptions!$B$32)))*$B$6*(1+Assumptions!$B$36)^(F$19-1) -> 0 | G37: =IF(G$19<=5,0,IF(G$19<=10,Assumptions!$B$30,IF(G$19<=15,Assumptions!$B$31,Assumptions!$B$32)))*$B$6*(1+Assumptions!$B$36)^(G$19-1) -> 0 | H37: =IF(H$19<=5,0,IF(H$19<=10,Assumptions!$B$30,IF(H$19<=15,Assumptions!$B$31,Assumptions!$B$32)))*$B$6*(1+Assumptions!$B$36)^(H$19-1) -> 37836.362 | I37: =IF(I$19<=5,0,IF(I$19<=10,Assumptions!$B$30,IF(I$19<=15,Assumptions!$B$31,Assumptions!$B$32)))*$B$6*(1+Assumptions!$B$36)^(I$19-1) -> 38214.725 | J37: =IF(J$19<=5,0,IF(J$19<=10,Assumptions!$B$30,IF(J$19<=15,Assumptions!$B$31,Assumptions!$B$32)))*$B$6*(1+Assumptions!$B$36)^(J$19-1) -> 38596.873 | ... V37: =IF(V$19<=5,0,IF(V$19<=10,Assumptions!$B$30,IF(V$19<=15,Assumptions!$B$31,Assumptions!$B$32)))*$B$6*(1+Assumptions!$B$36)^(V$19-1) -> 59197.339 | W37: =SUM(C$37:V$37) -> 719843.47
A38: Total Operating Costs | C38: =C$34+C$35+C$36+C$37 -> 251319.8 | D38: =D$34+D$35+D$36+D$37 -> 250520.55 | E38: =E$34+E$35+E$36+E$37 -> 249674.75 | F38: =F$34+F$35+F$36+F$37 -> 248781.51 | G38: =G$34+G$35+G$36+G$37 -> 247839.95 | H38: =H$34+H$35+H$36+H$37 -> 284685.52 | I38: =I$34+I$35+I$36+I$37 -> 284022.94 | J38: =J$34+J$35+J$36+J$37 -> 283313.07 | ... V38: =V$34+V$35+V$36+V$37 -> 286466.82 | W38: =SUM(C$38:V$38) -> 5536844.9
A39: EBITDA | C39: =C$33-C$38 -> 1041759.5 | D39: =D$33-D$38 -> 1030852.2 | E39: =E$33-E$38 -> 1020008.7 | F39: =F$33-F$38 -> 1009229.8 | G39: =G$33-G$38 -> 998516.36 | H39: =H$33-H$38 -> 950032.8 | I39: =I$33-I$38 -> 939074.32 | J39: =J$33-J$38 -> 928179.98 | ... V39: =V$33-V$38 -> 787059.64 | W39: =SUM(C$39:V$39) -> 18119774
A40: Depreciation | C40: =$B$15 -> 318478.2 | D40: =$B$15 -> 318478.2 | E40: =$B$15 -> 318478.2 | F40: =$B$15 -> 318478.2 | G40: =$B$15 -> 318478.2 | H40: =$B$15 -> 318478.2 | I40: =$B$15 -> 318478.2 | J40: =$B$15 -> 318478.2 | ... V40: =$B$15 -> 318478.2 | W40: =SUM(C$40:V$40) -> 6369564
A41: Interest Expense | C41: =IF(C$19<=Assumptions!$B$39,-IPMT(Assumptions!$B$38,C$19,Assumptions!$B$39,$B$13),0) -> 95958.95 | D41: =IF(D$19<=Assumptions!$B$39,-IPMT(Assumptions!$B$38,D$19,Assumptions!$B$39,$B$13),0) -> 91511.993 | E41: =IF(E$19<=Assumptions!$B$39,-IPMT(Assumptions!$B$38,E$19,Assumptions!$B$39,$B$13),0) -> 86842.688 | F41: =IF(F$19<=Assumptions!$B$39,-IPMT(Assumptions!$B$38,F$19,Assumptions!$B$39,$B$13),0) -> 81939.917 | G41: =IF(G$19<=Assumptions!$B$39,-IPMT(Assumptions!$B$38,G$19,Assumptions!$B$39,$B$13),0) -> 76792.008 | H41: =IF(H$19<=Assumptions!$B$39,-IPMT(Assumptions!$B$38,H$19,Assumptions!$B$39,$B$13),0) -> 71386.704 | I41: =IF(I$19<=Assumptions!$B$39,-IPMT(Assumptions!$B$38,I$19,Assumptions!$B$39,$B$13),0) -> 65711.134 | J41: =IF(J$19<=Assumptions!$B$39,-IPMT(Assumptions!$B$38,J$19,Assumptions!$B$39,$B$13),0) -> 59751.786 | ... V41: =IF(V$19<=Assumptions!$B$39,-IPMT(Assumptions!$B$38,V$19,Assumptions!$B$39,$B$13),0) -> 0 | W41: =SUM(C$41:V$41) -> 854292.43
A42: Earnings Before Tax | C42: =C$39-C$40-C$41 -> 627322.35 | D42: =D$39-D$40-D$41 -> 620861.98 | E42: =E$39-E$40-E$41 -> 614687.79 | F42: =F$39-F$40-F$41 -> 608811.69 | G42: =G$39-G$40-G$41 -> 603246.15 | H42: =H$39-H$40-H$41 -> 560167.9 | I42: =I$39-I$40-I$41 -> 554884.99 | J42: =J$39-J$40-J$41 -> 549950 | ... V42: =V$39-V$40-V$41 -> 468581.44 | W42: =SUM(C$42:V$42) -> 10895918
A43: Corporate Tax (12.5%) | C43: =MAX(0,C$42*Assumptions!$B$35) -> 78415.294 | D43: =MAX(0,D$42*Assumptions!$B$35) -> 77607.748 | E43: =MAX(0,E$42*Assumptions!$B$35) -> 76835.974 | F43: =MAX(0,F$42*Assumptions!$B$35) -> 76101.461 | G43: =MAX(0,G$42*Assumptions!$B$35) -> 75405.769 | H43: =MAX(0,H$42*Assumptions!$B$35) -> 70020.987 | I43: =MAX(0,I$42*Assumptions!$B$35) -> 69360.623 | J43: =MAX(0,J$42*Assumptions!$B$35) -> 68743.75 | ... V43: =MAX(0,V$42*Assumptions!$B$35) -> 58572.68 | W43: =SUM(C$43:V$43) -> 1361989.7
...

Sheet Type C - 3MWp
A1: SHARK — Type C: Small Hybrid Park
A2: 3 MWp + 12 MWh Hybrid Park — Per-Unit Financial Model
A4: CAPEX & FINANCING
A5: PV Capacity (MWp) | B5: 3
A6: BESS Capacity (MWh) | B6: 12
A7: BESS Power (MW) | B7: =B6/Assumptions!$B$6 -> 3
A8: PV EPC Self-Cost (EUR) | B8: 1680231
A9: RTB Acquisition (EUR) | B9: =B5*Assumptions!$B$5 -> 1050000
A10: BESS Installed Cost (EUR) | B10: 1399524
A11: Total CAPEX (EUR) | B11: =B8+B9+B10 -> 4129755
A12: Equity (PV + RTB) | B12: =B8+B9 -> 2730231
A13: Debt (BESS — 100% LTV) | B13: =B10 -> 1399524
A14: Annual Debt Service | B14: =-PMT(Assumptions!$B$38,Assumptions!$B$39,B13) -> 134833.34
A15: Annual Depreciation (SL) | B15: =B11/Assumptions!$B$7 -> 206487.75
A16: Units in Portfolio | B16: 4
A18: ANNUAL PRODUCTION & TECHNICAL DATA
A19: Year # | C19: 1 | D19: 2 | E19: 3 | F19: 4 | G19: 5 | H19: 6 | I19: 7 | J19: 8 | K19: 9 | L19: 10 | M19: 11 | N19: 12 | O19: 13 | P19: 14 | Q19: 15 | R19: 16 | S19: 17 | T19: 18 | U19: 19 | V19: 20 | W19: Total/Avg
A20: Calendar | C20: 2026 | D20: 2027 | E20: 2028 | F20: 2029 | G20: 2030 | H20: 2031 | I20: 2032 | J20: 2033 | K20: 2034 | L20: 2035 | M20: 2036 | N20: 2037 | O20: 2038 | P20: 2039 | Q20: 2040 | R20: 2041 | S20: 2042 | T20: 2043 | U20: 2044 | V20: 2045
A21: PV Production (MWh) | C21: =IF(C$19=1,$B$5*Assumptions!$B$10*(1-Assumptions!$B$11),$B$5*Assumptions!$B$10*(1-Assumptions!$B$11)*(1-Assumptions!$B$12)^(C$19-1)) -> 5118.75 | D21: =IF(D$19=1,$B$5*Assumptions!$B$10*(1-Assumptions!$B$11),$B$5*Assumptions!$B$10*(1-Assumptions!$B$11)*(1-Assumptions!$B$12)^(D$19-1)) -> 5093.1562 | E21: =IF(E$19=1,$B$5*Assumptions!$B$10*(1-Assumptions!$B$11),$B$5*Assumptions!$B$10*(1-Assumptions!$B$11)*(1-Assumptions!$B$12)^(E$19-1)) -> 5067.6905 | F21: =IF(F$19=1,$B$5*Assumptions!$B$10*(1-Assumptions!$B$11),$B$5*Assumptions!$B$10*(1-Assumptions!$B$11)*(1-Assumptions!$B$12)^(F$19-1)) -> 5042.352 | G21: =IF(G$19=1,$B$5*Assumptions!$B$10*(1-Assumptions!$B$11),$B$5*Assumptions!$B$10*(1-Assumptions!$B$11)*(1-Assumptions!$B$12)^(G$19-1)) -> 5017.1403 | H21: =IF(H$19=1,$B$5*Assumptions!$B$10*(1-Assumptions!$B$11),$B$5*Assumptions!$B$10*(1-Assumptions!$B$11)*(1-Assumptions!$B$12)^(H$19-1)) -> 4992.0546 | I21: =IF(I$19=1,$B$5*Assumptions!$B$10*(1-Assumptions!$B$11),$B$5*Assumptions!$B$10*(1-Assumptions!$B$11)*(1-Assumptions!$B$12)^(I$19-1)) -> 4967.0943 | J21: =IF(J$19=1,$B$5*Assumptions!$B$10*(1-Assumptions!$B$11),$B$5*Assumptions!$B$10*(1-Assumptions!$B$11)*(1-Assumptions!$B$12)^(J$19-1)) -> 4942.2588 | ... V21: =IF(V$19=1,$B$5*Assumptions!$B$10*(1-Assumptions!$B$11),$B$5*Assumptions!$B$10*(1-Assumptions!$B$11)*(1-Assumptions!$B$12)^(V$19-1)) -> 4653.7436 | W21: =SUM(C$21:V$21) -> 97655.021
A22: PV Direct Sales (MWh) | C22: =C$21*(1-Assumptions!$B$13) -> 2559.375 | D22: =D$21*(1-Assumptions!$B$13) -> 2546.5781 | E22: =E$21*(1-Assumptions!$B$13) -> 2533.8452 | F22: =F$21*(1-Assumptions!$B$13) -> 2521.176 | G22: =G$21*(1-Assumptions!$B$13) -> 2508.5701 | H22: =H$21*(1-Assumptions!$B$13) -> 2496.0273 | I22: =I$21*(1-Assumptions!$B$13) -> 2483.5471 | J22: =J$21*(1-Assumptions!$B$13) -> 2471.1294 | ... V22: =V$21*(1-Assumptions!$B$13) -> 2326.8718 | W22: =SUM(C$22:V$22) -> 48827.51
A23: PV Curtailed → BESS (MWh) | C23: =C$21*Assumptions!$B$13 -> 2559.375 | D23: =D$21*Assumptions!$B$13 -> 2546.5781 | E23: =E$21*Assumptions!$B$13 -> 2533.8452 | F23: =F$21*Assumptions!$B$13 -> 2521.176 | G23: =G$21*Assumptions!$B$13 -> 2508.5701 | H23: =H$21*Assumptions!$B$13 -> 2496.0273 | I23: =I$21*Assumptions!$B$13 -> 2483.5471 | J23: =J$21*Assumptions!$B$13 -> 2471.1294 | ... V23: =V$21*Assumptions!$B$13 -> 2326.8718 | W23: =SUM(C$23:V$23) -> 48827.51
A24: BESS State of Health (%) | C24: =MAX(0.6,Assumptions!$B$20-Assumptions!$B$21*(C$19-1)) -> 0.985 | D24: =MAX(0.6,Assumptions!$B$20-Assumptions!$B$21*(D$19-1)) -> 0.9715 | E24: =MAX(0.6,Assumptions!$B$20-Assumptions!$B$21*(E$19-1)) -> 0.958 | F24: =MAX(0.6,Assumptions!$B$20-Assumptions!$B$21*(F$19-1)) -> 0.9445 | G24: =MAX(0.6,Assumptions!$B$20-Assumptions!$B$21*(G$19-1)) -> 0.931 | H24: =MAX(0.6,Assumptions!$B$20-Assumptions!$B$21*(H$19-1)) -> 0.9175 | I24: =MAX(0.6,Assumptions!$B$20-Assumptions!$B$21*(I$19-1)) -> 0.904 | J24: =MAX(0.6,Assumptions!$B$20-Assumptions!$B$21*(J$19-1)) -> 0.8905 | ... V24: =MAX(0.6,Assumptions!$B$20-Assumptions!$B$21*(V$19-1)) -> 0.7285 | W24: =AVERAGE(C$24:V$24) -> 0.85675
A25: BESS Sellable Energy (MWh) | C25: =$B$6*C$24*Assumptions!$B$22*Assumptions!$B$19*Assumptions!$B$24*365*Assumptions!$B$23 -> 3283.8985 | D25: =$B$6*D$24*Assumptions!$B$22*Assumptions!$B$19*Assumptions!$B$24*365*Assumptions!$B$23 -> 3238.8907 | E25: =$B$6*E$24*Assumptions!$B$22*Assumptions!$B$19*Assumptions!$B$24*365*Assumptions!$B$23 -> 3193.883 | F25: =$B$6*F$24*Assumptions!$B$22*Assumptions!$B$19*Assumptions!$B$24*365*Assumptions!$B$23 -> 3148.8752 | G25: =$B$6*G$24*Assumptions!$B$22*Assumptions!$B$19*Assumptions!$B$24*365*Assumptions!$B$23 -> 3103.8675 | H25: =$B$6*H$24*Assumptions!$B$22*Assumptions!$B$19*Assumptions!$B$24*365*Assumptions!$B$23 -> 3058.8597 | I25: =$B$6*I$24*Assumptions!$B$22*Assumptions!$B$19*Assumptions!$B$24*365*Assumptions!$B$23 -> 3013.852 | J25: =$B$6*J$24*Assumptions!$B$22*Assumptions!$B$19*Assumptions!$B$24*365*Assumptions!$B$23 -> 2968.8443 | ... V25: =$B$6*V$24*Assumptions!$B$22*Assumptions!$B$19*Assumptions!$B$24*365*Assumptions!$B$23 -> 2428.7513 | W25: =SUM(C$25:V$25) -> 57126.498
A26: BESS Charging Needed (MWh) | C26: =$B$6*C$24*Assumptions!$B$22*Assumptions!$B$24*365*Assumptions!$B$23 -> 3805.2126 | D26: =$B$6*D$24*Assumptions!$B$22*Assumptions!$B$24*365*Assumptions!$B$23 -> 3753.0599 | E26: =$B$6*E$24*Assumptions!$B$22*Assumptions!$B$24*365*Assumptions!$B$23 -> 3700.9073 | F26: =$B$6*F$24*Assumptions!$B$22*Assumptions!$B$24*365*Assumptions!$B$23 -> 3648.7546 | G26: =$B$6*G$24*Assumptions!$B$22*Assumptions!$B$24*365*Assumptions!$B$23 -> 3596.602 | H26: =$B$6*H$24*Assumptions!$B$22*Assumptions!$B$24*365*Assumptions!$B$23 -> 3544.4493 | I26: =$B$6*I$24*Assumptions!$B$22*Assumptions!$B$24*365*Assumptions!$B$23 -> 3492.2966 | J26: =$B$6*J$24*Assumptions!$B$22*Assumptions!$B$24*365*Assumptions!$B$23 -> 3440.144 | ... V26: =$B$6*V$24*Assumptions!$B$22*Assumptions!$B$24*365*Assumptions!$B$23 -> 2814.3121 | W26: =SUM(C$26:V$26) -> 66195.247
A27: Grid Purchases for BESS (MWh) | C27: =MAX(0,C$26-C$23) -> 1245.8376 | D27: =MAX(0,D$26-D$23) -> 1206.4818 | E27: =MAX(0,E$26-E$23) -> 1167.062 | F27: =MAX(0,F$26-F$23) -> 1127.5786 | G27: =MAX(0,G$26-G$23) -> 1088.0318 | H27: =MAX(0,H$26-H$23) -> 1048.422 | I27: =MAX(0,I$26-I$23) -> 1008.7495 | J27: =MAX(0,J$26-J$23) -> 969.01457 | ... V27: =MAX(0,V$26-V$23) -> 487.44025 | W27: =SUM(C$27:V$27) -> 17367.736
A29: SCENARIO: LOW CASE (EUR 110/MWh)
A30: PV Direct Revenue | C30: =C$22*Assumptions!$B$14 -> 409500 | D30: =D$22*Assumptions!$B$14 -> 407452.5 | E30: =E$22*Assumptions!$B$14 -> 405415.24 | F30: =F$22*Assumptions!$B$14 -> 403388.16 | G30: =G$22*Assumptions!$B$14 -> 401371.22 | H30: =H$22*Assumptions!$B$14 -> 399364.36 | I30: =I$22*Assumptions!$B$14 -> 397367.54 | J30: =J$22*Assumptions!$B$14 -> 395380.7 | ... V30: =V$22*Assumptions!$B$14 -> 372299.49 | W30: =SUM(C$30:V$30) -> 7812401.7
A31: GoO Revenue | C31: =C$21*Assumptions!$B$15 -> 5118.75 | D31: =D$21*Assumptions!$B$15 -> 5093.1562 | E31: =E$21*Assumptions!$B$15 -> 5067.6905 | F31: =F$21*Assumptions!$B$15 -> 5042.352 | G31: =G$21*Assumptions!$B$15 -> 5017.1403 | H31: =H$21*Assumptions!$B$15 -> 4992.0546 | I31: =I$21*Assumptions!$B$15 -> 4967.0943 | J31: =J$21*Assumptions!$B$15 -> 4942.2588 | ... V31: =V$21*Assumptions!$B$15 -> 4653.7436 | W31: =SUM(C$31:V$31) -> 97655.021
A32: BESS Arbitrage Revenue | C32: =C$25*Assumptions!$B$42 -> 361228.83 | D32: =D$25*Assumptions!$B$42 -> 356277.98 | E32: =E$25*Assumptions!$B$42 -> 351327.13 | F32: =F$25*Assumptions!$B$42 -> 346376.28 | G32: =G$25*Assumptions!$B$42 -> 341425.42 | H32: =H$25*Assumptions!$B$42 -> 336474.57 | I32: =I$25*Assumptions!$B$42 -> 331523.72 | J32: =J$25*Assumptions!$B$42 -> 326572.87 | ... V32: =V$25*Assumptions!$B$42 -> 267162.64 | W32: =SUM(C$32:V$32) -> 6283914.8
A33: Total Revenue | C33: =C$30+C$31+C$32 -> 775847.58 | D33: =D$30+D$31+D$32 -> 768823.64 | E33: =E$30+E$31+E$32 -> 761810.06 | F33: =F$30+F$31+F$32 -> 754806.79 | G33: =G$30+G$31+G$32 -> 747813.78 | H33: =H$30+H$31+H$32 -> 740830.99 | I33: =I$30+I$31+I$32 -> 733858.36 | J33: =J$30+J$31+J$32 -> 726895.83 | ... V33: =V$30+V$31+V$32 -> 644115.88 | W33: =SUM(C$33:V$33) -> 14193971
A34: Energy Purchase Cost | C34: =C$27*Assumptions!$B$25*(1+Assumptions!$B$36)^(C$19-1) -> 62291.88 | D34: =D$27*Assumptions!$B$25*(1+Assumptions!$B$36)^(D$19-1) -> 60927.332 | E34: =E$27*Assumptions!$B$25*(1+Assumptions!$B$36)^(E$19-1) -> 59526 | F34: =F$27*Assumptions!$B$25*(1+Assumptions!$B$36)^(F$19-1) -> 58087.269 | G34: =G$27*Assumptions!$B$25*(1+Assumptions!$B$36)^(G$19-1) -> 56610.514 | H34: =H$27*Assumptions!$B$25*(1+Assumptions!$B$36)^(H$19-1) -> 55095.104 | I34: =I$27*Assumptions!$B$25*(1+Assumptions!$B$36)^(I$19-1) -> 53540.396 | J34: =J$27*Assumptions!$B$25*(1+Assumptions!$B$36)^(J$19-1) -> 51945.739 | ... V34: =V$27*Assumptions!$B$25*(1+Assumptions!$B$36)^(V$19-1) -> 29444.047 | W34: =SUM(C$34:V$34) -> 941519.02
A35: PV OPEX | C35: =$B$5*Assumptions!$B$16*(1+Assumptions!$B$36)^(C$19-1) -> 45000 | D35: =$B$5*Assumptions!$B$16*(1+Assumptions!$B$36)^(D$19-1) -> 45450 | E35: =$B$5*Assumptions!$B$16*(1+Assumptions!$B$36)^(E$19-1) -> 45904.5 | F35: =$B$5*Assumptions!$B$16*(1+Assumptions!$B$36)^(F$19-1) -> 46363.545 | G35: =$B$5*Assumptions!$B$16*(1+Assumptions!$B$36)^(G$19-1) -> 46827.18 | H35: =$B$5*Assumptions!$B$16*(1+Assumptions!$B$36)^(H$19-1) -> 47295.452 | I35: =$B$5*Assumptions!$B$16*(1+Assumptions!$B$36)^(I$19-1) -> 47768.407 | J35: =$B$5*Assumptions!$B$16*(1+Assumptions!$B$36)^(J$19-1) -> 48246.091 | ... V35: =$B$5*Assumptions!$B$16*(1+Assumptions!$B$36)^(V$19-1) -> 54364.903 | W35: =SUM(C$35:V$35) -> 990855.18
A36: BESS OPEX (O&M+Mgmt+CERA+Grounds) | C36: =($B$6*Assumptions!$B$26+$B$6*Assumptions!$B$27+$B$7*Assumptions!$B$28+Assumptions!$B$29)*(1+Assumptions!$B$36)^(C$19-1) -> 45100 | D36: =($B$6*Assumptions!$B$26+$B$6*Assumptions!$B$27+$B$7*Assumptions!$B$28+Assumptions!$B$29)*(1+Assumptions!$B$36)^(D$19-1) -> 45551 | E36: =($B$6*Assumptions!$B$26+$B$6*Assumptions!$B$27+$B$7*Assumptions!$B$28+Assumptions!$B$29)*(1+Assumptions!$B$36)^(E$19-1) -> 46006.51 | F36: =($B$6*Assumptions!$B$26+$B$6*Assumptions!$B$27+$B$7*Assumptions!$B$28+Assumptions!$B$29)*(1+Assumptions!$B$36)^(F$19-1) -> 46466.575 | G36: =($B$6*Assumptions!$B$26+$B$6*Assumptions!$B$27+$B$7*Assumptions!$B$28+Assumptions!$B$29)*(1+Assumptions!$B$36)^(G$19-1) -> 46931.241 | H36: =($B$6*Assumptions!$B$26+$B$6*Assumptions!$B$27+$B$7*Assumptions!$B$28+Assumptions!$B$29)*(1+Assumptions!$B$36)^(H$19-1) -> 47400.553 | I36: =($B$6*Assumptions!$B$26+$B$6*Assumptions!$B$27+$B$7*Assumptions!$B$28+Assumptions!$B$29)*(1+Assumptions!$B$36)^(I$19-1) -> 47874.559 | J36: =($B$6*Assumptions!$B$26+$B$6*Assumptions!$B$27+$B$7*Assumptions!$B$28+Assumptions!$B$29)*(1+Assumptions!$B$36)^(J$19-1) -> 48353.304 | ... V36: =($B$6*Assumptions!$B$26+$B$6*Assumptions!$B$27+$B$7*Assumptions!$B$28+Assumptions!$B$29)*(1+Assumptions!$B$36)^(V$19-1) -> 54485.714 | W36: =SUM(C$36:V$36) -> 993057.08
A37: BESS Warranty Extension | C37: =IF(C$19<=5,0,IF(C$19<=10,Assumptions!$B$30,IF(C$19<=15,Assumptions!$B$31,Assumptions!$B$32)))*$B$6*(1+Assumptions!$B$36)^(C$19-1) -> 0 | D37: =IF(D$19<=5,0,IF(D$19<=10,Assumptions!$B$30,IF(D$19<=15,Assumptions!$B$31,Assumptions!$B$32)))*$B$6*(1+Assumptions!$B$36)^(D$19-1) -> 0 | E37: =IF(E$19<=5,0,IF(E$19<=10,Assumptions!$B$30,IF(E$19<=15,Assumptions!$B$31,Assumptions!$B$32)))*$B$6*(1+Assumptions!$B$36)^(E$19-1) -> 0 | F37: =IF(F$19<=5,0,IF(F$19<=10,Assumptions!$B$30,IF(F$19<=15,Assumptions!$B$31,Assumptions!$B$32)))*$B$6*(1+Assumptions!$B$36)^(F$19-1) -> 0 | G37: =IF(G$19<=5,0,IF(G$19<=10,Assumptions!$B$30,IF(G$19<=15,Assumptions!$B$31,Assumptions!$B$32)))*$B$6*(1+Assumptions!$B$36)^(G$19-1) -> 0 | H37: =IF(H$19<=5,0,IF(H$19<=10,Assumptions!$B$30,IF(H$19<=15,Assumptions!$B$31,Assumptions!$B$32)))*$B$6*(1+Assumptions!$B$36)^(H$19-1) -> 22701.817 | I37: =IF(I$19<=5,0,IF(I$19<=10,Assumptions!$B$30,IF(I$19<=15,Assumptions!$B$31,Assumptions!$B$32)))*$B$6*(1+Assumptions!$B$36)^(I$19-1) -> 22928.835 | J37: =IF(J$19<=5,0,IF(J$19<=10,Assumptions!$B$30,IF(J$19<=15,Assumptions!$B$31,Assumptions!$B$32)))*$B$6*(1+Assumptions!$B$36)^(J$19-1) -> 23158.124 | ... V37: =IF(V$19<=5,0,IF(V$19<=10,Assumptions!$B$30,IF(V$19<=15,Assumptions!$B$31,Assumptions!$B$32)))*$B$6*(1+Assumptions!$B$36)^(V$19-1) -> 35518.403 | W37: =SUM(C$37:V$37) -> 431906.08
A38: Total Operating Costs | C38: =C$34+C$35+C$36+C$37 -> 152391.88 | D38: =D$34+D$35+D$36+D$37 -> 151928.33 | E38: =E$34+E$35+E$36+E$37 -> 151437.01 | F38: =F$34+F$35+F$36+F$37 -> 150917.39 | G38: =G$34+G$35+G$36+G$37 -> 150368.94 | H38: =H$34+H$35+H$36+H$37 -> 172492.93 | I38: =I$34+I$35+I$36+I$37 -> 172112.2 | J38: =J$34+J$35+J$36+J$37 -> 171703.26 | ... V38: =V$34+V$35+V$36+V$37 -> 173813.07 | W38: =SUM(C$38:V$38) -> 3357337.4
A39: EBITDA | C39: =C$33-C$38 -> 623455.7 | D39: =D$33-D$38 -> 616895.3 | E39: =E$33-E$38 -> 610373.05 | F39: =F$33-F$38 -> 603889.4 | G39: =G$33-G$38 -> 597444.85 | H39: =H$33-H$38 -> 568338.06 | I39: =I$33-I$38 -> 561746.16 | J39: =J$33-J$38 -> 555192.57 | ... V39: =V$33-V$38 -> 470302.81 | W39: =SUM(C$39:V$39) -> 10836634
A40: Depreciation | C40: =$B$15 -> 206487.75 | D40: =$B$15 -> 206487.75 | E40: =$B$15 -> 206487.75 | F40: =$B$15 -> 206487.75 | G40: =$B$15 -> 206487.75 | H40: =$B$15 -> 206487.75 | I40: =$B$15 -> 206487.75 | J40: =$B$15 -> 206487.75 | ... V40: =$B$15 -> 206487.75 | W40: =SUM(C$40:V$40) -> 4129755
A41: Interest Expense | C41: =IF(C$19<=Assumptions!$B$39,-IPMT(Assumptions!$B$38,C$19,Assumptions!$B$39,$B$13),0) -> 69976.2 | D41: =IF(D$19<=Assumptions!$B$39,-IPMT(Assumptions!$B$38,D$19,Assumptions!$B$39,$B$13),0) -> 66733.343 | E41: =IF(E$19<=Assumptions!$B$39,-IPMT(Assumptions!$B$38,E$19,Assumptions!$B$39,$B$13),0) -> 63328.343 | F41: =IF(F$19<=Assumptions!$B$39,-IPMT(Assumptions!$B$38,F$19,Assumptions!$B$39,$B$13),0) -> 59753.093 | G41: =IF(G$19<=Assumptions!$B$39,-IPMT(Assumptions!$B$38,G$19,Assumptions!$B$39,$B$13),0) -> 55999.08 | H41: =IF(H$19<=Assumptions!$B$39,-IPMT(Assumptions!$B$38,H$19,Assumptions!$B$39,$B$13),0) -> 52057.367 | I41: =IF(I$19<=Assumptions!$B$39,-IPMT(Assumptions!$B$38,I$19,Assumptions!$B$39,$B$13),0) -> 47918.568 | J41: =IF(J$19<=Assumptions!$B$39,-IPMT(Assumptions!$B$38,J$19,Assumptions!$B$39,$B$13),0) -> 43572.829 | ... V41: =IF(V$19<=Assumptions!$B$39,-IPMT(Assumptions!$B$38,V$19,Assumptions!$B$39,$B$13),0) -> 0 | W41: =SUM(C$41:V$41) -> 622976.16
A42: Earnings Before Tax | C42: =C$39-C$40-C$41 -> 346991.75 | D42: =D$39-D$40-D$41 -> 343674.21 | E42: =E$39-E$40-E$41 -> 340556.95 | F42: =F$39-F$40-F$41 -> 337648.56 | G42: =G$39-G$40-G$41 -> 334958.02 | H42: =H$39-H$40-H$41 -> 309792.95 | I42: =I$39-I$40-I$41 -> 307339.84 | J42: =J$39-J$40-J$41 -> 305131.99 | ... V42: =V$39-V$40-V$41 -> 263815.06 | W42: =SUM(C$42:V$42) -> 6083902.9
A43: Corporate Tax (12.5%) | C43: =MAX(0,C$42*Assumptions!$B$35) -> 43373.969 | D43: =MAX(0,D$42*Assumptions!$B$35) -> 42959.276 | E43: =MAX(0,E$42*Assumptions!$B$35) -> 42569.619 | F43: =MAX(0,F$42*Assumptions!$B$35) -> 42206.07 | G43: =MAX(0,G$42*Assumptions!$B$35) -> 41869.752 | H43: =MAX(0,H$42*Assumptions!$B$35) -> 38724.118 | I43: =MAX(0,I$42*Assumptions!$B$35) -> 38417.48 | J43: =MAX(0,J$42*Assumptions!$B$35) -> 38141.499 | ... V43: =MAX(0,V$42*Assumptions!$B$35) -> 32976.883 | W43: =SUM(C$43:V$43) -> 760487.87
...

Sheet Fund Portfolio
A1: SHARK Fund — Aggregated Portfolio Model
A2: All formulas reference asset sheets and scale by unit count
A4: PORTFOLIO — LOW CASE (EUR 110/MWh)
A5: Year | C5: 2026 | D5: 2027 | E5: 2028 | F5: 2029 | G5: 2030 | H5: 2031 | I5: 2032 | J5: 2033 | K5: 2034 | L5: 2035 | M5: 2036 | N5: 2037 | O5: 2038 | P5: 2039 | Q5: 2040 | R5: 2041 | S5: 2042 | T5: 2043 | U5: 2044 | V5: 2045 | W5: Total / Avg
A6: Total Revenue | C6: ='Type A - 10MWp'!C$33*'Type A - 10MWp'!$B$16+'Type B - 5MWp'!C$33*'Type B - 5MWp'!$B$16+'Type C - 3MWp'!C$33*'Type C - 3MWp'!$B$16 -> 14741104 | D6: ='Type A - 10MWp'!D$33*'Type A - 10MWp'!$B$16+'Type B - 5MWp'!D$33*'Type B - 5MWp'!$B$16+'Type C - 3MWp'!D$33*'Type C - 3MWp'!$B$16 -> 14607649 | E6: ='Type A - 10MWp'!E$33*'Type A - 10MWp'!$B$16+'Type B - 5MWp'!E$33*'Type B - 5MWp'!$B$16+'Type C - 3MWp'!E$33*'Type C - 3MWp'!$B$16 -> 14474391 | F6: ='Type A - 10MWp'!F$33*'Type A - 10MWp'!$B$16+'Type B - 5MWp'!F$33*'Type B - 5MWp'!$B$16+'Type C - 3MWp'!F$33*'Type C - 3MWp'!$B$16 -> 14341329 | G6: ='Type A - 10MWp'!G$33*'Type A - 10MWp'!$B$16+'Type B - 5MWp'!G$33*'Type B - 5MWp'!$B$16+'Type C - 3MWp'!G$33*'Type C - 3MWp'!$B$16 -> 14208462 | H6: ='Type A - 10MWp'!H$33*'Type A - 10MWp'!$B$16+'Type B - 5MWp'!H$33*'Type B - 5MWp'!$B$16+'Type C - 3MWp'!H$33*'Type C - 3MWp'!$B$16 -> 14075789 | I6: ='Type A - 10MWp'!I$33*'Type A - 10MWp'!$B$16+'Type B - 5MWp'!I$33*'Type B - 5MWp'!$B$16+'Type C - 3MWp'!I$33*'Type C - 3MWp'!$B$16 -> 13943309 | J6: ='Type A - 10MWp'!J$33*'Type A - 10MWp'!$B$16+'Type B - 5MWp'!J$33*'Type B - 5MWp'!$B$16+'Type C - 3MWp'!J$33*'Type C - 3MWp'!$B$16 -> 13811021 | ... V6: ='Type A - 10MWp'!V$33*'Type A - 10MWp'!$B$16+'Type B - 5MWp'!V$33*'Type B - 5MWp'!$B$16+'Type C - 3MWp'!V$33*'Type C - 3MWp'!$B$16 -> 12238202 | W6: =SUM(C$6:V$6) -> 2.6968546e+08
A7: Total Operating Costs | C7: ='Type A - 10MWp'!C$38*'Type A - 10MWp'!$B$16+'Type B - 5MWp'!C$38*'Type B - 5MWp'!$B$16+'Type C - 3MWp'!C$38*'Type C - 3MWp'!$B$16 -> 2859445.7 | D7: ='Type A - 10MWp'!D$38*'Type A - 10MWp'!$B$16+'Type B - 5MWp'!D$38*'Type B - 5MWp'!$B$16+'Type C - 3MWp'!D$38*'Type C - 3MWp'!$B$16 -> 2850278.3 | E7: ='Type A - 10MWp'!E$38*'Type A - 10MWp'!$B$16+'Type B - 5MWp'!E$38*'Type B - 5MWp'!$B$16+'Type C - 3MWp'!E$38*'Type C - 3MWp'!$B$16 -> 2840579.6 | F7: ='Type A - 10MWp'!F$38*'Type A - 10MWp'!$B$16+'Type B - 5MWp'!F$38*'Type B - 5MWp'!$B$16+'Type C - 3MWp'!F$38*'Type C - 3MWp'!$B$16 -> 2830339.5 | G7: ='Type A - 10MWp'!G$38*'Type A - 10MWp'!$B$16+'Type B - 5MWp'!G$38*'Type B - 5MWp'!$B$16+'Type C - 3MWp'!G$38*'Type C - 3MWp'!$B$16 -> 2819548 | H7: ='Type A - 10MWp'!H$38*'Type A - 10MWp'!$B$16+'Type B - 5MWp'!H$38*'Type B - 5MWp'!$B$16+'Type C - 3MWp'!H$38*'Type C - 3MWp'!$B$16 -> 3239529.2 | I7: ='Type A - 10MWp'!I$38*'Type A - 10MWp'!$B$16+'Type B - 5MWp'!I$38*'Type B - 5MWp'!$B$16+'Type C - 3MWp'!I$38*'Type C - 3MWp'!$B$16 -> 3231917 | J7: ='Type A - 10MWp'!J$38*'Type A - 10MWp'!$B$16+'Type B - 5MWp'!J$38*'Type B - 5MWp'!$B$16+'Type C - 3MWp'!J$38*'Type C - 3MWp'!$B$16 -> 3223765 | ... V7: ='Type A - 10MWp'!V$38*'Type A - 10MWp'!$B$16+'Type B - 5MWp'!V$38*'Type B - 5MWp'!$B$16+'Type C - 3MWp'!V$38*'Type C - 3MWp'!$B$16 -> 3258956.3 | W7: =SUM(C$7:V$7) -> 62996726
A8: Portfolio EBITDA | C8: ='Type A - 10MWp'!C$39*'Type A - 10MWp'!$B$16+'Type B - 5MWp'!C$39*'Type B - 5MWp'!$B$16+'Type C - 3MWp'!C$39*'Type C - 3MWp'!$B$16 -> 11881658 | D8: ='Type A - 10MWp'!D$39*'Type A - 10MWp'!$B$16+'Type B - 5MWp'!D$39*'Type B - 5MWp'!$B$16+'Type C - 3MWp'!D$39*'Type C - 3MWp'!$B$16 -> 11757371 | E8: ='Type A - 10MWp'!E$39*'Type A - 10MWp'!$B$16+'Type B - 5MWp'!E$39*'Type B - 5MWp'!$B$16+'Type C - 3MWp'!E$39*'Type C - 3MWp'!$B$16 -> 11633811 | F8: ='Type A - 10MWp'!F$39*'Type A - 10MWp'!$B$16+'Type B - 5MWp'!F$39*'Type B - 5MWp'!$B$16+'Type C - 3MWp'!F$39*'Type C - 3MWp'!$B$16 -> 11510989 | G8: ='Type A - 10MWp'!G$39*'Type A - 10MWp'!$B$16+'Type B - 5MWp'!G$39*'Type B - 5MWp'!$B$16+'Type C - 3MWp'!G$39*'Type C - 3MWp'!$B$16 -> 11388914 | H8: ='Type A - 10MWp'!H$39*'Type A - 10MWp'!$B$16+'Type B - 5MWp'!H$39*'Type B - 5MWp'!$B$16+'Type C - 3MWp'!H$39*'Type C - 3MWp'!$B$16 -> 10836260 | I8: ='Type A - 10MWp'!I$39*'Type A - 10MWp'!$B$16+'Type B - 5MWp'!I$39*'Type B - 5MWp'!$B$16+'Type C - 3MWp'!I$39*'Type C - 3MWp'!$B$16 -> 10711392 | J8: ='Type A - 10MWp'!J$39*'Type A - 10MWp'!$B$16+'Type B - 5MWp'!J$39*'Type B - 5MWp'!$B$16+'Type C - 3MWp'!J$39*'Type C - 3MWp'!$B$16 -> 10587256 | ... V8: ='Type A - 10MWp'!V$39*'Type A - 10MWp'!$B$16+'Type B - 5MWp'!V$39*'Type B - 5MWp'!$B$16+'Type C - 3MWp'!V$39*'Type C - 3MWp'!$B$16 -> 8979245.3 | W8: =SUM(C$8:V$8) -> 2.0668873e+08
A9: Total Debt Service | C9: ='Type A - 10MWp'!C$45*'Type A - 10MWp'!$B$16+'Type B - 5MWp'!C$45*'Type B - 5MWp'!$B$16+'Type C - 3MWp'!C$45*'Type C - 3MWp'!$B$16 -> 2175267.6 | D9: ='Type A - 10MWp'!D$45*'Type A - 10MWp'!$B$16+'Type B - 5MWp'!D$45*'Type B - 5MWp'!$B$16+'Type C - 3MWp'!D$45*'Type C - 3MWp'!$B$16 -> 2175267.6 | E9: ='Type A - 10MWp'!E$45*'Type A - 10MWp'!$B$16+'Type B - 5MWp'!E$45*'Type B - 5MWp'!$B$16+'Type C - 3MWp'!E$45*'Type C - 3MWp'!$B$16 -> 2175267.6 | F9: ='Type A - 10MWp'!F$45*'Type A - 10MWp'!$B$16+'Type B - 5MWp'!F$45*'Type B - 5MWp'!$B$16+'Type C - 3MWp'!F$45*'Type C - 3MWp'!$B$16 -> 2175267.6 | G9: ='Type A - 10MWp'!G$45*'Type A - 10MWp'!$B$16+'Type B - 5MWp'!G$45*'Type B - 5MWp'!$B$16+'Type C - 3MWp'!G$45*'Type C - 3MWp'!$B$16 -> 2175267.6 | H9: ='Type A - 10MWp'!H$45*'Type A - 10MWp'!$B$16+'Type B - 5MWp'!H$45*'Type B - 5MWp'!$B$16+'Type C - 3MWp'!H$45*'Type C - 3MWp'!$B$16 -> 2175267.6 | I9: ='Type A - 10MWp'!I$45*'Type A - 10MWp'!$B$16+'Type B - 5MWp'!I$45*'Type B - 5MWp'!$B$16+'Type C - 3MWp'!I$45*'Type C - 3MWp'!$B$16 -> 2175267.6 | J9: ='Type A - 10MWp'!J$45*'Type A - 10MWp'!$B$16+'Type B - 5MWp'!J$45*'Type B - 5MWp'!$B$16+'Type C - 3MWp'!J$45*'Type C - 3MWp'!$B$16 -> 2175267.6 | ... V9: ='Type A - 10MWp'!V$45*'Type A - 10MWp'!$B$16+'Type B - 5MWp'!V$45*'Type B - 5MWp'!$B$16+'Type C - 3MWp'!V$45*'Type C - 3MWp'!$B$16 -> 0 | W9: =SUM(C$9:V$9) -> 32629014
A10: Total Tax | C10: ='Type A - 10MWp'!C$43*'Type A - 10MWp'!$B$16+'Type B - 5MWp'!C$43*'Type B - 5MWp'!$B$16+'Type C - 3MWp'!C$43*'Type C - 3MWp'!$B$16 -> 890010.69 | D10: ='Type A - 10MWp'!D$43*'Type A - 10MWp'!$B$16+'Type B - 5MWp'!D$43*'Type B - 5MWp'!$B$16+'Type C - 3MWp'!D$43*'Type C - 3MWp'!$B$16 -> 881014.37 | E10: ='Type A - 10MWp'!E$43*'Type A - 10MWp'!$B$16+'Type B - 5MWp'!E$43*'Type B - 5MWp'!$B$16+'Type C - 3MWp'!E$43*'Type C - 3MWp'!$B$16 -> 872436.07 | F10: ='Type A - 10MWp'!F$43*'Type A - 10MWp'!$B$16+'Type B - 5MWp'!F$43*'Type B - 5MWp'!$B$16+'Type C - 3MWp'!F$43*'Type C - 3MWp'!$B$16 -> 864293.26 | G10: ='Type A - 10MWp'!G$43*'Type A - 10MWp'!$B$16+'Type B - 5MWp'!G$43*'Type B - 5MWp'!$B$16+'Type C - 3MWp'!G$43*'Type C - 3MWp'!$B$16 -> 856604.25 | H10: ='Type A - 10MWp'!H$43*'Type A - 10MWp'!$B$16+'Type B - 5MWp'!H$43*'Type B - 5MWp'!$B$16+'Type C - 3MWp'!H$43*'Type C - 3MWp'!$B$16 -> 795471.43 | I10: ='Type A - 10MWp'!I$43*'Type A - 10MWp'!$B$16+'Type B - 5MWp'!I$43*'Type B - 5MWp'!$B$16+'Type C - 3MWp'!I$43*'Type C - 3MWp'!$B$16 -> 788209.36 | J10: ='Type A - 10MWp'!J$43*'Type A - 10MWp'!$B$16+'Type B - 5MWp'!J$43*'Type B - 5MWp'!$B$16+'Type C - 3MWp'!J$43*'Type C - 3MWp'!$B$16 -> 781456.09 | ... V10: ='Type A - 10MWp'!V$43*'Type A - 10MWp'!$B$16+'Type B - 5MWp'!V$43*'Type B - 5MWp'!$B$16+'Type C - 3MWp'!V$43*'Type C - 3MWp'!$B$16 -> 668324.9 | W10: =SUM(C$10:V$10) -> 15498166
